<mujoco model="SN003_MSK">
  <compiler inertiafromgeom="auto" angle="radian" balanceinertia="true" boundmass="0.001" boundinertia="0.001">
    <lengthrange inttotal="50" useexisting="true" />
  </compiler>
  <default>
    <joint limited="true" damping="0.5" armature="0.1" stiffness="2" />
    <geom rgba="0.8 0.6 .4 1" margin="0.001" />
    <site size="0.001" />
    <tendon width="0.001" rgba=".95 .3 .3 1" limited="false" />
    <default class="muscle">
      <muscle ctrllimited="true" ctrlrange="0 1" scale="200" />
    </default>
    <default class="motor">
      <general gainprm="5 0 0 0 0 0 0 0 0 0" />
    </default>
  </default>
  <option timestep="0.002" />
  <worldbody>
    <geom name="floor" pos="0 0 0" size="10 10 0.125" type="plane" material="MatPlane" condim="3" />
    <body name="pelvis" pos="       0        0        0" quat="0.7071067811865475 0.7071067811865475 0.0 0.0">
      <light mode="trackcom" directional="false" pos="0 0 4.0" dir="0 0 -1" />
      <geom name="r_pelvis" type="mesh" mesh="r_pelvis" />
      <geom name="l_pelvis" type="mesh" mesh="l_pelvis" />
      <geom name="sacrum" type="mesh" mesh="sacrum" />
      <inertial pos="-0.0858408        0        0" mass="9.22313073257496" fullinertia="0.0869916 0.0869916 0.0668453        0        0        0" />
      <site name="addbrev_r-P1" pos="-0.0231904 -0.114131 0.0148211" />
      <site name="addlong_r-P1" pos="-0.0092033 -0.107938 0.0181703" />
      <site name="addmagDist_r-P1" pos="-0.089896 -0.155011 0.0383231" />
      <site name="addmagIsch_r-P1" pos="-0.108813 -0.157549 0.0401421" />
      <site name="addmagMid_r-P1" pos="-0.0639374 -0.146609 0.0274671" />
      <site name="addmagProx_r-P1" pos="-0.0376145 -0.130582 0.0131369" />
      <site name="bflh_r-P1" pos="-0.126272 -0.144606 0.0563971" />
      <site name="glmax1_r-P1" pos="-0.149462 0.0418883 0.0541836" />
      <site name="glmax1_r-P2" pos="-0.152619 -0.0293826 0.0749716" />
      <site name="glmax2_r-P1" pos="-0.159904 0.0105631 0.0444633" />
      <site name="glmax2_r-P2" pos="-0.163182 -0.073942 0.0782438" />
      <site name="glmax3_r-P1" pos="-0.15784 -0.0637431 0.00866168" />
      <site name="glmax3_r-P2" pos="-0.154562 -0.153348 0.0418648" />
      <site name="glmed1_r-P1" pos="-0.0540299 0.0297468 0.112794" />
      <site name="glmed2_r-P1" pos="-0.103203 0.0383673 0.0649626" />
      <site name="glmed3_r-P1" pos="-0.139871 -0.00886333 0.0506227" />
      <site name="glmin1_r-P1" pos="-0.0563368 -0.0180909 0.100283" />
      <site name="glmin2_r-P1" pos="-0.074792 -0.017241 0.0934499" />
      <site name="glmin3_r-P1" pos="-0.0957968 -0.0188194 0.0768002" />
      <site name="grac_r-P1" pos="-0.0575024 -0.157015 0.0236368" />
      <site name="iliacus_r-P1" pos="-0.0734564 0.0375174 0.0811311" />
      <site name="iliacus_r-P2" pos="-0.0163911 -0.0676284 0.0727581" />
      <site name="piri_r-P1" pos="-0.123613 -0.00792843 0.0130021" />
      <site name="piri_r-P2" pos="-0.123868 -0.037226 0.0586299" />
      <site name="psoas_r-P1" pos="-0.0735778 0.0752776 0.0375339" />
      <site name="psoas_r-P2" pos="-0.0248902 -0.0794057 0.063134" />
      <site name="recfem_r-P1" pos="-0.0291397 -0.0471092 0.0897927" />
      <site name="sart_r-P1" pos="-0.023676 -0.0189408 0.10163" />
      <site name="semimem_r-P1" pos="-0.119837 -0.138414 0.0590919" />
      <site name="semiten_r-P1" pos="-0.126029 -0.152134 0.049564" />
      <site name="tfl_r-P1" pos="-0.0377602 0.0259829 0.119435" />
      <site name="addbrev_l-P1" pos="-0.0231904 -0.114131 -0.0148211" />
      <site name="addlong_l-P1" pos="-0.0092033 -0.107938 -0.0181703" />
      <site name="addmagDist_l-P1" pos="-0.089896 -0.155011 -0.0383231" />
      <site name="addmagIsch_l-P1" pos="-0.108813 -0.157549 -0.0401421" />
      <site name="addmagMid_l-P1" pos="-0.0639374 -0.146609 -0.0274671" />
      <site name="addmagProx_l-P1" pos="-0.0376145 -0.130582 -0.0131369" />
      <site name="bflh_l-P1" pos="-0.126272 -0.144606 -0.0563971" />
      <site name="glmax1_l-P1" pos="-0.149462 0.0418883 -0.0541836" />
      <site name="glmax1_l-P2" pos="-0.152619 -0.0293826 -0.0749716" />
      <site name="glmax2_l-P1" pos="-0.159904 0.0105631 -0.0444633" />
      <site name="glmax2_l-P2" pos="-0.163182 -0.073942 -0.0782438" />
      <site name="glmax3_l-P1" pos="-0.15784 -0.0637431 -0.00866168" />
      <site name="glmax3_l-P2" pos="-0.154562 -0.153348 -0.0418648" />
      <site name="glmed1_l-P1" pos="-0.0540299 0.0297468 -0.112794" />
      <site name="glmed2_l-P1" pos="-0.103203 0.0383673 -0.0649626" />
      <site name="glmed3_l-P1" pos="-0.139871 -0.00886333 -0.0506227" />
      <site name="glmin1_l-P1" pos="-0.0563368 -0.0180909 -0.100283" />
      <site name="glmin2_l-P1" pos="-0.074792 -0.017241 -0.0934499" />
      <site name="glmin3_l-P1" pos="-0.0957968 -0.0188194 -0.0768002" />
      <site name="grac_l-P1" pos="-0.0575024 -0.157015 -0.0236368" />
      <site name="iliacus_l-P1" pos="-0.0734564 0.0375174 -0.0811311" />
      <site name="iliacus_l-P2" pos="-0.0163911 -0.0676284 -0.0727581" />
      <site name="piri_l-P1" pos="-0.123613 -0.00792843 -0.0130021" />
      <site name="piri_l-P2" pos="-0.123868 -0.037226 -0.0586299" />
      <site name="psoas_l-P1" pos="-0.0735778 0.0752776 -0.0375339" />
      <site name="psoas_l-P2" pos="-0.0248902 -0.0794057 -0.063134" />
      <site name="recfem_l-P1" pos="-0.0291397 -0.0471092 -0.0897927" />
      <site name="sart_l-P1" pos="-0.023676 -0.0189408 -0.10163" />
      <site name="semimem_l-P1" pos="-0.119837 -0.138414 -0.0590919" />
      <site name="semiten_l-P1" pos="-0.126029 -0.152134 -0.049564" />
      <site name="tfl_l-P1" pos="-0.0377602 0.0259829 -0.119435" />
      <joint name="pelvis_tz" type="slide" pos="0 0 0" axis="       0        0        1" limited="false" range="      -3        3" ref="0" armature="0" damping="0" stiffness="0" />
      <joint name="pelvis_ty" type="slide" pos="0 0 0" axis="       0        1        0" limited="false" range="      -1        2" ref="0" armature="0" damping="0" stiffness="0" />
      <joint name="pelvis_tx" type="slide" pos="0 0 0" axis="       1        0        0" limited="false" range="      -5        5" ref="0" armature="0" damping="0" stiffness="0" />
      <joint name="pelvis_tilt" type="hinge" pos="0 0 0" axis="       0        0        1" limited="false" range=" -1.5708   1.5708" ref="0" armature="0" damping="0" stiffness="0" />
      <joint name="pelvis_list" type="hinge" pos="0 0 0" axis="       1        0        0" limited="false" range=" -1.5708   1.5708" ref="0" armature="0" damping="0" stiffness="0" />
      <joint name="pelvis_rotation" type="hinge" pos="0 0 0" axis="       0        1        0" limited="false" range=" -1.5708   1.5708" ref="0" armature="0" damping="0" stiffness="0" />
      <body name="femur_r" pos="-0.0683278 -0.095299 0.0743557" quat="1.0 0.0 0.0 0.0">
        <geom name="r_femur" type="mesh" mesh="r_femur" />
        <inertial pos="       0 -0.146299        0" mass="7.28437022976758" fullinertia="0.0776624 0.0203581 0.0818965        0        0        0" />
        <site name="addbrev_r-P2" pos="-0.00172117 -0.101549 0.0214285" />
        <site name="addlong_r-P2" pos="0.00969018 -0.205998 0.013623" />
        <site name="addmagDist_r-P2" pos="0.00968157 -0.225903 0.0166093" />
        <site name="addmagIsch_r-P2" pos="0.00413941 -0.333881 -0.0281669" />
        <site name="addmagMid_r-P2" pos="0.00208261 -0.139759 0.0251463" />
        <site name="addmagProx_r-P2" pos="-0.0131411 -0.0678657 0.0275559" />
        <site name="bfsh_r-P1" pos="0.00430292 -0.181669 0.0201377" />
        <site name="gaslat_r-P1" pos="-0.00258175 -0.328227 0.0238382" />
        <site name="gasmed_r-P1" pos="0.00688467 -0.325989 -0.0179002" />
        <site name="glmax1_r-P3" pos="-0.0382099 -0.028055 0.0259896" />
        <site name="glmax1_r-P4" pos="-0.0238382 -0.0487091 0.0404475" />
        <site name="glmax2_r-P3" pos="-0.0387263 -0.0502581 0.0216867" />
        <site name="glmax2_r-P4" pos="-0.0134251 -0.0874354 0.0360585" />
        <site name="glmax3_r-P3" pos="-0.0241824 -0.0968157 0.00808949" />
        <site name="glmax3_r-P4" pos="-0.0051635 -0.122117 0.03537" />
        <site name="glmed1_r-P2" pos="-0.0187607 -0.0100688 0.0477624" />
        <site name="glmed2_r-P2" pos="-0.0222031 -0.00499139 0.0453528" />
        <site name="glmed3_r-P2" pos="-0.0265921 -0.00404475 0.0445783" />
        <site name="glmin1_r-P2" pos="-0.00619621 -0.00895008 0.0481927" />
        <site name="glmin2_r-P2" pos="-0.00826161 -0.00895008 0.0481927" />
        <site name="glmin3_r-P2" pos="-0.0116179 -0.00714285 0.0473321" />
        <site name="iliacus_r-P3" pos="-0.00197934 -0.048623 0.0119621" />
        <site name="iliacus_r-P4" pos="-0.0104991 -0.0548192 0.0168674" />
        <site name="piri_r-P3" pos="-0.0127366 -0.0030981 0.0376075" />
        <site name="psoas_r-P3" pos="-0.0113597 -0.0401893 0.00395869" />
        <site name="psoas_r-P4" pos="-0.0202237 -0.0450946 0.00757314" />
        <site name="sart_r-P2" pos="-0.00258175 -0.307056 -0.0362306" />
        <site name="tfl_r-P2" pos="0.0253012 -0.0856281 0.0513769" />
        <site name="tfl_r-P3" pos="0.00920825 -0.348537 0.0278829" />
        <site name="vasint_r-P1" pos="0.0249569 -0.165576 0.0266781" />
        <site name="vasint_r-P2" pos="0.0288296 -0.179346 0.0245266" />
        <site name="vaslat_r-P1" pos="0.0041308 -0.159552 0.0300344" />
        <site name="vaslat_r-P2" pos="0.0231497 -0.222977 0.0351979" />
        <site name="vasmed_r-P1" pos="0.0120482 -0.180637 0.016179" />
        <site name="vasmed_r-P2" pos="0.0306368 -0.238296 0.000774526" />
        <joint name="hip_flexion_r" type="hinge" pos="0 0 0" axis="       0        0        1" limited="false" range="-0.523599   2.0944" ref="0" />
        <joint name="hip_adduction_r" type="hinge" pos="0 0 0" axis="       1        0        0" limited="false" range="-0.872665 0.523599" ref="0" />
        <joint name="hip_rotation_r" type="hinge" pos="0 0 0" axis="       0        1        0" limited="false" range="-0.698132 0.698132" ref="0" />
        <body name="tibia_r" pos="0.00119137 -0.347521 -0.000870127" quat="1.0 7.240636975890137e-18 -9.456205735995121e-17 -2.960068750797159e-20">
          <geom name="r_tibia" type="mesh" mesh="r_tibia" />
          <geom name="r_fibula" type="mesh" mesh="r_fibula" />
          <inertial pos="       0 -0.188176        0" mass="2.90352018264598" fullinertia="0.0400973 0.00405746 0.0406542        0        0        0" />
          <site name="bflh_r-P2" pos="-0.0339664 -0.0352767 0.0255" />
          <site name="bflh_r-P3" pos="-0.0289269 -0.0458597 0.0305396" />
          <site name="bfsh_r-P2" pos="-0.030338 -0.0422313 0.0320514" />
          <site name="edl_r-P1" pos="-0.0161265 -0.116615 0.0206621" />
          <site name="edl_r-P2" pos="0.0165297 -0.378973 0.0112886" />
          <site name="ehl_r-P1" pos="-0.0141107 -0.156226 0.0190494" />
          <site name="ehl_r-P2" pos="0.00715614 -0.2932 0.0165297" />
          <site name="ehl_r-P3" pos="0.0201581 -0.37222 -0.00282214" />
          <site name="fdl_r-P1" pos="-0.00231818 -0.184648 -0.00181423" />
          <site name="fdl_r-P2" pos="-0.0177392 -0.367382 -0.012498" />
          <site name="fhl_r-P1" pos="-0.0312451 -0.21801 0.0201581" />
          <site name="fhl_r-P2" pos="-0.0243913 -0.370002 -0.00766009" />
          <site name="grac_r-P2" pos="-0.0185656 -0.047926 -0.0298441" />
          <site name="grac_r-P3" pos="0.00179407 -0.0701704 -0.0158544" />
          <site name="perbrev_r-P1" pos="-0.0244921 -0.255202 0.0252985" />
          <site name="perbrev_r-P2" pos="-0.034168 -0.392378 0.0250969" />
          <site name="perbrev_r-P3" pos="-0.0287253 -0.403566 0.0257016" />
          <site name="perlong_r-P1" pos="-0.0201581 -0.138386 0.028423" />
          <site name="perlong_r-P2" pos="-0.0319506 -0.393084 0.0238874" />
          <site name="perlong_r-P3" pos="-0.0274151 -0.404574 0.0241898" />
          <site name="recfem_r-P5" pos="0.0328578 -0.0636191 -0.000473716" />
          <site name="sart_r-P3" pos="-0.0252985 -0.040417 -0.0367886" />
          <site name="sart_r-P4" pos="-0.0160257 -0.0603736 -0.0266087" />
          <site name="sart_r-P5" pos="0.0137075 -0.0816404 -0.00262056" />
          <site name="semimem_r-P2" pos="-0.0292293 -0.0420297 -0.019755" />
          <site name="semiten_r-P2" pos="-0.0314467 -0.0512016 -0.0230811" />
          <site name="semiten_r-P3" pos="0.00191502 -0.0779112 -0.0117925" />
          <site name="soleus_r-P1" pos="-0.00766009 -0.0923242 0.00987748" />
          <site name="tfl_r-P4" pos="0.0108854 -0.0413242 0.0348736" />
          <site name="tibant_r-P1" pos="0.0155218 -0.132237 0.0163281" />
          <site name="tibant_r-P2" pos="0.0252985 -0.192107 0.0129012" />
          <site name="tibant_r-P3" pos="0.0234842 -0.368793 -0.0133044" />
          <site name="tibpost_r-P1" pos="-0.00413242 -0.131431 0.0103814" />
          <site name="tibpost_r-P2" pos="-0.0165297 -0.36839 -0.0176384" />
          <site name="vasint_r-P5" pos="0.0328275 -0.0636997 0.0004334" />
          <site name="vaslat_r-P5" pos="0.0327973 -0.0638811 0.0051504" />
          <site name="vasmed_r-P5" pos="0.0321522 -0.0640726 -0.00683361" />
          <joint name="knee_angle_r_translation2" type="slide" pos="0 0 0" axis="0.992246 0.123982 -0.00878916" limited="true" range="7.69254e-11 0.006792" ref="0" />
          <joint name="knee_angle_r_translation1" type="slide" pos="0 0 0" axis="-0.124293 0.989762 -0.0701648" limited="true" range="9.53733e-08 0.00159883" ref="0" />
          <joint name="knee_angle_r" type="hinge" pos="0 0 0" axis="-3.98373e-10 -0.0707131 -0.997497" limited="false" range="       0   2.0944" ref="0" />
          <joint name="knee_angle_r_rotation2" type="hinge" pos="0 0 0" axis="0.992246 0.123982 -0.00878916" limited="true" range="-0.00167821 0.0335354" ref="0" />
          <joint name="knee_angle_r_rotation3" type="hinge" pos="0 0 0" axis="-0.124293 0.989762 -0.0701648" limited="true" range="1.08939e-08 0.262788" ref="0" />
          <body name="talus_r" pos="-0.0100791 -0.403163        0" quat="1.0 -6.036754011562992e-18 1.5193252867388614e-18 -2.498419531737724e-19">
            <geom name="r_talus" type="mesh" mesh="r_talus" />
            <inertial pos="       0        0        0" mass="0.0783147722898443" fullinertia="0.00050902 0.00050902 0.00050902        0        0        0" />
            <joint name="ankle_angle_r" type="hinge" pos="0 0 0" axis="-0.105014 -0.174022 0.979126" limited="false" range="-0.698132 0.523599" ref="0" />
            <body name="calcn_r" pos="-0.0393186 -0.0338203 0.00638514" quat="1.0 -5.320429553087796e-19 1.609289071159989e-17 -2.1848634538867752e-17">
              <geom name="r_foot" type="mesh" mesh="r_foot" />
              <inertial pos="0.0806205 0.0241862        0" mass="0.978934653623054" fullinertia="0.000712628 0.00198518 0.00208698        0        0        0" />
              <site name="edl_r-P3" pos="0.0740903 0.0290234 0.000644964" />
              <site name="edl_r-P4" pos="0.130283 0.00443413 0.0104807" />
              <site name="ehl_r-P4" pos="0.0782019 0.0313614 -0.0170109" />
              <site name="ehl_r-P5" pos="0.104242 0.0249117 -0.0207195" />
              <site name="ehl_r-P6" pos="0.139796 0.0112063 -0.0225737" />
              <site name="fdl_r-P3" pos="0.0351505 0.0253955 -0.0225737" />
              <site name="fdl_r-P4" pos="0.0570793 0.0141892 -0.0212032" />
              <site name="fdl_r-P5" pos="0.133669 -0.00653026 0.00935198" />
              <site name="fhl_r-P3" pos="0.0301521 0.0222513 -0.0194295" />
              <site name="fhl_r-P4" pos="0.0836841 0.0054822 -0.0206389" />
              <site name="fhl_r-P5" pos="0.139151 -0.00427289 -0.0216869" />
              <site name="gaslat_r-P2" pos="0.0035473 0.0249924 -0.00427289" />
              <site name="gasmed_r-P2" pos="0.0035473 0.0249924 -0.00427289" />
              <site name="perbrev_r-P4" pos="0.0379723 0.0217675 0.0187846" />
              <site name="perbrev_r-P5" pos="0.0545801 0.0176559 0.0276528" />
              <site name="perlong_r-P4" pos="0.0353118 0.0185427 0.0178171" />
              <site name="perlong_r-P5" pos="0.0549026 0.00854577 0.0228962" />
              <site name="perlong_r-P6" pos="0.0686887 0.00556282 0.00951322" />
              <site name="perlong_r-P7" pos="0.0969865 0.00685274 -0.0148342" />
              <site name="soleus_r-P2" pos="0.0035473 0.0249924 -0.00427289" />
              <site name="tibant_r-P4" pos="0.0940035 0.0143505 -0.0245893" />
              <site name="tibpost_r-P3" pos="0.0336188 0.0269273 -0.0230575" />
              <site name="tibpost_r-P4" pos="0.062239 0.0128187 -0.0226544" />
              <joint name="subtalar_angle_r" type="hinge" pos="0 0 0" axis=" 0.78718 0.604747 -0.120949" limited="false" range="-0.349066 0.349066" ref="0" />
              <body name="toes_r" pos="0.144149 -0.00161241 0.000870702" quat="1.0 1.314867274624753e-31 -2.6810890689525335e-17 -3.939849802505862e-32">
                <geom name="r_bofoot" type="mesh" mesh="r_bofoot" />
                <inertial pos="0.0278947 0.00483723 -0.0141086" mass="0.169629796779803" fullinertia="5.0902e-05 0.000101804 0.00050902        0        0        0" />
                <site name="edl_r-P5" pos="0.000241862 0.00378916 0.0123349" />
                <site name="edl_r-P6" pos="0.0357149 -0.000322482 0.0201551" />
                <site name="ehl_r-P7" pos="0.0240249 0.00330544 -0.019752" />
                <site name="ehl_r-P8" pos="0.0453894 0.0027411 -0.0149954" />
                <site name="fdl_r-P6" pos="-0.00153179 -0.0062884 0.0118512" />
                <site name="fdl_r-P7" pos="0.0229768 -0.00572406 0.0173334" />
                <site name="fdl_r-P8" pos="0.0355536 -0.00483723 0.0195102" />
                <site name="fhl_r-P6" pos="0.0124962 -0.00515971 -0.0213644" />
                <site name="fhl_r-P7" pos="0.0453087 -0.00822329 -0.0145923" />
                <joint name="mtp_angle_r" type="hinge" pos="0 0 0" axis="0.580954 2.6299e-15 -0.813936" limited="false" range="-0.523599 0.523599" ref="0" />
              </body>
            </body>
          </body>
        </body>
        <body name="patella_r" pos="-0.00696213 -0.351084 0.000383394" quat="1.0 0.0 0.0 0.0">
          <geom name="r_patella" type="mesh" mesh="r_patella" />
          <inertial pos="  0.0018   0.0264        0" mass="0.0675073337138458" fullinertia="2.24763e-06 1.02671e-05 1.02671e-05        0        0        0" />
          <site name="recfem_r-P2" pos="0.01 0.049 0.0007" />
          <site name="recfem_r-P3" pos="0.0121 0.0437 -0.001" />
          <site name="recfem_r-P4" pos="0.005 0.00247 3e-005" />
          <site name="vasint_r-P3" pos="0.0058 0.048 -0.0006" />
          <site name="vasint_r-P4" pos="0.005 0.00247 -0.00039" />
          <site name="vaslat_r-P3" pos="0.0103 0.0423 0.0141" />
          <site name="vaslat_r-P4" pos="0.005 0.00247 0.00733" />
          <site name="vasmed_r-P3" pos="0.0063 0.0445 -0.017" />
          <site name="vasmed_r-P4" pos="0.005 0.00247 -0.0085" />
          <joint name="knee_angle_r_beta_translation2" type="slide" pos="0 0 0" axis="       0        1        0" limited="true" range="-0.0408267 -0.0108281" ref="0" />
          <joint name="knee_angle_r_beta_translation1" type="slide" pos="0 0 0" axis="       1        0        0" limited="true" range="-0.0227731 0.0524192" ref="0" />
          <joint name="knee_angle_r_beta_rotation1" type="hinge" pos="0 0 0" axis="       0        0        1" limited="true" range="-1.79241 0.010506" ref="0" />
        </body>
      </body>
      <body name="femur_l" pos="-0.0683278 -0.095299 -0.0743557" quat="1.0 0.0 0.0 0.0">
        <geom name="l_femur" type="mesh" mesh="l_femur" />
        <inertial pos="       0 -0.147638        0" mass="7.28437022976758" fullinertia="0.0790901 0.0207323 0.0834019        0        0        0" />
        <site name="addbrev_l-P2" pos="-0.00173692 -0.102478 -0.0216246" />
        <site name="addlong_l-P2" pos="0.00977884 -0.207883 -0.0137477" />
        <site name="addmagDist_l-P2" pos="0.00977015 -0.22797 -0.0167612" />
        <site name="addmagIsch_l-P2" pos="0.00417728 -0.336936 0.0284246" />
        <site name="addmagMid_l-P2" pos="0.00210167 -0.141038 -0.0253763" />
        <site name="addmagProx_l-P2" pos="-0.0132614 -0.0684866 -0.027808" />
        <site name="bfsh_l-P1" pos="0.00434229 -0.183331 -0.0203219" />
        <site name="gaslat_l-P1" pos="-0.00260537 -0.33123 -0.0240563" />
        <site name="gasmed_l-P1" pos="0.00694766 -0.328972 0.0180639" />
        <site name="glmax1_l-P3" pos="-0.0385595 -0.0283117 -0.0262274" />
        <site name="glmax1_l-P4" pos="-0.0240563 -0.0491547 -0.0408175" />
        <site name="glmax2_l-P3" pos="-0.0390806 -0.050718 -0.0218851" />
        <site name="glmax2_l-P4" pos="-0.0135479 -0.0882353 -0.0363884" />
        <site name="glmax3_l-P3" pos="-0.0244037 -0.0977015 -0.00816351" />
        <site name="glmax3_l-P4" pos="-0.00521075 -0.123234 -0.0356936" />
        <site name="glmed1_l-P2" pos="-0.0189324 -0.010161 -0.0481994" />
        <site name="glmed2_l-P2" pos="-0.0224062 -0.00503706 -0.0457677" />
        <site name="glmed3_l-P2" pos="-0.0268354 -0.00408175 -0.0449861" />
        <site name="glmin1_l-P2" pos="-0.0062529 -0.00903196 -0.0486337" />
        <site name="glmin2_l-P2" pos="-0.0083372 -0.00903196 -0.0486337" />
        <site name="glmin3_l-P2" pos="-0.0117242 -0.0072082 -0.0477652" />
        <site name="iliacus_l-P3" pos="-0.00199745 -0.0490679 -0.0120716" />
        <site name="iliacus_l-P4" pos="-0.0105952 -0.0553208 -0.0170218" />
        <site name="piri_l-P3" pos="-0.0128532 -0.00312645 -0.0379516" />
        <site name="psoas_l-P3" pos="-0.0114636 -0.040557 -0.00399491" />
        <site name="psoas_l-P4" pos="-0.0204088 -0.0455072 -0.00764243" />
        <site name="sart_l-P2" pos="-0.00260537 -0.309866 0.0365621" />
        <site name="tfl_l-P2" pos="0.0255327 -0.0864116 -0.0518469" />
        <site name="tfl_l-P3" pos="0.0092925 -0.351726 -0.028138" />
        <site name="vasint_l-P1" pos="0.0251853 -0.167091 -0.0269222" />
        <site name="vasint_l-P2" pos="0.0290933 -0.180987 -0.0247511" />
        <site name="vaslat_l-P1" pos="0.0041686 -0.161012 -0.0303092" />
        <site name="vaslat_l-P2" pos="0.0233615 -0.225017 -0.0355199" />
        <site name="vasmed_l-P1" pos="0.0121584 -0.182289 -0.016327" />
        <site name="vasmed_l-P2" pos="0.0309171 -0.240476 -0.000781612" />
        <joint name="hip_flexion_l" type="hinge" pos="0 0 0" axis="       0        0        1" limited="false" range="-0.523599   2.0944" ref="0" />
        <joint name="hip_adduction_l" type="hinge" pos="0 0 0" axis="      -1       -0       -0" limited="false" range="-0.872665 0.523599" ref="0" />
        <joint name="hip_rotation_l" type="hinge" pos="0 0 0" axis="      -0       -1       -0" limited="false" range="-0.698132 0.698132" ref="0" />
        <body name="tibia_l" pos="0.00101861 -0.350781 0.000911798" quat="1.0 -7.240636975890137e-18 9.456205735995121e-17 -2.960068750797159e-20">
          <geom name="l_tibia" type="mesh" mesh="l_tibia" />
          <geom name="l_fibula" type="mesh" mesh="l_fibula" />
          <inertial pos="       0 -0.185659        0" mass="2.90352018264598" fullinertia="0.0390317 0.00394964 0.0395738        0        0        0" />
          <site name="bflh_l-P2" pos="-0.0335121 -0.0348049 -0.0251589" />
          <site name="bflh_l-P3" pos="-0.02854 -0.0452463 -0.0301311" />
          <site name="bfsh_l-P2" pos="-0.0299322 -0.0416664 -0.0316227" />
          <site name="edl_l-P1" pos="-0.0159108 -0.115055 -0.0203857" />
          <site name="edl_l-P2" pos="0.0163086 -0.373904 -0.0111376" />
          <site name="ehl_l-P1" pos="-0.0139219 -0.154136 -0.0187946" />
          <site name="ehl_l-P2" pos="0.00706041 -0.289278 -0.0163086" />
          <site name="ehl_l-P3" pos="0.0198885 -0.367241 0.00278439" />
          <site name="fdl_l-P1" pos="-0.00228718 -0.182179 0.00178996" />
          <site name="fdl_l-P2" pos="-0.0175019 -0.362468 0.0123309" />
          <site name="fhl_l-P1" pos="-0.0308272 -0.215094 -0.0198885" />
          <site name="fhl_l-P2" pos="-0.0240651 -0.365053 0.00755763" />
          <site name="grac_l-P2" pos="-0.0183173 -0.0472849 0.0294449" />
          <site name="grac_l-P3" pos="0.00177008 -0.0692318 0.0156423" />
          <site name="perbrev_l-P1" pos="-0.0241645 -0.251788 -0.0249601" />
          <site name="perbrev_l-P2" pos="-0.033711 -0.387129 -0.0247612" />
          <site name="perbrev_l-P3" pos="-0.0283411 -0.398168 -0.0253578" />
          <site name="perlong_l-P1" pos="-0.0198885 -0.136534 -0.0280428" />
          <site name="perlong_l-P2" pos="-0.0315233 -0.387826 -0.0235679" />
          <site name="perlong_l-P3" pos="-0.0270483 -0.399162 -0.0238662" />
          <site name="recfem_l-P5" pos="0.0324182 -0.0627681 0.000467379" />
          <site name="sart_l-P3" pos="-0.0249601 -0.0398764 0.0362965" />
          <site name="sart_l-P4" pos="-0.0158113 -0.059566 0.0262528" />
          <site name="sart_l-P5" pos="0.0135242 -0.0805484 0.0025855" />
          <site name="semimem_l-P2" pos="-0.0288383 -0.0414675 0.0194907" />
          <site name="semiten_l-P2" pos="-0.031026 -0.0505168 0.0227723" />
          <site name="semiten_l-P3" pos="0.00188941 -0.076869 0.0116348" />
          <site name="soleus_l-P1" pos="-0.00755763 -0.0910893 -0.00974536" />
          <site name="tfl_l-P4" pos="0.0107398 -0.0407714 -0.0344071" />
          <site name="tibant_l-P1" pos="0.0153141 -0.130468 -0.0161097" />
          <site name="tibant_l-P2" pos="0.0249601 -0.189537 -0.0127286" />
          <site name="tibant_l-P3" pos="0.0231701 -0.36386 0.0131264" />
          <site name="tibpost_l-P1" pos="-0.00407714 -0.129673 -0.0102426" />
          <site name="tibpost_l-P2" pos="-0.0163086 -0.363462 0.0174024" />
          <site name="vasint_l-P5" pos="0.0323884 -0.0628476 -0.000427603" />
          <site name="vaslat_l-P5" pos="0.0323586 -0.0630266 -0.00508151" />
          <site name="vasmed_l-P5" pos="0.0317221 -0.0632156 0.0067422" />
          <joint name="knee_angle_l_translation2" type="slide" pos="0 0 0" axis="-0.992246 -0.123982 -0.00878916" limited="true" range="-0.006792 -7.69254e-11" ref="0" />
          <joint name="knee_angle_l_translation1" type="slide" pos="0 0 0" axis="-0.124293 0.989762 0.0701648" limited="true" range="9.53733e-08 0.00159883" ref="0" />
          <joint name="knee_angle_l" type="hinge" pos="0 0 0" axis="3.98373e-10 0.0707131 -0.997497" limited="false" range="       0   2.0944" ref="0" />
          <joint name="knee_angle_l_rotation2" type="hinge" pos="0 0 0" axis="-0.992246 -0.123982 -0.00878916" limited="true" range="-0.00167821 0.0335354" ref="0" />
          <joint name="knee_angle_l_rotation3" type="hinge" pos="0 0 0" axis="-0.124293 0.989762 0.0701648" limited="true" range="-0.262788 -1.08939e-08" ref="0" />
          <body name="talus_l" pos="-0.00994424 -0.39777        0" quat="1.0 6.036754011562992e-18 -1.5193252867388614e-18 -2.498419531737724e-19">
            <geom name="l_talus" type="mesh" mesh="l_talus" />
            <inertial pos="       0        0        0" mass="0.0783147722898443" fullinertia="0.000508819 0.000508819 0.000508819        0        0        0" />
            <joint name="ankle_angle_l" type="hinge" pos="0 0 0" axis="0.105014 0.174022 0.979126" limited="false" range="-0.698132 0.523599" ref="0" />
            <body name="calcn_l" pos="-0.0393109 -0.0338136 -0.00638388" quat="1.0 5.320429553087796e-19 -1.609289071159989e-17 -2.1848634538867752e-17">
              <geom name="l_foot" type="mesh" mesh="l_foot" />
              <inertial pos="0.0806046 0.0241814        0" mass="0.978934653623054" fullinertia="0.000712347 0.00198439 0.00208616        0        0        0" />
              <site name="edl_l-P3" pos="0.0740756 0.0290177 -0.000644837" />
              <site name="edl_l-P4" pos="0.130257 0.00443325 -0.0104786" />
              <site name="ehl_l-P4" pos="0.0781865 0.0313552 0.0170076" />
              <site name="ehl_l-P5" pos="0.104222 0.0249068 0.0207154" />
              <site name="ehl_l-P6" pos="0.139768 0.011204 0.0225693" />
              <site name="fdl_l-P3" pos="0.0351436 0.0253904 0.0225693" />
              <site name="fdl_l-P4" pos="0.0570681 0.0141864 0.021199" />
              <site name="fdl_l-P5" pos="0.133642 -0.00652897 -0.00935013" />
              <site name="fhl_l-P3" pos="0.0301461 0.0222469 0.0194257" />
              <site name="fhl_l-P4" pos="0.0836676 0.00548111 0.0206348" />
              <site name="fhl_l-P5" pos="0.139124 -0.00427204 0.0216826" />
              <site name="gaslat_l-P2" pos="0.0035466 0.0249874 0.00427204" />
              <site name="gasmed_l-P2" pos="0.0035466 0.0249874 0.00427204" />
              <site name="perbrev_l-P4" pos="0.0379648 0.0217632 -0.0187809" />
              <site name="perbrev_l-P5" pos="0.0545693 0.0176524 -0.0276474" />
              <site name="perlong_l-P4" pos="0.0353048 0.0185391 -0.0178136" />
              <site name="perlong_l-P5" pos="0.0548917 0.00854409 -0.0228917" />
              <site name="perlong_l-P6" pos="0.0686751 0.00556172 -0.00951134" />
              <site name="perlong_l-P7" pos="0.0969673 0.00685139 0.0148312" />
              <site name="soleus_l-P2" pos="0.0035466 0.0249874 0.00427204" />
              <site name="tibant_l-P4" pos="0.093985 0.0143476 0.0245844" />
              <site name="tibpost_l-P3" pos="0.0336121 0.0269219 0.0230529" />
              <site name="tibpost_l-P4" pos="0.0622267 0.0128161 0.0226499" />
              <joint name="subtalar_angle_l" type="hinge" pos="0 0 0" axis="-0.78718 -0.604747 -0.120949" limited="false" range="-0.349066 0.349066" ref="0" />
              <body name="toes_l" pos="0.144121 -0.00161209 -0.00087053" quat="1.0 1.314867274624753e-31 2.6810890689525335e-17 3.939849802505862e-32">
                <geom name="l_bofoot" type="mesh" mesh="l_bofoot" />
                <inertial pos="0.0278892 0.00483628 0.0141058" mass="0.169629796779803" fullinertia="5.08819e-05 0.000101764 0.000508819        0        0        0" />
                <site name="edl_l-P5" pos="0.000241814 0.00378842 -0.0123325" />
                <site name="edl_l-P6" pos="0.0357078 -0.000322418 -0.0201511" />
                <site name="ehl_l-P7" pos="0.0240202 0.00330479 0.0197481" />
                <site name="ehl_l-P8" pos="0.0453804 0.00274056 0.0149925" />
                <site name="fdl_l-P6" pos="-0.00153149 -0.00628716 -0.0118489" />
                <site name="fdl_l-P7" pos="0.0229723 -0.00572293 -0.01733" />
                <site name="fdl_l-P8" pos="0.0355466 -0.00483628 -0.0195063" />
                <site name="fhl_l-P6" pos="0.0124937 -0.00515869 0.0213602" />
                <site name="fhl_l-P7" pos="0.0452998 -0.00822167 0.0145894" />
                <joint name="mtp_angle_l" type="hinge" pos="0 0 0" axis="-0.580954 2.6299e-15 -0.813936" limited="false" range="-0.523599 0.523599" ref="0" />
              </body>
            </body>
          </body>
        </body>
        <body name="patella_l" pos="-0.00702583 -0.354296 -0.00036174" quat="1.0 0.0 0.0 0.0">
          <geom name="l_patella" type="mesh" mesh="l_patella" />
          <inertial pos="  0.0018   0.0264        0" mass="0.0675073337138458" fullinertia="2.24763e-06 1.02671e-05 1.02671e-05        0        0        0" />
          <site name="recfem_l-P2" pos="0.01 0.049 -0.0007" />
          <site name="recfem_l-P3" pos="0.0121 0.0437 0.001" />
          <site name="recfem_l-P4" pos="0.005 0.00247 -3e-005" />
          <site name="vasint_l-P3" pos="0.0058 0.048 0.0006" />
          <site name="vasint_l-P4" pos="0.005 0.00247 0.00039" />
          <site name="vaslat_l-P3" pos="0.0103 0.0423 -0.0141" />
          <site name="vaslat_l-P4" pos="0.005 0.00247 -0.00733" />
          <site name="vasmed_l-P3" pos="0.0063 0.0445 0.017" />
          <site name="vasmed_l-P4" pos="0.005 0.00247 0.0085" />
          <joint name="knee_angle_l_beta_translation2" type="slide" pos="0 0 0" axis="       0        1        0" limited="true" range="-0.0408267 -0.0108281" ref="0" />
          <joint name="knee_angle_l_beta_translation1" type="slide" pos="0 0 0" axis="       1        0        0" limited="true" range="-0.0227731 0.0524192" ref="0" />
          <joint name="knee_angle_l_beta_rotation1" type="hinge" pos="0 0 0" axis="       0        0        1" limited="true" range="-1.79241 0.010506" ref="0" />
        </body>
      </body>
      <body name="torso" pos="-0.122265 0.0989536        0" quat="1.0 0.0 0.0 0.0">
        <geom name="hat_spine" type="mesh" mesh="hat_spine" />
        <geom name="hat_jaw" type="mesh" mesh="hat_jaw" />
        <geom name="hat_skull" type="mesh" mesh="hat_skull" />
        <geom name="hat_ribs_scap" type="mesh" mesh="hat_ribs_scap" />
        <inertial pos="-0.0286062 0.305133        0" mass="21.0091907031074" fullinertia=" 1.04995 0.537969  1.01926        0        0        0" />
        <joint name="lumbar_extension" type="hinge" pos="0 0 0" axis="       0        0        1" limited="false" range=" -1.5708   1.5708" ref="0" />
        <joint name="lumbar_bending" type="hinge" pos="0 0 0" axis="       1        0        0" limited="false" range=" -1.5708   1.5708" ref="0" />
        <joint name="lumbar_rotation" type="hinge" pos="0 0 0" axis="       0        1        0" limited="false" range=" -1.5708   1.5708" ref="0" />
        <body name="humerus_r" pos="0.00300842  0.35424 0.162102" quat="1.0 0.0 0.0 0.0">
          <geom name="humerus_rv" type="mesh" mesh="humerus_rv" />
          <inertial pos="       0 -0.155224        0" mass="1.59174774679109" fullinertia="0.00832992 0.00287357 0.00935007        0        0        0" />
          <joint name="arm_flex_r" type="hinge" pos="0 0 0" axis="       0        0        1" limited="false" range=" -1.5708   1.5708" ref="0" />
          <joint name="arm_add_r" type="hinge" pos="0 0 0" axis="       1        0        0" limited="false" range=" -2.0944   1.5708" ref="0" />
          <joint name="arm_rot_r" type="hinge" pos="0 0 0" axis="       0        1        0" limited="false" range=" -1.5708   1.5708" ref="0" />
          <body name="ulna_r" pos="0.0124027 -0.270127 -0.00905383" quat="1.0 1.6893809785063376e-18 -6.938893903907228e-18 4.155190089080778e-20">
            <geom name="ulna_rv" type="mesh" mesh="ulna_rv" />
            <inertial pos="       0 -0.124358        0" mass="0.475762241660804" fullinertia="0.00246956 0.000515256 0.00267883        0        0        0" />
            <joint name="elbow_flex_r" type="hinge" pos="0 0 0" axis="0.226047 0.022269 0.973862" limited="false" range="       0    2.618" ref="0" />
            <body name="radius_r" pos="-0.00694092 -0.0134206 0.0269124" quat="1.0 2.301201592641875e-21 -6.933378131686372e-19 1.7489241099837954e-19">
              <geom name="radius_rv" type="mesh" mesh="radius_rv" />
              <inertial pos="       0 -0.123771        0" mass="0.475762241660804" fullinertia="0.00244633 0.000510408 0.00265363        0        0        0" />
              <joint name="pro_sup_r" type="hinge" pos="0 0 0" axis="0.056398 0.998406 0.001952" limited="false" range="       0   1.5708" ref="0" />
              <body name="hand_r" pos="-0.00903394 -0.242193 0.0139766" quat="1.0 0.0 8.407790785948892e-45 0.0">
                <geom name="pisiform_rvs" type="mesh" mesh="pisiform_rvs" />
                <geom name="lunate_rvs" type="mesh" mesh="lunate_rvs" />
                <geom name="scaphoid_rvs" type="mesh" mesh="scaphoid_rvs" />
                <geom name="triquetrum_rvs" type="mesh" mesh="triquetrum_rvs" />
                <geom name="hamate_rvs" type="mesh" mesh="hamate_rvs" />
                <geom name="capitate_rvs" type="mesh" mesh="capitate_rvs" />
                <geom name="trapezoid_rvs" type="mesh" mesh="trapezoid_rvs" />
                <geom name="trapezium_rvs" type="mesh" mesh="trapezium_rvs" />
                <geom name="metacarpal2_rvs" type="mesh" mesh="metacarpal2_rvs" />
                <geom name="index_proximal_rvs" type="mesh" mesh="index_proximal_rvs" />
                <geom name="index_medial_rvs" type="mesh" mesh="index_medial_rvs" />
                <geom name="index_distal_rvs" type="mesh" mesh="index_distal_rvs" />
                <geom name="metacarpal3_rvs" type="mesh" mesh="metacarpal3_rvs" />
                <geom name="middle_proximal_rvs" type="mesh" mesh="middle_proximal_rvs" />
                <geom name="middle_medial_rvs" type="mesh" mesh="middle_medial_rvs" />
                <geom name="middle_distal_rvs" type="mesh" mesh="middle_distal_rvs" />
                <geom name="metacarpal4_rvs" type="mesh" mesh="metacarpal4_rvs" />
                <geom name="ring_proximal_rvs" type="mesh" mesh="ring_proximal_rvs" />
                <geom name="ring_medial_rvs" type="mesh" mesh="ring_medial_rvs" />
                <geom name="ring_distal_rvs" type="mesh" mesh="ring_distal_rvs" />
                <geom name="metacarpal5_rvs" type="mesh" mesh="metacarpal5_rvs" />
                <geom name="little_proximal_rvs" type="mesh" mesh="little_proximal_rvs" />
                <geom name="little_medial_rvs" type="mesh" mesh="little_medial_rvs" />
                <geom name="little_distal_rvs" type="mesh" mesh="little_distal_rvs" />
                <geom name="metacarpal1_rvs" type="mesh" mesh="metacarpal1_rvs" />
                <geom name="thumb_proximal_rvs" type="mesh" mesh="thumb_proximal_rvs" />
                <geom name="thumb_distal_rvs" type="mesh" mesh="thumb_distal_rvs" />
                <inertial pos="       0 -0.068095        0" mass="0.358290083226038" fullinertia="0.000698568 0.000428382 0.00104942        0        0        0" />
                <joint name="wrist_flex_r" type="hinge" pos="0 0 0" axis="-3.55271e-15 3.55271e-15        1" limited="false" range="-1.22173  1.22173" ref="0" />
                <joint name="wrist_dev_r" type="hinge" pos="0 0 0" axis="       1        0 3.55271e-15" limited="false" range="-0.436332 0.610865" ref="0" />
              </body>
            </body>
          </body>
        </body>
        <body name="humerus_l" pos="0.00300842  0.35424 -0.162102" quat="1.0 0.0 0.0 0.0">
          <geom name="humerus_lv" type="mesh" mesh="humerus_lv" />
          <inertial pos="       0 -0.151629        0" mass="1.59174774679109" fullinertia="0.00794858 0.00274202 0.00892203        0        0        0" />
          <joint name="arm_flex_l" type="hinge" pos="0 0 0" axis="       0        0        1" limited="false" range=" -1.5708   1.5708" ref="0" />
          <joint name="arm_add_l" type="hinge" pos="0 0 0" axis="      -1        0        0" limited="false" range=" -2.0944   1.5708" ref="0" />
          <joint name="arm_rot_l" type="hinge" pos="0 0 0" axis="       0       -1        0" limited="false" range=" -1.5708   1.5708" ref="0" />
          <body name="ulna_l" pos="0.0121154 -0.263871 0.00884416" quat="1.0 -1.6893809785063376e-18 6.938893903907228e-18 4.155190089080778e-20">
            <geom name="ulna_lv" type="mesh" mesh="ulna_lv" />
            <inertial pos="       0 -0.121942        0" mass="0.475762241660804" fullinertia="0.00237456 0.000495435 0.00257578        0        0        0" />
            <joint name="elbow_flex_l" type="hinge" pos="0 0 0" axis="-0.226047 -0.022269 0.973862" limited="false" range="       0    2.618" ref="0" />
            <body name="radius_l" pos="-0.00680611 -0.01316 -0.0263897" quat="1.0 -2.301201592641875e-21 6.933378131686372e-19 1.7489241099837954e-19">
              <geom name="radius_lv" type="mesh" mesh="radius_lv" />
              <inertial pos="       0 -0.119756        0" mass="0.475762241660804" fullinertia="0.00229017 0.000477827 0.00248424        0        0        0" />
              <joint name="pro_sup_l" type="hinge" pos="0 0 0" axis="-0.056398 -0.998406 0.001952" limited="false" range="       0   1.5708" ref="0" />
              <body name="hand_l" pos="-0.00874086 -0.234336 -0.0135231" quat="1.0 0.0 8.407790785948892e-45 0.0">
                <geom name="pisiform_lvs" type="mesh" mesh="pisiform_lvs" />
                <geom name="lunate_lvs" type="mesh" mesh="lunate_lvs" />
                <geom name="scaphoid_lvs" type="mesh" mesh="scaphoid_lvs" />
                <geom name="triquetrum_lvs" type="mesh" mesh="triquetrum_lvs" />
                <geom name="hamate_lvs" type="mesh" mesh="hamate_lvs" />
                <geom name="capitate_lvs" type="mesh" mesh="capitate_lvs" />
                <geom name="trapezoid_lvs" type="mesh" mesh="trapezoid_lvs" />
                <geom name="trapezium_lvs" type="mesh" mesh="trapezium_lvs" />
                <geom name="metacarpal2_lvs" type="mesh" mesh="metacarpal2_lvs" />
                <geom name="index_proximal_lvs" type="mesh" mesh="index_proximal_lvs" />
                <geom name="index_medial_lvs" type="mesh" mesh="index_medial_lvs" />
                <geom name="index_distal_lvs" type="mesh" mesh="index_distal_lvs" />
                <geom name="metacarpal3_lvs" type="mesh" mesh="metacarpal3_lvs" />
                <geom name="middle_proximal_lvs" type="mesh" mesh="middle_proximal_lvs" />
                <geom name="middle_medial_lvs" type="mesh" mesh="middle_medial_lvs" />
                <geom name="middle_distal_lvs" type="mesh" mesh="middle_distal_lvs" />
                <geom name="metacarpal4_lvs" type="mesh" mesh="metacarpal4_lvs" />
                <geom name="ring_proximal_lvs" type="mesh" mesh="ring_proximal_lvs" />
                <geom name="ring_medial_lvs" type="mesh" mesh="ring_medial_lvs" />
                <geom name="ring_distal_lvs" type="mesh" mesh="ring_distal_lvs" />
                <geom name="metacarpal5_lvs" type="mesh" mesh="metacarpal5_lvs" />
                <geom name="little_proximal_lvs" type="mesh" mesh="little_proximal_lvs" />
                <geom name="little_medial_lvs" type="mesh" mesh="little_medial_lvs" />
                <geom name="little_distal_lvs" type="mesh" mesh="little_distal_lvs" />
                <geom name="metacarpal1_lvs" type="mesh" mesh="metacarpal1_lvs" />
                <geom name="thumb_proximal_lvs" type="mesh" mesh="thumb_proximal_lvs" />
                <geom name="thumb_distal_lvs" type="mesh" mesh="thumb_distal_lvs" />
                <inertial pos="       0 -0.068095        0" mass="0.358290083226038" fullinertia="0.000698568 0.000428382 0.00104942        0        0        0" />
                <joint name="wrist_flex_l" type="hinge" pos="0 0 0" axis="-3.55271e-15 -3.55271e-15        1" limited="false" range="-1.22173  1.22173" ref="0" />
                <joint name="wrist_dev_l" type="hinge" pos="0 0 0" axis="      -1        0 -3.55271e-15" limited="false" range="-0.436332 0.610865" ref="0" />
              </body>
            </body>
          </body>
        </body>
      </body>
    </body>
    <camera name="for_testing" pos="0 0 0" euler="0 0 0" />
  </worldbody>
  <asset>
    <mesh name="r_pelvis" file="Geometry/r_pelvis.stl" scale=" 1.21416  1.21416 0.962409" />
    <mesh name="l_pelvis" file="Geometry/l_pelvis.stl" scale=" 1.21416  1.21416 0.962409" />
    <mesh name="sacrum" file="Geometry/sacrum.stl" scale=" 1.21416  1.21416 0.962409" />
    <mesh name="r_femur" file="Geometry/r_femur.stl" scale="0.860584 0.860584 0.860584" />
    <mesh name="r_tibia" file="Geometry/r_tibia.stl" scale=" 1.00791  1.00791  1.00791" />
    <mesh name="r_fibula" file="Geometry/r_fibula.stl" scale=" 1.00791  1.00791  1.00791" />
    <mesh name="r_talus" file="Geometry/r_talus.stl" scale="0.806205 0.806205 0.806205" />
    <mesh name="r_foot" file="Geometry/r_foot.stl" scale="0.806205 0.806205 0.806205" />
    <mesh name="r_bofoot" file="Geometry/r_bofoot.stl" scale="0.806205 0.806205 0.806205" />
    <mesh name="r_patella" file="Geometry/r_patella.stl" scale="       1        1        1" />
    <mesh name="l_femur" file="Geometry/l_femur.stl" scale="0.868458 0.868458 0.868458" />
    <mesh name="l_tibia" file="Geometry/l_tibia.stl" scale="0.994424 0.994424 0.994424" />
    <mesh name="l_fibula" file="Geometry/l_fibula.stl" scale="0.994424 0.994424 0.994424" />
    <mesh name="l_talus" file="Geometry/l_talus.stl" scale="0.806046 0.806046 0.806046" />
    <mesh name="l_foot" file="Geometry/l_foot.stl" scale="0.806046 0.806046 0.806046" />
    <mesh name="l_bofoot" file="Geometry/l_bofoot.stl" scale="0.806046 0.806046 0.806046" />
    <mesh name="l_patella" file="Geometry/l_patella.stl" scale="       1        1        1" />
    <mesh name="hat_spine" file="Geometry/hat_spine.stl" scale="0.953541 0.953541 0.953541" />
    <mesh name="hat_jaw" file="Geometry/hat_jaw.stl" scale="0.953541 0.953541 0.953541" />
    <mesh name="hat_skull" file="Geometry/hat_skull.stl" scale="0.953541 0.953541 0.953541" />
    <mesh name="hat_ribs_scap" file="Geometry/hat_ribs_scap.stl" scale="0.953541 0.953541 0.953541" />
    <mesh name="humerus_rv" file="Geometry/humerus_rv.stl" scale="0.943599 0.943599 0.943599" />
    <mesh name="ulna_rv" file="Geometry/ulna_rv.stl" scale="  1.0318   1.0318   1.0318" />
    <mesh name="radius_rv" file="Geometry/radius_rv.stl" scale=" 1.02693  1.02693  1.02693" />
    <mesh name="pisiform_rvs" file="Geometry/pisiform_rvs.stl" scale="    0.85     0.85     0.85" />
    <mesh name="lunate_rvs" file="Geometry/lunate_rvs.stl" scale="    0.85     0.85     0.85" />
    <mesh name="scaphoid_rvs" file="Geometry/scaphoid_rvs.stl" scale="    0.85     0.85     0.85" />
    <mesh name="triquetrum_rvs" file="Geometry/triquetrum_rvs.stl" scale="    0.85     0.85     0.85" />
    <mesh name="hamate_rvs" file="Geometry/hamate_rvs.stl" scale="    0.85     0.85     0.85" />
    <mesh name="capitate_rvs" file="Geometry/capitate_rvs.stl" scale="    0.85     0.85     0.85" />
    <mesh name="trapezoid_rvs" file="Geometry/trapezoid_rvs.stl" scale="    0.85     0.85     0.85" />
    <mesh name="trapezium_rvs" file="Geometry/trapezium_rvs.stl" scale="    0.85     0.85     0.85" />
    <mesh name="metacarpal2_rvs" file="Geometry/metacarpal2_rvs.stl" scale="    0.85     0.85     0.85" />
    <mesh name="index_proximal_rvs" file="Geometry/index_proximal_rvs.stl" scale="    0.85     0.85     0.85" />
    <mesh name="index_medial_rvs" file="Geometry/index_medial_rvs.stl" scale="    0.85     0.85     0.85" />
    <mesh name="index_distal_rvs" file="Geometry/index_distal_rvs.stl" scale="    0.85     0.85     0.85" />
    <mesh name="metacarpal3_rvs" file="Geometry/metacarpal3_rvs.stl" scale="    0.85     0.85     0.85" />
    <mesh name="middle_proximal_rvs" file="Geometry/middle_proximal_rvs.stl" scale="    0.85     0.85     0.85" />
    <mesh name="middle_medial_rvs" file="Geometry/middle_medial_rvs.stl" scale="    0.85     0.85     0.85" />
    <mesh name="middle_distal_rvs" file="Geometry/middle_distal_rvs.stl" scale="    0.85     0.85     0.85" />
    <mesh name="metacarpal4_rvs" file="Geometry/metacarpal4_rvs.stl" scale="    0.85     0.85     0.85" />
    <mesh name="ring_proximal_rvs" file="Geometry/ring_proximal_rvs.stl" scale="    0.85     0.85     0.85" />
    <mesh name="ring_medial_rvs" file="Geometry/ring_medial_rvs.stl" scale="    0.85     0.85     0.85" />
    <mesh name="ring_distal_rvs" file="Geometry/ring_distal_rvs.stl" scale="    0.85     0.85     0.85" />
    <mesh name="metacarpal5_rvs" file="Geometry/metacarpal5_rvs.stl" scale="    0.85     0.85     0.85" />
    <mesh name="little_proximal_rvs" file="Geometry/little_proximal_rvs.stl" scale="    0.85     0.85     0.85" />
    <mesh name="little_medial_rvs" file="Geometry/little_medial_rvs.stl" scale="    0.85     0.85     0.85" />
    <mesh name="little_distal_rvs" file="Geometry/little_distal_rvs.stl" scale="    0.85     0.85     0.85" />
    <mesh name="metacarpal1_rvs" file="Geometry/metacarpal1_rvs.stl" scale="    0.85     0.85     0.85" />
    <mesh name="thumb_proximal_rvs" file="Geometry/thumb_proximal_rvs.stl" scale="    0.85     0.85     0.85" />
    <mesh name="thumb_distal_rvs" file="Geometry/thumb_distal_rvs.stl" scale="    0.85     0.85     0.85" />
    <mesh name="humerus_lv" file="Geometry/humerus_lv.stl" scale="0.921747 0.921747 0.921747" />
    <mesh name="ulna_lv" file="Geometry/ulna_lv.stl" scale=" 1.01176  1.01176  1.01176" />
    <mesh name="radius_lv" file="Geometry/radius_lv.stl" scale="0.993618 0.993618 0.993618" />
    <mesh name="pisiform_lvs" file="Geometry/pisiform_lvs.stl" scale="    0.85     0.85     0.85" />
    <mesh name="lunate_lvs" file="Geometry/lunate_lvs.stl" scale="    0.85     0.85     0.85" />
    <mesh name="scaphoid_lvs" file="Geometry/scaphoid_lvs.stl" scale="    0.85     0.85     0.85" />
    <mesh name="triquetrum_lvs" file="Geometry/triquetrum_lvs.stl" scale="    0.85     0.85     0.85" />
    <mesh name="hamate_lvs" file="Geometry/hamate_lvs.stl" scale="    0.85     0.85     0.85" />
    <mesh name="capitate_lvs" file="Geometry/capitate_lvs.stl" scale="    0.85     0.85     0.85" />
    <mesh name="trapezoid_lvs" file="Geometry/trapezoid_lvs.stl" scale="    0.85     0.85     0.85" />
    <mesh name="trapezium_lvs" file="Geometry/trapezium_lvs.stl" scale="    0.85     0.85     0.85" />
    <mesh name="metacarpal2_lvs" file="Geometry/metacarpal2_lvs.stl" scale="    0.85     0.85     0.85" />
    <mesh name="index_proximal_lvs" file="Geometry/index_proximal_lvs.stl" scale="    0.85     0.85     0.85" />
    <mesh name="index_medial_lvs" file="Geometry/index_medial_lvs.stl" scale="    0.85     0.85     0.85" />
    <mesh name="index_distal_lvs" file="Geometry/index_distal_lvs.stl" scale="    0.85     0.85     0.85" />
    <mesh name="metacarpal3_lvs" file="Geometry/metacarpal3_lvs.stl" scale="    0.85     0.85     0.85" />
    <mesh name="middle_proximal_lvs" file="Geometry/middle_proximal_lvs.stl" scale="    0.85     0.85     0.85" />
    <mesh name="middle_medial_lvs" file="Geometry/middle_medial_lvs.stl" scale="    0.85     0.85     0.85" />
    <mesh name="middle_distal_lvs" file="Geometry/middle_distal_lvs.stl" scale="    0.85     0.85     0.85" />
    <mesh name="metacarpal4_lvs" file="Geometry/metacarpal4_lvs.stl" scale="    0.85     0.85     0.85" />
    <mesh name="ring_proximal_lvs" file="Geometry/ring_proximal_lvs.stl" scale="    0.85     0.85     0.85" />
    <mesh name="ring_medial_lvs" file="Geometry/ring_medial_lvs.stl" scale="    0.85     0.85     0.85" />
    <mesh name="ring_distal_lvs" file="Geometry/ring_distal_lvs.stl" scale="    0.85     0.85     0.85" />
    <mesh name="metacarpal5_lvs" file="Geometry/metacarpal5_lvs.stl" scale="    0.85     0.85     0.85" />
    <mesh name="little_proximal_lvs" file="Geometry/little_proximal_lvs.stl" scale="    0.85     0.85     0.85" />
    <mesh name="little_medial_lvs" file="Geometry/little_medial_lvs.stl" scale="    0.85     0.85     0.85" />
    <mesh name="little_distal_lvs" file="Geometry/little_distal_lvs.stl" scale="    0.85     0.85     0.85" />
    <mesh name="metacarpal1_lvs" file="Geometry/metacarpal1_lvs.stl" scale="    0.85     0.85     0.85" />
    <mesh name="thumb_proximal_lvs" file="Geometry/thumb_proximal_lvs.stl" scale="    0.85     0.85     0.85" />
    <mesh name="thumb_distal_lvs" file="Geometry/thumb_distal_lvs.stl" scale="    0.85     0.85     0.85" />
    <texture name="texplane" type="2d" builtin="checker" rgb1=".2 .3 .4" rgb2=".1 0.15 0.2" width="100" height="100" />
    <material name="MatPlane" reflectance="0.0" texture="texplane" texrepeat="1 1" texuniform="true" />
  </asset>
  <tendon>
    <spatial name="addbrev_r_tendon">
      <site site="addbrev_r-P1" />
      <site site="addbrev_r-P2" />
    </spatial>
    <spatial name="addlong_r_tendon">
      <site site="addlong_r-P1" />
      <site site="addlong_r-P2" />
    </spatial>
    <spatial name="addmagDist_r_tendon">
      <site site="addmagDist_r-P1" />
      <site site="addmagDist_r-P2" />
    </spatial>
    <spatial name="addmagIsch_r_tendon">
      <site site="addmagIsch_r-P1" />
      <site site="addmagIsch_r-P2" />
    </spatial>
    <spatial name="addmagMid_r_tendon">
      <site site="addmagMid_r-P1" />
      <site site="addmagMid_r-P2" />
    </spatial>
    <spatial name="addmagProx_r_tendon">
      <site site="addmagProx_r-P1" />
      <site site="addmagProx_r-P2" />
    </spatial>
    <spatial name="bflh_r_tendon">
      <site site="bflh_r-P1" />
      <site site="bflh_r-P2" />
      <site site="bflh_r-P3" />
    </spatial>
    <spatial name="bfsh_r_tendon">
      <site site="bfsh_r-P1" />
      <site site="bfsh_r-P2" />
    </spatial>
    <spatial name="edl_r_tendon">
      <site site="edl_r-P1" />
      <site site="edl_r-P2" />
      <site site="edl_r-P3" />
      <site site="edl_r-P4" />
      <site site="edl_r-P5" />
      <site site="edl_r-P6" />
    </spatial>
    <spatial name="ehl_r_tendon">
      <site site="ehl_r-P1" />
      <site site="ehl_r-P2" />
      <site site="ehl_r-P3" />
      <site site="ehl_r-P4" />
      <site site="ehl_r-P5" />
      <site site="ehl_r-P6" />
      <site site="ehl_r-P7" />
      <site site="ehl_r-P8" />
    </spatial>
    <spatial name="fdl_r_tendon">
      <site site="fdl_r-P1" />
      <site site="fdl_r-P2" />
      <site site="fdl_r-P3" />
      <site site="fdl_r-P4" />
      <site site="fdl_r-P5" />
      <site site="fdl_r-P6" />
      <site site="fdl_r-P7" />
      <site site="fdl_r-P8" />
    </spatial>
    <spatial name="fhl_r_tendon">
      <site site="fhl_r-P1" />
      <site site="fhl_r-P2" />
      <site site="fhl_r-P3" />
      <site site="fhl_r-P4" />
      <site site="fhl_r-P5" />
      <site site="fhl_r-P6" />
      <site site="fhl_r-P7" />
    </spatial>
    <spatial name="gaslat_r_tendon">
      <site site="gaslat_r-P1" />
      <site site="gaslat_r-P2" />
    </spatial>
    <spatial name="gasmed_r_tendon">
      <site site="gasmed_r-P1" />
      <site site="gasmed_r-P2" />
    </spatial>
    <spatial name="glmax1_r_tendon">
      <site site="glmax1_r-P1" />
      <site site="glmax1_r-P2" />
      <site site="glmax1_r-P3" />
      <site site="glmax1_r-P4" />
    </spatial>
    <spatial name="glmax2_r_tendon">
      <site site="glmax2_r-P1" />
      <site site="glmax2_r-P2" />
      <site site="glmax2_r-P3" />
      <site site="glmax2_r-P4" />
    </spatial>
    <spatial name="glmax3_r_tendon">
      <site site="glmax3_r-P1" />
      <site site="glmax3_r-P2" />
      <site site="glmax3_r-P3" />
      <site site="glmax3_r-P4" />
    </spatial>
    <spatial name="glmed1_r_tendon">
      <site site="glmed1_r-P1" />
      <site site="glmed1_r-P2" />
    </spatial>
    <spatial name="glmed2_r_tendon">
      <site site="glmed2_r-P1" />
      <site site="glmed2_r-P2" />
    </spatial>
    <spatial name="glmed3_r_tendon">
      <site site="glmed3_r-P1" />
      <site site="glmed3_r-P2" />
    </spatial>
    <spatial name="glmin1_r_tendon">
      <site site="glmin1_r-P1" />
      <site site="glmin1_r-P2" />
    </spatial>
    <spatial name="glmin2_r_tendon">
      <site site="glmin2_r-P1" />
      <site site="glmin2_r-P2" />
    </spatial>
    <spatial name="glmin3_r_tendon">
      <site site="glmin3_r-P1" />
      <site site="glmin3_r-P2" />
    </spatial>
    <spatial name="grac_r_tendon">
      <site site="grac_r-P1" />
      <site site="grac_r-P2" />
      <site site="grac_r-P3" />
    </spatial>
    <spatial name="iliacus_r_tendon">
      <site site="iliacus_r-P1" />
      <site site="iliacus_r-P2" />
      <site site="iliacus_r-P3" />
      <site site="iliacus_r-P4" />
    </spatial>
    <spatial name="perbrev_r_tendon">
      <site site="perbrev_r-P1" />
      <site site="perbrev_r-P2" />
      <site site="perbrev_r-P3" />
      <site site="perbrev_r-P4" />
      <site site="perbrev_r-P5" />
    </spatial>
    <spatial name="perlong_r_tendon">
      <site site="perlong_r-P1" />
      <site site="perlong_r-P2" />
      <site site="perlong_r-P3" />
      <site site="perlong_r-P4" />
      <site site="perlong_r-P5" />
      <site site="perlong_r-P6" />
      <site site="perlong_r-P7" />
    </spatial>
    <spatial name="piri_r_tendon">
      <site site="piri_r-P1" />
      <site site="piri_r-P2" />
      <site site="piri_r-P3" />
    </spatial>
    <spatial name="psoas_r_tendon">
      <site site="psoas_r-P1" />
      <site site="psoas_r-P2" />
      <site site="psoas_r-P3" />
      <site site="psoas_r-P4" />
    </spatial>
    <spatial name="recfem_r_tendon">
      <site site="recfem_r-P1" />
      <site site="recfem_r-P2" />
      <site site="recfem_r-P3" />
      <site site="recfem_r-P4" />
      <site site="recfem_r-P5" />
    </spatial>
    <spatial name="sart_r_tendon">
      <site site="sart_r-P1" />
      <site site="sart_r-P2" />
      <site site="sart_r-P3" />
      <site site="sart_r-P4" />
      <site site="sart_r-P5" />
    </spatial>
    <spatial name="semimem_r_tendon">
      <site site="semimem_r-P1" />
      <site site="semimem_r-P2" />
    </spatial>
    <spatial name="semiten_r_tendon">
      <site site="semiten_r-P1" />
      <site site="semiten_r-P2" />
      <site site="semiten_r-P3" />
    </spatial>
    <spatial name="soleus_r_tendon">
      <site site="soleus_r-P1" />
      <site site="soleus_r-P2" />
    </spatial>
    <spatial name="tfl_r_tendon">
      <site site="tfl_r-P1" />
      <site site="tfl_r-P2" />
      <site site="tfl_r-P3" />
      <site site="tfl_r-P4" />
    </spatial>
    <spatial name="tibant_r_tendon">
      <site site="tibant_r-P1" />
      <site site="tibant_r-P2" />
      <site site="tibant_r-P3" />
      <site site="tibant_r-P4" />
    </spatial>
    <spatial name="tibpost_r_tendon">
      <site site="tibpost_r-P1" />
      <site site="tibpost_r-P2" />
      <site site="tibpost_r-P3" />
      <site site="tibpost_r-P4" />
    </spatial>
    <spatial name="vasint_r_tendon">
      <site site="vasint_r-P1" />
      <site site="vasint_r-P2" />
      <site site="vasint_r-P3" />
      <site site="vasint_r-P4" />
      <site site="vasint_r-P5" />
    </spatial>
    <spatial name="vaslat_r_tendon">
      <site site="vaslat_r-P1" />
      <site site="vaslat_r-P2" />
      <site site="vaslat_r-P3" />
      <site site="vaslat_r-P4" />
      <site site="vaslat_r-P5" />
    </spatial>
    <spatial name="vasmed_r_tendon">
      <site site="vasmed_r-P1" />
      <site site="vasmed_r-P2" />
      <site site="vasmed_r-P3" />
      <site site="vasmed_r-P4" />
      <site site="vasmed_r-P5" />
    </spatial>
    <spatial name="addbrev_l_tendon">
      <site site="addbrev_l-P1" />
      <site site="addbrev_l-P2" />
    </spatial>
    <spatial name="addlong_l_tendon">
      <site site="addlong_l-P1" />
      <site site="addlong_l-P2" />
    </spatial>
    <spatial name="addmagDist_l_tendon">
      <site site="addmagDist_l-P1" />
      <site site="addmagDist_l-P2" />
    </spatial>
    <spatial name="addmagIsch_l_tendon">
      <site site="addmagIsch_l-P1" />
      <site site="addmagIsch_l-P2" />
    </spatial>
    <spatial name="addmagMid_l_tendon">
      <site site="addmagMid_l-P1" />
      <site site="addmagMid_l-P2" />
    </spatial>
    <spatial name="addmagProx_l_tendon">
      <site site="addmagProx_l-P1" />
      <site site="addmagProx_l-P2" />
    </spatial>
    <spatial name="bflh_l_tendon">
      <site site="bflh_l-P1" />
      <site site="bflh_l-P2" />
      <site site="bflh_l-P3" />
    </spatial>
    <spatial name="bfsh_l_tendon">
      <site site="bfsh_l-P1" />
      <site site="bfsh_l-P2" />
    </spatial>
    <spatial name="edl_l_tendon">
      <site site="edl_l-P1" />
      <site site="edl_l-P2" />
      <site site="edl_l-P3" />
      <site site="edl_l-P4" />
      <site site="edl_l-P5" />
      <site site="edl_l-P6" />
    </spatial>
    <spatial name="ehl_l_tendon">
      <site site="ehl_l-P1" />
      <site site="ehl_l-P2" />
      <site site="ehl_l-P3" />
      <site site="ehl_l-P4" />
      <site site="ehl_l-P5" />
      <site site="ehl_l-P6" />
      <site site="ehl_l-P7" />
      <site site="ehl_l-P8" />
    </spatial>
    <spatial name="fdl_l_tendon">
      <site site="fdl_l-P1" />
      <site site="fdl_l-P2" />
      <site site="fdl_l-P3" />
      <site site="fdl_l-P4" />
      <site site="fdl_l-P5" />
      <site site="fdl_l-P6" />
      <site site="fdl_l-P7" />
      <site site="fdl_l-P8" />
    </spatial>
    <spatial name="fhl_l_tendon">
      <site site="fhl_l-P1" />
      <site site="fhl_l-P2" />
      <site site="fhl_l-P3" />
      <site site="fhl_l-P4" />
      <site site="fhl_l-P5" />
      <site site="fhl_l-P6" />
      <site site="fhl_l-P7" />
    </spatial>
    <spatial name="gaslat_l_tendon">
      <site site="gaslat_l-P1" />
      <site site="gaslat_l-P2" />
    </spatial>
    <spatial name="gasmed_l_tendon">
      <site site="gasmed_l-P1" />
      <site site="gasmed_l-P2" />
    </spatial>
    <spatial name="glmax1_l_tendon">
      <site site="glmax1_l-P1" />
      <site site="glmax1_l-P2" />
      <site site="glmax1_l-P3" />
      <site site="glmax1_l-P4" />
    </spatial>
    <spatial name="glmax2_l_tendon">
      <site site="glmax2_l-P1" />
      <site site="glmax2_l-P2" />
      <site site="glmax2_l-P3" />
      <site site="glmax2_l-P4" />
    </spatial>
    <spatial name="glmax3_l_tendon">
      <site site="glmax3_l-P1" />
      <site site="glmax3_l-P2" />
      <site site="glmax3_l-P3" />
      <site site="glmax3_l-P4" />
    </spatial>
    <spatial name="glmed1_l_tendon">
      <site site="glmed1_l-P1" />
      <site site="glmed1_l-P2" />
    </spatial>
    <spatial name="glmed2_l_tendon">
      <site site="glmed2_l-P1" />
      <site site="glmed2_l-P2" />
    </spatial>
    <spatial name="glmed3_l_tendon">
      <site site="glmed3_l-P1" />
      <site site="glmed3_l-P2" />
    </spatial>
    <spatial name="glmin1_l_tendon">
      <site site="glmin1_l-P1" />
      <site site="glmin1_l-P2" />
    </spatial>
    <spatial name="glmin2_l_tendon">
      <site site="glmin2_l-P1" />
      <site site="glmin2_l-P2" />
    </spatial>
    <spatial name="glmin3_l_tendon">
      <site site="glmin3_l-P1" />
      <site site="glmin3_l-P2" />
    </spatial>
    <spatial name="grac_l_tendon">
      <site site="grac_l-P1" />
      <site site="grac_l-P2" />
      <site site="grac_l-P3" />
    </spatial>
    <spatial name="iliacus_l_tendon">
      <site site="iliacus_l-P1" />
      <site site="iliacus_l-P2" />
      <site site="iliacus_l-P3" />
      <site site="iliacus_l-P4" />
    </spatial>
    <spatial name="perbrev_l_tendon">
      <site site="perbrev_l-P1" />
      <site site="perbrev_l-P2" />
      <site site="perbrev_l-P3" />
      <site site="perbrev_l-P4" />
      <site site="perbrev_l-P5" />
    </spatial>
    <spatial name="perlong_l_tendon">
      <site site="perlong_l-P1" />
      <site site="perlong_l-P2" />
      <site site="perlong_l-P3" />
      <site site="perlong_l-P4" />
      <site site="perlong_l-P5" />
      <site site="perlong_l-P6" />
      <site site="perlong_l-P7" />
    </spatial>
    <spatial name="piri_l_tendon">
      <site site="piri_l-P1" />
      <site site="piri_l-P2" />
      <site site="piri_l-P3" />
    </spatial>
    <spatial name="psoas_l_tendon">
      <site site="psoas_l-P1" />
      <site site="psoas_l-P2" />
      <site site="psoas_l-P3" />
      <site site="psoas_l-P4" />
    </spatial>
    <spatial name="recfem_l_tendon">
      <site site="recfem_l-P1" />
      <site site="recfem_l-P2" />
      <site site="recfem_l-P3" />
      <site site="recfem_l-P4" />
      <site site="recfem_l-P5" />
    </spatial>
    <spatial name="sart_l_tendon">
      <site site="sart_l-P1" />
      <site site="sart_l-P2" />
      <site site="sart_l-P3" />
      <site site="sart_l-P4" />
      <site site="sart_l-P5" />
    </spatial>
    <spatial name="semimem_l_tendon">
      <site site="semimem_l-P1" />
      <site site="semimem_l-P2" />
    </spatial>
    <spatial name="semiten_l_tendon">
      <site site="semiten_l-P1" />
      <site site="semiten_l-P2" />
      <site site="semiten_l-P3" />
    </spatial>
    <spatial name="soleus_l_tendon">
      <site site="soleus_l-P1" />
      <site site="soleus_l-P2" />
    </spatial>
    <spatial name="tfl_l_tendon">
      <site site="tfl_l-P1" />
      <site site="tfl_l-P2" />
      <site site="tfl_l-P3" />
      <site site="tfl_l-P4" />
    </spatial>
    <spatial name="tibant_l_tendon">
      <site site="tibant_l-P1" />
      <site site="tibant_l-P2" />
      <site site="tibant_l-P3" />
      <site site="tibant_l-P4" />
    </spatial>
    <spatial name="tibpost_l_tendon">
      <site site="tibpost_l-P1" />
      <site site="tibpost_l-P2" />
      <site site="tibpost_l-P3" />
      <site site="tibpost_l-P4" />
    </spatial>
    <spatial name="vasint_l_tendon">
      <site site="vasint_l-P1" />
      <site site="vasint_l-P2" />
      <site site="vasint_l-P3" />
      <site site="vasint_l-P4" />
      <site site="vasint_l-P5" />
    </spatial>
    <spatial name="vaslat_l_tendon">
      <site site="vaslat_l-P1" />
      <site site="vaslat_l-P2" />
      <site site="vaslat_l-P3" />
      <site site="vaslat_l-P4" />
      <site site="vaslat_l-P5" />
    </spatial>
    <spatial name="vasmed_l_tendon">
      <site site="vasmed_l-P1" />
      <site site="vasmed_l-P2" />
      <site site="vasmed_l-P3" />
      <site site="vasmed_l-P4" />
      <site site="vasmed_l-P5" />
    </spatial>
  </tendon>
  <actuator>
    <general name="lumbar_ext" joint="lumbar_extension" class="motor" />
    <general name="lumbar_bend" joint="lumbar_bending" class="motor" />
    <general name="lumbar_rot" joint="lumbar_rotation" class="motor" />
    <general name="shoulder_flex_r" joint="arm_flex_r" class="motor" />
    <general name="shoulder_add_r" joint="arm_add_r" class="motor" />
    <general name="shoulder_rot_r" joint="arm_rot_r" class="motor" />
    <general name="elbow_flex_r" joint="elbow_flex_r" class="motor" />
    <general name="pro_sup_r" joint="pro_sup_r" class="motor" />
    <general name="wrist_flex_r" joint="wrist_flex_r" class="motor" />
    <general name="wrist_dev_r" joint="wrist_dev_r" class="motor" />
    <general name="shoulder_flex_l" joint="arm_flex_l" class="motor" />
    <general name="shoulder_add_l" joint="arm_add_l" class="motor" />
    <general name="shoulder_rot_l" joint="arm_rot_l" class="motor" />
    <general name="elbow_flex_l" joint="elbow_flex_l" class="motor" />
    <general name="pro_sup_l" joint="pro_sup_l" class="motor" />
    <general name="wrist_flex_l" joint="wrist_flex_l" class="motor" />
    <general name="wrist_dev_l" joint="wrist_dev_l" class="motor" />
    <muscle name="addbrev_r" tendon="addbrev_r_tendon" class="muscle" force="625.819672131148" lengthrange="0.0774679 0.169024" />
    <muscle name="addlong_r" tendon="addlong_r_tendon" class="muscle" force="916.8" lengthrange="0.161102 0.254237" />
    <muscle name="addmagDist_r" tendon="addmagDist_r_tendon" class="muscle" force="597.295081967214" lengthrange="0.138591  0.27682" />
    <muscle name="addmagIsch_r" tendon="addmagIsch_r_tendon" class="muscle" force="597.295081967214" lengthrange="0.238381 0.363527" />
    <muscle name="addmagMid_r" tendon="addmagMid_r_tendon" class="muscle" force="597.295081967214" lengthrange="0.090831 0.198193" />
    <muscle name="addmagProx_r" tendon="addmagProx_r_tendon" class="muscle" force="597.295081967214" lengthrange="0.0820852 0.173174" />
    <muscle name="bflh_r" tendon="bflh_r_tendon" class="muscle" force="1313.18360655738" lengthrange=" 0.31548 0.396696" />
    <muscle name="bfsh_r" tendon="bfsh_r_tendon" class="muscle" force="557.11475409836" lengthrange="0.141076 0.235514" />
    <muscle name="edl_r" tendon="edl_r_tendon" class="muscle" force="603.4981556" lengthrange="0.375885 0.439035" />
    <muscle name="ehl_r" tendon="ehl_r_tendon" class="muscle" force="285.8675474" lengthrange="0.335774 0.403534" />
    <muscle name="fdl_r" tendon="fdl_r_tendon" class="muscle" force="423.177049180328" lengthrange="0.364127 0.403654" />
    <muscle name="fhl_r" tendon="fhl_r_tendon" class="muscle" force="907.839344262294" lengthrange="0.341416 0.387219" />
    <muscle name="gaslat_r" tendon="gaslat_r_tendon" class="muscle" force="1575.05901639344" lengthrange="0.403057 0.460312" />
    <muscle name="gasmed_r" tendon="gasmed_r_tendon" class="muscle" force="3115.51475409836" lengthrange="0.420756 0.470689" />
    <muscle name="glmax1_r" tendon="glmax1_r_tendon" class="muscle" force="983.783606557378" lengthrange="0.129821 0.281798" />
    <muscle name="glmax2_r" tendon="glmax2_r_tendon" class="muscle" force="1406.04590163935" lengthrange="0.149477 0.304645" />
    <muscle name="glmax3_r" tendon="glmax3_r_tendon" class="muscle" force="947.754098360656" lengthrange="0.148648 0.305124" />
    <muscle name="glmed1_r" tendon="glmed1_r_tendon" class="muscle" force="1093.4667688" lengthrange="0.104697 0.184949" />
    <muscle name="glmed2_r" tendon="glmed2_r_tendon" class="muscle" force="765.0916616" lengthrange="0.113542  0.19236" />
    <muscle name="glmed3_r" tendon="glmed3_r_tendon" class="muscle" force="871.1992642" lengthrange="0.0875612 0.163568" />
    <muscle name="glmin1_r" tendon="glmin1_r_tendon" class="muscle" force="374.045901639344" lengthrange="0.0554329 0.130243" />
    <muscle name="glmin2_r" tendon="glmin2_r_tendon" class="muscle" force="394.819672131148" lengthrange="0.0597435 0.121586" />
    <muscle name="glmin3_r" tendon="glmin3_r_tendon" class="muscle" force="446.773770491804" lengthrange="0.0755564 0.116643" />
    <muscle name="grac_r" tendon="grac_r_tendon" class="muscle" force="281.311475409836" lengthrange="0.241028 0.431351" />
    <muscle name="iliacus_r" tendon="iliacus_r_tendon" class="muscle" force="1021.14098360656" lengthrange=" 0.16504 0.279794" />
    <muscle name="perbrev_r" tendon="perbrev_r_tendon" class="muscle" force="521.2015988" lengthrange="0.164925 0.208108" />
    <muscle name="perlong_r" tendon="perlong_r_tendon" class="muscle" force="1115.3714214" lengthrange=" 0.33838 0.385078" />
    <muscle name="piri_r" tendon="piri_r_tendon" class="muscle" force="1029.7868852459" lengthrange="0.134999 0.162065" />
    <muscle name="psoas_r" tendon="psoas_r_tendon" class="muscle" force="1426.79016393443" lengthrange="0.176267  0.30477" />
    <muscle name="recfem_r" tendon="recfem_r_tendon" class="muscle" force="2191.74098360656" lengthrange="0.437889 0.504732" />
    <muscle name="sart_r" tendon="sart_r_tendon" class="muscle" force="249.413114754098" lengthrange="0.301948 0.675739" />
    <muscle name="semimem_r" tendon="semimem_r_tendon" class="muscle" force="2200.9868852459" lengthrange="0.321962 0.378395" />
    <muscle name="semiten_r" tendon="semiten_r_tendon" class="muscle" force="591.295081967214" lengthrange=" 0.29157 0.451858" />
    <muscle name="soleus_r" tendon="soleus_r_tendon" class="muscle" force="6194.84262295082" lengthrange="0.296435 0.337171" />
    <muscle name="tfl_r" tendon="tfl_r_tendon" class="muscle" force="411.20655737705" lengthrange="0.465004 0.553779" />
    <muscle name="tibant_r" tendon="tibant_r_tendon" class="muscle" force="1227.45245901639" lengthrange="0.266401 0.331554" />
    <muscle name="tibpost_r" tendon="tibpost_r_tendon" class="muscle" force="1730.15409836065" lengthrange="0.292381 0.328377" />
    <muscle name="vasint_r" tendon="vasint_r_tendon" class="muscle" force="1697.36065573771" lengthrange="0.223373   0.3113" />
    <muscle name="vaslat_r" tendon="vaslat_r_tendon" class="muscle" force="5148.76721311476" lengthrange="0.238206 0.323516" />
    <muscle name="vasmed_r" tendon="vasmed_r_tendon" class="muscle" force="2747.82295081966" lengthrange="0.217451 0.296125" />
    <muscle name="addbrev_l" tendon="addbrev_l_tendon" class="muscle" force="625.819672131148" lengthrange="0.0779332  0.17004" />
    <muscle name="addlong_l" tendon="addlong_l_tendon" class="muscle" force="916.8" lengthrange="0.162428  0.25633" />
    <muscle name="addmagDist_l" tendon="addmagDist_l_tendon" class="muscle" force="597.295081967214" lengthrange="0.140158 0.279951" />
    <muscle name="addmagIsch_l" tendon="addmagIsch_l_tendon" class="muscle" force="597.295081967214" lengthrange="0.240993  0.36751" />
    <muscle name="addmagMid_l" tendon="addmagMid_l_tendon" class="muscle" force="597.295081967214" lengthrange="0.0917376 0.200171" />
    <muscle name="addmagProx_l" tendon="addmagProx_l_tendon" class="muscle" force="597.295081967214" lengthrange="0.0824551 0.173954" />
    <muscle name="bflh_l" tendon="bflh_l_tendon" class="muscle" force="1313.18360655738" lengthrange="0.317789 0.399599" />
    <muscle name="bfsh_l" tendon="bfsh_l_tendon" class="muscle" force="557.11475409836" lengthrange="0.141714  0.23658" />
    <muscle name="edl_l" tendon="edl_l_tendon" class="muscle" force="603.4981556" lengthrange="0.372391 0.434954" />
    <muscle name="ehl_l" tendon="ehl_l_tendon" class="muscle" force="285.8675474" lengthrange="0.332842 0.400011" />
    <muscle name="fdl_l" tendon="fdl_l_tendon" class="muscle" force="423.177049180328" lengthrange="0.361331 0.400555" />
    <muscle name="fhl_l" tendon="fhl_l_tendon" class="muscle" force="907.839344262294" lengthrange="0.339022 0.384505" />
    <muscle name="gaslat_l" tendon="gaslat_l_tendon" class="muscle" force="1575.05901639344" lengthrange="0.398161  0.45472" />
    <muscle name="gasmed_l" tendon="gasmed_l_tendon" class="muscle" force="3115.51475409836" lengthrange=" 0.41583 0.465178" />
    <muscle name="glmax1_l" tendon="glmax1_l_tendon" class="muscle" force="983.783606557378" lengthrange="0.130065 0.282328" />
    <muscle name="glmax2_l" tendon="glmax2_l_tendon" class="muscle" force="1406.04590163935" lengthrange="0.149836 0.305377" />
    <muscle name="glmax3_l" tendon="glmax3_l_tendon" class="muscle" force="947.754098360656" lengthrange="0.149097 0.306048" />
    <muscle name="glmed1_l" tendon="glmed1_l_tendon" class="muscle" force="1093.4667688" lengthrange="0.104817 0.185161" />
    <muscle name="glmed2_l" tendon="glmed2_l_tendon" class="muscle" force="765.0916616" lengthrange="0.113677 0.192588" />
    <muscle name="glmed3_l" tendon="glmed3_l_tendon" class="muscle" force="871.1992642" lengthrange="0.0876812 0.163792" />
    <muscle name="glmin1_l" tendon="glmin1_l_tendon" class="muscle" force="374.045901639344" lengthrange="0.0555538 0.130527" />
    <muscle name="glmin2_l" tendon="glmin2_l_tendon" class="muscle" force="394.819672131148" lengthrange="0.0598867 0.121878" />
    <muscle name="glmin3_l" tendon="glmin3_l_tendon" class="muscle" force="446.773770491804" lengthrange="0.0757465 0.116936" />
    <muscle name="grac_l" tendon="grac_l_tendon" class="muscle" force="281.311475409836" lengthrange="0.242399 0.433804" />
    <muscle name="iliacus_l" tendon="iliacus_l_tendon" class="muscle" force="1021.14098360656" lengthrange=" 0.16527 0.280183" />
    <muscle name="perbrev_l" tendon="perbrev_l_tendon" class="muscle" force="521.2015988" lengthrange="0.162998 0.205677" />
    <muscle name="perlong_l" tendon="perlong_l_tendon" class="muscle" force="1115.3714214" lengthrange="0.334925 0.381146" />
    <muscle name="piri_l" tendon="piri_l_tendon" class="muscle" force="1029.7868852459" lengthrange="0.135151 0.162249" />
    <muscle name="psoas_l" tendon="psoas_l_tendon" class="muscle" force="1426.79016393443" lengthrange="0.176526 0.305218" />
    <muscle name="recfem_l" tendon="recfem_l_tendon" class="muscle" force="2191.74098360656" lengthrange="0.440355 0.507575" />
    <muscle name="sart_l" tendon="sart_l_tendon" class="muscle" force="249.413114754098" lengthrange="0.302922 0.677921" />
    <muscle name="semimem_l" tendon="semimem_l_tendon" class="muscle" force="2200.9868852459" lengthrange="0.324457 0.381327" />
    <muscle name="semiten_l" tendon="semiten_l_tendon" class="muscle" force="591.295081967214" lengthrange="0.293054 0.454159" />
    <muscle name="soleus_l" tendon="soleus_l_tendon" class="muscle" force="6194.84262295082" lengthrange="0.292628  0.33284" />
    <muscle name="tfl_l" tendon="tfl_l_tendon" class="muscle" force="411.20655737705" lengthrange="0.467365  0.55659" />
    <muscle name="tibant_l" tendon="tibant_l_tendon" class="muscle" force="1227.45245901639" lengthrange="0.263306 0.327703" />
    <muscle name="tibpost_l" tendon="tibpost_l_tendon" class="muscle" force="1730.15409836065" lengthrange="0.288943 0.324516" />
    <muscle name="vasint_l" tendon="vasint_l_tendon" class="muscle" force="1697.36065573771" lengthrange="0.224352 0.312665" />
    <muscle name="vaslat_l" tendon="vaslat_l_tendon" class="muscle" force="5148.76721311476" lengthrange="0.239295 0.324996" />
    <muscle name="vasmed_l" tendon="vasmed_l_tendon" class="muscle" force="2747.82295081966" lengthrange="0.218319 0.297307" />
  </actuator>
  <equality>
    <joint name="knee_angle_r_translation2_constraint" active="true" joint1="knee_angle_r_translation2" joint2="knee_angle_r" polycoef="7.69254e-11 0.00587971 -0.00125622 -2.61846e-06 6.24355e-07" solimp="0.9999 0.9999 0.001 0.5 2" />
    <joint name="knee_angle_r_translation1_constraint" active="true" joint1="knee_angle_r_translation1" joint2="knee_angle_r" polycoef="9.53733e-08 0.00312879 -0.00230804 0.000561561 5.68366e-07" solimp="0.9999 0.9999 0.001 0.5 2" />
    <joint name="knee_angle_r_rotation2_constraint" active="true" joint1="knee_angle_r_rotation2" joint2="knee_angle_r" polycoef="-1.47325e-08   0.0791 -0.0328478 -0.0252183 0.0108321" solimp="0.9999 0.9999 0.001 0.5 2" />
    <joint name="knee_angle_r_rotation3_constraint" active="true" joint1="knee_angle_r_rotation3" joint2="knee_angle_r" polycoef="1.08939e-08 0.369499 -0.169478 0.0251643 3.50498e-07" solimp="0.9999 0.9999 0.001 0.5 2" />
    <joint name="knee_angle_r_beta_translation2_constraint" active="true" joint1="knee_angle_r_beta_translation2" joint2="knee_angle_r" polycoef="-0.0108281 -0.0487847 0.00927644 0.0131673 -0.00349673" solimp="0.9999 0.9999 0.001 0.5 2" />
    <joint name="knee_angle_r_beta_translation1_constraint" active="true" joint1="knee_angle_r_beta_translation1" joint2="knee_angle_r" polycoef="0.0524192 -0.0150188 -0.0340522 0.0133393 -0.000879151" solimp="0.9999 0.9999 0.001 0.5 2" />
    <joint name="knee_angle_r_beta_rotation1_constraint" active="true" joint1="knee_angle_r_beta_rotation1" joint2="knee_angle_r" polycoef="0.010506 0.0247615 -1.31647 0.716337 -0.138302" solimp="0.9999 0.9999 0.001 0.5 2" />
    <joint name="subtalar_angle_r_constraint" active="true" joint1="subtalar_angle_r" polycoef="       0        0        0        0        0" />
    <joint name="mtp_angle_r_constraint" active="true" joint1="mtp_angle_r" polycoef="       0        0        0        0        0" />
    <joint name="knee_angle_l_translation2_constraint" active="true" joint1="knee_angle_l_translation2" joint2="knee_angle_l" polycoef="-7.69254e-11 -0.00587971 0.00125622 2.61846e-06 -6.24355e-07" solimp="0.9999 0.9999 0.001 0.5 2" />
    <joint name="knee_angle_l_translation1_constraint" active="true" joint1="knee_angle_l_translation1" joint2="knee_angle_l" polycoef="9.53733e-08 0.00312879 -0.00230804 0.000561561 5.68366e-07" solimp="0.9999 0.9999 0.001 0.5 2" />
    <joint name="knee_angle_l_rotation2_constraint" active="true" joint1="knee_angle_l_rotation2" joint2="knee_angle_l" polycoef="-1.47325e-08   0.0791 -0.0328478 -0.0252183 0.0108321" solimp="0.9999 0.9999 0.001 0.5 2" />
    <joint name="knee_angle_l_rotation3_constraint" active="true" joint1="knee_angle_l_rotation3" joint2="knee_angle_l" polycoef="-1.08939e-08 -0.369499 0.169478 -0.0251643 -3.50498e-07" solimp="0.9999 0.9999 0.001 0.5 2" />
    <joint name="knee_angle_l_beta_translation2_constraint" active="true" joint1="knee_angle_l_beta_translation2" joint2="knee_angle_l" polycoef="-0.0108281 -0.0487847 0.00927644 0.0131673 -0.00349673" solimp="0.9999 0.9999 0.001 0.5 2" />
    <joint name="knee_angle_l_beta_translation1_constraint" active="true" joint1="knee_angle_l_beta_translation1" joint2="knee_angle_l" polycoef="0.0524192 -0.0150188 -0.0340522 0.0133393 -0.000879151" solimp="0.9999 0.9999 0.001 0.5 2" />
    <joint name="knee_angle_l_beta_rotation1_constraint" active="true" joint1="knee_angle_l_beta_rotation1" joint2="knee_angle_l" polycoef="0.010506 0.0247615 -1.31647 0.716337 -0.138302" solimp="0.9999 0.9999 0.001 0.5 2" />
    <joint name="subtalar_angle_l_constraint" active="true" joint1="subtalar_angle_l" polycoef="       0        0        0        0        0" />
    <joint name="mtp_angle_l_constraint" active="true" joint1="mtp_angle_l" polycoef="       0        0        0        0        0" />
    <joint name="wrist_flex_r_constraint" active="true" joint1="wrist_flex_r" polycoef="       0        0        0        0        0" />
    <joint name="wrist_dev_r_constraint" active="true" joint1="wrist_dev_r" polycoef="       0        0        0        0        0" />
    <joint name="wrist_flex_l_constraint" active="true" joint1="wrist_flex_l" polycoef="       0        0        0        0        0" />
    <joint name="wrist_dev_l_constraint" active="true" joint1="wrist_dev_l" polycoef="       0        0        0        0        0" />
    <weld name="origin_to_worldbody" body1="pelvis" active="false" />
  </equality>
</mujoco>