<mujoco model="SN188_Rajagopal_Scaled">
  <compiler inertiafromgeom="auto" angle="radian" balanceinertia="true" boundmass="0.001" boundinertia="0.001">
    <lengthrange inttotal="50" useexisting="true" />
  </compiler>
  <default>
    <joint limited="true" damping="0.5" armature="0.1" stiffness="2" />
    <geom rgba="0.8 0.6 .4 1" margin="0.001" />
    <default class="motor">
      <general gainprm="5 0 0 0 0 0 0 0 0 0" />
    </default>
  </default>
  <option timestep="0.002" />
  <size njmax="1000" nconmax="400" nuser_jnt="1" />
  <worldbody>
    <geom name="floor" pos="0 0 0" size="10 10 0.125" type="plane" material="MatPlane" condim="3" />
    <body name="pelvis" pos="       0        0        0" quat="0.7071067811865475 0.7071067811865475 0.0 0.0">
      <light mode="trackcom" directional="false" pos="0 0 4.0" dir="0 0 -1" />
      <geom name="r_pelvis" type="mesh" mesh="r_pelvis" />
      <geom name="l_pelvis" type="mesh" mesh="l_pelvis" />
      <geom name="sacrum" type="mesh" mesh="sacrum" />
      <inertial pos="-0.085015        0        0" mass="13.0193873582137" fullinertia="0.164324 0.139228 0.0925522        0        0        0" />
      <joint name="pelvis_tz" type="slide" pos="0 0 0" axis="       0        0        1" limited="false" range="      -3        3" ref="0" armature="0" damping="0" stiffness="0" />
      <joint name="pelvis_ty" type="slide" pos="0 0 0" axis="       0        1        0" limited="false" range="      -1        2" ref="0" armature="0" damping="0" stiffness="0" />
      <joint name="pelvis_tx" type="slide" pos="0 0 0" axis="       1        0        0" limited="false" range="      -5        5" ref="0" armature="0" damping="0" stiffness="0" />
      <joint name="pelvis_tilt" type="hinge" pos="0 0 0" axis="       0        0        1" limited="false" range=" -1.5708   1.5708" ref="0" armature="0" damping="0" stiffness="0" />
      <joint name="pelvis_list" type="hinge" pos="0 0 0" axis="       1        0        0" limited="false" range=" -1.5708   1.5708" ref="0" armature="0" damping="0" stiffness="0" />
      <joint name="pelvis_rotation" type="hinge" pos="0 0 0" axis="       0        1        0" limited="false" range=" -1.5708   1.5708" ref="0" armature="0" damping="0" stiffness="0" />
      <body name="femur_r" pos="-0.0676705 -0.0943823 0.0929033" quat="1.0 0.0 0.0 0.0">
        <geom name="r_femur" type="mesh" mesh="r_femur" />
        <inertial pos="       0 -0.156271        0" mass="4.59375247083418" fullinertia="0.0558806 0.0146483 0.0589271        0        0        0" />
        <joint name="hip_flexion_r" type="hinge" pos="0 0 0" axis="       0        0        1" limited="false" range="-0.523599   2.0944" ref="0" />
        <joint name="hip_adduction_r" type="hinge" pos="0 0 0" axis="       1        0        0" limited="false" range="-0.872665 0.523599" ref="0" />
        <joint name="hip_rotation_r" type="hinge" pos="0 0 0" axis="       0        1        0" limited="false" range="-0.698132 0.698132" ref="0" />
        <body name="tibia_r" pos="-0.000281483 -0.371888 -0.00121467" quat="1.0 7.240636975890137e-18 -9.456205735995121e-17 -2.960068750797159e-20">
          <geom name="r_tibia" type="mesh" mesh="r_tibia" />
          <geom name="r_fibula" type="mesh" mesh="r_fibula" />
          <inertial pos="       0 -0.165136        0" mass="1.63118034735419" fullinertia="0.0173479 0.00175544 0.0175889        0        0        0" />
          <joint name="knee_angle_r_translation2" type="slide" pos="0 0 0" axis="0.992246 0.123982 -0.00878916" limited="true" range="7.69254e-11 0.006792" ref="0" />
          <joint name="knee_angle_r_translation1" type="slide" pos="0 0 0" axis="-0.124293 0.989762 -0.0701648" limited="true" range="9.53733e-08 0.00159883" ref="0" />
          <joint name="knee_angle_r" type="hinge" pos="0 0 0" axis="-3.98373e-10 -0.0707131 -0.997497" limited="false" range="       0   2.0944" ref="0" />
          <joint name="knee_angle_r_rotation2" type="hinge" pos="0 0 0" axis="0.992246 0.123982 -0.00878916" limited="true" range="-0.00167821 0.0335354" ref="0" />
          <joint name="knee_angle_r_rotation3" type="hinge" pos="0 0 0" axis="-0.124293 0.989762 -0.0701648" limited="true" range="1.08939e-08 0.262788" ref="0" />
          <body name="talus_r" pos="-0.008845  -0.3538        0" quat="1.0 -6.036754011562992e-18 1.5193252867388614e-18 -2.498419531737724e-19">
            <geom name="r_talus" type="mesh" mesh="r_talus" />
            <inertial pos="       0        0        0" mass="0.0269734232272222" fullinertia="0.000152291 0.000152291 0.000152291        0        0        0" />
            <joint name="ankle_angle_r" type="hinge" pos="0 0 0" axis="-0.105014 -0.174022 0.979126" limited="false" range="-0.698132 0.523599" ref="0" />
            <body name="calcn_r" pos="-0.0366456 -0.0315211 0.00595107" quat="1.0 -5.320429553087796e-19 1.609289071159989e-17 -2.1848634538867752e-17">
              <geom name="r_foot" type="mesh" mesh="r_foot" />
              <inertial pos="0.0751397 0.0225419        0" mass="0.337167790340277" fullinertia="0.000213208 0.000593936 0.000624395        0        0        0" />
              <joint name="subtalar_angle_r" type="hinge" pos="0 0 0" axis=" 0.78718 0.604747 -0.120949" limited="false" range="-0.349066 0.349066" ref="0" />
              <body name="toes_r" pos=" 0.13435 -0.00150279 0.000811509" quat="1.0 1.314867274624753e-31 -2.6810890689525335e-17 -3.939849802505862e-32">
                <geom name="r_bofoot" type="mesh" mesh="r_bofoot" />
                <inertial pos="0.0259983 0.00450838 -0.0131495" mass="0.0584244347101632" fullinertia="1.52291e-05 3.04583e-05 0.000152291        0        0        0" />
                <joint name="mtp_angle_r" type="hinge" pos="0 0 0" axis="0.580954 2.6299e-15 -0.813936" limited="false" range="-0.523599 0.523599" ref="0" />
              </body>
            </body>
          </body>
        </body>
        <body name="patella_r" pos="-0.00743668 -0.375015 0.00022208" quat="1.0 0.0 0.0 0.0">
          <geom name="r_patella" type="mesh" mesh="r_patella" />
          <inertial pos="  0.0018   0.0264        0" mass="0.054806801438868" fullinertia="1.82477e-06 8.33547e-06 8.33547e-06        0        0        0" />
          <joint name="knee_angle_r_beta_translation2" type="slide" pos="0 0 0" axis="       0        1        0" limited="true" range="-0.0408267 -0.0108281" ref="0" />
          <joint name="knee_angle_r_beta_translation1" type="slide" pos="0 0 0" axis="       1        0        0" limited="true" range="-0.0227731 0.0524192" ref="0" />
          <joint name="knee_angle_r_beta_rotation1" type="hinge" pos="0 0 0" axis="       0        0        1" limited="true" range="-1.79241 0.010506" ref="0" />
        </body>
      </body>
      <body name="femur_l" pos="-0.0676705 -0.0943823 -0.0929033" quat="1.0 0.0 0.0 0.0">
        <geom name="l_femur" type="mesh" mesh="l_femur" />
        <inertial pos="       0 -0.152254        0" mass="4.24847163027598" fullinertia="0.0490572 0.0128597 0.0517318        0        0        0" />
        <joint name="hip_flexion_l" type="hinge" pos="0 0 0" axis="       0        0        1" limited="false" range="-0.523599   2.0944" ref="0" />
        <joint name="hip_adduction_l" type="hinge" pos="0 0 0" axis="      -1       -0       -0" limited="false" range="-0.872665 0.523599" ref="0" />
        <joint name="hip_rotation_l" type="hinge" pos="0 0 0" axis="      -0       -1       -0" limited="false" range="-0.698132 0.698132" ref="0" />
        <body name="tibia_l" pos="7.49925e-07 -0.362207 0.00113297" quat="1.0 -7.240636975890137e-18 9.456205735995121e-17 -2.960068750797159e-20">
          <geom name="l_tibia" type="mesh" mesh="l_tibia" />
          <geom name="l_fibula" type="mesh" mesh="l_fibula" />
          <inertial pos="       0 -0.167237        0" mass="1.69423827984051" fullinertia=" 0.01848  0.00187 0.0187366        0        0        0" />
          <joint name="knee_angle_l_translation2" type="slide" pos="0 0 0" axis="-0.992246 -0.123982 -0.00878916" limited="true" range="-0.006792 -7.69254e-11" ref="0" />
          <joint name="knee_angle_l_translation1" type="slide" pos="0 0 0" axis="-0.124293 0.989762 0.0701648" limited="true" range="9.53733e-08 0.00159883" ref="0" />
          <joint name="knee_angle_l" type="hinge" pos="0 0 0" axis="3.98373e-10 0.0707131 -0.997497" limited="false" range="       0   2.0944" ref="0" />
          <joint name="knee_angle_l_rotation2" type="hinge" pos="0 0 0" axis="-0.992246 -0.123982 -0.00878916" limited="true" range="-0.00167821 0.0335354" ref="0" />
          <joint name="knee_angle_l_rotation3" type="hinge" pos="0 0 0" axis="-0.124293 0.989762 0.0701648" limited="true" range="-0.262788 -1.08939e-08" ref="0" />
          <body name="talus_l" pos="-0.00895754 -0.358302        0" quat="1.0 6.036754011562992e-18 -1.5193252867388614e-18 -2.498419531737724e-19">
            <geom name="l_talus" type="mesh" mesh="l_talus" />
            <inertial pos="       0        0        0" mass="0.0276743658789758" fullinertia="0.000158944 0.000158944 0.000158944        0        0        0" />
            <joint name="ankle_angle_l" type="hinge" pos="0 0 0" axis="0.105014 0.174022 0.979126" limited="false" range="-0.698132 0.523599" ref="0" />
            <body name="calcn_l" pos="-0.0369604 -0.0317918 -0.00600218" quat="1.0 5.320429553087796e-19 -1.609289071159989e-17 -2.1848634538867752e-17">
              <geom name="l_foot" type="mesh" mesh="l_foot" />
              <inertial pos="0.075785 0.0227355        0" mass="0.345929573487198" fullinertia="0.000222522 0.000619882 0.000651671        0        0        0" />
              <joint name="subtalar_angle_l" type="hinge" pos="0 0 0" axis="-0.78718 -0.604747 -0.120949" limited="false" range="-0.349066 0.349066" ref="0" />
              <body name="toes_l" pos="0.135504 -0.0015157 -0.000818478" quat="1.0 1.314867274624753e-31 2.6810890689525335e-17 3.939849802505862e-32">
                <geom name="l_bofoot" type="mesh" mesh="l_bofoot" />
                <inertial pos="0.0262216 0.0045471 0.0132624" mass="0.0599426764938616" fullinertia="1.58944e-05 3.17888e-05 0.000158944        0        0        0" />
                <joint name="mtp_angle_l" type="hinge" pos="0 0 0" axis="-0.580954 2.6299e-15 -0.813936" limited="false" range="-0.523599 0.523599" ref="0" />
              </body>
            </body>
          </body>
        </body>
        <body name="patella_l" pos="-0.00724549 -0.365373 -0.000287072" quat="1.0 0.0 0.0 0.0">
          <geom name="l_patella" type="mesh" mesh="l_patella" />
          <inertial pos="  0.0018   0.0264        0" mass="0.054806801438868" fullinertia="1.82477e-06 8.33547e-06 8.33547e-06        0        0        0" />
          <joint name="knee_angle_l_beta_translation2" type="slide" pos="0 0 0" axis="       0        1        0" limited="true" range="-0.0408267 -0.0108281" ref="0" />
          <joint name="knee_angle_l_beta_translation1" type="slide" pos="0 0 0" axis="       1        0        0" limited="true" range="-0.0227731 0.0524192" ref="0" />
          <joint name="knee_angle_l_beta_rotation1" type="hinge" pos="0 0 0" axis="       0        0        1" limited="true" range="-1.79241 0.010506" ref="0" />
        </body>
      </body>
      <body name="torso" pos="-0.121089 0.0980018        0" quat="1.0 0.0 0.0 0.0">
        <geom name="hat_spine" type="mesh" mesh="hat_spine" />
        <geom name="hat_jaw" type="mesh" mesh="hat_jaw" />
        <geom name="hat_skull" type="mesh" mesh="hat_skull" />
        <geom name="hat_ribs_scap" type="mesh" mesh="hat_ribs_scap" />
        <inertial pos="-0.0275582 0.293954        0" mass="13.2214803175921" fullinertia="0.613222 0.314201 0.595297        0        0        0" />
        <joint name="lumbar_extension" type="hinge" pos="0 0 0" axis="       0        0        1" limited="false" range=" -1.5708   1.5708" ref="0" />
        <joint name="lumbar_bending" type="hinge" pos="0 0 0" axis="       1        0        0" limited="false" range=" -1.5708   1.5708" ref="0" />
        <joint name="lumbar_rotation" type="hinge" pos="0 0 0" axis="       0        1        0" limited="false" range=" -1.5708   1.5708" ref="0" />
        <body name="humerus_r" pos="0.0028982 0.341262 0.156163" quat="1.0 0.0 0.0 0.0">
          <geom name="humerus_rv" type="mesh" mesh="humerus_rv" />
          <inertial pos="       0  -0.1407        0" mass="0.808585026780963" fullinertia="0.00347667 0.00119934 0.00390245        0        0        0" />
          <joint name="arm_flex_r" type="hinge" pos="0 0 0" axis="       0        0        1" limited="false" range=" -1.5708   1.5708" ref="0" />
          <joint name="arm_add_r" type="hinge" pos="0 0 0" axis="       1        0        0" limited="false" range=" -2.0944   1.5708" ref="0" />
          <joint name="arm_rot_r" type="hinge" pos="0 0 0" axis="       0        1        0" limited="false" range=" -1.5708   1.5708" ref="0" />
          <body name="ulna_r" pos="0.0112422 -0.244852 -0.00820668" quat="1.0 1.6893809785063376e-18 -6.938893903907228e-18 4.155190089080778e-20">
            <geom name="ulna_rv" type="mesh" mesh="ulna_rv" />
            <inertial pos="       0 -0.109506        0" mass="0.289706488292915" fullinertia="0.00116606 0.00024329 0.00126487        0        0        0" />
            <joint name="elbow_flex_r" type="hinge" pos="0 0 0" axis="0.226047 0.022269 0.973862" limited="false" range="       0    2.618" ref="0" />
            <body name="radius_r" pos="-0.006112 -0.0118179 0.0236984" quat="1.0 2.301201592641875e-21 -6.933378131686372e-19 1.7489241099837954e-19">
              <geom name="radius_rv" type="mesh" mesh="radius_rv" />
              <inertial pos="       0 -0.115379        0" mass="0.338858363397708" fullinertia="0.0015141 0.000315905 0.0016424        0        0        0" />
              <joint name="pro_sup_r" type="hinge" pos="0 0 0" axis="0.056398 0.998406 0.001952" limited="false" range="       0   1.5708" ref="0" />
              <body name="hand_r" pos="-0.00842137 -0.225771 0.0130289" quat="1.0 0.0 8.407790785948892e-45 0.0">
                <geom name="pisiform_rvs" type="mesh" mesh="pisiform_rvs" />
                <geom name="lunate_rvs" type="mesh" mesh="lunate_rvs" />
                <geom name="scaphoid_rvs" type="mesh" mesh="scaphoid_rvs" />
                <geom name="triquetrum_rvs" type="mesh" mesh="triquetrum_rvs" />
                <geom name="hamate_rvs" type="mesh" mesh="hamate_rvs" />
                <geom name="capitate_rvs" type="mesh" mesh="capitate_rvs" />
                <geom name="trapezoid_rvs" type="mesh" mesh="trapezoid_rvs" />
                <geom name="trapezium_rvs" type="mesh" mesh="trapezium_rvs" />
                <geom name="metacarpal2_rvs" type="mesh" mesh="metacarpal2_rvs" />
                <geom name="index_proximal_rvs" type="mesh" mesh="index_proximal_rvs" />
                <geom name="index_medial_rvs" type="mesh" mesh="index_medial_rvs" />
                <geom name="index_distal_rvs" type="mesh" mesh="index_distal_rvs" />
                <geom name="metacarpal3_rvs" type="mesh" mesh="metacarpal3_rvs" />
                <geom name="middle_proximal_rvs" type="mesh" mesh="middle_proximal_rvs" />
                <geom name="middle_medial_rvs" type="mesh" mesh="middle_medial_rvs" />
                <geom name="middle_distal_rvs" type="mesh" mesh="middle_distal_rvs" />
                <geom name="metacarpal4_rvs" type="mesh" mesh="metacarpal4_rvs" />
                <geom name="ring_proximal_rvs" type="mesh" mesh="ring_proximal_rvs" />
                <geom name="ring_medial_rvs" type="mesh" mesh="ring_medial_rvs" />
                <geom name="ring_distal_rvs" type="mesh" mesh="ring_distal_rvs" />
                <geom name="metacarpal5_rvs" type="mesh" mesh="metacarpal5_rvs" />
                <geom name="little_proximal_rvs" type="mesh" mesh="little_proximal_rvs" />
                <geom name="little_medial_rvs" type="mesh" mesh="little_medial_rvs" />
                <geom name="little_distal_rvs" type="mesh" mesh="little_distal_rvs" />
                <geom name="metacarpal1_rvs" type="mesh" mesh="metacarpal1_rvs" />
                <geom name="thumb_proximal_rvs" type="mesh" mesh="thumb_proximal_rvs" />
                <geom name="thumb_distal_rvs" type="mesh" mesh="thumb_distal_rvs" />
                <inertial pos="       0 -0.068095        0" mass="0.290882965873342" fullinertia="0.000567142 0.000347788 0.000851985        0        0        0" />
                <joint name="wrist_flex_r" type="hinge" pos="0 0 0" axis="-3.55271e-15 3.55271e-15        1" limited="false" range="-1.22173  1.22173" ref="0" />
                <joint name="wrist_dev_r" type="hinge" pos="0 0 0" axis="       1        0 3.55271e-15" limited="false" range="-0.436332 0.610865" ref="0" />
              </body>
            </body>
          </body>
        </body>
        <body name="humerus_l" pos="0.0028982 0.341262 -0.156163" quat="1.0 0.0 0.0 0.0">
          <geom name="humerus_lv" type="mesh" mesh="humerus_lv" />
          <inertial pos="       0 -0.143364        0" mass="0.85539360606989" fullinertia="0.00381854 0.00131728 0.00428618        0        0        0" />
          <joint name="arm_flex_l" type="hinge" pos="0 0 0" axis="       0        0        1" limited="false" range=" -1.5708   1.5708" ref="0" />
          <joint name="arm_add_l" type="hinge" pos="0 0 0" axis="      -1        0        0" limited="false" range=" -2.0944   1.5708" ref="0" />
          <joint name="arm_rot_l" type="hinge" pos="0 0 0" axis="       0       -1        0" limited="false" range=" -1.5708   1.5708" ref="0" />
          <body name="ulna_l" pos="0.011455 -0.249488 0.00836208" quat="1.0 -1.6893809785063376e-18 6.938893903907228e-18 4.155190089080778e-20">
            <geom name="ulna_lv" type="mesh" mesh="ulna_lv" />
            <inertial pos="       0 -0.110007        0" mass="0.293700094797636" fullinertia="0.00119297 0.000248905 0.00129406        0        0        0" />
            <joint name="elbow_flex_l" type="hinge" pos="0 0 0" axis="-0.226047 -0.022269 0.973862" limited="false" range="       0    2.618" ref="0" />
            <body name="radius_l" pos="-0.00613995 -0.0118719 -0.0238068" quat="1.0 -2.301201592641875e-21 6.933378131686372e-19 1.7489241099837954e-19">
              <geom name="radius_lv" type="mesh" mesh="radius_lv" />
              <inertial pos="       0 -0.120197        0" mass="0.383109686049747" fullinertia="0.00185778 0.000387613 0.00201521        0        0        0" />
              <joint name="pro_sup_l" type="hinge" pos="0 0 0" axis="-0.056398 -0.998406 0.001952" limited="false" range="       0   1.5708" ref="0" />
              <body name="hand_l" pos="-0.00877306 -0.235199 -0.013573" quat="1.0 0.0 8.407790785948892e-45 0.0">
                <geom name="pisiform_lvs" type="mesh" mesh="pisiform_lvs" />
                <geom name="lunate_lvs" type="mesh" mesh="lunate_lvs" />
                <geom name="scaphoid_lvs" type="mesh" mesh="scaphoid_lvs" />
                <geom name="triquetrum_lvs" type="mesh" mesh="triquetrum_lvs" />
                <geom name="hamate_lvs" type="mesh" mesh="hamate_lvs" />
                <geom name="capitate_lvs" type="mesh" mesh="capitate_lvs" />
                <geom name="trapezoid_lvs" type="mesh" mesh="trapezoid_lvs" />
                <geom name="trapezium_lvs" type="mesh" mesh="trapezium_lvs" />
                <geom name="metacarpal2_lvs" type="mesh" mesh="metacarpal2_lvs" />
                <geom name="index_proximal_lvs" type="mesh" mesh="index_proximal_lvs" />
                <geom name="index_medial_lvs" type="mesh" mesh="index_medial_lvs" />
                <geom name="index_distal_lvs" type="mesh" mesh="index_distal_lvs" />
                <geom name="metacarpal3_lvs" type="mesh" mesh="metacarpal3_lvs" />
                <geom name="middle_proximal_lvs" type="mesh" mesh="middle_proximal_lvs" />
                <geom name="middle_medial_lvs" type="mesh" mesh="middle_medial_lvs" />
                <geom name="middle_distal_lvs" type="mesh" mesh="middle_distal_lvs" />
                <geom name="metacarpal4_lvs" type="mesh" mesh="metacarpal4_lvs" />
                <geom name="ring_proximal_lvs" type="mesh" mesh="ring_proximal_lvs" />
                <geom name="ring_medial_lvs" type="mesh" mesh="ring_medial_lvs" />
                <geom name="ring_distal_lvs" type="mesh" mesh="ring_distal_lvs" />
                <geom name="metacarpal5_lvs" type="mesh" mesh="metacarpal5_lvs" />
                <geom name="little_proximal_lvs" type="mesh" mesh="little_proximal_lvs" />
                <geom name="little_medial_lvs" type="mesh" mesh="little_medial_lvs" />
                <geom name="little_distal_lvs" type="mesh" mesh="little_distal_lvs" />
                <geom name="metacarpal1_lvs" type="mesh" mesh="metacarpal1_lvs" />
                <geom name="thumb_proximal_lvs" type="mesh" mesh="thumb_proximal_lvs" />
                <geom name="thumb_distal_lvs" type="mesh" mesh="thumb_distal_lvs" />
                <inertial pos="       0 -0.068095        0" mass="0.290882965873342" fullinertia="0.000567142 0.000347788 0.000851985        0        0        0" />
                <joint name="wrist_flex_l" type="hinge" pos="0 0 0" axis="-3.55271e-15 -3.55271e-15        1" limited="false" range="-1.22173  1.22173" ref="0" />
                <joint name="wrist_dev_l" type="hinge" pos="0 0 0" axis="      -1        0 -3.55271e-15" limited="false" range="-0.436332 0.610865" ref="0" />
              </body>
            </body>
          </body>
        </body>
      </body>
    </body>
    <camera name="for_testing" pos="0 0 0" euler="0 0 0" />
  </worldbody>
  <asset>
    <mesh name="r_pelvis" file="Geometry/r_pelvis.stl" scale=" 1.20248  1.20248  1.20248" />
    <mesh name="l_pelvis" file="Geometry/l_pelvis.stl" scale=" 1.20248  1.20248  1.20248" />
    <mesh name="sacrum" file="Geometry/sacrum.stl" scale=" 1.20248  1.20248  1.20248" />
    <mesh name="r_femur" file="Geometry/r_femur.stl" scale="0.919244 0.919244 0.919244" />
    <mesh name="r_tibia" file="Geometry/r_tibia.stl" scale="  0.8845   0.8845   0.8845" />
    <mesh name="r_fibula" file="Geometry/r_fibula.stl" scale="  0.8845   0.8845   0.8845" />
    <mesh name="r_talus" file="Geometry/r_talus.stl" scale="0.751397 0.751397 0.751397" />
    <mesh name="r_foot" file="Geometry/r_foot.stl" scale="0.751397 0.751397 0.751397" />
    <mesh name="r_bofoot" file="Geometry/r_bofoot.stl" scale="0.751397 0.751397 0.751397" />
    <mesh name="r_patella" file="Geometry/r_patella.stl" scale="       1        1        1" />
    <mesh name="l_femur" file="Geometry/l_femur.stl" scale=" 0.89561  0.89561  0.89561" />
    <mesh name="l_tibia" file="Geometry/l_tibia.stl" scale="0.895754 0.895754 0.895754" />
    <mesh name="l_fibula" file="Geometry/l_fibula.stl" scale="0.895754 0.895754 0.895754" />
    <mesh name="l_talus" file="Geometry/l_talus.stl" scale=" 0.75785  0.75785  0.75785" />
    <mesh name="l_foot" file="Geometry/l_foot.stl" scale=" 0.75785  0.75785  0.75785" />
    <mesh name="l_bofoot" file="Geometry/l_bofoot.stl" scale=" 0.75785  0.75785  0.75785" />
    <mesh name="l_patella" file="Geometry/l_patella.stl" scale="       1        1        1" />
    <mesh name="hat_spine" file="Geometry/hat_spine.stl" scale="0.918606 0.918606 0.918606" />
    <mesh name="hat_jaw" file="Geometry/hat_jaw.stl" scale="0.918606 0.918606 0.918606" />
    <mesh name="hat_skull" file="Geometry/hat_skull.stl" scale="0.918606 0.918606 0.918606" />
    <mesh name="hat_ribs_scap" file="Geometry/hat_ribs_scap.stl" scale="0.918606 0.918606 0.918606" />
    <mesh name="humerus_rv" file="Geometry/humerus_rv.stl" scale="0.855308 0.855308 0.855308" />
    <mesh name="ulna_rv" file="Geometry/ulna_rv.stl" scale="0.908577 0.908577 0.908577" />
    <mesh name="radius_rv" file="Geometry/radius_rv.stl" scale="  0.9573   0.9573   0.9573" />
    <mesh name="pisiform_rvs" file="Geometry/pisiform_rvs.stl" scale="    0.85     0.85     0.85" />
    <mesh name="lunate_rvs" file="Geometry/lunate_rvs.stl" scale="    0.85     0.85     0.85" />
    <mesh name="scaphoid_rvs" file="Geometry/scaphoid_rvs.stl" scale="    0.85     0.85     0.85" />
    <mesh name="triquetrum_rvs" file="Geometry/triquetrum_rvs.stl" scale="    0.85     0.85     0.85" />
    <mesh name="hamate_rvs" file="Geometry/hamate_rvs.stl" scale="    0.85     0.85     0.85" />
    <mesh name="capitate_rvs" file="Geometry/capitate_rvs.stl" scale="    0.85     0.85     0.85" />
    <mesh name="trapezoid_rvs" file="Geometry/trapezoid_rvs.stl" scale="    0.85     0.85     0.85" />
    <mesh name="trapezium_rvs" file="Geometry/trapezium_rvs.stl" scale="    0.85     0.85     0.85" />
    <mesh name="metacarpal2_rvs" file="Geometry/metacarpal2_rvs.stl" scale="    0.85     0.85     0.85" />
    <mesh name="index_proximal_rvs" file="Geometry/index_proximal_rvs.stl" scale="    0.85     0.85     0.85" />
    <mesh name="index_medial_rvs" file="Geometry/index_medial_rvs.stl" scale="    0.85     0.85     0.85" />
    <mesh name="index_distal_rvs" file="Geometry/index_distal_rvs.stl" scale="    0.85     0.85     0.85" />
    <mesh name="metacarpal3_rvs" file="Geometry/metacarpal3_rvs.stl" scale="    0.85     0.85     0.85" />
    <mesh name="middle_proximal_rvs" file="Geometry/middle_proximal_rvs.stl" scale="    0.85     0.85     0.85" />
    <mesh name="middle_medial_rvs" file="Geometry/middle_medial_rvs.stl" scale="    0.85     0.85     0.85" />
    <mesh name="middle_distal_rvs" file="Geometry/middle_distal_rvs.stl" scale="    0.85     0.85     0.85" />
    <mesh name="metacarpal4_rvs" file="Geometry/metacarpal4_rvs.stl" scale="    0.85     0.85     0.85" />
    <mesh name="ring_proximal_rvs" file="Geometry/ring_proximal_rvs.stl" scale="    0.85     0.85     0.85" />
    <mesh name="ring_medial_rvs" file="Geometry/ring_medial_rvs.stl" scale="    0.85     0.85     0.85" />
    <mesh name="ring_distal_rvs" file="Geometry/ring_distal_rvs.stl" scale="    0.85     0.85     0.85" />
    <mesh name="metacarpal5_rvs" file="Geometry/metacarpal5_rvs.stl" scale="    0.85     0.85     0.85" />
    <mesh name="little_proximal_rvs" file="Geometry/little_proximal_rvs.stl" scale="    0.85     0.85     0.85" />
    <mesh name="little_medial_rvs" file="Geometry/little_medial_rvs.stl" scale="    0.85     0.85     0.85" />
    <mesh name="little_distal_rvs" file="Geometry/little_distal_rvs.stl" scale="    0.85     0.85     0.85" />
    <mesh name="metacarpal1_rvs" file="Geometry/metacarpal1_rvs.stl" scale="    0.85     0.85     0.85" />
    <mesh name="thumb_proximal_rvs" file="Geometry/thumb_proximal_rvs.stl" scale="    0.85     0.85     0.85" />
    <mesh name="thumb_distal_rvs" file="Geometry/thumb_distal_rvs.stl" scale="    0.85     0.85     0.85" />
    <mesh name="humerus_lv" file="Geometry/humerus_lv.stl" scale="0.871504 0.871504 0.871504" />
    <mesh name="ulna_lv" file="Geometry/ulna_lv.stl" scale="0.912733 0.912733 0.912733" />
    <mesh name="radius_lv" file="Geometry/radius_lv.stl" scale="0.997279 0.997279 0.997279" />
    <mesh name="pisiform_lvs" file="Geometry/pisiform_lvs.stl" scale="    0.85     0.85     0.85" />
    <mesh name="lunate_lvs" file="Geometry/lunate_lvs.stl" scale="    0.85     0.85     0.85" />
    <mesh name="scaphoid_lvs" file="Geometry/scaphoid_lvs.stl" scale="    0.85     0.85     0.85" />
    <mesh name="triquetrum_lvs" file="Geometry/triquetrum_lvs.stl" scale="    0.85     0.85     0.85" />
    <mesh name="hamate_lvs" file="Geometry/hamate_lvs.stl" scale="    0.85     0.85     0.85" />
    <mesh name="capitate_lvs" file="Geometry/capitate_lvs.stl" scale="    0.85     0.85     0.85" />
    <mesh name="trapezoid_lvs" file="Geometry/trapezoid_lvs.stl" scale="    0.85     0.85     0.85" />
    <mesh name="trapezium_lvs" file="Geometry/trapezium_lvs.stl" scale="    0.85     0.85     0.85" />
    <mesh name="metacarpal2_lvs" file="Geometry/metacarpal2_lvs.stl" scale="    0.85     0.85     0.85" />
    <mesh name="index_proximal_lvs" file="Geometry/index_proximal_lvs.stl" scale="    0.85     0.85     0.85" />
    <mesh name="index_medial_lvs" file="Geometry/index_medial_lvs.stl" scale="    0.85     0.85     0.85" />
    <mesh name="index_distal_lvs" file="Geometry/index_distal_lvs.stl" scale="    0.85     0.85     0.85" />
    <mesh name="metacarpal3_lvs" file="Geometry/metacarpal3_lvs.stl" scale="    0.85     0.85     0.85" />
    <mesh name="middle_proximal_lvs" file="Geometry/middle_proximal_lvs.stl" scale="    0.85     0.85     0.85" />
    <mesh name="middle_medial_lvs" file="Geometry/middle_medial_lvs.stl" scale="    0.85     0.85     0.85" />
    <mesh name="middle_distal_lvs" file="Geometry/middle_distal_lvs.stl" scale="    0.85     0.85     0.85" />
    <mesh name="metacarpal4_lvs" file="Geometry/metacarpal4_lvs.stl" scale="    0.85     0.85     0.85" />
    <mesh name="ring_proximal_lvs" file="Geometry/ring_proximal_lvs.stl" scale="    0.85     0.85     0.85" />
    <mesh name="ring_medial_lvs" file="Geometry/ring_medial_lvs.stl" scale="    0.85     0.85     0.85" />
    <mesh name="ring_distal_lvs" file="Geometry/ring_distal_lvs.stl" scale="    0.85     0.85     0.85" />
    <mesh name="metacarpal5_lvs" file="Geometry/metacarpal5_lvs.stl" scale="    0.85     0.85     0.85" />
    <mesh name="little_proximal_lvs" file="Geometry/little_proximal_lvs.stl" scale="    0.85     0.85     0.85" />
    <mesh name="little_medial_lvs" file="Geometry/little_medial_lvs.stl" scale="    0.85     0.85     0.85" />
    <mesh name="little_distal_lvs" file="Geometry/little_distal_lvs.stl" scale="    0.85     0.85     0.85" />
    <mesh name="metacarpal1_lvs" file="Geometry/metacarpal1_lvs.stl" scale="    0.85     0.85     0.85" />
    <mesh name="thumb_proximal_lvs" file="Geometry/thumb_proximal_lvs.stl" scale="    0.85     0.85     0.85" />
    <mesh name="thumb_distal_lvs" file="Geometry/thumb_distal_lvs.stl" scale="    0.85     0.85     0.85" />
    <texture name="texplane" type="2d" builtin="checker" rgb1=".2 .3 .4" rgb2=".1 0.15 0.2" width="100" height="100" />
    <material name="MatPlane" reflectance="0.0" texture="texplane" texrepeat="1 1" texuniform="true" />
  </asset>
  <actuator>
    <general name="lumbar_ext" joint="lumbar_extension" class="motor" />
    <general name="lumbar_bend" joint="lumbar_bending" class="motor" />
    <general name="lumbar_rot" joint="lumbar_rotation" class="motor" />
    <general name="shoulder_flex_r" joint="arm_flex_r" class="motor" />
    <general name="shoulder_add_r" joint="arm_add_r" class="motor" />
    <general name="shoulder_rot_r" joint="arm_rot_r" class="motor" />
    <general name="elbow_flex_r" joint="elbow_flex_r" class="motor" />
    <general name="pro_sup_r" joint="pro_sup_r" class="motor" />
    <general name="wrist_flex_r" joint="wrist_flex_r" class="motor" />
    <general name="wrist_dev_r" joint="wrist_dev_r" class="motor" />
    <general name="shoulder_flex_l" joint="arm_flex_l" class="motor" />
    <general name="shoulder_add_l" joint="arm_add_l" class="motor" />
    <general name="shoulder_rot_l" joint="arm_rot_l" class="motor" />
    <general name="elbow_flex_l" joint="elbow_flex_l" class="motor" />
    <general name="pro_sup_l" joint="pro_sup_l" class="motor" />
    <general name="wrist_flex_l" joint="wrist_flex_l" class="motor" />
    <general name="wrist_dev_l" joint="wrist_dev_l" class="motor" />
    <motor name="knee_angle_r_rotation3" joint="knee_angle_r_rotation3" class="motor" />
		<motor name="knee_angle_r_rotation2" joint="knee_angle_r_rotation2" class="motor" />
		<motor name="subtalar_angle_l" joint="subtalar_angle_l" class="motor" />
		<motor name="hip_rotation_r" joint="hip_rotation_r" class="motor" />
		<motor name="knee_angle_l_translation1" joint="knee_angle_l_translation1" class="motor" />
		<motor name="knee_angle_l_rotation3" joint="knee_angle_l_rotation3" class="motor" />
		<motor name="ankle_angle_l" joint="ankle_angle_l" class="motor" />
		<motor name="hip_rotation_l" joint="hip_rotation_l" class="motor" />
		<motor name="knee_angle_l_beta_rotation1" joint="knee_angle_l_beta_rotation1" class="motor" />
		<motor name="knee_angle_r_translation1" joint="knee_angle_r_translation1" class="motor" />
		<motor name="pelvis_tz" joint="pelvis_tz" class="motor" />
		<motor name="knee_angle_r_translation2" joint="knee_angle_r_translation2" class="motor" />
		<motor name="mtp_angle_l" joint="mtp_angle_l" class="motor" />
		<motor name="knee_angle_r_beta_translation1" joint="knee_angle_r_beta_translation1" class="motor" />
		<motor name="pelvis_ty" joint="pelvis_ty" class="motor" />
		<motor name="knee_angle_l_beta_translation2" joint="knee_angle_l_beta_translation2" class="motor" />
		<motor name="hip_adduction_l" joint="hip_adduction_l" class="motor" />
		<motor name="knee_angle_l_beta_translation1" joint="knee_angle_l_beta_translation1" class="motor" />
		<motor name="knee_angle_r_beta_rotation1" joint="knee_angle_r_beta_rotation1" class="motor" />
		<motor name="knee_angle_l" joint="knee_angle_l" class="motor" />
		<motor name="subtalar_angle_r" joint="subtalar_angle_r" class="motor" />
		<motor name="pelvis_rotation" joint="pelvis_rotation" class="motor" />
		<motor name="ankle_angle_r" joint="ankle_angle_r" class="motor" />
		<motor name="knee_angle_l_translation2" joint="knee_angle_l_translation2" class="motor" />
		<motor name="knee_angle_l_rotation2" joint="knee_angle_l_rotation2" class="motor" />
		<motor name="knee_angle_r" joint="knee_angle_r" class="motor" />
		<motor name="pelvis_tilt" joint="pelvis_tilt" class="motor" />
		<motor name="knee_angle_r_beta_translation2" joint="knee_angle_r_beta_translation2" class="motor" />
		<motor name="pelvis_list" joint="pelvis_list" class="motor" />
		<motor name="pelvis_tx" joint="pelvis_tx" class="motor" />
		<motor name="hip_flexion_r" joint="hip_flexion_r" class="motor" />
		<motor name="hip_adduction_r" joint="hip_adduction_r" class="motor" />
		<motor name="mtp_angle_r" joint="mtp_angle_r" class="motor" />
		<motor name="hip_flexion_l" joint="hip_flexion_l" class="motor" />
		</actuator>
  <equality>
    <joint name="knee_angle_r_translation2_constraint" active="true" joint1="knee_angle_r_translation2" joint2="knee_angle_r" polycoef="7.69254e-11 0.00587971 -0.00125622 -2.61846e-06 6.24355e-07" solimp="0.9999 0.9999 0.001 0.5 2" />
    <joint name="knee_angle_r_translation1_constraint" active="true" joint1="knee_angle_r_translation1" joint2="knee_angle_r" polycoef="9.53733e-08 0.00312879 -0.00230804 0.000561561 5.68366e-07" solimp="0.9999 0.9999 0.001 0.5 2" />
    <joint name="knee_angle_r_rotation2_constraint" active="true" joint1="knee_angle_r_rotation2" joint2="knee_angle_r" polycoef="-1.47325e-08   0.0791 -0.0328478 -0.0252183 0.0108321" solimp="0.9999 0.9999 0.001 0.5 2" />
    <joint name="knee_angle_r_rotation3_constraint" active="true" joint1="knee_angle_r_rotation3" joint2="knee_angle_r" polycoef="1.08939e-08 0.369499 -0.169478 0.0251643 3.50498e-07" solimp="0.9999 0.9999 0.001 0.5 2" />
    <joint name="knee_angle_r_beta_translation2_constraint" active="true" joint1="knee_angle_r_beta_translation2" joint2="knee_angle_r" polycoef="-0.0108281 -0.0487847 0.00927644 0.0131673 -0.00349673" solimp="0.9999 0.9999 0.001 0.5 2" />
    <joint name="knee_angle_r_beta_translation1_constraint" active="true" joint1="knee_angle_r_beta_translation1" joint2="knee_angle_r" polycoef="0.0524192 -0.0150188 -0.0340522 0.0133393 -0.000879151" solimp="0.9999 0.9999 0.001 0.5 2" />
    <joint name="knee_angle_r_beta_rotation1_constraint" active="true" joint1="knee_angle_r_beta_rotation1" joint2="knee_angle_r" polycoef="0.010506 0.0247615 -1.31647 0.716337 -0.138302" solimp="0.9999 0.9999 0.001 0.5 2" />
    <joint name="subtalar_angle_r_constraint" active="true" joint1="subtalar_angle_r" polycoef="       0        0        0        0        0" />
    <joint name="mtp_angle_r_constraint" active="true" joint1="mtp_angle_r" polycoef="       0        0        0        0        0" />
    <joint name="knee_angle_l_translation2_constraint" active="true" joint1="knee_angle_l_translation2" joint2="knee_angle_l" polycoef="-7.69254e-11 -0.00587971 0.00125622 2.61846e-06 -6.24355e-07" solimp="0.9999 0.9999 0.001 0.5 2" />
    <joint name="knee_angle_l_translation1_constraint" active="true" joint1="knee_angle_l_translation1" joint2="knee_angle_l" polycoef="9.53733e-08 0.00312879 -0.00230804 0.000561561 5.68366e-07" solimp="0.9999 0.9999 0.001 0.5 2" />
    <joint name="knee_angle_l_rotation2_constraint" active="true" joint1="knee_angle_l_rotation2" joint2="knee_angle_l" polycoef="-1.47325e-08   0.0791 -0.0328478 -0.0252183 0.0108321" solimp="0.9999 0.9999 0.001 0.5 2" />
    <joint name="knee_angle_l_rotation3_constraint" active="true" joint1="knee_angle_l_rotation3" joint2="knee_angle_l" polycoef="-1.08939e-08 -0.369499 0.169478 -0.0251643 -3.50498e-07" solimp="0.9999 0.9999 0.001 0.5 2" />
    <joint name="knee_angle_l_beta_translation2_constraint" active="true" joint1="knee_angle_l_beta_translation2" joint2="knee_angle_l" polycoef="-0.0108281 -0.0487847 0.00927644 0.0131673 -0.00349673" solimp="0.9999 0.9999 0.001 0.5 2" />
    <joint name="knee_angle_l_beta_translation1_constraint" active="true" joint1="knee_angle_l_beta_translation1" joint2="knee_angle_l" polycoef="0.0524192 -0.0150188 -0.0340522 0.0133393 -0.000879151" solimp="0.9999 0.9999 0.001 0.5 2" />
    <joint name="knee_angle_l_beta_rotation1_constraint" active="true" joint1="knee_angle_l_beta_rotation1" joint2="knee_angle_l" polycoef="0.010506 0.0247615 -1.31647 0.716337 -0.138302" solimp="0.9999 0.9999 0.001 0.5 2" />
    <joint name="subtalar_angle_l_constraint" active="true" joint1="subtalar_angle_l" polycoef="       0        0        0        0        0" />
    <joint name="mtp_angle_l_constraint" active="true" joint1="mtp_angle_l" polycoef="       0        0        0        0        0" />
    <joint name="wrist_flex_r_constraint" active="true" joint1="wrist_flex_r" polycoef="       0        0        0        0        0" />
    <joint name="wrist_dev_r_constraint" active="true" joint1="wrist_dev_r" polycoef="       0        0        0        0        0" />
    <joint name="wrist_flex_l_constraint" active="true" joint1="wrist_flex_l" polycoef="       0        0        0        0        0" />
    <joint name="wrist_dev_l_constraint" active="true" joint1="wrist_dev_l" polycoef="       0        0        0        0        0" />
    <weld name="origin_to_worldbody" body1="pelvis" active="false" />
  </equality>
</mujoco>