<mujoco model="RRIS Rajagopal">
  <compiler angle="radian" meshdir="character/rris_opensource/" boundmass="0.001" boundinertia="0.001"/>
  <option timestep="0.0003" tolerance="1e-06" integrator="implicitfast" solver="CG" iterations="1000"/>
  <size memory="3G"/>
  <visual>
    <quality shadowsize="2048"/>
    <headlight ambient="0.4 0.4 0.4" diffuse="0.8 0.8 0.8" specular="0.1 0.1 0.1"/>
  </visual>
  <statistic meansize="0.114898" extent="3.42" center="0 0 -0.29"/>
  <default class="main">
    <geom margin="0.001" rgba="0.8 0.6 0.4 1"/>
    <default class="motor">
      <general gainprm="5 0 0 0 0 0 0 0 0 0"/>
    </default>
  </default>
  <extension>
    <plugin plugin="mujoco.elasticity.solid">
      <instance name="flexcomp_softbody1">
        <config key="face" value="19 4 3 33 45 51 53 85 51 63 53 85 58 54 48 85 49 37 48 85 46 45 53 85 51 59 63 85 55 63 77 85 59 54 58 85 59 51 54 85 63 55 53 85 61 59 58 85 59 61 62 85 51 45 50 85 77 63 62 85 51 50 54 85 63 59 62 85 49 48 54 85 37 49 43 85 61 76 62 85 36 66 85 87 53 55 46 85 19 33 3 87 43 52 44 85 50 45 47 85 46 79 47 85 46 47 45 85 66 69 85 87 49 52 43 85 52 78 44 85 66 76 31 85 47 79 78 85 22 40 86 87 85 21 86 87 78 52 47 85 62 69 77 85 4 33 19 30 7 29 8 87 52 50 47 85 84 85 69 87 69 66 65 87 66 36 65 87 42 27 21 87 79 64 78 86 27 32 22 87 9 3 33 87 76 61 67 85 66 31 36 85 10 4 11 12 60 58 48 85 7 39 38 85 27 42 73 87 57 79 46 85 84 77 69 85 31 67 7 85 60 61 58 85 34 9 5 33 33 4 11 30 2 1 33 87 60 7 67 85 48 37 39 85 3 9 32 87 7 60 39 85 79 78 85 86 21 41 85 86 80 41 79 85 27 3 32 87 79 41 64 86 33 19 30 87 17 40 29 86 43 37 85 86 26 38 37 86 6 7 8 87 55 77 81 85 74 73 42 87 81 77 84 85 37 38 39 85 44 43 85 86 43 25 37 86 33 30 2 87 78 44 85 86 18 28 19 87 79 57 80 85 65 36 35 87 26 16 17 86 37 38 85 86 28 18 73 87 79 85 41 86 31 76 67 85 1 2 0 87 78 64 72 86 44 72 68 86 1 9 33 87 27 73 18 87 44 25 43 86 36 6 35 87 44 68 25 86 18 19 3 87 72 44 78 86 26 17 29 86 55 81 56 85 10 19 28 87 19 10 4 30 48 39 60 85 61 60 67 85 23 14 68 86 9 5 3 32 73 75 28 87 75 82 70 87 0 35 6 87 68 71 23 86 5 32 9 34 3 27 18 87 65 35 70 87 71 72 64 86 40 17 13 86 38 26 29 86 68 14 25 86 68 72 71 86 64 41 21 86 19 10 30 87 14 16 25 86 20 22 15 86 8 9 1 87 71 64 20 86 15 24 20 86 13 17 16 86 13 16 14 86 21 22 20 86 15 14 23 86 24 23 71 86 21 20 64 86 11 4 10 30 15 13 14 86 15 23 24 86 71 20 24 86 66 85 62 76 66 62 85 69 11 4 5 12 5 11 33 4 11 5 33 34 6 85 31 7 85 6 31 36 85 6 87 7 6 85 87 36 33 5 3 9 33 3 5 4 49 85 50 52 85 49 50 54 16 86 37 25 86 16 37 26 75 10 35 70 87 75 35 70 87 21 22 27 87 22 21 86 40 29 87 8 29 40 87 86 30 35 10 70 87 74 82 83 87 7 86 85 87 86 7 29 38 86 7 85 38 7 86 29 10 30 0 35 15 20 32 22 15 32 20 24 1 87 6 8 87 1 6 0 87 69 70 65 55 85 57 46 85 55 57 56 32 22 13 15 32 13 22 40 86 13 22 15 86 22 13 40 85 81 87 84 82 81 87 83 82 87 81 84 74 87 75 73 74 75 87 82 87 56 74 83 56 87 74 42 0 87 30 10 0 30 87 2 84 87 70 82 84 70 87 69 87 9 40 8 32 40 87 9 32 87 40 22 87 56 81 85 87 81 56 83 87 57 56 85 57 87 56 42 87 80 57 85 80 87 57 42 87 41 80 85 41 87 80 42 87 21 41 85 21 87 41 42 10 75 87 28 10 87 35 0 87 10 35 75"/>
        <config key="edge" value="0 1 2 3 4 5 6 7 8 9 10 11 12 13 7 9 11 14 15 16 17 18 19 20 21 22 23 18 24 25 26 8 27 9 28 10 29 30 12 14 11 31 32 33 34 35 36 14 37 15 38 19 31 20 29 39 37 20 31 11 32 40 13 9 14 36 41 38 42 19 43 31 41 44 45 46 31 43 6 47 48 49 11 10 33 50 51 46 35 14 48 52 39 20 11 49 30 45 50 46 14 31 23 16 53 20 24 18 21 54 55 56 25 24 57 58 44 46 43 59 60 61 62 63 64 65 40 66 27 28 9 36 4 3 2 67 68 69 70 71 72 73 56 74 47 75 76 77 49 10 78 79 80 77 28 81 80 75 26 10 28 77 82 83 61 63 65 84 85 70 54 56 24 74 86 87 71 73 74 88 89 90 91 92 61 59 79 93 94 88 77 81 95 96 97 98 99 100 101 102 103 98 63 104 86 105 94 77 88 74 106 107 51 35 46 83 5 4 0 108 109 110 111 112 113 114 115 116 117 76 105 77 74 49 118 83 119 84 120 63 82 121 122 123 84 65 60 124 121 123 65 64 125 126 127 104 128 129 130 131 93 132 133 134 135 136 137 99 129 138 139 3 140 69 141 67 57 142 143 144 59 43 91 145 60 62 61 92 146 147 148 149 150 151 152 17 153 18 154 19 155 156 157 158 159 160 125 161 162 163 129 128 164 78 165 28 166 81 167 107 119 83 118 35 168 169 170 159 92 144 171 42 152 19 154 43 172 173 174 175 176 140 5 147 177 178 110 109 179 180 181 69 182 183 184 169 185 144 154 159 22 186 187 160 18 25 139 188 189 138 67 141 184 190 155 160 159 154 93 88 81 103 133 132 191 192 101 103 102 193 194 195 196 81 197 192 198 189 135 138 129 67 195 199 130 134 133 193 4 108 110 200 69 68 201 202 203 204 205 96 55 25 56 103 206 207 208 209 210 207 211 212 213 113 214 114 215 115 34 216 217 218 36 35 219 161 220 128 221 163 216 167 222 118 218 35 209 156 186 160 25 158 72 56 73 103 223 206 224 225 55 207 206 226 110 227 181 182 69 200 87 73 88 103 132 223 228 229 230 68 231 232 164 233 196 197 81 166 124 234 235 236 123 64 237 238 239 205 211 240 209 158 25 103 207 212 228 241 242 163 232 231 81 192 195 193 133 103 90 143 168 144 92 59 179 243 244 245 183 182 131 246 247 248 132 134 249 250 251 252 223 248 253 140 180 69 183 141 162 241 254 231 129 163 255 224 72 206 223 226 256 257 234 236 64 215 251 258 255 226 223 252 230 2 259 67 231 68 249 87 247 132 248 223 239 203 260 204 211 205 217 261 262 263 36 218 264 229 265 232 266 68 264 146 0 109 108 267 187 190 153 154 18 160 171 185 142 144 43 154 268 269 270 252 271 272 173 273 139 189 188 274 275 276 242 232 163 277 278 279 280 281 277 282 283 257 284 215 245 236 285 286 270 271 252 287 274 188 173 172 174 288 198 254 259 231 67 129 235 289 290 281 123 236 291 246 292 134 287 248 201 293 294 295 96 205 208 260 296 204 212 211 269 297 258 226 252 272 250 291 285 287 252 248 199 191 298 102 134 193 264 267 108 200 68 266 299 300 297 226 272 240 301 302 303 304 305 97 306 253 307 183 114 141 292 308 309 305 287 134 310 311 303 305 304 312 293 238 313 240 295 205 313 299 314 272 295 240 315 301 316 305 102 97 317 268 318 271 304 272 319 286 320 287 312 271 316 308 298 134 102 305 147 146 148 267 178 109 321 314 317 272 304 295 318 319 310 312 304 271 309 311 320 312 287 305 61 46 322 58 89 59 322 46 61 83 82 106 147 323 324 325 149 151 324 177 175 5 323 147 324 175 177 176 326 174 327 92 328 170 213 159 327 328 92 145 62 256 327 215 63 115 159 213 327 63 215 64 256 62 175 273 3 139 140 173 3 273 175 323 5 1 24 49 329 117 85 74 24 329 49 52 20 53 240 207 330 225 300 226 240 330 207 210 211 237 331 332 333 289 280 334 277 333 236 289 281 280 104 315 99 137 129 126 99 315 104 102 98 97 202 116 100 114 335 112 202 100 116 98 204 96 336 332 267 334 337 289 221 338 282 339 340 341 115 342 98 103 63 159 98 342 115 111 116 204 212 342 157 159 158 103 157 342 212 204 296 111 267 343 344 283 332 336 303 345 346 136 302 301 346 345 303 311 310 347 183 215 348 214 307 114 183 348 215 284 245 244 84 349 281 290 123 122 36 166 350 165 66 28 36 350 166 351 263 262 136 352 353 321 346 302 353 352 136 95 354 294 295 352 97 302 304 321 97 352 295 294 96 95 218 355 63 120 118 222 356 355 282 340 339 357 282 355 356 222 358 120 221 277 359 275 219 163 359 277 221 282 338 278 360 361 221 341 340 362 360 221 361 220 363 128 245 200 343 267 344 266 343 200 245 182 243 227 120 281 364 279 358 282 364 281 120 84 119 349 141 365 100 335 114 306 354 100 138 141 188 365 138 100 354 95 136 99 360 261 355 218 63 263 355 261 360 362 340 357 366 351 360 263 63 166 366 360 351 363 367 128 368 233 366 166 63 197 368 366 233 367 369 128 370 194 368 197 63 192 370 368 194 369 371 128 104 191 370 192 63 101 104 370 191 371 127 128 331 277 266 232 265 276 266 236 332 283 344 245 266 332 236 333 277 331 0 0 0 0 0 0 0 0 0 0 0 0 0 0 0 0 0 0 0 0 0 0 0 0 0 0 0 0 0 0 0 0 0 0 0 0 0 0 0 0 0 0 0 0 0 0 0 0 0 0 0 0 0 0 0 0 0 0 0 0 0 0 0 0 0 0 0 0 0 0 0 0 0 0 0 0 0 0 0 0 0 0 0 0 0 0 0 0 0 0 0 0 0 0 0 0 0 0 0 0 0 0 0 0 0 0 0 0 0 0 0 0 0 0 0 0 0 0 0 0 0 0 0 0 0 0 0 0 0 0 0 0 0 0 0 0 0 0 0 0 0 0 0 0 0 0 0 0 0 0 0 0 0 0 0 0 0 0 0 0 0 0 0 0 0 0 0 0 0 0 0 0 0 0 0 0 0 0 0 0 0 0 0 0 0 0 0 0 0 0 0 0 0 0 0 0 0 0 0 0 0 0 0 0 0 0 0 0 0 0 0 0 0 0 0 0 0 0 0 0 0 0 0 0 0 0 0 0 0 0 0 0 0 0 0 0 0 0 0 0 0 0 0 0 0 0 0 0 0 0 0 0 0 0 0 0 0 0 0 0 0 0 0 0 0 0 0 0 0 0 0 0 0 0 0 0 0 0 0 0 0 0 0 0 0 0 0 0 0 0 0 0 0 0 0 0 0 0 0 0 0 0 0 0 0 0 0 0 0 0 0 0 0 0 0 0 0 0 0 0 0 0 0 0 0 0 0 0 0 0 0 0 0 0 0 0 0 0 0 0 0 0 0 0 0 0 0 0 0 0 0 0 0 0 0 0 0 0 0 0 0 0 0 0 0 0 0 0 0 0 0 0 0 0 0 0 0 0 0 0 0 0 0 0 0 0 0 0 0 0 0 0 0 0 0 0 0 0 0 0 0 0 0 0 0 0 0 0 0 0 0 0 0 0 0 0 0 0 0 0 0 0 0 0 0 0 0 0 0 0 0 0 0 0 0 0 0 0 0 0 0 0 0 0 0 0 0 0 0 0 0 0 0 0 0 0 0 0 0 0 0 0 0 0 0 0 0 0 0 0 0 0 0 0 0 0 0 0 0 0 0 0 0 0 0 0 0 0 0 0 0 0 0 0 0 0 0 0 0 0 0 0 0 0 0 0 0 0 0 0 0 0 0 0 0 0 0 0 0 0 0 0 0 0 0 0 0 0 0 0 0 0 0 0 0 0 0 0 0 0 0 0 0 0 0 0 0 0 0 0 0 0 0 0 0 0 0 0 0 0 0 0 0 0 0 0 0 0 0 0 0 0 0 0 0 0 0 0 0 0 0 0 0 0 0 0 0 0 0 0 0 0 0 0 0 0 0 0 0 0 0 0 0 0 0 0 0 0 0 0 0 0 0 0 0 0 0 0 0 0 0 0 0 0 0 0 0 0 0 0 0 0 0 0 0 0 0 0 0 0 0 0 0 0 0 0 0 0 0 0 0 0 0 0 0 0 0 0 0 0 0 0 0 0 0 0 0 0 0 0 0 0 0 0 0 0 0 0 0 0 0 0 0 0 0 0 0 0 0 0 0 0 0 0 0 0 0 0 0 0 0 0 0 0 0 0 0 0 0 0 0 0 0 0 0 0 0 0 0 0 0 0 0 0 0 0 0 0 0 0 0 0 0 0 0 0 0 0 0 0 0 0 0 0 0 0 0 0 0 0 0 0 0 0 0 0 0 0 0 0 0 0 0 0 0 0 0 0 0 0 0 0 0 0 0 0 0 0 0 0 0 0 0 0 0 0 0 0 0 0 0 0 0 0 0 0 0 0 0 0 0 0 0 0 0 0 0 0 0 0 0 0 0 0 0 0 0 0 0 0 0 0 0 0 0 0 0 0 0 0 0 0 0 0 0 0 0 0 0 0 0 0 0 0 0 0 0 0 0 0 0 0 0 0 0 0 0 0 0 0 0 0 0 0 0 0 0 0 0 0 0 0 0 0 0 0 0 0 0 0 0 0 0 0 0 0 0 0 0 0 0 0 0 0 0 0 0 0 0 0 0 0 0 0 0 0 0 0 0 0 0 0 0 0 0 0 0 0 0 0 0 0 0 0 0 0 0 0 0 0 0 0 0 0 0 0 0 0 0 0 0 0 0 0 0 0 0 0 0 0 0 0 0 0 0 0 0 0 0 0 0 0 0 0 0 0 0 0 0 0 0 0 0 0 0 0 0 0 0 0 0 0 0 0 0 0 0 0 0 0 0 0 0 0 0 0 0 0 0 0 0 0 0 0 0 0 0 0 0 0 0 0 0 0 0 0 0 0 0 0 0 0 0 0 0 0 0 0 0 0 0 0 0 0 0 0 0 0 0 0 0 0 0 0 0 0 0 0 0 0 0 0 0 0 0 0 0 0 0 0 0 0 0 0 0 0 0 0 0 0 0 0 0 0 0 0 0 0 0 0 0 0 0 0 0 0 0 0 0 0 0 0 0 0 0 0 0 0 0 0 0 0 0 0 0 0 0 0 0 0 0 0 0 0 0 0 0 0 0 0 0 0 0 0 0 0 0 0 0 0 0 0 0 0 0 0 0 0 0 0 0 0 0 0 0 0 0 0 0 0 0 0 0 0 0 0 0 0 0 0 0 0 0 0 0 0 0 0 0 0 0 0 0 0 0 0 0 0 0 0 0 0 0 0 0 0 0 0 0 0 0 0 0 0 0 0 0 0 0 0 0 0 0 0 0 0 0 0 0 0 0 0 0 0 0 0 0 0 0 0 0 0 0 0 0 0 0 0 0 0 0 0 0 0 0 0 0 0 0 0 0 0 0 0 0 0 0 0 0 0 0 0 0 0 0 0 0 0 0 0 0 0 0 0 0 0 0 0 0 0 0 0 0 0 0 0 0 0 0 0 0 0 0 0 0 0 0 0 0 0 0 0 0 0 0 0 0 0 0 0 0 0 0 0 0 0 0 0 0 0 0 0 0 0 0 0 0 0 0 0 0 0 0 0 0 0 0 0 0 0 0 0 0 0 0 0 0 0 0 0 0 0 0 0 0 0 0 0 0 0 0 0 0 0 0 0 0 0 0 0 0 0 0 0 0 0 0 0 0 0 0 0 0 0 0 0 0 0 0 0 0 0 0 0 0 0 0 0 0 0 0 0 0 0 0 0 0 0 0 0 0 0 0 0 0 0 0 0 0 0 0 0 0 0 0 0 0 0 0 0 0 0 0 0 0 0 0 0 0 0 0 0 0 0 0 0 0 0 0 0 0 0 0 0 0 0 0 0 0 0 0 0 0 0 0 0 0 0 0 0 0 0 0 0 0 0 0 0 0 0 0 0 0 0 0 0 0 0 0 0 0 0 0 0 0 0 0 0 0 0 0 0 0 0 0 0 0 0 0 0 0 0 0 0 0 0 0 0 0 0 0 0 0 0 0 0 0 0 0 0 0 0 0 0 0 0 0 0 0 0 0 0 0 0 0 0 0 0 0 0 0 0 0 0 0 0 0 0 0 0 0 0 0 0 0 0 0 0 0 0 0 0 0 0 0 0 0 0 0 0 0 0 0 0 0 0 0 0 0 0 0 0 0 0 0 0 0 0 0 0 0 0 0 0 0 0 0 0 0 0 0 0 0 0 0 0 0 0 0 0 0 0 0 0 0 0 0 0 0 0 0 0 0 0 0 0 0 0 0 0 0 0 0 0 0 0 0 0 0 0 0 0 0 0 0 0 0 0 0 0 0 0 0 0 0 0 0 0 0 0 0 0 0 0 0 0 0 0 0 0 0 0 0 0 0 0 0 0 0 0 0 0 0 0 0 0 0 0 0 0 0 0 0 0 0 0 0 0 0 0 0 0 0 0 0 0 0 0 0 0 0 0 0 0 0 0 0 0 0 0 0 0 0 0 0 0 0 0 0 0 0 0 0 0 0 0 0 0 0 0 0 0 0 0 0 0 0 0 0 0 0 0 0 0 0 0 0 0 0 0 0 0 0 0 0 0 0 0 0 0 0 0 0 0 0 0 0 0 0 0 0 0 0 0 0 0 0 0 0 0 0 0 0 0 0 0 0 0 0 0 0 0 0 0 0 0 0 0 0 0 0 0 0 0 0 0 0 0 0 0 0 0 0 0 0 0 0 0 0 0 0 0 0 0 0 0 0 0 0 0 0 0 0 0 0 0 0 0 0 0 0 0 0 0 0 0 0 0 0 0 0 0 0 0 0 0 0 0 0 0 0 0 0 0 0 0 0 0 0 0 0 0 0 0 0 0 0 0 0 0 0 0 0 0 0 0 0 0 0 0 0 0 0 0 0 0 0 0 0 0 0 0 0 0 0 0 0 0 0 0 0 0 0 0 0 0 0 0 0 0 0 0 0 0 0 0 0 0 0 0 0 0 0 0 0 0 0 0 0 0 0 0 0 0 0 0 0 0 0 0 0 0 0 0 0 0 0 0 0 0 0 0 0 0 0 0 0 0 0 0 0 0 0 0 0 0 0 0 0 0 0 0 0 0 0 0 0 0 0 0 0 0 0 0 0 0 0 0 0 0 0 0 0 0 0 0 0 0 0 0 0 0 0 0 0 0 0 0 0 0 0 0 0 0 0 0 0 0 0 0 0 0 0 0 0 0 0 0 0 0 0 0 0 0 0 0 0 0 0 0 0 0 0 0 0 0 0 0 0 0 0 0 0 0 0 0 0 0 0 0 0 0 0 0 0 0 0 0 0 0 0 0 0 0 0 0 0 0 0 0 0 0 0 0 0 0 0 0 0 0 0 0 0 0 0 0 0 0 0 0 0 0 0 0 0 0 0 0 0 0 0 0 0 0 0 0 0 0 0 0 0 0 0 0 0 0 0 0 0 0 0 0 0 0 0 0 0 0 0 0 0 0 0 0 0 0 0 0 0 0 0 0 0 0 0 0 0 0 0 0 0 0 0 0 0 0 0 0 0 0 0 0 0 0 0 0 0 0 0 0 0 0 0 0 0 0 0 0 0 0 0 0 0 0 0 0 0 0 0 0 0 0 0 0 0 0 0 0 0 0 0 0 0 0 0 0 0 0 0 0 0 0 0 0 0 0 0 0 0 0 0 0 0 0 0 0 0 0 0 0 0 0 0 0 0 0 0 0 0 0 0 0 0 0 0 0 0 0 0 0 0 0 0 0 0 0 0 0 0 0 0 0 0 0 0 0 0 0 0 0 0 0 0 0 0 0 0 0 0 0 0 0 0 0 0 0 0 0 0 0 0 0 0 0 0 0 0 0 0 0 0 0 0 0 0 0 0 0 0 0 0 0 0 0 0 0 0 0 0 0 0 0 0 0 0 0 0 0 0 0 0 0 0 0 0 0 0 0 0 0 0 0 0 0 0 0 0 0 0 0 0 0 0 0 0 0 0 0 0 0 0 0 0 0 0 0 0 0 0 0 0 0 0 0 0 0 0 0 0 0 0 0 0 0 0 0 0 0 0 0 0 0 0 0 0 0 0 0 0 0 0 0 0 0 0 0 0 0 0 0 0 0 0 0 0 0 0 0 0 0 0 0 0 0 0 0 0 0 0 0 0 0 0 0 0 0 0 0 0 0 0 0 0 0 0 0 0 0 0 0 0 0 0 0 0 0 0 0 0 0 0 0 0 0 0 0 0 0 0 0 0 0 0 0 0 0 0 0 0 0 0 0 0 0 0 0 0 0 0 0 0 0 0 0 0 0 0 0 0 0 0 0 0 0 0 0 0 0 0 0 0 0 0 0 0 0 0 0 0 0 0 0 0 0 0 0 0 0 0 0 0 0 0 0 0 0 0 0 0 0 0 0 0 0 0 0 0 0 0 0 0 0 0 0 0 0 0 0 0 0 0 0 0 0 0 0 0 0 0 0 0 0 0 0 0 0 0 0 0 0 0 0 0 0 0 0 0 0 0 0 0 0 0 0 0 0 0 0 0 0 0 0 0 0 0 0 0 0 0 0 0 0 0 0 0 0 0 0 0 0 0 0 0 0 0 0 0 0 0 0 0 0 0 0 0 0 0 0 0 0 0 0 0 0 0 0 0 0 0 0 0 0 0 0 0 0 0 0 0 0 0 0 0 0 0 0 0 0 0 0 0 0 0 0 0 0 0 0 0 0 0 0 0 0 0 0 0 0 0 0 0 0 0 0 0 0 0 0 0 0 0 0 0 0 0 0 0 0 0 0 0 0 0 0 0 0 0 0 0 0 0 0 0 0 0 0 0 0 0 0 0 0 0 0 0 0 0 0 0 0 0 0 0 0 0 0 0 0 0 0 0 0 0 0 0 0 0 0 0 0 0 0 0 0 0 0 0 0 0 0 0 0 0 0 0 0 0 0 0 0 0 0 0 0 0 0 0 0 0 0 0 0 0 0 0 0 0 0 0 0 0 0 0 0 0 0 0 0 0 0 0 0 0 0 0 0 0 0 0 0 0 0 0 0 0 0 0 0 0 0 0 0 0 0 0 0 0 0 0 0 0 0 0 0 0 0 0 0 0 0 0 0 0 0 0 0 0 0 0 0 0 0 0 0 0 0 0 0 0 0 0 0 0 0 0 0 0 0 0 0 0 0 0 0 0 0 0 0 0 0 0 0 0 0 0 0 0 0 0 0 0 0 0 0 0 0 0 0 0 0 0 0 0 0 0 0 0 0 0 0 0 0 0 0 0 0 0 0 0 0 0 0 0 0 0 0 0 0 0 0 0 0 0 0 0 0 0 0 0 0 0 0 0 0 0 0 0 0 0 0 0 0 0 0 0 0 0 0 0 0 0 0 0 0 0 0 0 0 0 0 0 0 0 0 0 0 0 0 0 0 0 0 0 0 0 0 0 0 0 0 0 0 0 0 0 0 0 0 0 0 0 0 0 0 0 0 0 0 0 0 0 0 0 0 0 0 0 0 0 0 0 0 0 0 0 0 0 0 0 0 0 0 0 0 0 0 0 0 0 0 0 0 0 0 0 0 0 0 0 0 0 0 0 0 0 0 0 0 0 0 0 0 0 0 0 0 0 0 0 0 0 0 0 0 0 0 0 0 0 0 0 0 0 0 0 0 0 0 0 0 0 0 0 0 0 0 0 0 0 0 0 0 0 0 0 0 0 0 0 0 0 0 0 0 0 0 0 0 0 0 0 0 0 0 0 0 0 0 0 0 0 0 0 0 0 0 0 0 0 0 0 0 0 0 0 0 0 0 0 0 0 0 0 0 0 0 0 0 0 0 0 0 0 0 0 0 0 0 0 0 0 0 0 0 0 0 0 0 0 0 0 0 0 0 0 0 0 0 0 0 0 0 0 0 0 0 0 0 0 0 0 0 0 0 0 0 0 0 0 0 0 0 0 0 0 0 0 0 0 0 0 0 0 0 0 0 0 0 0 0 0 0 0 0 0 0 0 0 0 0 0 0 0 0 0 0 0 0 0 0 0 0 0 0 0 0 0 0 0 0 0 0 0 0 0 0 0 0 0 0 0 0 0 0 0 0 0 0 0 0 0 0 0 0 0 0 0 0 0 0 0 0 0 0 0 0 0 0 0 0 0 0 0 0 0 0 0 0 0 0 0 0 0 0 0 0 0 0 0 0 0 0 0 0 0 0 0 0 0 0 0 0 0 0 0 0 0 0 0 0 0 0 0 0 0 0 0 0 0 0 0 0 0 0 0 0 0 0 0 0 0 0 0 0 0 0 0 0 0 0 0 0 0 0 0 0 0 0 0 0 0 0 0 0 0 0 0 0 0 0 0 0 0 0 0 0 0 0 0 0 0 0 0 0 0 0 0 0 0 0 0 0 0 0 0 0 0 0 0 0 0 0 0 0 0 0 0 0 0 0 0 0 0 0 0 0 0 0 0 0 0 0 0 0 0 0 0 0 0 0 0 0 0 0 0 0 0 0 0 0 0 0 0 0 0 0 0 0 0 0 0 0 0 0 0 0 0 0 0 0 0 0 0 0 0 0 0 0 0 0 0 0 0 0 0 0 0 0 0 0 0 0 0 0 0 0 0 0 0 0 0 0 0 0 0 0 0 0 0 0 0 0 0 0 0 0 0 0 0 0 0 0 0 0 0 0 0 0 0 0 0 0 0 0 0 0 0 0 0 0 0 0 0 0 0 0 0 0 0 0 0 0 0 0 0 0 0 0 0 0 0 0 0 0 0 0 0 0 0 0 0 0 0 0 0 0 0 0 0 0 0 0 0 0 0 0"/>
        <config key="young" value="1.5e6"/>
        <config key="poisson" value="0.4"/>
        <config key="damping" value="0.1"/>
      </instance>
    </plugin>
  </extension>
  <asset>
    <texture type="skybox" name="skybox" builtin="gradient" mark="random" rgb1="0.4 0.6 0.8" rgb2="0 0 0" markrgb="1 1 1" width="800" height="4800"/>
    <texture type="2d" name="texplane" builtin="checker" rgb1="0.2 0.3 0.4" rgb2="0.1 0.15 0.2" width="100" height="100"/>
    <material name="MatPlane" texture="texplane" texuniform="true"/>
    <mesh name="r_pelvis" file="Geometry/r_pelvis.stl" scale="1.15666 1.15666 0.936706"/>
    <mesh name="l_pelvis" file="Geometry/l_pelvis.stl" scale="1.15666 1.15666 0.936706"/>
    <mesh name="sacrum" file="Geometry/sacrum.stl" scale="1.15666 1.15666 0.936706"/>
    <mesh name="r_femur" file="Geometry/r_femur.stl" scale="0.974653 0.974653 0.974653"/>
    <mesh name="r_tibia" file="Geometry/r_tibia.stl" scale="1.10963 1.10963 1.10963"/>
    <mesh name="r_fibula" file="Geometry/r_fibula.stl" scale="1.10963 1.10963 1.10963"/>
    <mesh name="r_talus" file="Geometry/r_talus.stl" scale="0.863394 0.863394 0.863394"/>
    <mesh name="r_foot" file="Geometry/r_foot.stl" scale="0.863394 0.863394 0.863394"/>
    <mesh name="r_bofoot" file="Geometry/r_bofoot.stl" scale="0.863394 0.863394 0.863394"/>
    <mesh name="r_patella" file="Geometry/r_patella.stl"/>
    <mesh name="l_femur" file="Geometry/l_femur.stl" scale="0.981062 0.981062 0.981062"/>
    <mesh name="l_tibia" file="Geometry/l_tibia.stl" scale="1.13552 1.13552 1.13552"/>
    <mesh name="l_fibula" file="Geometry/l_fibula.stl" scale="1.13552 1.13552 1.13552"/>
    <mesh name="l_talus" file="Geometry/l_talus.stl" scale="0.919209 0.919209 0.919209"/>
    <mesh name="l_foot" file="Geometry/l_foot.stl" scale="0.919209 0.919209 0.919209"/>
    <mesh name="l_bofoot" file="Geometry/l_bofoot.stl" scale="0.919209 0.919209 0.919209"/>
    <mesh name="l_patella" file="Geometry/l_patella.stl"/>
    <mesh name="hat_spine" file="Geometry/hat_spine.stl" scale="1.09445 1.09445 1.09445"/>
    <mesh name="hat_jaw" file="Geometry/hat_jaw.stl" scale="1.09445 1.09445 1.09445"/>
    <mesh name="hat_skull" file="Geometry/hat_skull.stl" scale="1.09445 1.09445 1.09445"/>
    <mesh name="hat_ribs_scap" file="Geometry/hat_ribs_scap.stl" scale="1.09445 1.09445 1.09445"/>
    <mesh name="humerus_rv" file="Geometry/humerus_rv.stl" scale="1.08795 1.08795 1.08795"/>
    <mesh name="ulna_rv" file="Geometry/ulna_rv.stl" scale="1.10717 1.10717 1.10717"/>
    <mesh name="radius_rv" file="Geometry/radius_rv.stl" scale="1.16388 1.16388 1.16388"/>
    <mesh name="pisiform_rvs" file="Geometry/pisiform_rvs.stl" scale="0.85 0.85 0.85"/>
    <mesh name="lunate_rvs" file="Geometry/lunate_rvs.stl" scale="0.85 0.85 0.85"/>
    <mesh name="scaphoid_rvs" file="Geometry/scaphoid_rvs.stl" scale="0.85 0.85 0.85"/>
    <mesh name="triquetrum_rvs" file="Geometry/triquetrum_rvs.stl" scale="0.85 0.85 0.85"/>
    <mesh name="hamate_rvs" file="Geometry/hamate_rvs.stl" scale="0.85 0.85 0.85"/>
    <mesh name="capitate_rvs" file="Geometry/capitate_rvs.stl" scale="0.85 0.85 0.85"/>
    <mesh name="trapezoid_rvs" file="Geometry/trapezoid_rvs.stl" scale="0.85 0.85 0.85"/>
    <mesh name="trapezium_rvs" file="Geometry/trapezium_rvs.stl" scale="0.85 0.85 0.85"/>
    <mesh name="metacarpal2_rvs" file="Geometry/metacarpal2_rvs.stl" scale="0.85 0.85 0.85"/>
    <mesh name="index_proximal_rvs" file="Geometry/index_proximal_rvs.stl" scale="0.85 0.85 0.85"/>
    <mesh name="index_medial_rvs" file="Geometry/index_medial_rvs.stl" scale="0.85 0.85 0.85"/>
    <mesh name="index_distal_rvs" file="Geometry/index_distal_rvs.stl" scale="0.85 0.85 0.85"/>
    <mesh name="metacarpal3_rvs" file="Geometry/metacarpal3_rvs.stl" scale="0.85 0.85 0.85"/>
    <mesh name="middle_proximal_rvs" file="Geometry/middle_proximal_rvs.stl" scale="0.85 0.85 0.85"/>
    <mesh name="middle_medial_rvs" file="Geometry/middle_medial_rvs.stl" scale="0.85 0.85 0.85"/>
    <mesh name="middle_distal_rvs" file="Geometry/middle_distal_rvs.stl" scale="0.85 0.85 0.85"/>
    <mesh name="metacarpal4_rvs" file="Geometry/metacarpal4_rvs.stl" scale="0.85 0.85 0.85"/>
    <mesh name="ring_proximal_rvs" file="Geometry/ring_proximal_rvs.stl" scale="0.85 0.85 0.85"/>
    <mesh name="ring_medial_rvs" file="Geometry/ring_medial_rvs.stl" scale="0.85 0.85 0.85"/>
    <mesh name="ring_distal_rvs" file="Geometry/ring_distal_rvs.stl" scale="0.85 0.85 0.85"/>
    <mesh name="metacarpal5_rvs" file="Geometry/metacarpal5_rvs.stl" scale="0.85 0.85 0.85"/>
    <mesh name="little_proximal_rvs" file="Geometry/little_proximal_rvs.stl" scale="0.85 0.85 0.85"/>
    <mesh name="little_medial_rvs" file="Geometry/little_medial_rvs.stl" scale="0.85 0.85 0.85"/>
    <mesh name="little_distal_rvs" file="Geometry/little_distal_rvs.stl" scale="0.85 0.85 0.85"/>
    <mesh name="metacarpal1_rvs" file="Geometry/metacarpal1_rvs.stl" scale="0.85 0.85 0.85"/>
    <mesh name="thumb_proximal_rvs" file="Geometry/thumb_proximal_rvs.stl" scale="0.85 0.85 0.85"/>
    <mesh name="thumb_distal_rvs" file="Geometry/thumb_distal_rvs.stl" scale="0.85 0.85 0.85"/>
    <mesh name="humerus_lv" file="Geometry/humerus_lv.stl" scale="1.07291 1.07291 1.07291"/>
    <mesh name="ulna_lv" file="Geometry/ulna_lv.stl" scale="1.11541 1.11541 1.11541"/>
    <mesh name="radius_lv" file="Geometry/radius_lv.stl" scale="1.16522 1.16522 1.16522"/>
    <mesh name="pisiform_lvs" file="Geometry/pisiform_lvs.stl" scale="0.85 0.85 0.85"/>
    <mesh name="lunate_lvs" file="Geometry/lunate_lvs.stl" scale="0.85 0.85 0.85"/>
    <mesh name="scaphoid_lvs" file="Geometry/scaphoid_lvs.stl" scale="0.85 0.85 0.85"/>
    <mesh name="triquetrum_lvs" file="Geometry/triquetrum_lvs.stl" scale="0.85 0.85 0.85"/>
    <mesh name="hamate_lvs" file="Geometry/hamate_lvs.stl" scale="0.85 0.85 0.85"/>
    <mesh name="capitate_lvs" file="Geometry/capitate_lvs.stl" scale="0.85 0.85 0.85"/>
    <mesh name="trapezoid_lvs" file="Geometry/trapezoid_lvs.stl" scale="0.85 0.85 0.85"/>
    <mesh name="trapezium_lvs" file="Geometry/trapezium_lvs.stl" scale="0.85 0.85 0.85"/>
    <mesh name="metacarpal2_lvs" file="Geometry/metacarpal2_lvs.stl" scale="0.85 0.85 0.85"/>
    <mesh name="index_proximal_lvs" file="Geometry/index_proximal_lvs.stl" scale="0.85 0.85 0.85"/>
    <mesh name="index_medial_lvs" file="Geometry/index_medial_lvs.stl" scale="0.85 0.85 0.85"/>
    <mesh name="index_distal_lvs" file="Geometry/index_distal_lvs.stl" scale="0.85 0.85 0.85"/>
    <mesh name="metacarpal3_lvs" file="Geometry/metacarpal3_lvs.stl" scale="0.85 0.85 0.85"/>
    <mesh name="middle_proximal_lvs" file="Geometry/middle_proximal_lvs.stl" scale="0.85 0.85 0.85"/>
    <mesh name="middle_medial_lvs" file="Geometry/middle_medial_lvs.stl" scale="0.85 0.85 0.85"/>
    <mesh name="middle_distal_lvs" file="Geometry/middle_distal_lvs.stl" scale="0.85 0.85 0.85"/>
    <mesh name="metacarpal4_lvs" file="Geometry/metacarpal4_lvs.stl" scale="0.85 0.85 0.85"/>
    <mesh name="ring_proximal_lvs" file="Geometry/ring_proximal_lvs.stl" scale="0.85 0.85 0.85"/>
    <mesh name="ring_medial_lvs" file="Geometry/ring_medial_lvs.stl" scale="0.85 0.85 0.85"/>
    <mesh name="ring_distal_lvs" file="Geometry/ring_distal_lvs.stl" scale="0.85 0.85 0.85"/>
    <mesh name="metacarpal5_lvs" file="Geometry/metacarpal5_lvs.stl" scale="0.85 0.85 0.85"/>
    <mesh name="little_proximal_lvs" file="Geometry/little_proximal_lvs.stl" scale="0.85 0.85 0.85"/>
    <mesh name="little_medial_lvs" file="Geometry/little_medial_lvs.stl" scale="0.85 0.85 0.85"/>
    <mesh name="little_distal_lvs" file="Geometry/little_distal_lvs.stl" scale="0.85 0.85 0.85"/>
    <mesh name="metacarpal1_lvs" file="Geometry/metacarpal1_lvs.stl" scale="0.85 0.85 0.85"/>
    <mesh name="thumb_proximal_lvs" file="Geometry/thumb_proximal_lvs.stl" scale="0.85 0.85 0.85"/>
    <mesh name="thumb_distal_lvs" file="Geometry/thumb_distal_lvs.stl" scale="0.85 0.85 0.85"/>
  </asset>
  <worldbody>
    <geom name="floor" size="10 10 0.125" pos="0 0 -1" type="plane" material="MatPlane"/>
    <camera name="for_testing" pos="0 0 0"/>
    <body name="test" pos="-0.22 0 0.71">
      <body name="softbody1_0" pos="0.107834 0.0621072 -0.0945101">
        <inertial pos="0 0 0" mass="1.13636" diaginertia="0.001 0.001 0.001"/>
        <joint pos="0 0 0" axis="1 0 0" type="slide"/>
        <joint pos="0 0 0" axis="0 1 0" type="slide"/>
        <joint pos="0 0 0" axis="0 0 1" type="slide"/>
        <plugin instance="flexcomp_softbody1"/>
      </body>
      <body name="softbody1_1" pos="0.171312 0.0581395 -0.0723952">
        <inertial pos="0 0 0" mass="1.13636" diaginertia="0.001 0.001 0.001"/>
        <joint pos="0 0 0" axis="1 0 0" type="slide"/>
        <joint pos="0 0 0" axis="0 1 0" type="slide"/>
        <joint pos="0 0 0" axis="0 0 1" type="slide"/>
        <plugin instance="flexcomp_softbody1"/>
      </body>
      <body name="softbody1_2" pos="0.13413 0.0525769 -0.101508">
        <inertial pos="0 0 0" mass="1.13636" diaginertia="0.001 0.001 0.001"/>
        <joint pos="0 0 0" axis="1 0 0" type="slide"/>
        <joint pos="0 0 0" axis="0 1 0" type="slide"/>
        <joint pos="0 0 0" axis="0 0 1" type="slide"/>
        <plugin instance="flexcomp_softbody1"/>
      </body>
      <body name="softbody1_3" pos="0.187544 -0.0490479 -0.063489">
        <inertial pos="0 0 0" mass="1.13636" diaginertia="0.001 0.001 0.001"/>
        <joint pos="0 0 0" axis="1 0 0" type="slide"/>
        <joint pos="0 0 0" axis="0 1 0" type="slide"/>
        <joint pos="0 0 0" axis="0 0 1" type="slide"/>
        <plugin instance="flexcomp_softbody1"/>
      </body>
      <body name="softbody1_4" pos="0.198939 -0.0274488 -0.0978359">
        <inertial pos="0 0 0" mass="1.13636" diaginertia="0.001 0.001 0.001"/>
        <joint pos="0 0 0" axis="1 0 0" type="slide"/>
        <joint pos="0 0 0" axis="0 1 0" type="slide"/>
        <joint pos="0 0 0" axis="0 0 1" type="slide"/>
        <plugin instance="flexcomp_softbody1"/>
      </body>
      <body name="softbody1_5" pos="0.215609 -0.0133249 -0.0926856">
        <inertial pos="0 0 0" mass="1.13636" diaginertia="0.001 0.001 0.001"/>
        <joint pos="0 0 0" axis="1 0 0" type="slide"/>
        <joint pos="0 0 0" axis="0 1 0" type="slide"/>
        <joint pos="0 0 0" axis="0 0 1" type="slide"/>
        <plugin instance="flexcomp_softbody1"/>
      </body>
      <body name="softbody1_6" pos="0.0867928 0.0929105 -0.0204018">
        <inertial pos="0 0 0" mass="1.13636" diaginertia="0.001 0.001 0.001"/>
        <joint pos="0 0 0" axis="1 0 0" type="slide"/>
        <joint pos="0 0 0" axis="0 1 0" type="slide"/>
        <joint pos="0 0 0" axis="0 0 1" type="slide"/>
        <plugin instance="flexcomp_softbody1"/>
      </body>
      <body name="softbody1_7" pos="0.0877423 0.0951701 -0.000979011">
        <inertial pos="0 0 0" mass="1.13636" diaginertia="0.001 0.001 0.001"/>
        <joint pos="0 0 0" axis="1 0 0" type="slide"/>
        <joint pos="0 0 0" axis="0 1 0" type="slide"/>
        <joint pos="0 0 0" axis="0 0 1" type="slide"/>
        <plugin instance="flexcomp_softbody1"/>
      </body>
      <body name="softbody1_8" pos="0.174531 0.0631872 -0.0204634">
        <inertial pos="0 0 0" mass="1.13636" diaginertia="0.001 0.001 0.001"/>
        <joint pos="0 0 0" axis="1 0 0" type="slide"/>
        <joint pos="0 0 0" axis="0 1 0" type="slide"/>
        <joint pos="0 0 0" axis="0 0 1" type="slide"/>
        <plugin instance="flexcomp_softbody1"/>
      </body>
      <body name="softbody1_9" pos="0.190266 0.0499363 -0.0551238">
        <inertial pos="0 0 0" mass="1.13636" diaginertia="0.001 0.001 0.001"/>
        <joint pos="0 0 0" axis="1 0 0" type="slide"/>
        <joint pos="0 0 0" axis="0 1 0" type="slide"/>
        <joint pos="0 0 0" axis="0 0 1" type="slide"/>
        <plugin instance="flexcomp_softbody1"/>
      </body>
      <body name="softbody1_10" pos="0.169403 -0.0170699 -0.12234">
        <inertial pos="0 0 0" mass="1.13636" diaginertia="0.001 0.001 0.001"/>
        <joint pos="0 0 0" axis="1 0 0" type="slide"/>
        <joint pos="0 0 0" axis="0 1 0" type="slide"/>
        <joint pos="0 0 0" axis="0 0 1" type="slide"/>
        <plugin instance="flexcomp_softbody1"/>
      </body>
      <body name="softbody1_11" pos="0.206811 0.0152968 -0.103705">
        <inertial pos="0 0 0" mass="1.13636" diaginertia="0.001 0.001 0.001"/>
        <joint pos="0 0 0" axis="1 0 0" type="slide"/>
        <joint pos="0 0 0" axis="0 1 0" type="slide"/>
        <joint pos="0 0 0" axis="0 0 1" type="slide"/>
        <plugin instance="flexcomp_softbody1"/>
      </body>
      <body name="softbody1_12" pos="0.205381 -0.0144015 -0.103624">
        <inertial pos="0 0 0" mass="1.13636" diaginertia="0.001 0.001 0.001"/>
        <joint pos="0 0 0" axis="1 0 0" type="slide"/>
        <joint pos="0 0 0" axis="0 1 0" type="slide"/>
        <joint pos="0 0 0" axis="0 0 1" type="slide"/>
        <plugin instance="flexcomp_softbody1"/>
      </body>
      <body name="softbody1_13" pos="0.180845 0.034679 0.0780506">
        <inertial pos="0 0 0" mass="1.13636" diaginertia="0.001 0.001 0.001"/>
        <joint pos="0 0 0" axis="1 0 0" type="slide"/>
        <joint pos="0 0 0" axis="0 1 0" type="slide"/>
        <joint pos="0 0 0" axis="0 0 1" type="slide"/>
        <plugin instance="flexcomp_softbody1"/>
      </body>
      <body name="softbody1_14" pos="0.16125 0.02175 0.1045">
        <inertial pos="0 0 0" mass="1.13636" diaginertia="0.001 0.001 0.001"/>
        <joint pos="0 0 0" axis="1 0 0" type="slide"/>
        <joint pos="0 0 0" axis="0 1 0" type="slide"/>
        <joint pos="0 0 0" axis="0 0 1" type="slide"/>
        <plugin instance="flexcomp_softbody1"/>
      </body>
      <body name="softbody1_15" pos="0.183066 0.018357 0.084337">
        <inertial pos="0 0 0" mass="1.13636" diaginertia="0.001 0.001 0.001"/>
        <joint pos="0 0 0" axis="1 0 0" type="slide"/>
        <joint pos="0 0 0" axis="0 1 0" type="slide"/>
        <joint pos="0 0 0" axis="0 0 1" type="slide"/>
        <plugin instance="flexcomp_softbody1"/>
      </body>
      <body name="softbody1_16" pos="0.147247 0.0432264 0.0990303">
        <inertial pos="0 0 0" mass="1.13636" diaginertia="0.001 0.001 0.001"/>
        <joint pos="0 0 0" axis="1 0 0" type="slide"/>
        <joint pos="0 0 0" axis="0 1 0" type="slide"/>
        <joint pos="0 0 0" axis="0 0 1" type="slide"/>
        <plugin instance="flexcomp_softbody1"/>
      </body>
      <body name="softbody1_17" pos="0.172073 0.05097 0.066762">
        <inertial pos="0 0 0" mass="1.13636" diaginertia="0.001 0.001 0.001"/>
        <joint pos="0 0 0" axis="1 0 0" type="slide"/>
        <joint pos="0 0 0" axis="0 1 0" type="slide"/>
        <joint pos="0 0 0" axis="0 0 1" type="slide"/>
        <plugin instance="flexcomp_softbody1"/>
      </body>
      <body name="softbody1_18" pos="0.169078 -0.0594582 -0.0662467">
        <inertial pos="0 0 0" mass="1.13636" diaginertia="0.001 0.001 0.001"/>
        <joint pos="0 0 0" axis="1 0 0" type="slide"/>
        <joint pos="0 0 0" axis="0 1 0" type="slide"/>
        <joint pos="0 0 0" axis="0 0 1" type="slide"/>
        <plugin instance="flexcomp_softbody1"/>
      </body>
      <body name="softbody1_19" pos="0.177362 -0.0478895 -0.0850807">
        <inertial pos="0 0 0" mass="1.13636" diaginertia="0.001 0.001 0.001"/>
        <joint pos="0 0 0" axis="1 0 0" type="slide"/>
        <joint pos="0 0 0" axis="0 1 0" type="slide"/>
        <joint pos="0 0 0" axis="0 0 1" type="slide"/>
        <plugin instance="flexcomp_softbody1"/>
      </body>
      <body name="softbody1_20" pos="0.176813 -0.0361459 0.0756697">
        <inertial pos="0 0 0" mass="1.13636" diaginertia="0.001 0.001 0.001"/>
        <joint pos="0 0 0" axis="1 0 0" type="slide"/>
        <joint pos="0 0 0" axis="0 1 0" type="slide"/>
        <joint pos="0 0 0" axis="0 0 1" type="slide"/>
        <plugin instance="flexcomp_softbody1"/>
      </body>
      <body name="softbody1_21" pos="0.150044 -0.064163 0.0573907">
        <inertial pos="0 0 0" mass="1.13636" diaginertia="0.001 0.001 0.001"/>
        <joint pos="0 0 0" axis="1 0 0" type="slide"/>
        <joint pos="0 0 0" axis="0 1 0" type="slide"/>
        <joint pos="0 0 0" axis="0 0 1" type="slide"/>
        <plugin instance="flexcomp_softbody1"/>
      </body>
      <body name="softbody1_22" pos="0.18682 -0.0481523 0.0327571">
        <inertial pos="0 0 0" mass="1.13636" diaginertia="0.001 0.001 0.001"/>
        <joint pos="0 0 0" axis="1 0 0" type="slide"/>
        <joint pos="0 0 0" axis="0 1 0" type="slide"/>
        <joint pos="0 0 0" axis="0 0 1" type="slide"/>
        <plugin instance="flexcomp_softbody1"/>
      </body>
      <body name="softbody1_23" pos="0.163 -0.0005 0.107">
        <inertial pos="0 0 0" mass="1.13636" diaginertia="0.001 0.001 0.001"/>
        <joint pos="0 0 0" axis="1 0 0" type="slide"/>
        <joint pos="0 0 0" axis="0 1 0" type="slide"/>
        <joint pos="0 0 0" axis="0 0 1" type="slide"/>
        <plugin instance="flexcomp_softbody1"/>
      </body>
      <body name="softbody1_24" pos="0.180954 -0.00817008 0.0887331">
        <inertial pos="0 0 0" mass="1.13636" diaginertia="0.001 0.001 0.001"/>
        <joint pos="0 0 0" axis="1 0 0" type="slide"/>
        <joint pos="0 0 0" axis="0 1 0" type="slide"/>
        <joint pos="0 0 0" axis="0 0 1" type="slide"/>
        <plugin instance="flexcomp_softbody1"/>
      </body>
      <body name="softbody1_25" pos="0.13175 0.022 0.1165">
        <inertial pos="0 0 0" mass="1.13636" diaginertia="0.001 0.001 0.001"/>
        <joint pos="0 0 0" axis="1 0 0" type="slide"/>
        <joint pos="0 0 0" axis="0 1 0" type="slide"/>
        <joint pos="0 0 0" axis="0 0 1" type="slide"/>
        <plugin instance="flexcomp_softbody1"/>
      </body>
      <body name="softbody1_26" pos="0.139661 0.0574327 0.0864849">
        <inertial pos="0 0 0" mass="1.13636" diaginertia="0.001 0.001 0.001"/>
        <joint pos="0 0 0" axis="1 0 0" type="slide"/>
        <joint pos="0 0 0" axis="0 1 0" type="slide"/>
        <joint pos="0 0 0" axis="0 0 1" type="slide"/>
        <plugin instance="flexcomp_softbody1"/>
      </body>
      <body name="softbody1_27" pos="0.173753 -0.0629451 -0.0175606">
        <inertial pos="0 0 0" mass="1.13636" diaginertia="0.001 0.001 0.001"/>
        <joint pos="0 0 0" axis="1 0 0" type="slide"/>
        <joint pos="0 0 0" axis="0 1 0" type="slide"/>
        <joint pos="0 0 0" axis="0 0 1" type="slide"/>
        <plugin instance="flexcomp_softbody1"/>
      </body>
      <body name="softbody1_28" pos="0.116603 -0.0611038 -0.0984488">
        <inertial pos="0 0 0" mass="1.13636" diaginertia="0.001 0.001 0.001"/>
        <joint pos="0 0 0" axis="1 0 0" type="slide"/>
        <joint pos="0 0 0" axis="0 1 0" type="slide"/>
        <joint pos="0 0 0" axis="0 0 1" type="slide"/>
        <plugin instance="flexcomp_softbody1"/>
      </body>
      <body name="softbody1_29" pos="0.139142 0.0715661 0.058955">
        <inertial pos="0 0 0" mass="1.13636" diaginertia="0.001 0.001 0.001"/>
        <joint pos="0 0 0" axis="1 0 0" type="slide"/>
        <joint pos="0 0 0" axis="0 1 0" type="slide"/>
        <joint pos="0 0 0" axis="0 0 1" type="slide"/>
        <plugin instance="flexcomp_softbody1"/>
      </body>
      <body name="softbody1_30" pos="0.170496 0.0159708 -0.122587">
        <inertial pos="0 0 0" mass="1.13636" diaginertia="0.001 0.001 0.001"/>
        <joint pos="0 0 0" axis="1 0 0" type="slide"/>
        <joint pos="0 0 0" axis="0 1 0" type="slide"/>
        <joint pos="0 0 0" axis="0 0 1" type="slide"/>
        <plugin instance="flexcomp_softbody1"/>
      </body>
      <body name="softbody1_31" pos="0.0254715 0.0584695 0.0172159">
        <inertial pos="0 0 0" mass="1.13636" diaginertia="0.001 0.001 0.001"/>
        <joint pos="0 0 0" axis="1 0 0" type="slide"/>
        <joint pos="0 0 0" axis="0 1 0" type="slide"/>
        <joint pos="0 0 0" axis="0 0 1" type="slide"/>
        <plugin instance="flexcomp_softbody1"/>
      </body>
      <body name="softbody1_32" pos="0.233841 0.00139498 -0.0128227">
        <inertial pos="0 0 0" mass="1.13636" diaginertia="0.001 0.001 0.001"/>
        <joint pos="0 0 0" axis="1 0 0" type="slide"/>
        <joint pos="0 0 0" axis="0 1 0" type="slide"/>
        <joint pos="0 0 0" axis="0 0 1" type="slide"/>
        <plugin instance="flexcomp_softbody1"/>
      </body>
      <body name="softbody1_33" pos="0.186152 0.0448837 -0.0859469">
        <inertial pos="0 0 0" mass="1.13636" diaginertia="0.001 0.001 0.001"/>
        <joint pos="0 0 0" axis="1 0 0" type="slide"/>
        <joint pos="0 0 0" axis="0 1 0" type="slide"/>
        <joint pos="0 0 0" axis="0 0 1" type="slide"/>
        <plugin instance="flexcomp_softbody1"/>
      </body>
      <body name="softbody1_34" pos="0.216497 0.0140777 -0.0925793">
        <inertial pos="0 0 0" mass="1.13636" diaginertia="0.001 0.001 0.001"/>
        <joint pos="0 0 0" axis="1 0 0" type="slide"/>
        <joint pos="0 0 0" axis="0 1 0" type="slide"/>
        <joint pos="0 0 0" axis="0 0 1" type="slide"/>
        <plugin instance="flexcomp_softbody1"/>
      </body>
      <body name="softbody1_35" pos="0.075663 0.051258 -0.0902657">
        <inertial pos="0 0 0" mass="1.13636" diaginertia="0.001 0.001 0.001"/>
        <joint pos="0 0 0" axis="1 0 0" type="slide"/>
        <joint pos="0 0 0" axis="0 1 0" type="slide"/>
        <joint pos="0 0 0" axis="0 0 1" type="slide"/>
        <plugin instance="flexcomp_softbody1"/>
      </body>
      <body name="softbody1_36" pos="0.0323775 0.0537467 -0.0222136">
        <inertial pos="0 0 0" mass="1.13636" diaginertia="0.001 0.001 0.001"/>
        <joint pos="0 0 0" axis="1 0 0" type="slide"/>
        <joint pos="0 0 0" axis="0 1 0" type="slide"/>
        <joint pos="0 0 0" axis="0 0 1" type="slide"/>
        <plugin instance="flexcomp_softbody1"/>
      </body>
      <body name="softbody1_37" pos="0.0979745 0.0547611 0.102126">
        <inertial pos="0 0 0" mass="1.13636" diaginertia="0.001 0.001 0.001"/>
        <joint pos="0 0 0" axis="1 0 0" type="slide"/>
        <joint pos="0 0 0" axis="0 1 0" type="slide"/>
        <joint pos="0 0 0" axis="0 0 1" type="slide"/>
        <plugin instance="flexcomp_softbody1"/>
      </body>
      <body name="softbody1_38" pos="0.118847 0.075787 0.0639364">
        <inertial pos="0 0 0" mass="1.13636" diaginertia="0.001 0.001 0.001"/>
        <joint pos="0 0 0" axis="1 0 0" type="slide"/>
        <joint pos="0 0 0" axis="0 1 0" type="slide"/>
        <joint pos="0 0 0" axis="0 0 1" type="slide"/>
        <plugin instance="flexcomp_softbody1"/>
      </body>
      <body name="softbody1_39" pos="0.0777676 0.0718629 0.0790171">
        <inertial pos="0 0 0" mass="1.13636" diaginertia="0.001 0.001 0.001"/>
        <joint pos="0 0 0" axis="1 0 0" type="slide"/>
        <joint pos="0 0 0" axis="0 1 0" type="slide"/>
        <joint pos="0 0 0" axis="0 0 1" type="slide"/>
        <plugin instance="flexcomp_softbody1"/>
      </body>
      <body name="softbody1_40" pos="0.188547 0.0497248 0.0367678">
        <inertial pos="0 0 0" mass="1.13636" diaginertia="0.001 0.001 0.001"/>
        <joint pos="0 0 0" axis="1 0 0" type="slide"/>
        <joint pos="0 0 0" axis="0 1 0" type="slide"/>
        <joint pos="0 0 0" axis="0 0 1" type="slide"/>
        <plugin instance="flexcomp_softbody1"/>
      </body>
      <body name="softbody1_41" pos="0.109951 -0.074911 0.0683173">
        <inertial pos="0 0 0" mass="1.13636" diaginertia="0.001 0.001 0.001"/>
        <joint pos="0 0 0" axis="1 0 0" type="slide"/>
        <joint pos="0 0 0" axis="0 1 0" type="slide"/>
        <joint pos="0 0 0" axis="0 0 1" type="slide"/>
        <plugin instance="flexcomp_softbody1"/>
      </body>
      <body name="softbody1_42" pos="0.0854543 -0.0951233 0.00102748">
        <inertial pos="0 0 0" mass="1.13636" diaginertia="0.001 0.001 0.001"/>
        <joint pos="0 0 0" axis="1 0 0" type="slide"/>
        <joint pos="0 0 0" axis="0 1 0" type="slide"/>
        <joint pos="0 0 0" axis="0 0 1" type="slide"/>
        <plugin instance="flexcomp_softbody1"/>
      </body>
      <body name="softbody1_43" pos="0.0965 0.02325 0.1205">
        <inertial pos="0 0 0" mass="1.13636" diaginertia="0.001 0.001 0.001"/>
        <joint pos="0 0 0" axis="1 0 0" type="slide"/>
        <joint pos="0 0 0" axis="0 1 0" type="slide"/>
        <joint pos="0 0 0" axis="0 0 1" type="slide"/>
        <plugin instance="flexcomp_softbody1"/>
      </body>
      <body name="softbody1_44" pos="0.09675 -0.0005 0.12375">
        <inertial pos="0 0 0" mass="1.13636" diaginertia="0.001 0.001 0.001"/>
        <joint pos="0 0 0" axis="1 0 0" type="slide"/>
        <joint pos="0 0 0" axis="0 1 0" type="slide"/>
        <joint pos="0 0 0" axis="0 0 1" type="slide"/>
        <plugin instance="flexcomp_softbody1"/>
      </body>
      <body name="softbody1_45" pos="0.0295 -0.028 0.09675">
        <inertial pos="0 0 0" mass="1.13636" diaginertia="0.001 0.001 0.001"/>
        <joint pos="0 0 0" axis="1 0 0" type="slide"/>
        <joint pos="0 0 0" axis="0 1 0" type="slide"/>
        <joint pos="0 0 0" axis="0 0 1" type="slide"/>
        <plugin instance="flexcomp_softbody1"/>
      </body>
      <body name="softbody1_46" pos="0.03675 -0.05025 0.08525">
        <inertial pos="0 0 0" mass="1.13636" diaginertia="0.001 0.001 0.001"/>
        <joint pos="0 0 0" axis="1 0 0" type="slide"/>
        <joint pos="0 0 0" axis="0 1 0" type="slide"/>
        <joint pos="0 0 0" axis="0 0 1" type="slide"/>
        <plugin instance="flexcomp_softbody1"/>
      </body>
      <body name="softbody1_47" pos="0.0594358 -0.0387426 0.107716">
        <inertial pos="0 0 0" mass="1.13636" diaginertia="0.001 0.001 0.001"/>
        <joint pos="0 0 0" axis="1 0 0" type="slide"/>
        <joint pos="0 0 0" axis="0 1 0" type="slide"/>
        <joint pos="0 0 0" axis="0 0 1" type="slide"/>
        <plugin instance="flexcomp_softbody1"/>
      </body>
      <body name="softbody1_48" pos="0.06425 0.04725 0.10375">
        <inertial pos="0 0 0" mass="1.13636" diaginertia="0.001 0.001 0.001"/>
        <joint pos="0 0 0" axis="1 0 0" type="slide"/>
        <joint pos="0 0 0" axis="0 1 0" type="slide"/>
        <joint pos="0 0 0" axis="0 0 1" type="slide"/>
        <plugin instance="flexcomp_softbody1"/>
      </body>
      <body name="softbody1_49" pos="0.0595 0.0255 0.1165">
        <inertial pos="0 0 0" mass="1.13636" diaginertia="0.001 0.001 0.001"/>
        <joint pos="0 0 0" axis="1 0 0" type="slide"/>
        <joint pos="0 0 0" axis="0 1 0" type="slide"/>
        <joint pos="0 0 0" axis="0 0 1" type="slide"/>
        <plugin instance="flexcomp_softbody1"/>
      </body>
      <body name="softbody1_50" pos="0.028 -0.0005 0.10175">
        <inertial pos="0 0 0" mass="1.13636" diaginertia="0.001 0.001 0.001"/>
        <joint pos="0 0 0" axis="1 0 0" type="slide"/>
        <joint pos="0 0 0" axis="0 1 0" type="slide"/>
        <joint pos="0 0 0" axis="0 0 1" type="slide"/>
        <plugin instance="flexcomp_softbody1"/>
      </body>
      <body name="softbody1_51" pos="0.009 -0.00075 0.074">
        <inertial pos="0 0 0" mass="1.13636" diaginertia="0.001 0.001 0.001"/>
        <joint pos="0 0 0" axis="1 0 0" type="slide"/>
        <joint pos="0 0 0" axis="0 1 0" type="slide"/>
        <joint pos="0 0 0" axis="0 0 1" type="slide"/>
        <plugin instance="flexcomp_softbody1"/>
      </body>
      <body name="softbody1_52" pos="0.05875 -0.0005 0.11925">
        <inertial pos="0 0 0" mass="1.13636" diaginertia="0.001 0.001 0.001"/>
        <joint pos="0 0 0" axis="1 0 0" type="slide"/>
        <joint pos="0 0 0" axis="0 1 0" type="slide"/>
        <joint pos="0 0 0" axis="0 0 1" type="slide"/>
        <plugin instance="flexcomp_softbody1"/>
      </body>
      <body name="softbody1_53" pos="0.012 -0.0275 0.069">
        <inertial pos="0 0 0" mass="1.13636" diaginertia="0.001 0.001 0.001"/>
        <joint pos="0 0 0" axis="1 0 0" type="slide"/>
        <joint pos="0 0 0" axis="0 1 0" type="slide"/>
        <joint pos="0 0 0" axis="0 0 1" type="slide"/>
        <plugin instance="flexcomp_softbody1"/>
      </body>
      <body name="softbody1_54" pos="0.0295 0.02625 0.09775">
        <inertial pos="0 0 0" mass="1.13636" diaginertia="0.001 0.001 0.001"/>
        <joint pos="0 0 0" axis="1 0 0" type="slide"/>
        <joint pos="0 0 0" axis="0 1 0" type="slide"/>
        <joint pos="0 0 0" axis="0 0 1" type="slide"/>
        <plugin instance="flexcomp_softbody1"/>
      </body>
      <body name="softbody1_55" pos="0.0168691 -0.0482751 0.0522847">
        <inertial pos="0 0 0" mass="1.13636" diaginertia="0.001 0.001 0.001"/>
        <joint pos="0 0 0" axis="1 0 0" type="slide"/>
        <joint pos="0 0 0" axis="0 1 0" type="slide"/>
        <joint pos="0 0 0" axis="0 0 1" type="slide"/>
        <plugin instance="flexcomp_softbody1"/>
      </body>
      <body name="softbody1_56" pos="0.0314502 -0.064287 0.0426071">
        <inertial pos="0 0 0" mass="1.13636" diaginertia="0.001 0.001 0.001"/>
        <joint pos="0 0 0" axis="1 0 0" type="slide"/>
        <joint pos="0 0 0" axis="0 1 0" type="slide"/>
        <joint pos="0 0 0" axis="0 0 1" type="slide"/>
        <plugin instance="flexcomp_softbody1"/>
      </body>
      <body name="softbody1_57" pos="0.0514749 -0.0707385 0.0671076">
        <inertial pos="0 0 0" mass="1.13636" diaginertia="0.001 0.001 0.001"/>
        <joint pos="0 0 0" axis="1 0 0" type="slide"/>
        <joint pos="0 0 0" axis="0 1 0" type="slide"/>
        <joint pos="0 0 0" axis="0 0 1" type="slide"/>
        <plugin instance="flexcomp_softbody1"/>
      </body>
      <body name="softbody1_58" pos="0.03725 0.04875 0.08675">
        <inertial pos="0 0 0" mass="1.13636" diaginertia="0.001 0.001 0.001"/>
        <joint pos="0 0 0" axis="1 0 0" type="slide"/>
        <joint pos="0 0 0" axis="0 1 0" type="slide"/>
        <joint pos="0 0 0" axis="0 0 1" type="slide"/>
        <plugin instance="flexcomp_softbody1"/>
      </body>
      <body name="softbody1_59" pos="0.01125 0.02575 0.0695">
        <inertial pos="0 0 0" mass="1.13636" diaginertia="0.001 0.001 0.001"/>
        <joint pos="0 0 0" axis="1 0 0" type="slide"/>
        <joint pos="0 0 0" axis="0 1 0" type="slide"/>
        <joint pos="0 0 0" axis="0 0 1" type="slide"/>
        <plugin instance="flexcomp_softbody1"/>
      </body>
      <body name="softbody1_60" pos="0.0524656 0.0681202 0.0694929">
        <inertial pos="0 0 0" mass="1.13636" diaginertia="0.001 0.001 0.001"/>
        <joint pos="0 0 0" axis="1 0 0" type="slide"/>
        <joint pos="0 0 0" axis="0 1 0" type="slide"/>
        <joint pos="0 0 0" axis="0 0 1" type="slide"/>
        <plugin instance="flexcomp_softbody1"/>
      </body>
      <body name="softbody1_61" pos="0.02025 0.0475 0.0615">
        <inertial pos="0 0 0" mass="1.13636" diaginertia="0.001 0.001 0.001"/>
        <joint pos="0 0 0" axis="1 0 0" type="slide"/>
        <joint pos="0 0 0" axis="0 1 0" type="slide"/>
        <joint pos="0 0 0" axis="0 0 1" type="slide"/>
        <plugin instance="flexcomp_softbody1"/>
      </body>
      <body name="softbody1_62" pos="0.00156554 0.0246938 0.0282899">
        <inertial pos="0 0 0" mass="1.13636" diaginertia="0.001 0.001 0.001"/>
        <joint pos="0 0 0" axis="1 0 0" type="slide"/>
        <joint pos="0 0 0" axis="0 1 0" type="slide"/>
        <joint pos="0 0 0" axis="0 0 1" type="slide"/>
        <plugin instance="flexcomp_softbody1"/>
      </body>
      <body name="softbody1_63" pos="0.000719792 -0.0104498 0.0426466">
        <inertial pos="0 0 0" mass="1.13636" diaginertia="0.001 0.001 0.001"/>
        <joint pos="0 0 0" axis="1 0 0" type="slide"/>
        <joint pos="0 0 0" axis="0 1 0" type="slide"/>
        <joint pos="0 0 0" axis="0 0 1" type="slide"/>
        <plugin instance="flexcomp_softbody1"/>
      </body>
      <body name="softbody1_64" pos="0.13067 -0.0580945 0.0885084">
        <inertial pos="0 0 0" mass="1.13636" diaginertia="0.001 0.001 0.001"/>
        <joint pos="0 0 0" axis="1 0 0" type="slide"/>
        <joint pos="0 0 0" axis="0 1 0" type="slide"/>
        <joint pos="0 0 0" axis="0 0 1" type="slide"/>
        <plugin instance="flexcomp_softbody1"/>
      </body>
      <body name="softbody1_65" pos="0.0455 0.02375 -0.08725">
        <inertial pos="0 0 0" mass="1.13636" diaginertia="0.001 0.001 0.001"/>
        <joint pos="0 0 0" axis="1 0 0" type="slide"/>
        <joint pos="0 0 0" axis="0 1 0" type="slide"/>
        <joint pos="0 0 0" axis="0 0 1" type="slide"/>
        <plugin instance="flexcomp_softbody1"/>
      </body>
      <body name="softbody1_66" pos="0.01743 0.0360319 -0.0233573">
        <inertial pos="0 0 0" mass="1.13636" diaginertia="0.001 0.001 0.001"/>
        <joint pos="0 0 0" axis="1 0 0" type="slide"/>
        <joint pos="0 0 0" axis="0 1 0" type="slide"/>
        <joint pos="0 0 0" axis="0 0 1" type="slide"/>
        <plugin instance="flexcomp_softbody1"/>
      </body>
      <body name="softbody1_67" pos="0.0358964 0.0643439 0.0499491">
        <inertial pos="0 0 0" mass="1.13636" diaginertia="0.001 0.001 0.001"/>
        <joint pos="0 0 0" axis="1 0 0" type="slide"/>
        <joint pos="0 0 0" axis="0 1 0" type="slide"/>
        <joint pos="0 0 0" axis="0 0 1" type="slide"/>
        <plugin instance="flexcomp_softbody1"/>
      </body>
      <body name="softbody1_68" pos="0.13325 -0.0005 0.11975">
        <inertial pos="0 0 0" mass="1.13636" diaginertia="0.001 0.001 0.001"/>
        <joint pos="0 0 0" axis="1 0 0" type="slide"/>
        <joint pos="0 0 0" axis="0 1 0" type="slide"/>
        <joint pos="0 0 0" axis="0 0 1" type="slide"/>
        <plugin instance="flexcomp_softbody1"/>
      </body>
      <body name="softbody1_69" pos="0.00994351 0.0198672 -0.0217354">
        <inertial pos="0 0 0" mass="1.13636" diaginertia="0.001 0.001 0.001"/>
        <joint pos="0 0 0" axis="1 0 0" type="slide"/>
        <joint pos="0 0 0" axis="0 1 0" type="slide"/>
        <joint pos="0 0 0" axis="0 0 1" type="slide"/>
        <plugin instance="flexcomp_softbody1"/>
      </body>
      <body name="softbody1_70" pos="0.0415 -0.0035 -0.10075">
        <inertial pos="0 0 0" mass="1.13636" diaginertia="0.001 0.001 0.001"/>
        <joint pos="0 0 0" axis="1 0 0" type="slide"/>
        <joint pos="0 0 0" axis="0 1 0" type="slide"/>
        <joint pos="0 0 0" axis="0 0 1" type="slide"/>
        <plugin instance="flexcomp_softbody1"/>
      </body>
      <body name="softbody1_71" pos="0.158173 -0.0286375 0.100628">
        <inertial pos="0 0 0" mass="1.13636" diaginertia="0.001 0.001 0.001"/>
        <joint pos="0 0 0" axis="1 0 0" type="slide"/>
        <joint pos="0 0 0" axis="0 1 0" type="slide"/>
        <joint pos="0 0 0" axis="0 0 1" type="slide"/>
        <plugin instance="flexcomp_softbody1"/>
      </body>
      <body name="softbody1_72" pos="0.130384 -0.0323625 0.112299">
        <inertial pos="0 0 0" mass="1.13636" diaginertia="0.001 0.001 0.001"/>
        <joint pos="0 0 0" axis="1 0 0" type="slide"/>
        <joint pos="0 0 0" axis="0 1 0" type="slide"/>
        <joint pos="0 0 0" axis="0 0 1" type="slide"/>
        <plugin instance="flexcomp_softbody1"/>
      </body>
      <body name="softbody1_73" pos="0.095704 -0.0879729 -0.0386996">
        <inertial pos="0 0 0" mass="1.13636" diaginertia="0.001 0.001 0.001"/>
        <joint pos="0 0 0" axis="1 0 0" type="slide"/>
        <joint pos="0 0 0" axis="0 1 0" type="slide"/>
        <joint pos="0 0 0" axis="0 0 1" type="slide"/>
        <plugin instance="flexcomp_softbody1"/>
      </body>
      <body name="softbody1_74" pos="0.0823166 -0.0937293 -0.0175556">
        <inertial pos="0 0 0" mass="1.13636" diaginertia="0.001 0.001 0.001"/>
        <joint pos="0 0 0" axis="1 0 0" type="slide"/>
        <joint pos="0 0 0" axis="0 1 0" type="slide"/>
        <joint pos="0 0 0" axis="0 0 1" type="slide"/>
        <plugin instance="flexcomp_softbody1"/>
      </body>
      <body name="softbody1_75" pos="0.0907322 -0.0629225 -0.0938927">
        <inertial pos="0 0 0" mass="1.13636" diaginertia="0.001 0.001 0.001"/>
        <joint pos="0 0 0" axis="1 0 0" type="slide"/>
        <joint pos="0 0 0" axis="0 1 0" type="slide"/>
        <joint pos="0 0 0" axis="0 0 1" type="slide"/>
        <plugin instance="flexcomp_softbody1"/>
      </body>
      <body name="softbody1_76" pos="0.0121687 0.0444265 0.0252123">
        <inertial pos="0 0 0" mass="1.13636" diaginertia="0.001 0.001 0.001"/>
        <joint pos="0 0 0" axis="1 0 0" type="slide"/>
        <joint pos="0 0 0" axis="0 1 0" type="slide"/>
        <joint pos="0 0 0" axis="0 0 1" type="slide"/>
        <plugin instance="flexcomp_softbody1"/>
      </body>
      <body name="softbody1_77" pos="0.000567019 -0.0116915 0.0108379">
        <inertial pos="0 0 0" mass="1.13636" diaginertia="0.001 0.001 0.001"/>
        <joint pos="0 0 0" axis="1 0 0" type="slide"/>
        <joint pos="0 0 0" axis="0 1 0" type="slide"/>
        <joint pos="0 0 0" axis="0 0 1" type="slide"/>
        <plugin instance="flexcomp_softbody1"/>
      </body>
      <body name="softbody1_78" pos="0.097056 -0.0346448 0.114518">
        <inertial pos="0 0 0" mass="1.13636" diaginertia="0.001 0.001 0.001"/>
        <joint pos="0 0 0" axis="1 0 0" type="slide"/>
        <joint pos="0 0 0" axis="0 1 0" type="slide"/>
        <joint pos="0 0 0" axis="0 0 1" type="slide"/>
        <plugin instance="flexcomp_softbody1"/>
      </body>
      <body name="softbody1_79" pos="0.0808789 -0.0663491 0.0881447">
        <inertial pos="0 0 0" mass="1.13636" diaginertia="0.001 0.001 0.001"/>
        <joint pos="0 0 0" axis="1 0 0" type="slide"/>
        <joint pos="0 0 0" axis="0 1 0" type="slide"/>
        <joint pos="0 0 0" axis="0 0 1" type="slide"/>
        <plugin instance="flexcomp_softbody1"/>
      </body>
      <body name="softbody1_80" pos="0.0809613 -0.0772896 0.0664159">
        <inertial pos="0 0 0" mass="1.13636" diaginertia="0.001 0.001 0.001"/>
        <joint pos="0 0 0" axis="1 0 0" type="slide"/>
        <joint pos="0 0 0" axis="0 1 0" type="slide"/>
        <joint pos="0 0 0" axis="0 0 1" type="slide"/>
        <plugin instance="flexcomp_softbody1"/>
      </body>
      <body name="softbody1_81" pos="0.0130939 -0.0428795 0.00434488">
        <inertial pos="0 0 0" mass="1.13636" diaginertia="0.001 0.001 0.001"/>
        <joint pos="0 0 0" axis="1 0 0" type="slide"/>
        <joint pos="0 0 0" axis="0 1 0" type="slide"/>
        <joint pos="0 0 0" axis="0 0 1" type="slide"/>
        <plugin instance="flexcomp_softbody1"/>
      </body>
      <body name="softbody1_82" pos="0.052875 -0.0399877 -0.089474">
        <inertial pos="0 0 0" mass="1.13636" diaginertia="0.001 0.001 0.001"/>
        <joint pos="0 0 0" axis="1 0 0" type="slide"/>
        <joint pos="0 0 0" axis="0 1 0" type="slide"/>
        <joint pos="0 0 0" axis="0 0 1" type="slide"/>
        <plugin instance="flexcomp_softbody1"/>
      </body>
      <body name="softbody1_83" pos="0.0249093 -0.0548074 -0.00041295">
        <inertial pos="0 0 0" mass="1.13636" diaginertia="0.001 0.001 0.001"/>
        <joint pos="0 0 0" axis="1 0 0" type="slide"/>
        <joint pos="0 0 0" axis="0 1 0" type="slide"/>
        <joint pos="0 0 0" axis="0 0 1" type="slide"/>
        <plugin instance="flexcomp_softbody1"/>
      </body>
      <body name="softbody1_84" pos="0.00891667 -0.0106305 -0.0202238">
        <inertial pos="0 0 0" mass="1.13636" diaginertia="0.001 0.001 0.001"/>
        <joint pos="0 0 0" axis="1 0 0" type="slide"/>
        <joint pos="0 0 0" axis="0 1 0" type="slide"/>
        <joint pos="0 0 0" axis="0 0 1" type="slide"/>
        <plugin instance="flexcomp_softbody1"/>
      </body>
      <body name="softbody1_85" pos="0.0674732 0.00782313 0.0435965">
        <inertial pos="0 0 0" mass="1.13636" diaginertia="0.001 0.001 0.001"/>
        <joint pos="0 0 0" axis="1 0 0" type="slide"/>
        <joint pos="0 0 0" axis="0 1 0" type="slide"/>
        <joint pos="0 0 0" axis="0 0 1" type="slide"/>
        <plugin instance="flexcomp_softbody1"/>
      </body>
      <body name="softbody1_86" pos="0.128118 -0.000591808 0.0666924">
        <inertial pos="0 0 0" mass="1.13636" diaginertia="0.001 0.001 0.001"/>
        <joint pos="0 0 0" axis="1 0 0" type="slide"/>
        <joint pos="0 0 0" axis="0 1 0" type="slide"/>
        <joint pos="0 0 0" axis="0 0 1" type="slide"/>
        <plugin instance="flexcomp_softbody1"/>
      </body>
      <body name="softbody1_87" pos="0.117573 -0.00172647 -0.0254962">
        <inertial pos="0 0 0" mass="1.13636" diaginertia="0.001 0.001 0.001"/>
        <joint pos="0 0 0" axis="1 0 0" type="slide"/>
        <joint pos="0 0 0" axis="0 1 0" type="slide"/>
        <joint pos="0 0 0" axis="0 0 1" type="slide"/>
        <plugin instance="flexcomp_softbody1"/>
      </body>
    </body>
    <body name="pelvis" quat="0.707107 0.707107 0 0">
      <inertial pos="-0.0817759 0 0" mass="10.9271" diaginertia="0.0960569 0.0960569 0.0718719"/>
      <joint name="pelvis_tz" pos="0 0 0" axis="0 0 1" limited="false" type="slide" range="-3 3"/>
      <joint name="pelvis_ty" pos="0 0 0" axis="0 1 0" limited="false" type="slide" range="-1 2"/>
      <joint name="pelvis_tx" pos="0 0 0" axis="1 0 0" limited="false" type="slide" range="-5 5"/>
      <joint name="pelvis_tilt" pos="0 0 0" axis="0 0 1" limited="false" range="-1.5708 1.5708"/>
      <joint name="pelvis_list" pos="0 0 0" axis="1 0 0" limited="false" range="-1.5708 1.5708"/>
      <joint name="pelvis_rotation" pos="0 0 0" axis="0 1 0" limited="false" range="-1.5708 1.5708"/>
      <geom name="r_pelvis" type="mesh" mesh="r_pelvis"/>
      <geom name="l_pelvis" type="mesh" mesh="l_pelvis"/>
      <geom name="sacrum" type="mesh" mesh="sacrum"/>
      <light pos="0 0 4" dir="0 0 -1" mode="trackcom"/>
      <body name="femur_r" pos="-0.0650922 -0.0907863 0.0723699">
        <inertial pos="0 -0.165691 0" quat="0.5 0.5 -0.5 0.5" mass="8.63013" diaginertia="0.124453 0.118018 0.0309369"/>
        <joint name="hip_flexion_r" pos="0 0 0" axis="0 0 1" limited="false" range="-0.523599 2.0944"/>
        <joint name="hip_adduction_r" pos="0 0 0" axis="1 0 0" limited="false" range="-0.872665 0.523599"/>
        <joint name="hip_rotation_r" pos="0 0 0" axis="0 1 0" limited="false" range="-0.698132 0.698132"/>
        <geom name="r_femur" type="mesh" mesh="r_femur"/>
        <body name="tibia_r" pos="0.00109144 -0.393697 -0.00103279">
          <inertial pos="0 -0.207168 0" quat="0.5 0.5 -0.5 0.5" mass="3.43993" diaginertia="0.0583775 0.0575778 0.00582632"/>
          <joint name="knee_angle_r_translation2" pos="0 0 0" axis="0.992246 0.123982 -0.00878916" type="slide" range="7.69254e-11 0.006792"/>
          <joint name="knee_angle_r_translation1" pos="0 0 0" axis="-0.124293 0.989762 -0.0701648" type="slide" range="9.53733e-08 0.00159883"/>
          <joint name="knee_angle_r" pos="0 0 0" axis="-3.98373e-10 -0.0707131 -0.997497" limited="false" range="0 2.0944"/>
          <joint name="knee_angle_r_rotation2" pos="0 0 0" axis="0.992246 0.123982 -0.00878916" range="-0.00167821 0.0335354"/>
          <joint name="knee_angle_r_rotation3" pos="0 0 0" axis="-0.124293 0.989762 -0.0701648" range="1.08939e-08 0.262788"/>
          <geom name="r_tibia" type="mesh" mesh="r_tibia"/>
          <geom name="r_fibula" type="mesh" mesh="r_fibula"/>
          <body name="talus_r" pos="-0.0110963 -0.443852 0">
            <inertial pos="0 0 0" mass="0.0927831" diaginertia="0.001 0.001 0.001"/>
            <joint name="ankle_angle_r" pos="0 0 0" axis="-0.105014 -0.174022 0.979126" limited="false" range="-0.698132 0.523599"/>
            <geom name="r_talus" type="mesh" mesh="r_talus"/>
            <body name="calcn_r" pos="-0.0421077 -0.0362194 0.00683808">
              <inertial pos="0.0863394 0.0259018 0" quat="0 0.707107 0 0.707107" mass="1.15979" diaginertia="0.00283577 0.00269744 0.001"/>
              <joint name="subtalar_angle_r" pos="0 0 0" axis="0.78718 0.604747 -0.120949" limited="false" range="-0.349066 0.349066"/>
              <geom name="r_foot" type="mesh" mesh="r_foot"/>
              <body name="toes_r" pos="0.154375 -0.00172679 0.000932466">
                <inertial pos="0.0298734 0.00518037 -0.0151094" quat="0 0.707107 0 0.707107" mass="0.200968" diaginertia="0.001 0.001 0.001"/>
                <joint name="mtp_angle_r" pos="0 0 0" axis="0.580954 0 -0.813936" limited="false" range="-0.523599 0.523599"/>
                <geom name="r_bofoot" type="mesh" mesh="r_bofoot"/>
              </body>
            </body>
          </body>
        </body>
        <body name="patella_r" pos="-0.00788495 -0.39762 6.9703e-05">
          <inertial pos="0.0018 0.0264 0" quat="0.5 0.5 0.5 0.5" mass="0.079979" diaginertia="0.001 0.001 0.001"/>
          <joint name="knee_angle_r_beta_translation2" pos="0 0 0" axis="0 1 0" type="slide" range="-0.0408267 -0.0108281"/>
          <joint name="knee_angle_r_beta_translation1" pos="0 0 0" axis="1 0 0" type="slide" range="-0.0227731 0.0524192"/>
          <joint name="knee_angle_r_beta_rotation1" pos="0 0 0" axis="0 0 1" range="-1.79241 0.010506"/>
          <geom name="r_patella" type="mesh" mesh="r_patella"/>
        </body>
      </body>
      <body name="femur_l" pos="-0.0650922 -0.0907863 -0.0723699">
        <inertial pos="0 -0.166781 0" quat="0.5 0.5 -0.5 0.5" mass="8.63013" diaginertia="0.126095 0.119576 0.031345"/>
        <joint name="hip_flexion_l" pos="0 0 0" axis="0 0 1" limited="false" range="-0.523599 2.0944"/>
        <joint name="hip_adduction_l" pos="0 0 0" axis="-1 0 0" limited="false" range="-0.872665 0.523599"/>
        <joint name="hip_rotation_l" pos="0 0 0" axis="0 -1 0" limited="false" range="-0.698132 0.698132"/>
        <geom name="l_femur" type="mesh" mesh="l_femur"/>
        <body name="tibia_l" pos="0.00124904 -0.39622 0.00101197">
          <inertial pos="0 -0.212002 0" quat="0.5 0.5 -0.5 0.5" mass="3.43993" diaginertia="0.0611335 0.060296 0.00610138"/>
          <joint name="knee_angle_l_translation2" pos="0 0 0" axis="-0.992246 -0.123982 -0.00878916" type="slide" range="-0.006792 -7.69254e-11"/>
          <joint name="knee_angle_l_translation1" pos="0 0 0" axis="-0.124293 0.989762 0.0701648" type="slide" range="9.53733e-08 0.00159883"/>
          <joint name="knee_angle_l" pos="0 0 0" axis="3.98373e-10 0.0707131 -0.997497" limited="false" range="0 2.0944"/>
          <joint name="knee_angle_l_rotation2" pos="0 0 0" axis="-0.992246 -0.123982 -0.00878916" range="-0.00167821 0.0335354"/>
          <joint name="knee_angle_l_rotation3" pos="0 0 0" axis="-0.124293 0.989762 0.0701648" range="-0.262788 -1.08939e-08"/>
          <geom name="l_tibia" type="mesh" mesh="l_tibia"/>
          <geom name="l_fibula" type="mesh" mesh="l_fibula"/>
          <body name="talus_l" pos="-0.0113552 -0.454208 0">
            <inertial pos="0 0 0" mass="0.0927831" diaginertia="0.001 0.001 0.001"/>
            <joint name="ankle_angle_l" pos="0 0 0" axis="0.105014 0.174022 0.979126" limited="false" range="-0.698132 0.523599"/>
            <geom name="l_talus" type="mesh" mesh="l_talus"/>
            <body name="calcn_l" pos="-0.0448298 -0.0385608 -0.00728013">
              <inertial pos="0.0919209 0.0275763 0" quat="0 0.707107 0 0.707107" mass="1.15979" diaginertia="0.00321426 0.00305747 0.00109755"/>
              <joint name="subtalar_angle_l" pos="0 0 0" axis="-0.78718 -0.604747 -0.120949" limited="false" range="-0.349066 0.349066"/>
              <geom name="l_foot" type="mesh" mesh="l_foot"/>
              <body name="toes_l" pos="0.164355 -0.00183842 -0.000992746">
                <inertial pos="0.0318046 0.00551525 0.0160862" quat="0 0.707107 0 0.707107" mass="0.200968" diaginertia="0.001 0.001 0.001"/>
                <joint name="mtp_angle_l" pos="0 0 0" axis="-0.580954 0 -0.813936" limited="false" range="-0.523599 0.523599"/>
                <geom name="l_bofoot" type="mesh" mesh="l_bofoot"/>
              </body>
            </body>
          </body>
        </body>
        <body name="patella_l" pos="-0.00793679 -0.400234 -5.20799e-05">
          <inertial pos="0.0018 0.0264 0" quat="0.5 0.5 0.5 0.5" mass="0.079979" diaginertia="0.001 0.001 0.001"/>
          <joint name="knee_angle_l_beta_translation2" pos="0 0 0" axis="0 1 0" type="slide" range="-0.0408267 -0.0108281"/>
          <joint name="knee_angle_l_beta_translation1" pos="0 0 0" axis="1 0 0" type="slide" range="-0.0227731 0.0524192"/>
          <joint name="knee_angle_l_beta_rotation1" pos="0 0 0" axis="0 0 1" range="-1.79241 0.010506"/>
          <geom name="l_patella" type="mesh" mesh="l_patella"/>
        </body>
      </body>
      <body name="torso" pos="-0.116476 0.0942678 0">
        <inertial pos="-0.0328335 0.350224 0" quat="0.707107 0.707107 0 0" mass="24.8905" diaginertia="1.63872 1.59082 0.839645"/>
        <joint name="lumbar_extension" pos="0 0 0" axis="0 0 1" limited="false" range="-1.5708 1.5708"/>
        <joint name="lumbar_bending" pos="0 0 0" axis="1 0 0" limited="false" range="-1.5708 1.5708"/>
        <joint name="lumbar_rotation" pos="0 0 0" axis="0 1 0" limited="false" range="-1.5708 1.5708"/>
        <geom name="hat_spine" type="mesh" mesh="hat_spine"/>
        <geom name="hat_jaw" type="mesh" mesh="hat_jaw"/>
        <geom name="hat_skull" type="mesh" mesh="hat_skull"/>
        <geom name="hat_ribs_scap" type="mesh" mesh="hat_ribs_scap"/>
        <body name="humerus_r" pos="0.00345299 0.406588 0.186057">
          <inertial pos="0 -0.17897 0" quat="0.5 0.5 -0.5 0.5" mass="1.88582" diaginertia="0.014726 0.0131193 0.00452576"/>
          <joint name="arm_flex_r" pos="0 0 0" axis="0 0 1" limited="false" range="-1.5708 1.5708"/>
          <joint name="arm_add_r" pos="0 0 0" axis="1 0 0" limited="false" range="-2.0944 1.5708"/>
          <joint name="arm_rot_r" pos="0 0 0" axis="0 1 0" limited="false" range="-1.5708 1.5708"/>
          <geom name="humerus_rv" type="mesh" mesh="humerus_rv"/>
          <body name="ulna_r" pos="0.0143001 -0.311452 -0.0104389">
            <inertial pos="0 -0.133441 0" quat="0.5 0.5 -0.5 0.5" mass="0.563657" diaginertia="0.00365432 0.00336884 0.001"/>
            <joint name="elbow_flex_r" pos="0 0 0" axis="0.226047 0.022269 0.973862" limited="false" range="0 2.618"/>
            <geom name="ulna_rv" type="mesh" mesh="ulna_rv"/>
            <body name="radius_r" pos="-0.00744792 -0.0144009 0.0288783">
              <inertial pos="0 -0.140277 0" quat="0.5 0.5 -0.5 0.5" mass="0.563657" diaginertia="0.00403828 0.00372281 0.001"/>
              <joint name="pro_sup_r" pos="0 0 0" axis="0.056398 0.998406 0.001952" limited="false" range="0 1.5708"/>
              <geom name="radius_rv" type="mesh" mesh="radius_rv"/>
              <body name="hand_r" pos="-0.0102387 -0.274491 0.0158404">
                <inertial pos="0 -0.068095 0" quat="0.5 0.5 -0.5 0.5" mass="0.424483" diaginertia="0.00124329 0.001 0.001"/>
                <joint name="wrist_flex_r" pos="0 0 0" axis="0 0 1" limited="false" range="-1.22173 1.22173"/>
                <joint name="wrist_dev_r" pos="0 0 0" axis="1 0 0" limited="false" range="-0.436332 0.610865"/>
                <geom name="pisiform_rvs" type="mesh" mesh="pisiform_rvs"/>
                <geom name="lunate_rvs" type="mesh" mesh="lunate_rvs"/>
                <geom name="scaphoid_rvs" type="mesh" mesh="scaphoid_rvs"/>
                <geom name="triquetrum_rvs" type="mesh" mesh="triquetrum_rvs"/>
                <geom name="hamate_rvs" type="mesh" mesh="hamate_rvs"/>
                <geom name="capitate_rvs" type="mesh" mesh="capitate_rvs"/>
                <geom name="trapezoid_rvs" type="mesh" mesh="trapezoid_rvs"/>
                <geom name="trapezium_rvs" type="mesh" mesh="trapezium_rvs"/>
                <geom name="metacarpal2_rvs" type="mesh" mesh="metacarpal2_rvs"/>
                <geom name="index_proximal_rvs" type="mesh" mesh="index_proximal_rvs"/>
                <geom name="index_medial_rvs" type="mesh" mesh="index_medial_rvs"/>
                <geom name="index_distal_rvs" type="mesh" mesh="index_distal_rvs"/>
                <geom name="metacarpal3_rvs" type="mesh" mesh="metacarpal3_rvs"/>
                <geom name="middle_proximal_rvs" type="mesh" mesh="middle_proximal_rvs"/>
                <geom name="middle_medial_rvs" type="mesh" mesh="middle_medial_rvs"/>
                <geom name="middle_distal_rvs" type="mesh" mesh="middle_distal_rvs"/>
                <geom name="metacarpal4_rvs" type="mesh" mesh="metacarpal4_rvs"/>
                <geom name="ring_proximal_rvs" type="mesh" mesh="ring_proximal_rvs"/>
                <geom name="ring_medial_rvs" type="mesh" mesh="ring_medial_rvs"/>
                <geom name="ring_distal_rvs" type="mesh" mesh="ring_distal_rvs"/>
                <geom name="metacarpal5_rvs" type="mesh" mesh="metacarpal5_rvs"/>
                <geom name="little_proximal_rvs" type="mesh" mesh="little_proximal_rvs"/>
                <geom name="little_medial_rvs" type="mesh" mesh="little_medial_rvs"/>
                <geom name="little_distal_rvs" type="mesh" mesh="little_distal_rvs"/>
                <geom name="metacarpal1_rvs" type="mesh" mesh="metacarpal1_rvs"/>
                <geom name="thumb_proximal_rvs" type="mesh" mesh="thumb_proximal_rvs"/>
                <geom name="thumb_distal_rvs" type="mesh" mesh="thumb_distal_rvs"/>
              </body>
            </body>
          </body>
        </body>
        <body name="humerus_l" pos="0.00345299 0.406588 -0.186057">
          <inertial pos="0 -0.176496 0" quat="0.5 0.5 -0.5 0.5" mass="1.88582" diaginertia="0.0143216 0.0127591 0.00440148"/>
          <joint name="arm_flex_l" pos="0 0 0" axis="0 0 1" limited="false" range="-1.5708 1.5708"/>
          <joint name="arm_add_l" pos="0 0 0" axis="-1 0 0" limited="false" range="-2.0944 1.5708"/>
          <joint name="arm_rot_l" pos="0 0 0" axis="0 -1 0" limited="false" range="-1.5708 1.5708"/>
          <geom name="humerus_lv" type="mesh" mesh="humerus_lv"/>
          <body name="ulna_l" pos="0.0141023 -0.307145 0.0102946">
            <inertial pos="0 -0.134435 0" quat="0.5 0.5 -0.5 0.5" mass="0.563657" diaginertia="0.00370895 0.00341921 0.001"/>
            <joint name="elbow_flex_l" pos="0 0 0" axis="-0.226047 -0.022269 0.973862" limited="false" range="0 2.618"/>
            <geom name="ulna_lv" type="mesh" mesh="ulna_lv"/>
            <body name="radius_l" pos="-0.00750339 -0.0145082 -0.0290933">
              <inertial pos="0 -0.140438 0" quat="0.5 0.5 -0.5 0.5" mass="0.563657" diaginertia="0.00404759 0.00373139 0.001"/>
              <joint name="pro_sup_l" pos="0 0 0" axis="-0.056398 -0.998406 0.001952" limited="false" range="0 1.5708"/>
              <geom name="radius_lv" type="mesh" mesh="radius_lv"/>
              <body name="hand_l" pos="-0.0102504 -0.274807 -0.0158587">
                <inertial pos="0 -0.068095 0" quat="0.5 0.5 -0.5 0.5" mass="0.424483" diaginertia="0.00124329 0.001 0.001"/>
                <joint name="wrist_flex_l" pos="0 0 0" axis="0 0 1" limited="false" range="-1.22173 1.22173"/>
                <joint name="wrist_dev_l" pos="0 0 0" axis="-1 0 0" limited="false" range="-0.436332 0.610865"/>
                <geom name="pisiform_lvs" type="mesh" mesh="pisiform_lvs"/>
                <geom name="lunate_lvs" type="mesh" mesh="lunate_lvs"/>
                <geom name="scaphoid_lvs" type="mesh" mesh="scaphoid_lvs"/>
                <geom name="triquetrum_lvs" type="mesh" mesh="triquetrum_lvs"/>
                <geom name="hamate_lvs" type="mesh" mesh="hamate_lvs"/>
                <geom name="capitate_lvs" type="mesh" mesh="capitate_lvs"/>
                <geom name="trapezoid_lvs" type="mesh" mesh="trapezoid_lvs"/>
                <geom name="trapezium_lvs" type="mesh" mesh="trapezium_lvs"/>
                <geom name="metacarpal2_lvs" type="mesh" mesh="metacarpal2_lvs"/>
                <geom name="index_proximal_lvs" type="mesh" mesh="index_proximal_lvs"/>
                <geom name="index_medial_lvs" type="mesh" mesh="index_medial_lvs"/>
                <geom name="index_distal_lvs" type="mesh" mesh="index_distal_lvs"/>
                <geom name="metacarpal3_lvs" type="mesh" mesh="metacarpal3_lvs"/>
                <geom name="middle_proximal_lvs" type="mesh" mesh="middle_proximal_lvs"/>
                <geom name="middle_medial_lvs" type="mesh" mesh="middle_medial_lvs"/>
                <geom name="middle_distal_lvs" type="mesh" mesh="middle_distal_lvs"/>
                <geom name="metacarpal4_lvs" type="mesh" mesh="metacarpal4_lvs"/>
                <geom name="ring_proximal_lvs" type="mesh" mesh="ring_proximal_lvs"/>
                <geom name="ring_medial_lvs" type="mesh" mesh="ring_medial_lvs"/>
                <geom name="ring_distal_lvs" type="mesh" mesh="ring_distal_lvs"/>
                <geom name="metacarpal5_lvs" type="mesh" mesh="metacarpal5_lvs"/>
                <geom name="little_proximal_lvs" type="mesh" mesh="little_proximal_lvs"/>
                <geom name="little_medial_lvs" type="mesh" mesh="little_medial_lvs"/>
                <geom name="little_distal_lvs" type="mesh" mesh="little_distal_lvs"/>
                <geom name="metacarpal1_lvs" type="mesh" mesh="metacarpal1_lvs"/>
                <geom name="thumb_proximal_lvs" type="mesh" mesh="thumb_proximal_lvs"/>
                <geom name="thumb_distal_lvs" type="mesh" mesh="thumb_distal_lvs"/>
              </body>
            </body>
          </body>
        </body>
      </body>
    </body>
  </worldbody>
  <deformable>
    <flex name="softbody1" rgba="0 0.7 0.7 1" dim="3" body="softbody1_0 softbody1_1 softbody1_2 softbody1_3 softbody1_4 softbody1_5 softbody1_6 softbody1_7 softbody1_8 softbody1_9 softbody1_10 softbody1_11 softbody1_12 softbody1_13 softbody1_14 softbody1_15 softbody1_16 softbody1_17 softbody1_18 softbody1_19 softbody1_20 softbody1_21 softbody1_22 softbody1_23 softbody1_24 softbody1_25 softbody1_26 softbody1_27 softbody1_28 softbody1_29 softbody1_30 softbody1_31 softbody1_32 softbody1_33 softbody1_34 softbody1_35 softbody1_36 softbody1_37 softbody1_38 softbody1_39 softbody1_40 softbody1_41 softbody1_42 softbody1_43 softbody1_44 softbody1_45 softbody1_46 softbody1_47 softbody1_48 softbody1_49 softbody1_50 softbody1_51 softbody1_52 softbody1_53 softbody1_54 softbody1_55 softbody1_56 softbody1_57 softbody1_58 softbody1_59 softbody1_60 softbody1_61 softbody1_62 softbody1_63 softbody1_64 softbody1_65 softbody1_66 softbody1_67 softbody1_68 softbody1_69 softbody1_70 softbody1_71 softbody1_72 softbody1_73 softbody1_74 softbody1_75 softbody1_76 softbody1_77 softbody1_78 softbody1_79 softbody1_80 softbody1_81 softbody1_82 softbody1_83 softbody1_84 softbody1_85 softbody1_86 softbody1_87" element="19 4 3 33 45 51 53 85 51 63 53 85 58 54 48 85 49 37 48 85 46 45 53 85 51 59 63 85 55 63 77 85 59 54 58 85 59 51 54 85 63 55 53 85 61 59 58 85 59 61 62 85 51 45 50 85 77 63 62 85 51 50 54 85 63 59 62 85 49 48 54 85 37 49 43 85 61 76 62 85 36 66 85 87 53 55 46 85 19 33 3 87 43 52 44 85 50 45 47 85 46 79 47 85 46 47 45 85 66 69 85 87 49 52 43 85 52 78 44 85 66 76 31 85 47 79 78 85 22 40 86 87 85 21 86 87 78 52 47 85 62 69 77 85 4 33 19 30 7 29 8 87 52 50 47 85 84 85 69 87 69 66 65 87 66 36 65 87 42 27 21 87 79 64 78 86 27 32 22 87 9 3 33 87 76 61 67 85 66 31 36 85 10 4 11 12 60 58 48 85 7 39 38 85 27 42 73 87 57 79 46 85 84 77 69 85 31 67 7 85 60 61 58 85 34 9 5 33 33 4 11 30 2 1 33 87 60 7 67 85 48 37 39 85 3 9 32 87 7 60 39 85 79 78 85 86 21 41 85 86 80 41 79 85 27 3 32 87 79 41 64 86 33 19 30 87 17 40 29 86 43 37 85 86 26 38 37 86 6 7 8 87 55 77 81 85 74 73 42 87 81 77 84 85 37 38 39 85 44 43 85 86 43 25 37 86 33 30 2 87 78 44 85 86 18 28 19 87 79 57 80 85 65 36 35 87 26 16 17 86 37 38 85 86 28 18 73 87 79 85 41 86 31 76 67 85 1 2 0 87 78 64 72 86 44 72 68 86 1 9 33 87 27 73 18 87 44 25 43 86 36 6 35 87 44 68 25 86 18 19 3 87 72 44 78 86 26 17 29 86 55 81 56 85 10 19 28 87 19 10 4 30 48 39 60 85 61 60 67 85 23 14 68 86 9 5 3 32 73 75 28 87 75 82 70 87 0 35 6 87 68 71 23 86 5 32 9 34 3 27 18 87 65 35 70 87 71 72 64 86 40 17 13 86 38 26 29 86 68 14 25 86 68 72 71 86 64 41 21 86 19 10 30 87 14 16 25 86 20 22 15 86 8 9 1 87 71 64 20 86 15 24 20 86 13 17 16 86 13 16 14 86 21 22 20 86 15 14 23 86 24 23 71 86 21 20 64 86 11 4 10 30 15 13 14 86 15 23 24 86 71 20 24 86 66 85 62 76 66 62 85 69 11 4 5 12 5 11 33 4 11 5 33 34 6 85 31 7 85 6 31 36 85 6 87 7 6 85 87 36 33 5 3 9 33 3 5 4 49 85 50 52 85 49 50 54 16 86 37 25 86 16 37 26 75 10 35 70 87 75 35 70 87 21 22 27 87 22 21 86 40 29 87 8 29 40 87 86 30 35 10 70 87 74 82 83 87 7 86 85 87 86 7 29 38 86 7 85 38 7 86 29 10 30 0 35 15 20 32 22 15 32 20 24 1 87 6 8 87 1 6 0 87 69 70 65 55 85 57 46 85 55 57 56 32 22 13 15 32 13 22 40 86 13 22 15 86 22 13 40 85 81 87 84 82 81 87 83 82 87 81 84 74 87 75 73 74 75 87 82 87 56 74 83 56 87 74 42 0 87 30 10 0 30 87 2 84 87 70 82 84 70 87 69 87 9 40 8 32 40 87 9 32 87 40 22 87 56 81 85 87 81 56 83 87 57 56 85 57 87 56 42 87 80 57 85 80 87 57 42 87 41 80 85 41 87 80 42 87 21 41 85 21 87 41 42 10 75 87 28 10 87 35 0 87 10 35 75">
      <contact solref="0.01 1" solimp="0.95 0.99 0.0001 0.5 2" selfcollide="none"/>
      <edge damping="1"/>
    </flex>
  </deformable>
</mujoco>
