<mujoco model="SN001_MSK">
  <compiler inertiafromgeom="auto" angle="radian" balanceinertia="true" boundmass="0.001" boundinertia="0.001">
    <lengthrange inttotal="50" useexisting="true" />
  </compiler>
  <default>
    <joint limited="true" damping="0.5" armature="0.1" stiffness="2" />
    <geom rgba="0.8 0.6 .4 1" margin="0.001" />
    <site size="0.001" />
    <tendon width="0.001" rgba=".95 .3 .3 1" limited="false" />
    <default class="muscle">
      <muscle ctrllimited="true" ctrlrange="0 1" scale="200" />
    </default>
    <default class="motor">
      <general gainprm="5 0 0 0 0 0 0 0 0 0" />
    </default>
  </default>
  <option timestep="0.002" />
  <worldbody>
    <geom name="floor" pos="0 0 0" size="10 10 0.125" type="plane" material="MatPlane" condim="3" />
    <body name="pelvis" pos="       0        0        0" quat="0.7071067811865475 0.7071067811865475 0.0 0.0">
      <light mode="trackcom" directional="false" pos="0 0 4.0" dir="0 0 -1" />
      <geom name="r_pelvis" type="mesh" mesh="r_pelvis" />
      <geom name="l_pelvis" type="mesh" mesh="l_pelvis" />
      <geom name="sacrum" type="mesh" mesh="sacrum" />
      <inertial pos="-0.0817759        0        0" mass="10.9270650543558" fullinertia="0.0960569 0.0960569 0.0718719        0        0        0" />
      <site name="addbrev_r-P1" pos="-0.0220922 -0.108726 0.0144253" />
      <site name="addlong_r-P1" pos="-0.00876749 -0.102827 0.017685" />
      <site name="addmagDist_r-P1" pos="-0.0856392 -0.147671 0.0372996" />
      <site name="addmagIsch_r-P1" pos="-0.10366 -0.150088 0.03907" />
      <site name="addmagMid_r-P1" pos="-0.0609097 -0.139667 0.0267336" />
      <site name="addmagProx_r-P1" pos="-0.0358333 -0.124399 0.012786" />
      <site name="bflh_r-P1" pos="-0.120293 -0.137758 0.054891" />
      <site name="glmax1_r-P1" pos="-0.142385 0.0399048 0.0527366" />
      <site name="glmax1_r-P2" pos="-0.145392 -0.0279912 0.0729694" />
      <site name="glmax2_r-P1" pos="-0.152332 0.0100629 0.0432758" />
      <site name="glmax2_r-P2" pos="-0.155455 -0.0704406 0.0761542" />
      <site name="glmax3_r-P1" pos="-0.150366 -0.0607247 0.00843036" />
      <site name="glmax3_r-P2" pos="-0.147243 -0.146086 0.0407467" />
      <site name="glmed1_r-P1" pos="-0.0514714 0.0283382 0.109782" />
      <site name="glmed2_r-P1" pos="-0.0983162 0.0365505 0.0632277" />
      <site name="glmed3_r-P1" pos="-0.133247 -0.00844362 0.0492707" />
      <site name="glmin1_r-P1" pos="-0.0536691 -0.0172342 0.0976048" />
      <site name="glmin2_r-P1" pos="-0.0712503 -0.0164246 0.0909542" />
      <site name="glmin3_r-P1" pos="-0.0912605 -0.0179282 0.0747491" />
      <site name="grac_r-P1" pos="-0.0547794 -0.149579 0.0230055" />
      <site name="iliacus_r-P1" pos="-0.069978 0.0357408 0.0789643" />
      <site name="iliacus_r-P2" pos="-0.0156149 -0.064426 0.070815" />
      <site name="piri_r-P1" pos="-0.11776 -0.00755299 0.0126549" />
      <site name="piri_r-P2" pos="-0.118003 -0.0354632 0.0570641" />
      <site name="psoas_r-P1" pos="-0.0700936 0.071713 0.0365315" />
      <site name="psoas_r-P2" pos="-0.0237115 -0.0756456 0.0614479" />
      <site name="recfem_r-P1" pos="-0.0277599 -0.0448784 0.0873947" />
      <site name="sart_r-P1" pos="-0.0225549 -0.0180439 0.0989162" />
      <site name="semimem_r-P1" pos="-0.114162 -0.131859 0.0575138" />
      <site name="semiten_r-P1" pos="-0.120061 -0.14493 0.0482404" />
      <site name="tfl_r-P1" pos="-0.0359721 0.0247525 0.116245" />
      <site name="addbrev_l-P1" pos="-0.0220922 -0.108726 -0.0144253" />
      <site name="addlong_l-P1" pos="-0.00876749 -0.102827 -0.017685" />
      <site name="addmagDist_l-P1" pos="-0.0856392 -0.147671 -0.0372996" />
      <site name="addmagIsch_l-P1" pos="-0.10366 -0.150088 -0.03907" />
      <site name="addmagMid_l-P1" pos="-0.0609097 -0.139667 -0.0267336" />
      <site name="addmagProx_l-P1" pos="-0.0358333 -0.124399 -0.012786" />
      <site name="bflh_l-P1" pos="-0.120293 -0.137758 -0.054891" />
      <site name="glmax1_l-P1" pos="-0.142385 0.0399048 -0.0527366" />
      <site name="glmax1_l-P2" pos="-0.145392 -0.0279912 -0.0729694" />
      <site name="glmax2_l-P1" pos="-0.152332 0.0100629 -0.0432758" />
      <site name="glmax2_l-P2" pos="-0.155455 -0.0704406 -0.0761542" />
      <site name="glmax3_l-P1" pos="-0.150366 -0.0607247 -0.00843036" />
      <site name="glmax3_l-P2" pos="-0.147243 -0.146086 -0.0407467" />
      <site name="glmed1_l-P1" pos="-0.0514714 0.0283382 -0.109782" />
      <site name="glmed2_l-P1" pos="-0.0983162 0.0365505 -0.0632277" />
      <site name="glmed3_l-P1" pos="-0.133247 -0.00844362 -0.0492707" />
      <site name="glmin1_l-P1" pos="-0.0536691 -0.0172342 -0.0976048" />
      <site name="glmin2_l-P1" pos="-0.0712503 -0.0164246 -0.0909542" />
      <site name="glmin3_l-P1" pos="-0.0912605 -0.0179282 -0.0747491" />
      <site name="grac_l-P1" pos="-0.0547794 -0.149579 -0.0230055" />
      <site name="iliacus_l-P1" pos="-0.069978 0.0357408 -0.0789643" />
      <site name="iliacus_l-P2" pos="-0.0156149 -0.064426 -0.070815" />
      <site name="piri_l-P1" pos="-0.11776 -0.00755299 -0.0126549" />
      <site name="piri_l-P2" pos="-0.118003 -0.0354632 -0.0570641" />
      <site name="psoas_l-P1" pos="-0.0700936 0.071713 -0.0365315" />
      <site name="psoas_l-P2" pos="-0.0237115 -0.0756456 -0.0614479" />
      <site name="recfem_l-P1" pos="-0.0277599 -0.0448784 -0.0873947" />
      <site name="sart_l-P1" pos="-0.0225549 -0.0180439 -0.0989162" />
      <site name="semimem_l-P1" pos="-0.114162 -0.131859 -0.0575138" />
      <site name="semiten_l-P1" pos="-0.120061 -0.14493 -0.0482404" />
      <site name="tfl_l-P1" pos="-0.0359721 0.0247525 -0.116245" />
      <joint name="pelvis_tz" type="slide" pos="0 0 0" axis="       0        0        1" limited="false" range="      -3        3" ref="0" armature="0" damping="0" stiffness="0" />
      <joint name="pelvis_ty" type="slide" pos="0 0 0" axis="       0        1        0" limited="false" range="      -1        2" ref="0" armature="0" damping="0" stiffness="0" />
      <joint name="pelvis_tx" type="slide" pos="0 0 0" axis="       1        0        0" limited="false" range="      -5        5" ref="0" armature="0" damping="0" stiffness="0" />
      <joint name="pelvis_tilt" type="hinge" pos="0 0 0" axis="       0        0        1" limited="false" range=" -1.5708   1.5708" ref="0" armature="0" damping="0" stiffness="0" />
      <joint name="pelvis_list" type="hinge" pos="0 0 0" axis="       1        0        0" limited="false" range=" -1.5708   1.5708" ref="0" armature="0" damping="0" stiffness="0" />
      <joint name="pelvis_rotation" type="hinge" pos="0 0 0" axis="       0        1        0" limited="false" range=" -1.5708   1.5708" ref="0" armature="0" damping="0" stiffness="0" />
      <body name="femur_r" pos="-0.0650922 -0.0907863 0.0723699" quat="1.0 0.0 0.0 0.0">
        <geom name="r_femur" type="mesh" mesh="r_femur" />
        <inertial pos="       0 -0.165691        0" mass="8.63012676374159" fullinertia="0.118018 0.0309369 0.124453        0        0        0" />
        <site name="addbrev_r-P2" pos="-0.00194931 -0.115009 0.0242689" />
        <site name="addlong_r-P2" pos="0.0109746 -0.233303 0.0154288" />
        <site name="addmagDist_r-P2" pos="0.0109649 -0.255847 0.0188108" />
        <site name="addmagIsch_r-P2" pos="0.00468808 -0.378136 -0.0319004" />
        <site name="addmagMid_r-P2" pos="0.00235866 -0.158284 0.0284794" />
        <site name="addmagProx_r-P2" pos="-0.014883 -0.0768612 0.0312084" />
        <site name="bfsh_r-P1" pos="0.00487327 -0.205749 0.0228069" />
        <site name="gaslat_r-P1" pos="-0.00292396 -0.371733 0.0269979" />
        <site name="gasmed_r-P1" pos="0.00779723 -0.369199 -0.0202728" />
        <site name="glmax1_r-P3" pos="-0.0432746 -0.0317737 0.0294345" />
        <site name="glmax1_r-P4" pos="-0.0269979 -0.0551654 0.0458087" />
        <site name="glmax2_r-P3" pos="-0.0438594 -0.0569198 0.0245613" />
        <site name="glmax2_r-P4" pos="-0.0152046 -0.0990248 0.040838" />
        <site name="glmax3_r-P3" pos="-0.0273878 -0.109649 0.00916174" />
        <site name="glmax3_r-P4" pos="-0.00584792 -0.138303 0.0400583" />
        <site name="glmed1_r-P2" pos="-0.0212474 -0.0114034 0.0540933" />
        <site name="glmed2_r-P2" pos="-0.0251461 -0.00565299 0.0513642" />
        <site name="glmed3_r-P2" pos="-0.0301168 -0.00458087 0.050487" />
        <site name="glmin1_r-P2" pos="-0.0070175 -0.0101364 0.0545806" />
        <site name="glmin2_r-P2" pos="-0.00935667 -0.0101364 0.0545806" />
        <site name="glmin3_r-P2" pos="-0.0131578 -0.00808962 0.0536059" />
        <site name="iliacus_r-P3" pos="-0.0022417 -0.0550679 0.0135477" />
        <site name="iliacus_r-P4" pos="-0.0118908 -0.0620854 0.0191032" />
        <site name="piri_r-P3" pos="-0.0144249 -0.00350875 0.0425924" />
        <site name="psoas_r-P3" pos="-0.0128654 -0.0455163 0.00448341" />
        <site name="psoas_r-P4" pos="-0.0229044 -0.0510718 0.00857695" />
        <site name="sart_r-P2" pos="-0.00292396 -0.347756 -0.0410329" />
        <site name="tfl_r-P2" pos="0.0286548 -0.096978 0.0581868" />
        <site name="tfl_r-P3" pos="0.0104288 -0.394735 0.0315788" />
        <site name="vasint_r-P1" pos="0.0282649 -0.187523 0.0302143" />
        <site name="vasint_r-P2" pos="0.0326509 -0.203118 0.0277776" />
        <site name="vaslat_r-P1" pos="0.00467834 -0.180701 0.0340154" />
        <site name="vaslat_r-P2" pos="0.0262182 -0.252533 0.0398633" />
        <site name="vasmed_r-P1" pos="0.0136451 -0.20458 0.0183235" />
        <site name="vasmed_r-P2" pos="0.0346977 -0.269882 0.000877188" />
        <joint name="hip_flexion_r" type="hinge" pos="0 0 0" axis="       0        0        1" limited="false" range="-0.523599   2.0944" ref="0" />
        <joint name="hip_adduction_r" type="hinge" pos="0 0 0" axis="       1        0        0" limited="false" range="-0.872665 0.523599" ref="0" />
        <joint name="hip_rotation_r" type="hinge" pos="0 0 0" axis="       0        1        0" limited="false" range="-0.698132 0.698132" ref="0" />
        <body name="tibia_r" pos="0.00109144 -0.393697 -0.00103279" quat="1.0 7.240636975890137e-18 -9.456205735995121e-17 -2.960068750797159e-20">
          <geom name="r_tibia" type="mesh" mesh="r_tibia" />
          <geom name="r_fibula" type="mesh" mesh="r_fibula" />
          <inertial pos="       0 -0.207168        0" mass="3.4399332333382" fullinertia="0.0575778 0.00582632 0.0583775        0        0        0" />
          <site name="bflh_r-P2" pos="-0.0373945 -0.038837 0.0280736" />
          <site name="bflh_r-P3" pos="-0.0318463 -0.0504881 0.0336218" />
          <site name="bfsh_r-P2" pos="-0.0333998 -0.0464934 0.0352862" />
          <site name="edl_r-P1" pos="-0.0177541 -0.128384 0.0227474" />
          <site name="edl_r-P2" pos="0.0181979 -0.41722 0.0124278" />
          <site name="ehl_r-P1" pos="-0.0155348 -0.171992 0.020972" />
          <site name="ehl_r-P2" pos="0.00787836 -0.322791 0.0181979" />
          <site name="ehl_r-P3" pos="0.0221926 -0.409786 -0.00310696" />
          <site name="fdl_r-P1" pos="-0.00255215 -0.203284 -0.00199733" />
          <site name="fdl_r-P2" pos="-0.0195295 -0.40446 -0.0137594" />
          <site name="fhl_r-P1" pos="-0.0343985 -0.240013 0.0221926" />
          <site name="fhl_r-P2" pos="-0.026853 -0.407345 -0.00843318" />
          <site name="grac_r-P2" pos="-0.0204394 -0.0527629 -0.0328561" />
          <site name="grac_r-P3" pos="0.00197514 -0.0772524 -0.0174545" />
          <site name="perbrev_r-P1" pos="-0.026964 -0.280958 0.0278517" />
          <site name="perbrev_r-P2" pos="-0.0376164 -0.431979 0.0276298" />
          <site name="perbrev_r-P3" pos="-0.0316244 -0.444295 0.0282955" />
          <site name="perlong_r-P1" pos="-0.0221926 -0.152352 0.0312915" />
          <site name="perlong_r-P2" pos="-0.0351752 -0.432755 0.0262982" />
          <site name="perlong_r-P3" pos="-0.0301819 -0.445405 0.0266311" />
          <site name="recfem_r-P5" pos="0.0361739 -0.0700398 -0.000521526" />
          <site name="sart_r-P3" pos="-0.0278517 -0.0444961 -0.0405015" />
          <site name="sart_r-P4" pos="-0.0176431 -0.0664668 -0.0292942" />
          <site name="sart_r-P5" pos="0.015091 -0.0898799 -0.00288504" />
          <site name="semimem_r-P2" pos="-0.0321792 -0.0462715 -0.0217487" />
          <site name="semiten_r-P2" pos="-0.0346204 -0.0563691 -0.0254105" />
          <site name="semiten_r-P3" pos="0.00210829 -0.0857743 -0.0129827" />
          <site name="soleus_r-P1" pos="-0.00843318 -0.101642 0.0108744" />
          <site name="tfl_r-P4" pos="0.011984 -0.0454948 0.0383932" />
          <site name="tibant_r-P1" pos="0.0170883 -0.145583 0.017976" />
          <site name="tibant_r-P2" pos="0.0278517 -0.211495 0.0142032" />
          <site name="tibant_r-P3" pos="0.0258544 -0.406013 -0.0146471" />
          <site name="tibpost_r-P1" pos="-0.00454948 -0.144696 0.0114292" />
          <site name="tibpost_r-P2" pos="-0.0181979 -0.405569 -0.0194185" />
          <site name="vasint_r-P5" pos="0.0361406 -0.0701285 0.00047714" />
          <site name="vaslat_r-P5" pos="0.0361073 -0.0703283 0.0056702" />
          <site name="vasmed_r-P5" pos="0.0353972 -0.0705391 -0.00752328" />
          <joint name="knee_angle_r_translation2" type="slide" pos="0 0 0" axis="0.992246 0.123982 -0.00878916" limited="true" range="7.69254e-11 0.006792" ref="0" />
          <joint name="knee_angle_r_translation1" type="slide" pos="0 0 0" axis="-0.124293 0.989762 -0.0701648" limited="true" range="9.53733e-08 0.00159883" ref="0" />
          <joint name="knee_angle_r" type="hinge" pos="0 0 0" axis="-3.98373e-10 -0.0707131 -0.997497" limited="false" range="       0   2.0944" ref="0" />
          <joint name="knee_angle_r_rotation2" type="hinge" pos="0 0 0" axis="0.992246 0.123982 -0.00878916" limited="true" range="-0.00167821 0.0335354" ref="0" />
          <joint name="knee_angle_r_rotation3" type="hinge" pos="0 0 0" axis="-0.124293 0.989762 -0.0701648" limited="true" range="1.08939e-08 0.262788" ref="0" />
          <body name="talus_r" pos="-0.0110963 -0.443852        0" quat="1.0 -6.036754011562992e-18 1.5193252867388614e-18 -2.498419531737724e-19">
            <geom name="r_talus" type="mesh" mesh="r_talus" />
            <inertial pos="       0        0        0" mass="0.0927830946281376" fullinertia="0.000691652 0.000691652 0.000691652        0        0        0" />
            <joint name="ankle_angle_r" type="hinge" pos="0 0 0" axis="-0.105014 -0.174022 0.979126" limited="false" range="-0.698132 0.523599" ref="0" />
            <body name="calcn_r" pos="-0.0421077 -0.0362194 0.00683808" quat="1.0 -5.320429553087796e-19 1.609289071159989e-17 -2.1848634538867752e-17">
              <geom name="r_foot" type="mesh" mesh="r_foot" />
              <inertial pos="0.0863394 0.0259018        0" mass="1.15978868285172" fullinertia="0.000968312 0.00269744 0.00283577        0        0        0" />
              <site name="edl_r-P3" pos="0.079346 0.0310822 0.000690716" />
              <site name="edl_r-P4" pos="0.139525 0.00474867 0.0112241" />
              <site name="ehl_r-P4" pos="0.0837493 0.033586 -0.0182176" />
              <site name="ehl_r-P5" pos="0.111637 0.0266789 -0.0221892" />
              <site name="ehl_r-P6" pos="0.149713 0.0120012 -0.024175" />
              <site name="fdl_r-P3" pos="0.037644 0.0271969 -0.024175" />
              <site name="fdl_r-P4" pos="0.0611283 0.0151957 -0.0227073" />
              <site name="fdl_r-P5" pos="0.143151 -0.0069935 0.0100154" />
              <site name="fhl_r-P3" pos="0.032291 0.0238297 -0.0208078" />
              <site name="fhl_r-P4" pos="0.0896203 0.00587108 -0.0221029" />
              <site name="fhl_r-P5" pos="0.149022 -0.00457599 -0.0232253" />
              <site name="gaslat_r-P2" pos="0.00379894 0.0267652 -0.00457599" />
              <site name="gasmed_r-P2" pos="0.00379894 0.0267652 -0.00457599" />
              <site name="perbrev_r-P4" pos="0.0406659 0.0233117 0.0201171" />
              <site name="perbrev_r-P5" pos="0.0584518 0.0189083 0.0296144" />
              <site name="perlong_r-P4" pos="0.0378167 0.0198581 0.019081" />
              <site name="perlong_r-P5" pos="0.0587972 0.00915198 0.0245204" />
              <site name="perlong_r-P6" pos="0.0735612 0.00595742 0.0101881" />
              <site name="perlong_r-P7" pos="0.103866 0.00733885 -0.0158865" />
              <site name="soleus_r-P2" pos="0.00379894 0.0267652 -0.00457599" />
              <site name="tibant_r-P4" pos="0.100672 0.0153684 -0.0263335" />
              <site name="tibpost_r-P3" pos="0.0360035 0.0288374 -0.0246931" />
              <site name="tibpost_r-P4" pos="0.0666541 0.013728 -0.0242614" />
              <joint name="subtalar_angle_r" type="hinge" pos="0 0 0" axis=" 0.78718 0.604747 -0.120949" limited="false" range="-0.349066 0.349066" ref="0" />
              <body name="toes_r" pos="0.154375 -0.00172679 0.000932466" quat="1.0 1.314867274624753e-31 -2.6810890689525335e-17 -3.939849802505862e-32">
                <geom name="r_bofoot" type="mesh" mesh="r_bofoot" />
                <inertial pos="0.0298734 0.00518037 -0.0151094" mass="0.200968182964546" fullinertia="6.91652e-05 0.00013833 0.000691652        0        0        0" />
                <site name="edl_r-P5" pos="0.000259018 0.00405795 0.0132099" />
                <site name="edl_r-P6" pos="0.0382484 -0.000345358 0.0215849" />
                <site name="ehl_r-P7" pos="0.0257292 0.00353992 -0.0211532" />
                <site name="ehl_r-P8" pos="0.0486091 0.00293554 -0.0160591" />
                <site name="fdl_r-P6" pos="-0.00164045 -0.00673448 0.0126919" />
                <site name="fdl_r-P7" pos="0.0246067 -0.0061301 0.018563" />
                <site name="fdl_r-P8" pos="0.0380757 -0.00518037 0.0208941" />
                <site name="fhl_r-P6" pos="0.0133826 -0.00552572 -0.02288" />
                <site name="fhl_r-P7" pos="0.0485228 -0.00880662 -0.0156274" />
                <joint name="mtp_angle_r" type="hinge" pos="0 0 0" axis="0.580954 2.6299e-15 -0.813936" limited="false" range="-0.523599 0.523599" ref="0" />
              </body>
            </body>
          </body>
        </body>
        <body name="patella_r" pos="-0.00788495 -0.39762 6.9703e-05" quat="1.0 0.0 0.0 0.0">
          <geom name="r_patella" type="mesh" mesh="r_patella" />
          <inertial pos="  0.0018   0.0264        0" mass="0.0799790275694546" fullinertia="2.66287e-06 1.21639e-05 1.21639e-05        0        0        0" />
          <site name="recfem_r-P2" pos="0.01 0.049 0.0007" />
          <site name="recfem_r-P3" pos="0.0121 0.0437 -0.001" />
          <site name="recfem_r-P4" pos="0.005 0.00247 3e-005" />
          <site name="vasint_r-P3" pos="0.0058 0.048 -0.0006" />
          <site name="vasint_r-P4" pos="0.005 0.00247 -0.00039" />
          <site name="vaslat_r-P3" pos="0.0103 0.0423 0.0141" />
          <site name="vaslat_r-P4" pos="0.005 0.00247 0.00733" />
          <site name="vasmed_r-P3" pos="0.0063 0.0445 -0.017" />
          <site name="vasmed_r-P4" pos="0.005 0.00247 -0.0085" />
          <joint name="knee_angle_r_beta_translation2" type="slide" pos="0 0 0" axis="       0        1        0" limited="true" range="-0.0408267 -0.0108281" ref="0" />
          <joint name="knee_angle_r_beta_translation1" type="slide" pos="0 0 0" axis="       1        0        0" limited="true" range="-0.0227731 0.0524192" ref="0" />
          <joint name="knee_angle_r_beta_rotation1" type="hinge" pos="0 0 0" axis="       0        0        1" limited="true" range="-1.79241 0.010506" ref="0" />
        </body>
      </body>
      <body name="femur_l" pos="-0.0650922 -0.0907863 -0.0723699" quat="1.0 0.0 0.0 0.0">
        <geom name="l_femur" type="mesh" mesh="l_femur" />
        <inertial pos="       0 -0.166781        0" mass="8.63012676374159" fullinertia="0.119576 0.031345 0.126095        0        0        0" />
        <site name="addbrev_l-P2" pos="-0.00196212 -0.115765 -0.0244284" />
        <site name="addlong_l-P2" pos="0.0110468 -0.234837 -0.0155302" />
        <site name="addmagDist_l-P2" pos="0.0110369 -0.257529 -0.0189345" />
        <site name="addmagIsch_l-P2" pos="0.00471891 -0.380623 0.0321102" />
        <site name="addmagMid_l-P2" pos="0.00237417 -0.159324 -0.0286666" />
        <site name="addmagProx_l-P2" pos="-0.0149808 -0.0773665 -0.0314136" />
        <site name="bfsh_l-P1" pos="0.00490531 -0.207102 -0.0229568" />
        <site name="gaslat_l-P1" pos="-0.00294319 -0.374177 -0.0271754" />
        <site name="gasmed_l-P1" pos="0.00784849 -0.371626 0.0204061" />
        <site name="glmax1_l-P3" pos="-0.0435591 -0.0319826 -0.0296281" />
        <site name="glmax1_l-P4" pos="-0.0271754 -0.0555281 -0.0461099" />
        <site name="glmax2_l-P3" pos="-0.0441478 -0.057294 -0.0247228" />
        <site name="glmax2_l-P4" pos="-0.0153046 -0.0996759 -0.0411065" />
        <site name="glmax3_l-P3" pos="-0.0275678 -0.110369 -0.00922198" />
        <site name="glmax3_l-P4" pos="-0.00588637 -0.139213 -0.0403216" />
        <site name="glmed1_l-P2" pos="-0.0213871 -0.0114784 -0.0544489" />
        <site name="glmed2_l-P2" pos="-0.0253114 -0.00569016 -0.051702" />
        <site name="glmed3_l-P2" pos="-0.0303148 -0.00461099 -0.050819" />
        <site name="glmin1_l-P2" pos="-0.00706365 -0.010203 -0.0549395" />
        <site name="glmin2_l-P2" pos="-0.00941819 -0.010203 -0.0549395" />
        <site name="glmin3_l-P2" pos="-0.0132443 -0.00814281 -0.0539584" />
        <site name="iliacus_l-P3" pos="-0.00225644 -0.05543 -0.0136368" />
        <site name="iliacus_l-P4" pos="-0.011969 -0.0624936 -0.0192288" />
        <site name="piri_l-P3" pos="-0.0145197 -0.00353182 -0.0428724" />
        <site name="psoas_l-P3" pos="-0.01295 -0.0458156 -0.00451288" />
        <site name="psoas_l-P4" pos="-0.023055 -0.0514076 -0.00863334" />
        <site name="sart_l-P2" pos="-0.00294319 -0.350043 0.0413027" />
        <site name="tfl_l-P2" pos="0.0288432 -0.0976157 -0.0585694" />
        <site name="tfl_l-P3" pos="0.0104974 -0.39733 -0.0317864" />
        <site name="vasint_l-P1" pos="0.0284508 -0.188756 -0.0304129" />
        <site name="vasint_l-P2" pos="0.0328656 -0.204453 -0.0279603" />
        <site name="vaslat_l-P1" pos="0.0047091 -0.181889 -0.0342391" />
        <site name="vaslat_l-P2" pos="0.0263906 -0.254193 -0.0401254" />
        <site name="vasmed_l-P1" pos="0.0137349 -0.205925 -0.018444" />
        <site name="vasmed_l-P2" pos="0.0349258 -0.271656 -0.000882956" />
        <joint name="hip_flexion_l" type="hinge" pos="0 0 0" axis="       0        0        1" limited="false" range="-0.523599   2.0944" ref="0" />
        <joint name="hip_adduction_l" type="hinge" pos="0 0 0" axis="      -1       -0       -0" limited="false" range="-0.872665 0.523599" ref="0" />
        <joint name="hip_rotation_l" type="hinge" pos="0 0 0" axis="      -0       -1       -0" limited="false" range="-0.698132 0.698132" ref="0" />
        <body name="tibia_l" pos="0.00124904 -0.39622 0.00101197" quat="1.0 -7.240636975890137e-18 9.456205735995121e-17 -2.960068750797159e-20">
          <geom name="l_tibia" type="mesh" mesh="l_tibia" />
          <geom name="l_fibula" type="mesh" mesh="l_fibula" />
          <inertial pos="       0 -0.212002        0" mass="3.4399332333382" fullinertia="0.060296 0.00610138 0.0611335        0        0        0" />
          <site name="bflh_l-P2" pos="-0.038267 -0.0397432 -0.0287286" />
          <site name="bflh_l-P3" pos="-0.0325894 -0.0516661 -0.0344062" />
          <site name="bfsh_l-P2" pos="-0.0341791 -0.0475783 -0.0361095" />
          <site name="edl_l-P1" pos="-0.0181683 -0.13138 -0.0232782" />
          <site name="edl_l-P2" pos="0.0186225 -0.426955 -0.0127178" />
          <site name="ehl_l-P1" pos="-0.0158973 -0.176006 -0.0214613" />
          <site name="ehl_l-P2" pos="0.00806219 -0.330323 -0.0186225" />
          <site name="ehl_l-P3" pos="0.0227104 -0.419347 0.00317945" />
          <site name="fdl_l-P1" pos="-0.0026117 -0.208027 0.00204394" />
          <site name="fdl_l-P2" pos="-0.0199851 -0.413897 0.0140804" />
          <site name="fhl_l-P1" pos="-0.0352011 -0.245613 -0.0227104" />
          <site name="fhl_l-P2" pos="-0.0274796 -0.416849 0.00862995" />
          <site name="grac_l-P2" pos="-0.0209163 -0.053994 0.0336227" />
          <site name="grac_l-P3" pos="0.00202122 -0.0790549 0.0178617" />
          <site name="perbrev_l-P1" pos="-0.0275931 -0.287514 -0.0285015" />
          <site name="perbrev_l-P2" pos="-0.0384941 -0.442058 -0.0282744" />
          <site name="perbrev_l-P3" pos="-0.0323623 -0.454662 -0.0289558" />
          <site name="perlong_l-P1" pos="-0.0227104 -0.155907 -0.0320217" />
          <site name="perlong_l-P2" pos="-0.035996 -0.442853 -0.0269118" />
          <site name="perlong_l-P3" pos="-0.0308861 -0.455798 -0.0272525" />
          <site name="recfem_l-P5" pos="0.0370179 -0.071674 0.000533694" />
          <site name="sart_l-P3" pos="-0.0285015 -0.0455343 0.0414465" />
          <site name="sart_l-P4" pos="-0.0180548 -0.0680176 0.0299777" />
          <site name="sart_l-P5" pos="0.0154431 -0.0919771 0.00295235" />
          <site name="semimem_l-P2" pos="-0.0329301 -0.0473512 0.0222562" />
          <site name="semiten_l-P2" pos="-0.0354282 -0.0576844 0.0260034" />
          <site name="semiten_l-P3" pos="0.00215749 -0.0877757 0.0132856" />
          <site name="soleus_l-P1" pos="-0.00862995 -0.104014 -0.0111281" />
          <site name="tfl_l-P4" pos="0.0122636 -0.0465563 -0.039289" />
          <site name="tibant_l-P1" pos="0.017487 -0.14898 -0.0183954" />
          <site name="tibant_l-P2" pos="0.0285015 -0.21643 -0.0145347" />
          <site name="tibant_l-P3" pos="0.0264576 -0.415487 0.0149889" />
          <site name="tibpost_l-P1" pos="-0.00465563 -0.148072 -0.0116959" />
          <site name="tibpost_l-P2" pos="-0.0186225 -0.415032 0.0198716" />
          <site name="vasint_l-P5" pos="0.0369839 -0.0717648 -0.000488273" />
          <site name="vaslat_l-P5" pos="0.0369498 -0.0719692 -0.00580251" />
          <site name="vasmed_l-P5" pos="0.0362231 -0.072185 0.00769882" />
          <joint name="knee_angle_l_translation2" type="slide" pos="0 0 0" axis="-0.992246 -0.123982 -0.00878916" limited="true" range="-0.006792 -7.69254e-11" ref="0" />
          <joint name="knee_angle_l_translation1" type="slide" pos="0 0 0" axis="-0.124293 0.989762 0.0701648" limited="true" range="9.53733e-08 0.00159883" ref="0" />
          <joint name="knee_angle_l" type="hinge" pos="0 0 0" axis="3.98373e-10 0.0707131 -0.997497" limited="false" range="       0   2.0944" ref="0" />
          <joint name="knee_angle_l_rotation2" type="hinge" pos="0 0 0" axis="-0.992246 -0.123982 -0.00878916" limited="true" range="-0.00167821 0.0335354" ref="0" />
          <joint name="knee_angle_l_rotation3" type="hinge" pos="0 0 0" axis="-0.124293 0.989762 0.0701648" limited="true" range="-0.262788 -1.08939e-08" ref="0" />
          <body name="talus_l" pos="-0.0113552 -0.454208        0" quat="1.0 6.036754011562992e-18 -1.5193252867388614e-18 -2.498419531737724e-19">
            <geom name="l_talus" type="mesh" mesh="l_talus" />
            <inertial pos="       0        0        0" mass="0.0927830946281376" fullinertia="0.000783966 0.000783966 0.000783966        0        0        0" />
            <joint name="ankle_angle_l" type="hinge" pos="0 0 0" axis="0.105014 0.174022 0.979126" limited="false" range="-0.698132 0.523599" ref="0" />
            <body name="calcn_l" pos="-0.0448298 -0.0385608 -0.00728013" quat="1.0 5.320429553087796e-19 -1.609289071159989e-17 -2.1848634538867752e-17">
              <geom name="l_foot" type="mesh" mesh="l_foot" />
              <inertial pos="0.0919209 0.0275763        0" mass="1.15978868285172" fullinertia="0.00109755 0.00305747 0.00321426        0        0        0" />
              <site name="edl_l-P3" pos="0.0844753 0.0330915 -0.000735367" />
              <site name="edl_l-P4" pos="0.148544 0.00505565 -0.0119497" />
              <site name="ehl_l-P4" pos="0.0891633 0.0357572 0.0193953" />
              <site name="ehl_l-P5" pos="0.118854 0.0284036 0.0236237" />
              <site name="ehl_l-P6" pos="0.159391 0.012777 0.0257378" />
              <site name="fdl_l-P3" pos="0.0400775 0.0289551 0.0257378" />
              <site name="fdl_l-P4" pos="0.06508 0.0161781 0.0241752" />
              <site name="fdl_l-P5" pos="0.152405 -0.00744559 -0.0106628" />
              <site name="fhl_l-P3" pos="0.0343784 0.0253702 0.0221529" />
              <site name="fhl_l-P4" pos="0.0954139 0.00625062 0.0235317" />
              <site name="fhl_l-P5" pos="0.158655 -0.00487181 0.0247267" />
              <site name="gaslat_l-P2" pos="0.00404452 0.0284955 0.00487181" />
              <site name="gasmed_l-P2" pos="0.00404452 0.0284955 0.00487181" />
              <site name="perbrev_l-P4" pos="0.0432947 0.0248186 -0.0214176" />
              <site name="perbrev_l-P5" pos="0.0622304 0.0201307 -0.0315289" />
              <site name="perlong_l-P4" pos="0.0402614 0.0211418 -0.0203145" />
              <site name="perlong_l-P5" pos="0.0625981 0.00974361 -0.0261055" />
              <site name="perlong_l-P6" pos="0.0783166 0.00634254 -0.0108467" />
              <site name="perlong_l-P7" pos="0.110581 0.00781328 0.0169134" />
              <site name="soleus_l-P2" pos="0.00404452 0.0284955 0.00487181" />
              <site name="tibant_l-P4" pos="0.10718 0.0163619 0.0280359" />
              <site name="tibpost_l-P3" pos="0.038331 0.0307016 0.0262894" />
              <site name="tibpost_l-P4" pos="0.0709629 0.0146154 0.0258298" />
              <joint name="subtalar_angle_l" type="hinge" pos="0 0 0" axis="-0.78718 -0.604747 -0.120949" limited="false" range="-0.349066 0.349066" ref="0" />
              <body name="toes_l" pos="0.164355 -0.00183842 -0.000992746" quat="1.0 1.314867274624753e-31 2.6810890689525335e-17 3.939849802505862e-32">
                <geom name="l_bofoot" type="mesh" mesh="l_bofoot" />
                <inertial pos="0.0318046 0.00551525 0.0160862" mass="0.200968182964546" fullinertia="7.83966e-05 0.000156793 0.000783966        0        0        0" />
                <site name="edl_l-P5" pos="0.000275763 0.00432028 -0.0140639" />
                <site name="edl_l-P6" pos="0.040721 -0.000367684 -0.0229802" />
                <site name="ehl_l-P7" pos="0.0273924 0.00376876 0.0225206" />
                <site name="ehl_l-P8" pos="0.0517515 0.00312531 0.0170973" />
                <site name="fdl_l-P6" pos="-0.0017465 -0.00716983 -0.0135124" />
                <site name="fdl_l-P7" pos="0.0261975 -0.00652638 -0.019763" />
                <site name="fdl_l-P8" pos="0.0405371 -0.00551525 -0.0222449" />
                <site name="fhl_l-P6" pos="0.0142477 -0.00588294 0.024359" />
                <site name="fhl_l-P7" pos="0.0516595 -0.00937593 0.0166377" />
                <joint name="mtp_angle_l" type="hinge" pos="0 0 0" axis="-0.580954 2.6299e-15 -0.813936" limited="false" range="-0.523599 0.523599" ref="0" />
              </body>
            </body>
          </body>
        </body>
        <body name="patella_l" pos="-0.00793679 -0.400234 -5.20799e-05" quat="1.0 0.0 0.0 0.0">
          <geom name="l_patella" type="mesh" mesh="l_patella" />
          <inertial pos="  0.0018   0.0264        0" mass="0.0799790275694546" fullinertia="2.66287e-06 1.21639e-05 1.21639e-05        0        0        0" />
          <site name="recfem_l-P2" pos="0.01 0.049 -0.0007" />
          <site name="recfem_l-P3" pos="0.0121 0.0437 0.001" />
          <site name="recfem_l-P4" pos="0.005 0.00247 -3e-005" />
          <site name="vasint_l-P3" pos="0.0058 0.048 0.0006" />
          <site name="vasint_l-P4" pos="0.005 0.00247 0.00039" />
          <site name="vaslat_l-P3" pos="0.0103 0.0423 -0.0141" />
          <site name="vaslat_l-P4" pos="0.005 0.00247 -0.00733" />
          <site name="vasmed_l-P3" pos="0.0063 0.0445 0.017" />
          <site name="vasmed_l-P4" pos="0.005 0.00247 0.0085" />
          <joint name="knee_angle_l_beta_translation2" type="slide" pos="0 0 0" axis="       0        1        0" limited="true" range="-0.0408267 -0.0108281" ref="0" />
          <joint name="knee_angle_l_beta_translation1" type="slide" pos="0 0 0" axis="       1        0        0" limited="true" range="-0.0227731 0.0524192" ref="0" />
          <joint name="knee_angle_l_beta_rotation1" type="hinge" pos="0 0 0" axis="       0        0        1" limited="true" range="-1.79241 0.010506" ref="0" />
        </body>
      </body>
      <body name="torso" pos="-0.116476 0.0942678        0" quat="1.0 0.0 0.0 0.0">
        <geom name="hat_spine" type="mesh" mesh="hat_spine" />
        <geom name="hat_jaw" type="mesh" mesh="hat_jaw" />
        <geom name="hat_skull" type="mesh" mesh="hat_skull" />
        <geom name="hat_ribs_scap" type="mesh" mesh="hat_ribs_scap" />
        <inertial pos="-0.0328335 0.350224        0" mass="24.890549663512" fullinertia=" 1.63872 0.839645  1.59082        0        0        0" />
        <joint name="lumbar_extension" type="hinge" pos="0 0 0" axis="       0        0        1" limited="false" range=" -1.5708   1.5708" ref="0" />
        <joint name="lumbar_bending" type="hinge" pos="0 0 0" axis="       1        0        0" limited="false" range=" -1.5708   1.5708" ref="0" />
        <joint name="lumbar_rotation" type="hinge" pos="0 0 0" axis="       0        1        0" limited="false" range=" -1.5708   1.5708" ref="0" />
        <body name="humerus_r" pos="0.00345299 0.406588 0.186057" quat="1.0 0.0 0.0 0.0">
          <geom name="humerus_rv" type="mesh" mesh="humerus_rv" />
          <inertial pos="       0 -0.17897        0" mass="1.8858163983169" fullinertia="0.0131193 0.00452576 0.014726        0        0        0" />
          <joint name="arm_flex_r" type="hinge" pos="0 0 0" axis="       0        0        1" limited="false" range=" -1.5708   1.5708" ref="0" />
          <joint name="arm_add_r" type="hinge" pos="0 0 0" axis="       1        0        0" limited="false" range=" -2.0944   1.5708" ref="0" />
          <joint name="arm_rot_r" type="hinge" pos="0 0 0" axis="       0        1        0" limited="false" range=" -1.5708   1.5708" ref="0" />
          <body name="ulna_r" pos="0.0143001 -0.311452 -0.0104389" quat="1.0 1.6893809785063376e-18 -6.938893903907228e-18 4.155190089080778e-20">
            <geom name="ulna_rv" type="mesh" mesh="ulna_rv" />
            <inertial pos="       0 -0.133441        0" mass="0.563657299865936" fullinertia="0.00336884 0.000702885 0.00365432        0        0        0" />
            <joint name="elbow_flex_r" type="hinge" pos="0 0 0" axis="0.226047 0.022269 0.973862" limited="false" range="       0    2.618" ref="0" />
            <body name="radius_r" pos="-0.00744792 -0.0144009 0.0288783" quat="1.0 2.301201592641875e-21 -6.933378131686372e-19 1.7489241099837954e-19">
              <geom name="radius_rv" type="mesh" mesh="radius_rv" />
              <inertial pos="       0 -0.140277        0" mass="0.563657299865936" fullinertia="0.00372281 0.000776736 0.00403828        0        0        0" />
              <joint name="pro_sup_r" type="hinge" pos="0 0 0" axis="0.056398 0.998406 0.001952" limited="false" range="       0   1.5708" ref="0" />
              <body name="hand_r" pos="-0.0102387 -0.274491 0.0158404" quat="1.0 0.0 8.407790785948892e-45 0.0">
                <geom name="pisiform_rvs" type="mesh" mesh="pisiform_rvs" />
                <geom name="lunate_rvs" type="mesh" mesh="lunate_rvs" />
                <geom name="scaphoid_rvs" type="mesh" mesh="scaphoid_rvs" />
                <geom name="triquetrum_rvs" type="mesh" mesh="triquetrum_rvs" />
                <geom name="hamate_rvs" type="mesh" mesh="hamate_rvs" />
                <geom name="capitate_rvs" type="mesh" mesh="capitate_rvs" />
                <geom name="trapezoid_rvs" type="mesh" mesh="trapezoid_rvs" />
                <geom name="trapezium_rvs" type="mesh" mesh="trapezium_rvs" />
                <geom name="metacarpal2_rvs" type="mesh" mesh="metacarpal2_rvs" />
                <geom name="index_proximal_rvs" type="mesh" mesh="index_proximal_rvs" />
                <geom name="index_medial_rvs" type="mesh" mesh="index_medial_rvs" />
                <geom name="index_distal_rvs" type="mesh" mesh="index_distal_rvs" />
                <geom name="metacarpal3_rvs" type="mesh" mesh="metacarpal3_rvs" />
                <geom name="middle_proximal_rvs" type="mesh" mesh="middle_proximal_rvs" />
                <geom name="middle_medial_rvs" type="mesh" mesh="middle_medial_rvs" />
                <geom name="middle_distal_rvs" type="mesh" mesh="middle_distal_rvs" />
                <geom name="metacarpal4_rvs" type="mesh" mesh="metacarpal4_rvs" />
                <geom name="ring_proximal_rvs" type="mesh" mesh="ring_proximal_rvs" />
                <geom name="ring_medial_rvs" type="mesh" mesh="ring_medial_rvs" />
                <geom name="ring_distal_rvs" type="mesh" mesh="ring_distal_rvs" />
                <geom name="metacarpal5_rvs" type="mesh" mesh="metacarpal5_rvs" />
                <geom name="little_proximal_rvs" type="mesh" mesh="little_proximal_rvs" />
                <geom name="little_medial_rvs" type="mesh" mesh="little_medial_rvs" />
                <geom name="little_distal_rvs" type="mesh" mesh="little_distal_rvs" />
                <geom name="metacarpal1_rvs" type="mesh" mesh="metacarpal1_rvs" />
                <geom name="thumb_proximal_rvs" type="mesh" mesh="thumb_proximal_rvs" />
                <geom name="thumb_distal_rvs" type="mesh" mesh="thumb_distal_rvs" />
                <inertial pos="       0 -0.068095        0" mass="0.424482657923729" fullinertia="0.000827625 0.000507524 0.00124329        0        0        0" />
                <joint name="wrist_flex_r" type="hinge" pos="0 0 0" axis="-3.55271e-15 3.55271e-15        1" limited="false" range="-1.22173  1.22173" ref="0" />
                <joint name="wrist_dev_r" type="hinge" pos="0 0 0" axis="       1        0 3.55271e-15" limited="false" range="-0.436332 0.610865" ref="0" />
              </body>
            </body>
          </body>
        </body>
        <body name="humerus_l" pos="0.00345299 0.406588 -0.186057" quat="1.0 0.0 0.0 0.0">
          <geom name="humerus_lv" type="mesh" mesh="humerus_lv" />
          <inertial pos="       0 -0.176496        0" mass="1.8858163983169" fullinertia="0.0127591 0.00440148 0.0143216        0        0        0" />
          <joint name="arm_flex_l" type="hinge" pos="0 0 0" axis="       0        0        1" limited="false" range=" -1.5708   1.5708" ref="0" />
          <joint name="arm_add_l" type="hinge" pos="0 0 0" axis="      -1        0        0" limited="false" range=" -2.0944   1.5708" ref="0" />
          <joint name="arm_rot_l" type="hinge" pos="0 0 0" axis="       0       -1        0" limited="false" range=" -1.5708   1.5708" ref="0" />
          <body name="ulna_l" pos="0.0141023 -0.307145 0.0102946" quat="1.0 -1.6893809785063376e-18 6.938893903907228e-18 4.155190089080778e-20">
            <geom name="ulna_lv" type="mesh" mesh="ulna_lv" />
            <inertial pos="       0 -0.134435        0" mass="0.563657299865936" fullinertia="0.00341921 0.000713394 0.00370895        0        0        0" />
            <joint name="elbow_flex_l" type="hinge" pos="0 0 0" axis="-0.226047 -0.022269 0.973862" limited="false" range="       0    2.618" ref="0" />
            <body name="radius_l" pos="-0.00750339 -0.0145082 -0.0290933" quat="1.0 -2.301201592641875e-21 6.933378131686372e-19 1.7489241099837954e-19">
              <geom name="radius_lv" type="mesh" mesh="radius_lv" />
              <inertial pos="       0 -0.140438        0" mass="0.563657299865936" fullinertia="0.00373139 0.000778527 0.00404759        0        0        0" />
              <joint name="pro_sup_l" type="hinge" pos="0 0 0" axis="-0.056398 -0.998406 0.001952" limited="false" range="       0   1.5708" ref="0" />
              <body name="hand_l" pos="-0.0102504 -0.274807 -0.0158587" quat="1.0 0.0 8.407790785948892e-45 0.0">
                <geom name="pisiform_lvs" type="mesh" mesh="pisiform_lvs" />
                <geom name="lunate_lvs" type="mesh" mesh="lunate_lvs" />
                <geom name="scaphoid_lvs" type="mesh" mesh="scaphoid_lvs" />
                <geom name="triquetrum_lvs" type="mesh" mesh="triquetrum_lvs" />
                <geom name="hamate_lvs" type="mesh" mesh="hamate_lvs" />
                <geom name="capitate_lvs" type="mesh" mesh="capitate_lvs" />
                <geom name="trapezoid_lvs" type="mesh" mesh="trapezoid_lvs" />
                <geom name="trapezium_lvs" type="mesh" mesh="trapezium_lvs" />
                <geom name="metacarpal2_lvs" type="mesh" mesh="metacarpal2_lvs" />
                <geom name="index_proximal_lvs" type="mesh" mesh="index_proximal_lvs" />
                <geom name="index_medial_lvs" type="mesh" mesh="index_medial_lvs" />
                <geom name="index_distal_lvs" type="mesh" mesh="index_distal_lvs" />
                <geom name="metacarpal3_lvs" type="mesh" mesh="metacarpal3_lvs" />
                <geom name="middle_proximal_lvs" type="mesh" mesh="middle_proximal_lvs" />
                <geom name="middle_medial_lvs" type="mesh" mesh="middle_medial_lvs" />
                <geom name="middle_distal_lvs" type="mesh" mesh="middle_distal_lvs" />
                <geom name="metacarpal4_lvs" type="mesh" mesh="metacarpal4_lvs" />
                <geom name="ring_proximal_lvs" type="mesh" mesh="ring_proximal_lvs" />
                <geom name="ring_medial_lvs" type="mesh" mesh="ring_medial_lvs" />
                <geom name="ring_distal_lvs" type="mesh" mesh="ring_distal_lvs" />
                <geom name="metacarpal5_lvs" type="mesh" mesh="metacarpal5_lvs" />
                <geom name="little_proximal_lvs" type="mesh" mesh="little_proximal_lvs" />
                <geom name="little_medial_lvs" type="mesh" mesh="little_medial_lvs" />
                <geom name="little_distal_lvs" type="mesh" mesh="little_distal_lvs" />
                <geom name="metacarpal1_lvs" type="mesh" mesh="metacarpal1_lvs" />
                <geom name="thumb_proximal_lvs" type="mesh" mesh="thumb_proximal_lvs" />
                <geom name="thumb_distal_lvs" type="mesh" mesh="thumb_distal_lvs" />
                <inertial pos="       0 -0.068095        0" mass="0.424482657923729" fullinertia="0.000827625 0.000507524 0.00124329        0        0        0" />
                <joint name="wrist_flex_l" type="hinge" pos="0 0 0" axis="-3.55271e-15 -3.55271e-15        1" limited="false" range="-1.22173  1.22173" ref="0" />
                <joint name="wrist_dev_l" type="hinge" pos="0 0 0" axis="      -1        0 -3.55271e-15" limited="false" range="-0.436332 0.610865" ref="0" />
              </body>
            </body>
          </body>
        </body>
      </body>
    </body>
    <camera name="for_testing" pos="0 0 0" euler="0 0 0" />
  </worldbody>
  <asset>
    <mesh name="r_pelvis" file="Geometry/r_pelvis.stl" scale=" 1.15666  1.15666 0.936706" />
    <mesh name="l_pelvis" file="Geometry/l_pelvis.stl" scale=" 1.15666  1.15666 0.936706" />
    <mesh name="sacrum" file="Geometry/sacrum.stl" scale=" 1.15666  1.15666 0.936706" />
    <mesh name="r_femur" file="Geometry/r_femur.stl" scale="0.974653 0.974653 0.974653" />
    <mesh name="r_tibia" file="Geometry/r_tibia.stl" scale=" 1.10963  1.10963  1.10963" />
    <mesh name="r_fibula" file="Geometry/r_fibula.stl" scale=" 1.10963  1.10963  1.10963" />
    <mesh name="r_talus" file="Geometry/r_talus.stl" scale="0.863394 0.863394 0.863394" />
    <mesh name="r_foot" file="Geometry/r_foot.stl" scale="0.863394 0.863394 0.863394" />
    <mesh name="r_bofoot" file="Geometry/r_bofoot.stl" scale="0.863394 0.863394 0.863394" />
    <mesh name="r_patella" file="Geometry/r_patella.stl" scale="       1        1        1" />
    <mesh name="l_femur" file="Geometry/l_femur.stl" scale="0.981062 0.981062 0.981062" />
    <mesh name="l_tibia" file="Geometry/l_tibia.stl" scale=" 1.13552  1.13552  1.13552" />
    <mesh name="l_fibula" file="Geometry/l_fibula.stl" scale=" 1.13552  1.13552  1.13552" />
    <mesh name="l_talus" file="Geometry/l_talus.stl" scale="0.919209 0.919209 0.919209" />
    <mesh name="l_foot" file="Geometry/l_foot.stl" scale="0.919209 0.919209 0.919209" />
    <mesh name="l_bofoot" file="Geometry/l_bofoot.stl" scale="0.919209 0.919209 0.919209" />
    <mesh name="l_patella" file="Geometry/l_patella.stl" scale="       1        1        1" />
    <mesh name="hat_spine" file="Geometry/hat_spine.stl" scale=" 1.09445  1.09445  1.09445" />
    <mesh name="hat_jaw" file="Geometry/hat_jaw.stl" scale=" 1.09445  1.09445  1.09445" />
    <mesh name="hat_skull" file="Geometry/hat_skull.stl" scale=" 1.09445  1.09445  1.09445" />
    <mesh name="hat_ribs_scap" file="Geometry/hat_ribs_scap.stl" scale=" 1.09445  1.09445  1.09445" />
    <mesh name="humerus_rv" file="Geometry/humerus_rv.stl" scale=" 1.08795  1.08795  1.08795" />
    <mesh name="ulna_rv" file="Geometry/ulna_rv.stl" scale=" 1.10717  1.10717  1.10717" />
    <mesh name="radius_rv" file="Geometry/radius_rv.stl" scale=" 1.16388  1.16388  1.16388" />
    <mesh name="pisiform_rvs" file="Geometry/pisiform_rvs.stl" scale="    0.85     0.85     0.85" />
    <mesh name="lunate_rvs" file="Geometry/lunate_rvs.stl" scale="    0.85     0.85     0.85" />
    <mesh name="scaphoid_rvs" file="Geometry/scaphoid_rvs.stl" scale="    0.85     0.85     0.85" />
    <mesh name="triquetrum_rvs" file="Geometry/triquetrum_rvs.stl" scale="    0.85     0.85     0.85" />
    <mesh name="hamate_rvs" file="Geometry/hamate_rvs.stl" scale="    0.85     0.85     0.85" />
    <mesh name="capitate_rvs" file="Geometry/capitate_rvs.stl" scale="    0.85     0.85     0.85" />
    <mesh name="trapezoid_rvs" file="Geometry/trapezoid_rvs.stl" scale="    0.85     0.85     0.85" />
    <mesh name="trapezium_rvs" file="Geometry/trapezium_rvs.stl" scale="    0.85     0.85     0.85" />
    <mesh name="metacarpal2_rvs" file="Geometry/metacarpal2_rvs.stl" scale="    0.85     0.85     0.85" />
    <mesh name="index_proximal_rvs" file="Geometry/index_proximal_rvs.stl" scale="    0.85     0.85     0.85" />
    <mesh name="index_medial_rvs" file="Geometry/index_medial_rvs.stl" scale="    0.85     0.85     0.85" />
    <mesh name="index_distal_rvs" file="Geometry/index_distal_rvs.stl" scale="    0.85     0.85     0.85" />
    <mesh name="metacarpal3_rvs" file="Geometry/metacarpal3_rvs.stl" scale="    0.85     0.85     0.85" />
    <mesh name="middle_proximal_rvs" file="Geometry/middle_proximal_rvs.stl" scale="    0.85     0.85     0.85" />
    <mesh name="middle_medial_rvs" file="Geometry/middle_medial_rvs.stl" scale="    0.85     0.85     0.85" />
    <mesh name="middle_distal_rvs" file="Geometry/middle_distal_rvs.stl" scale="    0.85     0.85     0.85" />
    <mesh name="metacarpal4_rvs" file="Geometry/metacarpal4_rvs.stl" scale="    0.85     0.85     0.85" />
    <mesh name="ring_proximal_rvs" file="Geometry/ring_proximal_rvs.stl" scale="    0.85     0.85     0.85" />
    <mesh name="ring_medial_rvs" file="Geometry/ring_medial_rvs.stl" scale="    0.85     0.85     0.85" />
    <mesh name="ring_distal_rvs" file="Geometry/ring_distal_rvs.stl" scale="    0.85     0.85     0.85" />
    <mesh name="metacarpal5_rvs" file="Geometry/metacarpal5_rvs.stl" scale="    0.85     0.85     0.85" />
    <mesh name="little_proximal_rvs" file="Geometry/little_proximal_rvs.stl" scale="    0.85     0.85     0.85" />
    <mesh name="little_medial_rvs" file="Geometry/little_medial_rvs.stl" scale="    0.85     0.85     0.85" />
    <mesh name="little_distal_rvs" file="Geometry/little_distal_rvs.stl" scale="    0.85     0.85     0.85" />
    <mesh name="metacarpal1_rvs" file="Geometry/metacarpal1_rvs.stl" scale="    0.85     0.85     0.85" />
    <mesh name="thumb_proximal_rvs" file="Geometry/thumb_proximal_rvs.stl" scale="    0.85     0.85     0.85" />
    <mesh name="thumb_distal_rvs" file="Geometry/thumb_distal_rvs.stl" scale="    0.85     0.85     0.85" />
    <mesh name="humerus_lv" file="Geometry/humerus_lv.stl" scale=" 1.07291  1.07291  1.07291" />
    <mesh name="ulna_lv" file="Geometry/ulna_lv.stl" scale=" 1.11541  1.11541  1.11541" />
    <mesh name="radius_lv" file="Geometry/radius_lv.stl" scale=" 1.16522  1.16522  1.16522" />
    <mesh name="pisiform_lvs" file="Geometry/pisiform_lvs.stl" scale="    0.85     0.85     0.85" />
    <mesh name="lunate_lvs" file="Geometry/lunate_lvs.stl" scale="    0.85     0.85     0.85" />
    <mesh name="scaphoid_lvs" file="Geometry/scaphoid_lvs.stl" scale="    0.85     0.85     0.85" />
    <mesh name="triquetrum_lvs" file="Geometry/triquetrum_lvs.stl" scale="    0.85     0.85     0.85" />
    <mesh name="hamate_lvs" file="Geometry/hamate_lvs.stl" scale="    0.85     0.85     0.85" />
    <mesh name="capitate_lvs" file="Geometry/capitate_lvs.stl" scale="    0.85     0.85     0.85" />
    <mesh name="trapezoid_lvs" file="Geometry/trapezoid_lvs.stl" scale="    0.85     0.85     0.85" />
    <mesh name="trapezium_lvs" file="Geometry/trapezium_lvs.stl" scale="    0.85     0.85     0.85" />
    <mesh name="metacarpal2_lvs" file="Geometry/metacarpal2_lvs.stl" scale="    0.85     0.85     0.85" />
    <mesh name="index_proximal_lvs" file="Geometry/index_proximal_lvs.stl" scale="    0.85     0.85     0.85" />
    <mesh name="index_medial_lvs" file="Geometry/index_medial_lvs.stl" scale="    0.85     0.85     0.85" />
    <mesh name="index_distal_lvs" file="Geometry/index_distal_lvs.stl" scale="    0.85     0.85     0.85" />
    <mesh name="metacarpal3_lvs" file="Geometry/metacarpal3_lvs.stl" scale="    0.85     0.85     0.85" />
    <mesh name="middle_proximal_lvs" file="Geometry/middle_proximal_lvs.stl" scale="    0.85     0.85     0.85" />
    <mesh name="middle_medial_lvs" file="Geometry/middle_medial_lvs.stl" scale="    0.85     0.85     0.85" />
    <mesh name="middle_distal_lvs" file="Geometry/middle_distal_lvs.stl" scale="    0.85     0.85     0.85" />
    <mesh name="metacarpal4_lvs" file="Geometry/metacarpal4_lvs.stl" scale="    0.85     0.85     0.85" />
    <mesh name="ring_proximal_lvs" file="Geometry/ring_proximal_lvs.stl" scale="    0.85     0.85     0.85" />
    <mesh name="ring_medial_lvs" file="Geometry/ring_medial_lvs.stl" scale="    0.85     0.85     0.85" />
    <mesh name="ring_distal_lvs" file="Geometry/ring_distal_lvs.stl" scale="    0.85     0.85     0.85" />
    <mesh name="metacarpal5_lvs" file="Geometry/metacarpal5_lvs.stl" scale="    0.85     0.85     0.85" />
    <mesh name="little_proximal_lvs" file="Geometry/little_proximal_lvs.stl" scale="    0.85     0.85     0.85" />
    <mesh name="little_medial_lvs" file="Geometry/little_medial_lvs.stl" scale="    0.85     0.85     0.85" />
    <mesh name="little_distal_lvs" file="Geometry/little_distal_lvs.stl" scale="    0.85     0.85     0.85" />
    <mesh name="metacarpal1_lvs" file="Geometry/metacarpal1_lvs.stl" scale="    0.85     0.85     0.85" />
    <mesh name="thumb_proximal_lvs" file="Geometry/thumb_proximal_lvs.stl" scale="    0.85     0.85     0.85" />
    <mesh name="thumb_distal_lvs" file="Geometry/thumb_distal_lvs.stl" scale="    0.85     0.85     0.85" />
    <texture name="texplane" type="2d" builtin="checker" rgb1=".2 .3 .4" rgb2=".1 0.15 0.2" width="100" height="100" />
    <material name="MatPlane" reflectance="0.0" texture="texplane" texrepeat="1 1" texuniform="true" />
  </asset>
  <tendon>
    <spatial name="addbrev_r_tendon">
      <site site="addbrev_r-P1" />
      <site site="addbrev_r-P2" />
    </spatial>
    <spatial name="addlong_r_tendon">
      <site site="addlong_r-P1" />
      <site site="addlong_r-P2" />
    </spatial>
    <spatial name="addmagDist_r_tendon">
      <site site="addmagDist_r-P1" />
      <site site="addmagDist_r-P2" />
    </spatial>
    <spatial name="addmagIsch_r_tendon">
      <site site="addmagIsch_r-P1" />
      <site site="addmagIsch_r-P2" />
    </spatial>
    <spatial name="addmagMid_r_tendon">
      <site site="addmagMid_r-P1" />
      <site site="addmagMid_r-P2" />
    </spatial>
    <spatial name="addmagProx_r_tendon">
      <site site="addmagProx_r-P1" />
      <site site="addmagProx_r-P2" />
    </spatial>
    <spatial name="bflh_r_tendon">
      <site site="bflh_r-P1" />
      <site site="bflh_r-P2" />
      <site site="bflh_r-P3" />
    </spatial>
    <spatial name="bfsh_r_tendon">
      <site site="bfsh_r-P1" />
      <site site="bfsh_r-P2" />
    </spatial>
    <spatial name="edl_r_tendon">
      <site site="edl_r-P1" />
      <site site="edl_r-P2" />
      <site site="edl_r-P3" />
      <site site="edl_r-P4" />
      <site site="edl_r-P5" />
      <site site="edl_r-P6" />
    </spatial>
    <spatial name="ehl_r_tendon">
      <site site="ehl_r-P1" />
      <site site="ehl_r-P2" />
      <site site="ehl_r-P3" />
      <site site="ehl_r-P4" />
      <site site="ehl_r-P5" />
      <site site="ehl_r-P6" />
      <site site="ehl_r-P7" />
      <site site="ehl_r-P8" />
    </spatial>
    <spatial name="fdl_r_tendon">
      <site site="fdl_r-P1" />
      <site site="fdl_r-P2" />
      <site site="fdl_r-P3" />
      <site site="fdl_r-P4" />
      <site site="fdl_r-P5" />
      <site site="fdl_r-P6" />
      <site site="fdl_r-P7" />
      <site site="fdl_r-P8" />
    </spatial>
    <spatial name="fhl_r_tendon">
      <site site="fhl_r-P1" />
      <site site="fhl_r-P2" />
      <site site="fhl_r-P3" />
      <site site="fhl_r-P4" />
      <site site="fhl_r-P5" />
      <site site="fhl_r-P6" />
      <site site="fhl_r-P7" />
    </spatial>
    <spatial name="gaslat_r_tendon">
      <site site="gaslat_r-P1" />
      <site site="gaslat_r-P2" />
    </spatial>
    <spatial name="gasmed_r_tendon">
      <site site="gasmed_r-P1" />
      <site site="gasmed_r-P2" />
    </spatial>
    <spatial name="glmax1_r_tendon">
      <site site="glmax1_r-P1" />
      <site site="glmax1_r-P2" />
      <site site="glmax1_r-P3" />
      <site site="glmax1_r-P4" />
    </spatial>
    <spatial name="glmax2_r_tendon">
      <site site="glmax2_r-P1" />
      <site site="glmax2_r-P2" />
      <site site="glmax2_r-P3" />
      <site site="glmax2_r-P4" />
    </spatial>
    <spatial name="glmax3_r_tendon">
      <site site="glmax3_r-P1" />
      <site site="glmax3_r-P2" />
      <site site="glmax3_r-P3" />
      <site site="glmax3_r-P4" />
    </spatial>
    <spatial name="glmed1_r_tendon">
      <site site="glmed1_r-P1" />
      <site site="glmed1_r-P2" />
    </spatial>
    <spatial name="glmed2_r_tendon">
      <site site="glmed2_r-P1" />
      <site site="glmed2_r-P2" />
    </spatial>
    <spatial name="glmed3_r_tendon">
      <site site="glmed3_r-P1" />
      <site site="glmed3_r-P2" />
    </spatial>
    <spatial name="glmin1_r_tendon">
      <site site="glmin1_r-P1" />
      <site site="glmin1_r-P2" />
    </spatial>
    <spatial name="glmin2_r_tendon">
      <site site="glmin2_r-P1" />
      <site site="glmin2_r-P2" />
    </spatial>
    <spatial name="glmin3_r_tendon">
      <site site="glmin3_r-P1" />
      <site site="glmin3_r-P2" />
    </spatial>
    <spatial name="grac_r_tendon">
      <site site="grac_r-P1" />
      <site site="grac_r-P2" />
      <site site="grac_r-P3" />
    </spatial>
    <spatial name="iliacus_r_tendon">
      <site site="iliacus_r-P1" />
      <site site="iliacus_r-P2" />
      <site site="iliacus_r-P3" />
      <site site="iliacus_r-P4" />
    </spatial>
    <spatial name="perbrev_r_tendon">
      <site site="perbrev_r-P1" />
      <site site="perbrev_r-P2" />
      <site site="perbrev_r-P3" />
      <site site="perbrev_r-P4" />
      <site site="perbrev_r-P5" />
    </spatial>
    <spatial name="perlong_r_tendon">
      <site site="perlong_r-P1" />
      <site site="perlong_r-P2" />
      <site site="perlong_r-P3" />
      <site site="perlong_r-P4" />
      <site site="perlong_r-P5" />
      <site site="perlong_r-P6" />
      <site site="perlong_r-P7" />
    </spatial>
    <spatial name="piri_r_tendon">
      <site site="piri_r-P1" />
      <site site="piri_r-P2" />
      <site site="piri_r-P3" />
    </spatial>
    <spatial name="psoas_r_tendon">
      <site site="psoas_r-P1" />
      <site site="psoas_r-P2" />
      <site site="psoas_r-P3" />
      <site site="psoas_r-P4" />
    </spatial>
    <spatial name="recfem_r_tendon">
      <site site="recfem_r-P1" />
      <site site="recfem_r-P2" />
      <site site="recfem_r-P3" />
      <site site="recfem_r-P4" />
      <site site="recfem_r-P5" />
    </spatial>
    <spatial name="sart_r_tendon">
      <site site="sart_r-P1" />
      <site site="sart_r-P2" />
      <site site="sart_r-P3" />
      <site site="sart_r-P4" />
      <site site="sart_r-P5" />
    </spatial>
    <spatial name="semimem_r_tendon">
      <site site="semimem_r-P1" />
      <site site="semimem_r-P2" />
    </spatial>
    <spatial name="semiten_r_tendon">
      <site site="semiten_r-P1" />
      <site site="semiten_r-P2" />
      <site site="semiten_r-P3" />
    </spatial>
    <spatial name="soleus_r_tendon">
      <site site="soleus_r-P1" />
      <site site="soleus_r-P2" />
    </spatial>
    <spatial name="tfl_r_tendon">
      <site site="tfl_r-P1" />
      <site site="tfl_r-P2" />
      <site site="tfl_r-P3" />
      <site site="tfl_r-P4" />
    </spatial>
    <spatial name="tibant_r_tendon">
      <site site="tibant_r-P1" />
      <site site="tibant_r-P2" />
      <site site="tibant_r-P3" />
      <site site="tibant_r-P4" />
    </spatial>
    <spatial name="tibpost_r_tendon">
      <site site="tibpost_r-P1" />
      <site site="tibpost_r-P2" />
      <site site="tibpost_r-P3" />
      <site site="tibpost_r-P4" />
    </spatial>
    <spatial name="vasint_r_tendon">
      <site site="vasint_r-P1" />
      <site site="vasint_r-P2" />
      <site site="vasint_r-P3" />
      <site site="vasint_r-P4" />
      <site site="vasint_r-P5" />
    </spatial>
    <spatial name="vaslat_r_tendon">
      <site site="vaslat_r-P1" />
      <site site="vaslat_r-P2" />
      <site site="vaslat_r-P3" />
      <site site="vaslat_r-P4" />
      <site site="vaslat_r-P5" />
    </spatial>
    <spatial name="vasmed_r_tendon">
      <site site="vasmed_r-P1" />
      <site site="vasmed_r-P2" />
      <site site="vasmed_r-P3" />
      <site site="vasmed_r-P4" />
      <site site="vasmed_r-P5" />
    </spatial>
    <spatial name="addbrev_l_tendon">
      <site site="addbrev_l-P1" />
      <site site="addbrev_l-P2" />
    </spatial>
    <spatial name="addlong_l_tendon">
      <site site="addlong_l-P1" />
      <site site="addlong_l-P2" />
    </spatial>
    <spatial name="addmagDist_l_tendon">
      <site site="addmagDist_l-P1" />
      <site site="addmagDist_l-P2" />
    </spatial>
    <spatial name="addmagIsch_l_tendon">
      <site site="addmagIsch_l-P1" />
      <site site="addmagIsch_l-P2" />
    </spatial>
    <spatial name="addmagMid_l_tendon">
      <site site="addmagMid_l-P1" />
      <site site="addmagMid_l-P2" />
    </spatial>
    <spatial name="addmagProx_l_tendon">
      <site site="addmagProx_l-P1" />
      <site site="addmagProx_l-P2" />
    </spatial>
    <spatial name="bflh_l_tendon">
      <site site="bflh_l-P1" />
      <site site="bflh_l-P2" />
      <site site="bflh_l-P3" />
    </spatial>
    <spatial name="bfsh_l_tendon">
      <site site="bfsh_l-P1" />
      <site site="bfsh_l-P2" />
    </spatial>
    <spatial name="edl_l_tendon">
      <site site="edl_l-P1" />
      <site site="edl_l-P2" />
      <site site="edl_l-P3" />
      <site site="edl_l-P4" />
      <site site="edl_l-P5" />
      <site site="edl_l-P6" />
    </spatial>
    <spatial name="ehl_l_tendon">
      <site site="ehl_l-P1" />
      <site site="ehl_l-P2" />
      <site site="ehl_l-P3" />
      <site site="ehl_l-P4" />
      <site site="ehl_l-P5" />
      <site site="ehl_l-P6" />
      <site site="ehl_l-P7" />
      <site site="ehl_l-P8" />
    </spatial>
    <spatial name="fdl_l_tendon">
      <site site="fdl_l-P1" />
      <site site="fdl_l-P2" />
      <site site="fdl_l-P3" />
      <site site="fdl_l-P4" />
      <site site="fdl_l-P5" />
      <site site="fdl_l-P6" />
      <site site="fdl_l-P7" />
      <site site="fdl_l-P8" />
    </spatial>
    <spatial name="fhl_l_tendon">
      <site site="fhl_l-P1" />
      <site site="fhl_l-P2" />
      <site site="fhl_l-P3" />
      <site site="fhl_l-P4" />
      <site site="fhl_l-P5" />
      <site site="fhl_l-P6" />
      <site site="fhl_l-P7" />
    </spatial>
    <spatial name="gaslat_l_tendon">
      <site site="gaslat_l-P1" />
      <site site="gaslat_l-P2" />
    </spatial>
    <spatial name="gasmed_l_tendon">
      <site site="gasmed_l-P1" />
      <site site="gasmed_l-P2" />
    </spatial>
    <spatial name="glmax1_l_tendon">
      <site site="glmax1_l-P1" />
      <site site="glmax1_l-P2" />
      <site site="glmax1_l-P3" />
      <site site="glmax1_l-P4" />
    </spatial>
    <spatial name="glmax2_l_tendon">
      <site site="glmax2_l-P1" />
      <site site="glmax2_l-P2" />
      <site site="glmax2_l-P3" />
      <site site="glmax2_l-P4" />
    </spatial>
    <spatial name="glmax3_l_tendon">
      <site site="glmax3_l-P1" />
      <site site="glmax3_l-P2" />
      <site site="glmax3_l-P3" />
      <site site="glmax3_l-P4" />
    </spatial>
    <spatial name="glmed1_l_tendon">
      <site site="glmed1_l-P1" />
      <site site="glmed1_l-P2" />
    </spatial>
    <spatial name="glmed2_l_tendon">
      <site site="glmed2_l-P1" />
      <site site="glmed2_l-P2" />
    </spatial>
    <spatial name="glmed3_l_tendon">
      <site site="glmed3_l-P1" />
      <site site="glmed3_l-P2" />
    </spatial>
    <spatial name="glmin1_l_tendon">
      <site site="glmin1_l-P1" />
      <site site="glmin1_l-P2" />
    </spatial>
    <spatial name="glmin2_l_tendon">
      <site site="glmin2_l-P1" />
      <site site="glmin2_l-P2" />
    </spatial>
    <spatial name="glmin3_l_tendon">
      <site site="glmin3_l-P1" />
      <site site="glmin3_l-P2" />
    </spatial>
    <spatial name="grac_l_tendon">
      <site site="grac_l-P1" />
      <site site="grac_l-P2" />
      <site site="grac_l-P3" />
    </spatial>
    <spatial name="iliacus_l_tendon">
      <site site="iliacus_l-P1" />
      <site site="iliacus_l-P2" />
      <site site="iliacus_l-P3" />
      <site site="iliacus_l-P4" />
    </spatial>
    <spatial name="perbrev_l_tendon">
      <site site="perbrev_l-P1" />
      <site site="perbrev_l-P2" />
      <site site="perbrev_l-P3" />
      <site site="perbrev_l-P4" />
      <site site="perbrev_l-P5" />
    </spatial>
    <spatial name="perlong_l_tendon">
      <site site="perlong_l-P1" />
      <site site="perlong_l-P2" />
      <site site="perlong_l-P3" />
      <site site="perlong_l-P4" />
      <site site="perlong_l-P5" />
      <site site="perlong_l-P6" />
      <site site="perlong_l-P7" />
    </spatial>
    <spatial name="piri_l_tendon">
      <site site="piri_l-P1" />
      <site site="piri_l-P2" />
      <site site="piri_l-P3" />
    </spatial>
    <spatial name="psoas_l_tendon">
      <site site="psoas_l-P1" />
      <site site="psoas_l-P2" />
      <site site="psoas_l-P3" />
      <site site="psoas_l-P4" />
    </spatial>
    <spatial name="recfem_l_tendon">
      <site site="recfem_l-P1" />
      <site site="recfem_l-P2" />
      <site site="recfem_l-P3" />
      <site site="recfem_l-P4" />
      <site site="recfem_l-P5" />
    </spatial>
    <spatial name="sart_l_tendon">
      <site site="sart_l-P1" />
      <site site="sart_l-P2" />
      <site site="sart_l-P3" />
      <site site="sart_l-P4" />
      <site site="sart_l-P5" />
    </spatial>
    <spatial name="semimem_l_tendon">
      <site site="semimem_l-P1" />
      <site site="semimem_l-P2" />
    </spatial>
    <spatial name="semiten_l_tendon">
      <site site="semiten_l-P1" />
      <site site="semiten_l-P2" />
      <site site="semiten_l-P3" />
    </spatial>
    <spatial name="soleus_l_tendon">
      <site site="soleus_l-P1" />
      <site site="soleus_l-P2" />
    </spatial>
    <spatial name="tfl_l_tendon">
      <site site="tfl_l-P1" />
      <site site="tfl_l-P2" />
      <site site="tfl_l-P3" />
      <site site="tfl_l-P4" />
    </spatial>
    <spatial name="tibant_l_tendon">
      <site site="tibant_l-P1" />
      <site site="tibant_l-P2" />
      <site site="tibant_l-P3" />
      <site site="tibant_l-P4" />
    </spatial>
    <spatial name="tibpost_l_tendon">
      <site site="tibpost_l-P1" />
      <site site="tibpost_l-P2" />
      <site site="tibpost_l-P3" />
      <site site="tibpost_l-P4" />
    </spatial>
    <spatial name="vasint_l_tendon">
      <site site="vasint_l-P1" />
      <site site="vasint_l-P2" />
      <site site="vasint_l-P3" />
      <site site="vasint_l-P4" />
      <site site="vasint_l-P5" />
    </spatial>
    <spatial name="vaslat_l_tendon">
      <site site="vaslat_l-P1" />
      <site site="vaslat_l-P2" />
      <site site="vaslat_l-P3" />
      <site site="vaslat_l-P4" />
      <site site="vaslat_l-P5" />
    </spatial>
    <spatial name="vasmed_l_tendon">
      <site site="vasmed_l-P1" />
      <site site="vasmed_l-P2" />
      <site site="vasmed_l-P3" />
      <site site="vasmed_l-P4" />
      <site site="vasmed_l-P5" />
    </spatial>
  </tendon>
  <actuator>
    <general name="lumbar_ext" joint="lumbar_extension" class="motor" />
    <general name="lumbar_bend" joint="lumbar_bending" class="motor" />
    <general name="lumbar_rot" joint="lumbar_rotation" class="motor" />
    <general name="shoulder_flex_r" joint="arm_flex_r" class="motor" />
    <general name="shoulder_add_r" joint="arm_add_r" class="motor" />
    <general name="shoulder_rot_r" joint="arm_rot_r" class="motor" />
    <general name="elbow_flex_r" joint="elbow_flex_r" class="motor" />
    <general name="pro_sup_r" joint="pro_sup_r" class="motor" />
    <general name="wrist_flex_r" joint="wrist_flex_r" class="motor" />
    <general name="wrist_dev_r" joint="wrist_dev_r" class="motor" />
    <general name="shoulder_flex_l" joint="arm_flex_l" class="motor" />
    <general name="shoulder_add_l" joint="arm_add_l" class="motor" />
    <general name="shoulder_rot_l" joint="arm_rot_l" class="motor" />
    <general name="elbow_flex_l" joint="elbow_flex_l" class="motor" />
    <general name="pro_sup_l" joint="pro_sup_l" class="motor" />
    <general name="wrist_flex_l" joint="wrist_flex_l" class="motor" />
    <general name="wrist_dev_l" joint="wrist_dev_l" class="motor" />
    <muscle name="addbrev_r" tendon="addbrev_r_tendon" class="muscle" force="625.819672131148" lengthrange="0.0836861 0.182592" />
    <muscle name="addlong_r" tendon="addlong_r_tendon" class="muscle" force="916.8" lengthrange="0.180115 0.284242" />
    <muscle name="addmagDist_r" tendon="addmagDist_r_tendon" class="muscle" force="597.295081967214" lengthrange="0.163215 0.326004" />
    <muscle name="addmagIsch_r" tendon="addmagIsch_r_tendon" class="muscle" force="597.295081967214" lengthrange="0.278597 0.424855" />
    <muscle name="addmagMid_r" tendon="addmagMid_r_tendon" class="muscle" force="597.295081967214" lengthrange="0.105223 0.229597" />
    <muscle name="addmagProx_r" tendon="addmagProx_r_tendon" class="muscle" force="597.295081967214" lengthrange="0.0865885 0.182674" />
    <muscle name="bflh_r" tendon="bflh_r_tendon" class="muscle" force="1313.18360655738" lengthrange="0.363024 0.456479" />
    <muscle name="bfsh_r" tendon="bfsh_r_tendon" class="muscle" force="557.11475409836" lengthrange=" 0.15886 0.265203" />
    <muscle name="edl_r" tendon="edl_r_tendon" class="muscle" force="603.4981556" lengthrange="0.410351 0.479292" />
    <muscle name="ehl_r" tendon="ehl_r_tendon" class="muscle" force="285.8675474" lengthrange="0.366134 0.440021" />
    <muscle name="fdl_r" tendon="fdl_r_tendon" class="muscle" force="423.177049180328" lengthrange="0.396157 0.439162" />
    <muscle name="fhl_r" tendon="fhl_r_tendon" class="muscle" force="907.839344262294" lengthrange=" 0.37093 0.420693" />
    <muscle name="gaslat_r" tendon="gaslat_r_tendon" class="muscle" force="1575.05901639344" lengthrange="0.444101 0.507185" />
    <muscle name="gasmed_r" tendon="gasmed_r_tendon" class="muscle" force="3115.51475409836" lengthrange="0.463891 0.518942" />
    <muscle name="glmax1_r" tendon="glmax1_r_tendon" class="muscle" force="983.783606557378" lengthrange="0.128931 0.279867" />
    <muscle name="glmax2_r" tendon="glmax2_r_tendon" class="muscle" force="1406.04590163935" lengthrange="0.150595 0.306925" />
    <muscle name="glmax3_r" tendon="glmax3_r_tendon" class="muscle" force="947.754098360656" lengthrange="0.151912 0.311826" />
    <muscle name="glmed1_r" tendon="glmed1_r_tendon" class="muscle" force="1093.4667688" lengthrange="0.102232 0.180596" />
    <muscle name="glmed2_r" tendon="glmed2_r_tendon" class="muscle" force="765.0916616" lengthrange="0.111052 0.188141" />
    <muscle name="glmed3_r" tendon="glmed3_r_tendon" class="muscle" force="871.1992642" lengthrange="0.0862081  0.16104" />
    <muscle name="glmin1_r" tendon="glmin1_r_tendon" class="muscle" force="374.045901639344" lengthrange="0.0552823 0.129889" />
    <muscle name="glmin2_r" tendon="glmin2_r_tendon" class="muscle" force="394.819672131148" lengthrange="0.0598341 0.121771" />
    <muscle name="glmin3_r" tendon="glmin3_r_tendon" class="muscle" force="446.773770491804" lengthrange="0.075911  0.11719" />
    <muscle name="grac_r" tendon="grac_r_tendon" class="muscle" force="281.311475409836" lengthrange="0.278138 0.497764" />
    <muscle name="iliacus_r" tendon="iliacus_r_tendon" class="muscle" force="1021.14098360656" lengthrange="  0.1626 0.275657" />
    <muscle name="perbrev_r" tendon="perbrev_r_tendon" class="muscle" force="521.2015988" lengthrange="0.180952 0.228332" />
    <muscle name="perlong_r" tendon="perlong_r_tendon" class="muscle" force="1115.3714214" lengthrange="0.370117 0.421195" />
    <muscle name="piri_r" tendon="piri_r_tendon" class="muscle" force="1029.7868852459" lengthrange="0.132732 0.159344" />
    <muscle name="psoas_r" tendon="psoas_r_tendon" class="muscle" force="1426.79016393443" lengthrange=" 0.17335 0.299727" />
    <muscle name="recfem_r" tendon="recfem_r_tendon" class="muscle" force="2191.74098360656" lengthrange=" 0.48598 0.560165" />
    <muscle name="sart_r" tendon="sart_r_tendon" class="muscle" force="249.413114754098" lengthrange="0.331684 0.742287" />
    <muscle name="semimem_r" tendon="semimem_r_tendon" class="muscle" force="2200.9868852459" lengthrange="0.370354 0.435269" />
    <muscle name="semiten_r" tendon="semiten_r_tendon" class="muscle" force="591.295081967214" lengthrange=" 0.33537 0.519737" />
    <muscle name="soleus_r" tendon="soleus_r_tendon" class="muscle" force="6194.84262295082" lengthrange="0.325997 0.370795" />
    <muscle name="tfl_r" tendon="tfl_r_tendon" class="muscle" force="411.20655737705" lengthrange="0.505857 0.602431" />
    <muscle name="tibant_r" tendon="tibant_r_tendon" class="muscle" force="1227.45245901639" lengthrange=" 0.29224 0.363713" />
    <muscle name="tibpost_r" tendon="tibpost_r_tendon" class="muscle" force="1730.15409836065" lengthrange="0.320818 0.360314" />
    <muscle name="vasint_r" tendon="vasint_r_tendon" class="muscle" force="1697.36065573771" lengthrange="0.251203 0.350086" />
    <muscle name="vaslat_r" tendon="vaslat_r_tendon" class="muscle" force="5148.76721311476" lengthrange="0.267835 0.363756" />
    <muscle name="vasmed_r" tendon="vasmed_r_tendon" class="muscle" force="2747.82295081966" lengthrange="0.243861  0.33209" />
    <muscle name="addbrev_l" tendon="addbrev_l_tendon" class="muscle" force="625.819672131148" lengthrange="0.0840868 0.183466" />
    <muscle name="addlong_l" tendon="addlong_l_tendon" class="muscle" force="916.8" lengthrange="0.181218 0.285983" />
    <muscle name="addmagDist_l" tendon="addmagDist_l_tendon" class="muscle" force="597.295081967214" lengthrange="0.164507 0.328584" />
    <muscle name="addmagIsch_l" tendon="addmagIsch_l_tendon" class="muscle" force="597.295081967214" lengthrange="0.280734 0.428115" />
    <muscle name="addmagMid_l" tendon="addmagMid_l_tendon" class="muscle" force="597.295081967214" lengthrange="0.105994 0.231278" />
    <muscle name="addmagProx_l" tendon="addmagProx_l_tendon" class="muscle" force="597.295081967214" lengthrange="0.086916 0.183365" />
    <muscle name="bflh_l" tendon="bflh_l_tendon" class="muscle" force="1313.18360655738" lengthrange="0.366427 0.460758" />
    <muscle name="bfsh_l" tendon="bfsh_l_tendon" class="muscle" force="557.11475409836" lengthrange="0.160438 0.267837" />
    <muscle name="edl_l" tendon="edl_l_tendon" class="muscle" force="603.4981556" lengthrange="0.425054 0.496465" />
    <muscle name="ehl_l" tendon="ehl_l_tendon" class="muscle" force="285.8675474" lengthrange="0.379891 0.456554" />
    <muscle name="fdl_l" tendon="fdl_l_tendon" class="muscle" force="423.177049180328" lengthrange="0.412364 0.457128" />
    <muscle name="fhl_l" tendon="fhl_l_tendon" class="muscle" force="907.839344262294" lengthrange="0.386879 0.438781" />
    <muscle name="gaslat_l" tendon="gaslat_l_tendon" class="muscle" force="1575.05901639344" lengthrange="0.454422 0.518973" />
    <muscle name="gasmed_l" tendon="gasmed_l_tendon" class="muscle" force="3115.51475409836" lengthrange="0.474483 0.530792" />
    <muscle name="glmax1_l" tendon="glmax1_l_tendon" class="muscle" force="983.783606557378" lengthrange="0.129107 0.280249" />
    <muscle name="glmax2_l" tendon="glmax2_l_tendon" class="muscle" force="1406.04590163935" lengthrange="0.150955 0.307658" />
    <muscle name="glmax3_l" tendon="glmax3_l_tendon" class="muscle" force="947.754098360656" lengthrange="0.152368 0.312761" />
    <muscle name="glmed1_l" tendon="glmed1_l_tendon" class="muscle" force="1093.4667688" lengthrange="0.102346 0.180797" />
    <muscle name="glmed2_l" tendon="glmed2_l_tendon" class="muscle" force="765.0916616" lengthrange="0.111177 0.188353" />
    <muscle name="glmed3_l" tendon="glmed3_l_tendon" class="muscle" force="871.1992642" lengthrange="0.0863251 0.161258" />
    <muscle name="glmin1_l" tendon="glmin1_l_tendon" class="muscle" force="374.045901639344" lengthrange="0.0553969 0.130158" />
    <muscle name="glmin2_l" tendon="glmin2_l_tendon" class="muscle" force="394.819672131148" lengthrange="0.0599672 0.122042" />
    <muscle name="glmin3_l" tendon="glmin3_l_tendon" class="muscle" force="446.773770491804" lengthrange="0.0760838 0.117457" />
    <muscle name="grac_l" tendon="grac_l_tendon" class="muscle" force="281.311475409836" lengthrange="0.281177 0.503202" />
    <muscle name="iliacus_l" tendon="iliacus_l_tendon" class="muscle" force="1021.14098360656" lengthrange="0.162845 0.276073" />
    <muscle name="perbrev_l" tendon="perbrev_l_tendon" class="muscle" force="521.2015988" lengthrange="0.186094  0.23482" />
    <muscle name="perlong_l" tendon="perlong_l_tendon" class="muscle" force="1115.3714214" lengthrange="0.382324 0.435087" />
    <muscle name="piri_l" tendon="piri_l_tendon" class="muscle" force="1029.7868852459" lengthrange="0.132874 0.159515" />
    <muscle name="psoas_l" tendon="psoas_l_tendon" class="muscle" force="1426.79016393443" lengthrange=" 0.17358 0.300124" />
    <muscle name="recfem_l" tendon="recfem_l_tendon" class="muscle" force="2191.74098360656" lengthrange="0.489786 0.564552" />
    <muscle name="sart_l" tendon="sart_l_tendon" class="muscle" force="249.413114754098" lengthrange="0.334683 0.748998" />
    <muscle name="semimem_l" tendon="semimem_l_tendon" class="muscle" force="2200.9868852459" lengthrange="0.373695 0.439195" />
    <muscle name="semiten_l" tendon="semiten_l_tendon" class="muscle" force="591.295081967214" lengthrange="0.339122 0.525551" />
    <muscle name="soleus_l" tendon="soleus_l_tendon" class="muscle" force="6194.84262295082" lengthrange="0.334129 0.380046" />
    <muscle name="tfl_l" tendon="tfl_l_tendon" class="muscle" force="411.20655737705" lengthrange=" 0.50924  0.60646" />
    <muscle name="tibant_l" tendon="tibant_l_tendon" class="muscle" force="1227.45245901639" lengthrange="0.300612 0.374133" />
    <muscle name="tibpost_l" tendon="tibpost_l_tendon" class="muscle" force="1730.15409836065" lengthrange="0.329887   0.3705" />
    <muscle name="vasint_l" tendon="vasint_l_tendon" class="muscle" force="1697.36065573771" lengthrange="0.253695 0.353558" />
    <muscle name="vaslat_l" tendon="vaslat_l_tendon" class="muscle" force="5148.76721311476" lengthrange="0.270443 0.367298" />
    <muscle name="vasmed_l" tendon="vasmed_l_tendon" class="muscle" force="2747.82295081966" lengthrange="0.246286 0.335393" />
  </actuator>
  <equality>
    <joint name="knee_angle_r_translation2_constraint" active="true" joint1="knee_angle_r_translation2" joint2="knee_angle_r" polycoef="7.69254e-11 0.00587971 -0.00125622 -2.61846e-06 6.24355e-07" solimp="0.9999 0.9999 0.001 0.5 2" />
    <joint name="knee_angle_r_translation1_constraint" active="true" joint1="knee_angle_r_translation1" joint2="knee_angle_r" polycoef="9.53733e-08 0.00312879 -0.00230804 0.000561561 5.68366e-07" solimp="0.9999 0.9999 0.001 0.5 2" />
    <joint name="knee_angle_r_rotation2_constraint" active="true" joint1="knee_angle_r_rotation2" joint2="knee_angle_r" polycoef="-1.47325e-08   0.0791 -0.0328478 -0.0252183 0.0108321" solimp="0.9999 0.9999 0.001 0.5 2" />
    <joint name="knee_angle_r_rotation3_constraint" active="true" joint1="knee_angle_r_rotation3" joint2="knee_angle_r" polycoef="1.08939e-08 0.369499 -0.169478 0.0251643 3.50498e-07" solimp="0.9999 0.9999 0.001 0.5 2" />
    <joint name="knee_angle_r_beta_translation2_constraint" active="true" joint1="knee_angle_r_beta_translation2" joint2="knee_angle_r" polycoef="-0.0108281 -0.0487847 0.00927644 0.0131673 -0.00349673" solimp="0.9999 0.9999 0.001 0.5 2" />
    <joint name="knee_angle_r_beta_translation1_constraint" active="true" joint1="knee_angle_r_beta_translation1" joint2="knee_angle_r" polycoef="0.0524192 -0.0150188 -0.0340522 0.0133393 -0.000879151" solimp="0.9999 0.9999 0.001 0.5 2" />
    <joint name="knee_angle_r_beta_rotation1_constraint" active="true" joint1="knee_angle_r_beta_rotation1" joint2="knee_angle_r" polycoef="0.010506 0.0247615 -1.31647 0.716337 -0.138302" solimp="0.9999 0.9999 0.001 0.5 2" />
    <joint name="subtalar_angle_r_constraint" active="true" joint1="subtalar_angle_r" polycoef="       0        0        0        0        0" />
    <joint name="mtp_angle_r_constraint" active="true" joint1="mtp_angle_r" polycoef="       0        0        0        0        0" />
    <joint name="knee_angle_l_translation2_constraint" active="true" joint1="knee_angle_l_translation2" joint2="knee_angle_l" polycoef="-7.69254e-11 -0.00587971 0.00125622 2.61846e-06 -6.24355e-07" solimp="0.9999 0.9999 0.001 0.5 2" />
    <joint name="knee_angle_l_translation1_constraint" active="true" joint1="knee_angle_l_translation1" joint2="knee_angle_l" polycoef="9.53733e-08 0.00312879 -0.00230804 0.000561561 5.68366e-07" solimp="0.9999 0.9999 0.001 0.5 2" />
    <joint name="knee_angle_l_rotation2_constraint" active="true" joint1="knee_angle_l_rotation2" joint2="knee_angle_l" polycoef="-1.47325e-08   0.0791 -0.0328478 -0.0252183 0.0108321" solimp="0.9999 0.9999 0.001 0.5 2" />
    <joint name="knee_angle_l_rotation3_constraint" active="true" joint1="knee_angle_l_rotation3" joint2="knee_angle_l" polycoef="-1.08939e-08 -0.369499 0.169478 -0.0251643 -3.50498e-07" solimp="0.9999 0.9999 0.001 0.5 2" />
    <joint name="knee_angle_l_beta_translation2_constraint" active="true" joint1="knee_angle_l_beta_translation2" joint2="knee_angle_l" polycoef="-0.0108281 -0.0487847 0.00927644 0.0131673 -0.00349673" solimp="0.9999 0.9999 0.001 0.5 2" />
    <joint name="knee_angle_l_beta_translation1_constraint" active="true" joint1="knee_angle_l_beta_translation1" joint2="knee_angle_l" polycoef="0.0524192 -0.0150188 -0.0340522 0.0133393 -0.000879151" solimp="0.9999 0.9999 0.001 0.5 2" />
    <joint name="knee_angle_l_beta_rotation1_constraint" active="true" joint1="knee_angle_l_beta_rotation1" joint2="knee_angle_l" polycoef="0.010506 0.0247615 -1.31647 0.716337 -0.138302" solimp="0.9999 0.9999 0.001 0.5 2" />
    <joint name="subtalar_angle_l_constraint" active="true" joint1="subtalar_angle_l" polycoef="       0        0        0        0        0" />
    <joint name="mtp_angle_l_constraint" active="true" joint1="mtp_angle_l" polycoef="       0        0        0        0        0" />
    <joint name="wrist_flex_r_constraint" active="true" joint1="wrist_flex_r" polycoef="       0        0        0        0        0" />
    <joint name="wrist_dev_r_constraint" active="true" joint1="wrist_dev_r" polycoef="       0        0        0        0        0" />
    <joint name="wrist_flex_l_constraint" active="true" joint1="wrist_flex_l" polycoef="       0        0        0        0        0" />
    <joint name="wrist_dev_l_constraint" active="true" joint1="wrist_dev_l" polycoef="       0        0        0        0        0" />
    <weld name="origin_to_worldbody" body1="pelvis" active="false" />
  </equality>
</mujoco>