<mujoco model="SN001_SK">
  <compiler inertiafromgeom="auto" angle="radian" balanceinertia="true" boundmass="0.001" boundinertia="0.001">
    <lengthrange inttotal="50" useexisting="true" />
  </compiler>
  <default>
    <!-- <joint limited="true" damping="0.5" armature="0.1" stiffness="2" /> -->
    <geom rgba="0.8 0.6 .4 1" margin="0.001" />
    <default class="motor">
      <general gainprm="5 0 0 0 0 0 0 0 0 0" />
    </default>
  </default>
  <extension>
      <plugin plugin="mujoco.elasticity.solid"/>
  </extension>
  <!-- <option timestep="0.002" /> -->
  <option solver="CG" tolerance="1e-6" timestep=".0001" iterations="1000"/>
  <worldbody>
    <geom name="floor" pos="0 0 -1" size="10 10 0.125" type="plane" material="MatPlane" condim="3" />
    <body name="l_foot"  pos="-0.22 0 0.71">            
      <flexcomp type="gmsh" file = 'C:\mujoco\mujoco-3.0.0\model\plugin\elasticity\asset\overallRemeshDecimateAlot.msh'
          rgba="0 .7 .7 1" name="softbody_1_foot" mass="70"
          scale = "1 1.02 1" pos="0.20 -0.026 -0.71" quat="0.5 0.5 0.5 0.5 ">
          <contact condim="3" solref="0.01 1" solimp=".95 .99 .0001" selfcollide="none" contype="1" conaffinity="2"/>
          <edge damping="1"/>
          <plugin plugin="mujoco.elasticity.solid">
              <config key="poisson" value="0.4"/>
              <config key="damping" value="0.1"/>
              <config key="young" value="4.5e6"/>
          </plugin>
        </flexcomp>
    </body>
    <!-- <body name="r_foot"  pos="-0.22 0.05 0.71">            
      <flexcomp type="gmsh" file = 'C:\mujoco\mujoco-3.0.0\model\plugin\elasticity\asset\r_ankle_reduceMax.msh'
          rgba="0 .7 .7 1" name="softbody_r_foot" mass="1.395399456"
          scale = "1.05 1.05 1.05" pos="0.22 -0.026 -0.685" quat="0.5 0.5 0.5 0.5 ">
          <contact condim="3" solref="0.01 1" solimp=".95 .99 .0001" selfcollide="none" contype="1" conaffinity="2"/>
          <edge damping="1"/>
          <plugin plugin="mujoco.elasticity.solid">
              <config key="poisson" value="0.4"/>
              <config key="damping" value="0.1"/>
              <config key="young" value="4.5e6"/>
          </plugin>
        </flexcomp>
    </body>

    <body name="l_calf"  pos="-0.22 0 0.71">            
      <flexcomp group = "1" type="gmsh" file = 'C:\mujoco\mujoco-3.0.0\model\plugin\elasticity\asset\l_calf.msh'
          rgba="0 .7 .7 1" name="softbody_l_calf" mass="3.3023359040046"
          scale = "0.85 1.05 0.8" pos="0.182 0 -0.72" quat="0.5 0.5 0.5 0.5 ">
          <contact condim="3" solref="0.01 1" solimp=".95 .99 .0001" selfcollide="none" contype="1" conaffinity="2"/>
          <edge damping="1"/>
          <plugin plugin="mujoco.elasticity.solid">
              <config key="poisson" value="0.4"/>
              <config key="damping" value="0.1"/>
              <config key="young" value="4.5e6"/>
          </plugin>
        </flexcomp>
    </body>
    <body name="r_calf"  pos="-0.22 0.05 0.71">            
      <flexcomp group = "1" type="gmsh" file = 'C:\mujoco\mujoco-3.0.0\model\plugin\elasticity\asset\r_calf.msh'
          rgba="0 .7 .7 1" name="softbody_r_calf" mass="3.3023359040046"
          scale = "0.85 1.05 0.8" pos="0.185 -0.043 -0.72" quat="0.5 0.5 0.5 0.5 ">
          <contact condim="3" solref="0.01 1" solimp=".95 .99 .0001" selfcollide="none" contype="1" conaffinity="2"/>
          <edge damping="1"/>
          <plugin plugin="mujoco.elasticity.solid">
              <config key="poisson" value="0.4"/>
              <config key="damping" value="0.1"/>
              <config key="young" value="4.5e6"/>
          </plugin>
        </flexcomp>
    </body>
    
    <body name="l_thigh"  pos="-0.22 0 0.71">            
      <flexcomp group = "2" type="gmsh" file = 'C:\mujoco\mujoco-3.0.0\model\plugin\elasticity\asset\l_thigh.msh'
          rgba="0 .7 .7 1" name="softbody_l_thigh" mass="8.2849216931919"
          scale = "0.85 1.05 0.8" pos="0.165 0 -0.72" quat="0.5 0.5 0.5 0.5 ">
          <contact condim="3" solref="0.01 1" solimp=".95 .99 .0001" selfcollide="none" contype="1" conaffinity="2"/>
          <edge damping="1"/>
          <plugin plugin="mujoco.elasticity.solid">
              <config key="poisson" value="0.4"/>
              <config key="damping" value="0.1"/>
              <config key="young" value="4.5e6"/>
          </plugin>
        </flexcomp>
    </body>
    <body name="r_thigh"  pos="-0.22 0.05 0.71">            
      <flexcomp group = "2" type="gmsh" file = 'C:\mujoco\mujoco-3.0.0\model\plugin\elasticity\asset\r_thigh.msh'
          rgba="0 .7 .7 1" name="softbody_r_thigh" mass="8.2849216931919"
          scale = "0.85 1.05 0.8" pos="0.182 -0.046 -0.72" quat="0.5 0.5 0.5 0.5 ">
          <contact condim="3" solref="0.01 1" solimp=".95 .99 .0001" selfcollide="none" contype="1" conaffinity="2"/>
          <edge damping="1"/>
          <plugin plugin="mujoco.elasticity.solid">
              <config key="poisson" value="0.4"/>
              <config key="damping" value="0.1"/>
              <config key="young" value="4.5e6"/>
          </plugin>
        </flexcomp>
    </body> -->

    <body name="pelvis" pos="       0        0        0" quat="0.7071067811865475 0.7071067811865475 0.0 0.0">
      <light mode="trackcom" directional="false" pos="0 0 4.0" dir="0 0 -1" />
      <geom name="r_pelvis" type="mesh" mesh="r_pelvis" contype="1" conaffinity="2"/>
      <geom name="l_pelvis" type="mesh" mesh="l_pelvis" contype="1" conaffinity="2"/>
      <geom name="sacrum" type="mesh" mesh="sacrum" contype="1" conaffinity="2"/>
      <inertial pos="-0.0817759        0        0" mass="10.9270650543558" fullinertia="0.0960569 0.0960569 0.0718719        0        0        0" />
      <joint name="pelvis_tz" type="slide" pos="0 0 0" axis="       0        0        1" limited="false" range="      -3        3" ref="0" armature="0" damping="0" stiffness="0" />
      <joint name="pelvis_ty" type="slide" pos="0 0 0" axis="       0        1        0" limited="false" range="      -1        2" ref="0" armature="0" damping="0" stiffness="0" />
      <joint name="pelvis_tx" type="slide" pos="0 0 0" axis="       1        0        0" limited="false" range="      -5        5" ref="0" armature="0" damping="0" stiffness="0" />
      <joint name="pelvis_tilt" type="hinge" pos="0 0 0" axis="       0        0        1" limited="false" range=" -1.5708   1.5708" ref="0" armature="0" damping="0" stiffness="0" />
      <joint name="pelvis_list" type="hinge" pos="0 0 0" axis="       1        0        0" limited="false" range=" -1.5708   1.5708" ref="0" armature="0" damping="0" stiffness="0" />
      <joint name="pelvis_rotation" type="hinge" pos="0 0 0" axis="       0        1        0" limited="false" range=" -1.5708   1.5708" ref="0" armature="0" damping="0" stiffness="0" />
      <body name="femur_r" pos="-0.0650922 -0.0907863 0.0723699" quat="1.0 0.0 0.0 0.0">
        <geom name="r_femur" type="mesh" mesh="r_femur"  contype="1" conaffinity="2"/>
        <inertial pos="       0 -0.165691        0" mass="0.34520507055" fullinertia="0.118018 0.0309369 0.124453        0        0        0" />
        <joint name="hip_flexion_r" type="hinge" pos="0 0 0" axis="       0        0        1" limited="false" range="-0.523599   2.0944" ref="0" />
        <joint name="hip_adduction_r" type="hinge" pos="0 0 0" axis="       1        0        0" limited="false" range="-0.872665 0.523599" ref="0" />
        <joint name="hip_rotation_r" type="hinge" pos="0 0 0" axis="       0        1        0" limited="false" range="-0.698132 0.698132" ref="0" />
        <body name="tibia_r" pos="0.00109144 -0.393697 -0.00103279" quat="1.0 7.240636975890137e-18 -9.456205735995121e-17 -2.960068750797159e-20">
          <geom name="r_tibia" type="mesh" mesh="r_tibia"  contype="1" conaffinity="2"/>
          <geom name="r_fibula" type="mesh" mesh="r_fibula"  contype="1" conaffinity="2"/>
          <inertial pos="       0 -0.207168        0" mass="0.1375973293335" fullinertia="0.0575778 0.00582632 0.0583775        0        0        0" />
          <joint name="knee_angle_r_translation2" type="slide" pos="0 0 0" axis="0.992246 0.123982 -0.00878916" limited="true" range="7.69254e-11 0.006792" ref="0" />
          <joint name="knee_angle_r_translation1" type="slide" pos="0 0 0" axis="-0.124293 0.989762 -0.0701648" limited="true" range="9.53733e-08 0.00159883" ref="0" />
          <joint name="knee_angle_r" type="hinge" pos="0 0 0" axis="-3.98373e-10 -0.0707131 -0.997497" limited="false" range="       0   2.0944" ref="0" />
          <joint name="knee_angle_r_rotation2" type="hinge" pos="0 0 0" axis="0.992246 0.123982 -0.00878916" limited="true" range="-0.00167821 0.0335354" ref="0" />
          <joint name="knee_angle_r_rotation3" type="hinge" pos="0 0 0" axis="-0.124293 0.989762 -0.0701648" limited="true" range="1.08939e-08 0.262788" ref="0" />
          <body name="talus_r" pos="-0.0110963 -0.443852        0" quat="1.0 -6.036754011562992e-18 1.5193252867388614e-18 -2.498419531737724e-19">
            <geom name="r_talus" type="mesh" mesh="r_talus"  contype="1" conaffinity="2"/>
            <inertial pos="       0        0        0" mass="0.00370664198457084" fullinertia="0.000691652 0.000691652 0.000691652        0        0        0" />
            <joint name="ankle_angle_r" type="hinge" pos="0 0 0" axis="-0.105014 -0.174022 0.979126" limited="false" range="-0.698132 0.523599" ref="0" />
            <body name="calcn_r" pos="-0.0421077 -0.0362194 0.00683808" quat="1.0 -5.320429553087796e-19 1.609289071159989e-17 -2.1848634538867752e-17">
              <geom name="r_foot" type="mesh" mesh="r_foot" contype="1" conaffinity="2"/>
              <inertial pos="0.0863394 0.0259018        0" mass="0.04633986957981706" fullinertia="0.000968312 0.00269744 0.00283577        0        0        0" />
              <joint name="subtalar_angle_r" type="hinge" pos="0 0 0" axis=" 0.78718 0.604747 -0.120949" limited="false" range="-0.349066 0.349066" ref="0" />
              <body name="toes_r" pos="0.154375 -0.00172679 0.000932466" quat="1.0 1.314867274624753e-31 -2.6810890689525335e-17 -3.939849802505862e-32">
                <geom name="r_bofoot" type="mesh" mesh="r_bofoot"  contype="1" conaffinity="2"/>
                <inertial pos="0.0298734 0.00518037 -0.0151094" mass="0.00803812672981933" fullinertia="6.91652e-05 0.00013833 0.000691652        0        0        0" />
                <joint name="mtp_angle_r" type="hinge" pos="0 0 0" axis="0.580954 2.6299e-15 -0.813936" limited="false" range="-0.523599 0.523599" ref="0" />
              </body>
            </body>
          </body>
        </body>
        <body name="patella_r" pos="-0.00788495 -0.39762 6.9703e-05" quat="1.0 0.0 0.0 0.0">
          <geom name="r_patella" type="mesh" mesh="r_patella"  contype="1" conaffinity="2"/>
          <inertial pos="  0.0018   0.0264        0" mass="0.0799790275694546" fullinertia="2.66287e-06 1.21639e-05 1.21639e-05        0        0        0" />
          <joint name="knee_angle_r_beta_translation2" type="slide" pos="0 0 0" axis="       0        1        0" limited="true" range="-0.0408267 -0.0108281" ref="0" />
          <joint name="knee_angle_r_beta_translation1" type="slide" pos="0 0 0" axis="       1        0        0" limited="true" range="-0.0227731 0.0524192" ref="0" />
          <joint name="knee_angle_r_beta_rotation1" type="hinge" pos="0 0 0" axis="       0        0        1" limited="true" range="-1.79241 0.010506" ref="0" />
        </body>
      </body>
      <body name="femur_l" pos="-0.0650922 -0.0907863 -0.0723699" quat="1.0 0.0 0.0 0.0">
        <geom name="l_femur" type="mesh" mesh="l_femur" contype="1" conaffinity="2" />
        <inertial pos="       0 -0.166781        0" mass="0.34520507055" fullinertia="0.119576 0.031345 0.126095        0        0        0" />
        <joint name="hip_flexion_l" type="hinge" pos="0 0 0" axis="       0        0        1" limited="false" range="-0.523599   2.0944" ref="0" />
        <joint name="hip_adduction_l" type="hinge" pos="0 0 0" axis="      -1       -0       -0" limited="false" range="-0.872665 0.523599" ref="0" />
        <joint name="hip_rotation_l" type="hinge" pos="0 0 0" axis="      -0       -1       -0" limited="false" range="-0.698132 0.698132" ref="0" />
        <body name="tibia_l" pos="0.00124904 -0.39622 0.00101197" quat="1.0 -7.240636975890137e-18 9.456205735995121e-17 -2.960068750797159e-20">
          <geom name="l_tibia" type="mesh" mesh="l_tibia" contype="1" conaffinity="2" />
          <geom name="l_fibula" type="mesh" mesh="l_fibula" contype="1" conaffinity="2" />
          <inertial pos="       0 -0.212002        0" mass="0.1375973293335" fullinertia="0.060296 0.00610138 0.0611335        0        0        0" />
          <joint name="knee_angle_l_translation2" type="slide" pos="0 0 0" axis="-0.992246 -0.123982 -0.00878916" limited="true" range="-0.006792 -7.69254e-11" ref="0" />
          <joint name="knee_angle_l_translation1" type="slide" pos="0 0 0" axis="-0.124293 0.989762 0.0701648" limited="true" range="9.53733e-08 0.00159883" ref="0" />
          <joint name="knee_angle_l" type="hinge" pos="0 0 0" axis="3.98373e-10 0.0707131 -0.997497" limited="false" range="       0   2.0944" ref="0" />
          <joint name="knee_angle_l_rotation2" type="hinge" pos="0 0 0" axis="-0.992246 -0.123982 -0.00878916" limited="true" range="-0.00167821 0.0335354" ref="0" />
          <joint name="knee_angle_l_rotation3" type="hinge" pos="0 0 0" axis="-0.124293 0.989762 0.0701648" limited="true" range="-0.262788 -1.08939e-08" ref="0" />
          <body name="talus_l" pos="-0.0113552 -0.454208        0" quat="1.0 6.036754011562992e-18 -1.5193252867388614e-18 -2.498419531737724e-19">
            <geom name="l_talus" type="mesh" mesh="l_talus" contype="1" conaffinity="2"/>
            <inertial pos="       0        0        0" mass="0.00370664198457084" fullinertia="0.000783966 0.000783966 0.000783966        0        0        0" />
            <joint name="ankle_angle_l" type="hinge" pos="0 0 0" axis="0.105014 0.174022 0.979126" limited="false" range="-0.698132 0.523599" ref="0" />
            <body name="calcn_l" pos="-0.0448298 -0.0385608 -0.00728013" quat="1.0 5.320429553087796e-19 -1.609289071159989e-17 -2.1848634538867752e-17">
              <geom name="l_foot" type="mesh" mesh="l_foot" contype="1" conaffinity="2"/>
              <inertial pos="0.0919209 0.0275763        0" mass="0.04633986957981706" fullinertia="0.00109755 0.00305747 0.00321426        0        0        0" />
              <joint name="subtalar_angle_l" type="hinge" pos="0 0 0" axis="-0.78718 -0.604747 -0.120949" limited="false" range="-0.349066 0.349066" ref="0" />
              <body name="toes_l" pos="0.164355 -0.00183842 -0.000992746" quat="1.0 1.314867274624753e-31 2.6810890689525335e-17 3.939849802505862e-32">
                <geom name="l_bofoot" type="mesh" mesh="l_bofoot" contype="1" conaffinity="2" />
                <inertial pos="0.0318046 0.00551525 0.0160862" mass="0.00803812672981933" fullinertia="7.83966e-05 0.000156793 0.000783966        0        0        0" />
                <joint name="mtp_angle_l" type="hinge" pos="0 0 0" axis="-0.580954 2.6299e-15 -0.813936" limited="false" range="-0.523599 0.523599" ref="0" />
              </body>
            </body>
          </body>
        </body>
        <body name="patella_l" pos="-0.00793679 -0.400234 -5.20799e-05" quat="1.0 0.0 0.0 0.0">
          <geom name="l_patella" type="mesh" mesh="l_patella" contype="1" conaffinity="2" />
          <inertial pos="  0.0018   0.0264        0" mass="0.0799790275694546" fullinertia="2.66287e-06 1.21639e-05 1.21639e-05        0        0        0" />
          <joint name="knee_angle_l_beta_translation2" type="slide" pos="0 0 0" axis="       0        1        0" limited="true" range="-0.0408267 -0.0108281" ref="0" />
          <joint name="knee_angle_l_beta_translation1" type="slide" pos="0 0 0" axis="       1        0        0" limited="true" range="-0.0227731 0.0524192" ref="0" />
          <joint name="knee_angle_l_beta_rotation1" type="hinge" pos="0 0 0" axis="       0        0        1" limited="true" range="-1.79241 0.010506" ref="0" />
        </body>
      </body>
      <body name="torso" pos="-0.116476 0.0942678        0" quat="1.0 0.0 0.0 0.0">
        <geom name="hat_spine" type="mesh" mesh="hat_spine" contype="1" conaffinity="2"/>
        <geom name="hat_jaw" type="mesh" mesh="hat_jaw" contype="1" conaffinity="2"/>
        <geom name="hat_skull" type="mesh" mesh="hat_skull" contype="1" conaffinity="2" />
        <geom name="hat_ribs_scap" type="mesh" mesh="hat_ribs_scap" contype="1" conaffinity="2"/>
        <inertial pos="-0.0328335 0.350224        0" mass="24.890549663512" fullinertia=" 1.63872 0.839645  1.59082        0        0        0" />
        <joint name="lumbar_extension" type="hinge" pos="0 0 0" axis="       0        0        1" limited="false" range=" -1.5708   1.5708" ref="0" />
        <joint name="lumbar_bending" type="hinge" pos="0 0 0" axis="       1        0        0" limited="false" range=" -1.5708   1.5708" ref="0" />
        <joint name="lumbar_rotation" type="hinge" pos="0 0 0" axis="       0        1        0" limited="false" range=" -1.5708   1.5708" ref="0" />
        <body name="humerus_r" pos="0.00345299 0.406588 0.186057" quat="1.0 0.0 0.0 0.0">
          <geom name="humerus_rv" type="mesh" mesh="humerus_rv" contype="1" conaffinity="2"/>
          <inertial pos="       0 -0.17897        0" mass="1.8858163983169" fullinertia="0.0131193 0.00452576 0.014726        0        0        0" />
          <joint name="arm_flex_r" type="hinge" pos="0 0 0" axis="       0        0        1" limited="false" range=" -1.5708   1.5708" ref="0" />
          <joint name="arm_add_r" type="hinge" pos="0 0 0" axis="       1        0        0" limited="false" range=" -2.0944   1.5708" ref="0" />
          <joint name="arm_rot_r" type="hinge" pos="0 0 0" axis="       0        1        0" limited="false" range=" -1.5708   1.5708" ref="0" />
          <body name="ulna_r" pos="0.0143001 -0.311452 -0.0104389" quat="1.0 1.6893809785063376e-18 -6.938893903907228e-18 4.155190089080778e-20">
            <geom name="ulna_rv" type="mesh" mesh="ulna_rv" contype="1" conaffinity="2"/>
            <inertial pos="       0 -0.133441        0" mass="0.563657299865936" fullinertia="0.00336884 0.000702885 0.00365432        0        0        0" />
            <joint name="elbow_flex_r" type="hinge" pos="0 0 0" axis="0.226047 0.022269 0.973862" limited="false" range="       0    2.618" ref="0" />
            <body name="radius_r" pos="-0.00744792 -0.0144009 0.0288783" quat="1.0 2.301201592641875e-21 -6.933378131686372e-19 1.7489241099837954e-19">
              <geom name="radius_rv" type="mesh" mesh="radius_rv" contype="1" conaffinity="2"/>
              <inertial pos="       0 -0.140277        0" mass="0.563657299865936" fullinertia="0.00372281 0.000776736 0.00403828        0        0        0" />
              <joint name="pro_sup_r" type="hinge" pos="0 0 0" axis="0.056398 0.998406 0.001952" limited="false" range="       0   1.5708" ref="0" />
              <body name="hand_r" pos="-0.0102387 -0.274491 0.0158404" quat="1.0 0.0 8.407790785948892e-45 0.0">
                <geom name="pisiform_rvs" type="mesh" mesh="pisiform_rvs" contype="1" conaffinity="2"/>
                <geom name="lunate_rvs" type="mesh" mesh="lunate_rvs" contype="1" conaffinity="2"/>
                <geom name="scaphoid_rvs" type="mesh" mesh="scaphoid_rvs" contype="1" conaffinity="2"/>
                <geom name="triquetrum_rvs" type="mesh" mesh="triquetrum_rvs" contype="1" conaffinity="2"/>
                <geom name="hamate_rvs" type="mesh" mesh="hamate_rvs" contype="1" conaffinity="2"/>
                <geom name="capitate_rvs" type="mesh" mesh="capitate_rvs" contype="1" conaffinity="2"/>
                <geom name="trapezoid_rvs" type="mesh" mesh="trapezoid_rvs" contype="1" conaffinity="2"/>
                <geom name="trapezium_rvs" type="mesh" mesh="trapezium_rvs" contype="1" conaffinity="2"/>
                <geom name="metacarpal2_rvs" type="mesh" mesh="metacarpal2_rvs" contype="1" conaffinity="2"/>
                <geom name="index_proximal_rvs" type="mesh" mesh="index_proximal_rvs" contype="1" conaffinity="2"/>
                <geom name="index_medial_rvs" type="mesh" mesh="index_medial_rvs" contype="1" conaffinity="2"/>
                <geom name="index_distal_rvs" type="mesh" mesh="index_distal_rvs" contype="1" conaffinity="2"/>
                <geom name="metacarpal3_rvs" type="mesh" mesh="metacarpal3_rvs" contype="1" conaffinity="2"/>
                <geom name="middle_proximal_rvs" type="mesh" mesh="middle_proximal_rvs" contype="1" conaffinity="2"/>
                <geom name="middle_medial_rvs" type="mesh" mesh="middle_medial_rvs" contype="1" conaffinity="2"/>
                <geom name="middle_distal_rvs" type="mesh" mesh="middle_distal_rvs" contype="1" conaffinity="2"/>
                <geom name="metacarpal4_rvs" type="mesh" mesh="metacarpal4_rvs" contype="1" conaffinity="2"/>
                <geom name="ring_proximal_rvs" type="mesh" mesh="ring_proximal_rvs" contype="1" conaffinity="2"/>
                <geom name="ring_medial_rvs" type="mesh" mesh="ring_medial_rvs" contype="1" conaffinity="2"/>
                <geom name="ring_distal_rvs" type="mesh" mesh="ring_distal_rvs" contype="1" conaffinity="2"/>
                <geom name="metacarpal5_rvs" type="mesh" mesh="metacarpal5_rvs" contype="1" conaffinity="2"/>
                <geom name="little_proximal_rvs" type="mesh" mesh="little_proximal_rvs" contype="1" conaffinity="2"/>
                <geom name="little_medial_rvs" type="mesh" mesh="little_medial_rvs" contype="1" conaffinity="2"/>
                <geom name="little_distal_rvs" type="mesh" mesh="little_distal_rvs" contype="1" conaffinity="2"/>
                <geom name="metacarpal1_rvs" type="mesh" mesh="metacarpal1_rvs" contype="1" conaffinity="2"/>
                <geom name="thumb_proximal_rvs" type="mesh" mesh="thumb_proximal_rvs" contype="1" conaffinity="2"/>
                <geom name="thumb_distal_rvs" type="mesh" mesh="thumb_distal_rvs" contype="1" conaffinity="2"/>
                <inertial pos="       0 -0.068095        0" mass="0.424482657923729" fullinertia="0.000827625 0.000507524 0.00124329        0        0        0" />
                <joint name="wrist_flex_r" type="hinge" pos="0 0 0" axis="-3.55271e-15 3.55271e-15        1" limited="false" range="-1.22173  1.22173" ref="0" />
                <joint name="wrist_dev_r" type="hinge" pos="0 0 0" axis="       1        0 3.55271e-15" limited="false" range="-0.436332 0.610865" ref="0" />
              </body>
            </body>
          </body>
        </body>
        <body name="humerus_l" pos="0.00345299 0.406588 -0.186057" quat="1.0 0.0 0.0 0.0">
          <geom name="humerus_lv" type="mesh" mesh="humerus_lv" contype="1" conaffinity="2"/>
          <inertial pos="       0 -0.176496        0" mass="1.8858163983169" fullinertia="0.0127591 0.00440148 0.0143216        0        0        0" />
          <joint name="arm_flex_l" type="hinge" pos="0 0 0" axis="       0        0        1" limited="false" range=" -1.5708   1.5708" ref="0" />
          <joint name="arm_add_l" type="hinge" pos="0 0 0" axis="      -1        0        0" limited="false" range=" -2.0944   1.5708" ref="0" />
          <joint name="arm_rot_l" type="hinge" pos="0 0 0" axis="       0       -1        0" limited="false" range=" -1.5708   1.5708" ref="0" />
          <body name="ulna_l" pos="0.0141023 -0.307145 0.0102946" quat="1.0 -1.6893809785063376e-18 6.938893903907228e-18 4.155190089080778e-20">
            <geom name="ulna_lv" type="mesh" mesh="ulna_lv" contype="1" conaffinity="2"/>
            <inertial pos="       0 -0.134435        0" mass="0.563657299865936" fullinertia="0.00341921 0.000713394 0.00370895        0        0        0" />
            <joint name="elbow_flex_l" type="hinge" pos="0 0 0" axis="-0.226047 -0.022269 0.973862" limited="false" range="       0    2.618" ref="0" />
            <body name="radius_l" pos="-0.00750339 -0.0145082 -0.0290933" quat="1.0 -2.301201592641875e-21 6.933378131686372e-19 1.7489241099837954e-19">
              <geom name="radius_lv" type="mesh" mesh="radius_lv" contype="1" conaffinity="2"/>
              <inertial pos="       0 -0.140438        0" mass="0.563657299865936" fullinertia="0.00373139 0.000778527 0.00404759        0        0        0" />
              <joint name="pro_sup_l" type="hinge" pos="0 0 0" axis="-0.056398 -0.998406 0.001952" limited="false" range="       0   1.5708" ref="0" />
              <body name="hand_l" pos="-0.0102504 -0.274807 -0.0158587" quat="1.0 0.0 8.407790785948892e-45 0.0">
                <geom name="pisiform_lvs" type="mesh" mesh="pisiform_lvs" contype="1" conaffinity="2"/>
                <geom name="lunate_lvs" type="mesh" mesh="lunate_lvs" contype="1" conaffinity="2"/>
                <geom name="scaphoid_lvs" type="mesh" mesh="scaphoid_lvs" contype="1" conaffinity="2"/>
                <geom name="triquetrum_lvs" type="mesh" mesh="triquetrum_lvs" contype="1" conaffinity="2"/>
                <geom name="hamate_lvs" type="mesh" mesh="hamate_lvs" contype="1" conaffinity="2"/>
                <geom name="capitate_lvs" type="mesh" mesh="capitate_lvs" contype="1" conaffinity="2"/>
                <geom name="trapezoid_lvs" type="mesh" mesh="trapezoid_lvs" contype="1" conaffinity="2"/>
                <geom name="trapezium_lvs" type="mesh" mesh="trapezium_lvs" contype="1" conaffinity="2"/>
                <geom name="metacarpal2_lvs" type="mesh" mesh="metacarpal2_lvs" contype="1" conaffinity="2"/>
                <geom name="index_proximal_lvs" type="mesh" mesh="index_proximal_lvs" contype="1" conaffinity="2"/>
                <geom name="index_medial_lvs" type="mesh" mesh="index_medial_lvs" contype="1" conaffinity="2"/>
                <geom name="index_distal_lvs" type="mesh" mesh="index_distal_lvs" contype="1" conaffinity="2"/>
                <geom name="metacarpal3_lvs" type="mesh" mesh="metacarpal3_lvs" contype="1" conaffinity="2"/>
                <geom name="middle_proximal_lvs" type="mesh" mesh="middle_proximal_lvs" contype="1" conaffinity="2"/>
                <geom name="middle_medial_lvs" type="mesh" mesh="middle_medial_lvs" contype="1" conaffinity="2"/>
                <geom name="middle_distal_lvs" type="mesh" mesh="middle_distal_lvs" contype="1" conaffinity="2"/>
                <geom name="metacarpal4_lvs" type="mesh" mesh="metacarpal4_lvs" contype="1" conaffinity="2"/>
                <geom name="ring_proximal_lvs" type="mesh" mesh="ring_proximal_lvs" contype="1" conaffinity="2"/>
                <geom name="ring_medial_lvs" type="mesh" mesh="ring_medial_lvs" contype="1" conaffinity="2"/>
                <geom name="ring_distal_lvs" type="mesh" mesh="ring_distal_lvs" contype="1" conaffinity="2"/>
                <geom name="metacarpal5_lvs" type="mesh" mesh="metacarpal5_lvs" contype="1" conaffinity="2"/>
                <geom name="little_proximal_lvs" type="mesh" mesh="little_proximal_lvs" contype="1" conaffinity="2"/>
                <geom name="little_medial_lvs" type="mesh" mesh="little_medial_lvs" contype="1" conaffinity="2"/>
                <geom name="little_distal_lvs" type="mesh" mesh="little_distal_lvs" contype="1" conaffinity="2"/>
                <geom name="metacarpal1_lvs" type="mesh" mesh="metacarpal1_lvs" contype="1" conaffinity="2"/>
                <geom name="thumb_proximal_lvs" type="mesh" mesh="thumb_proximal_lvs" contype="1" conaffinity="2"/>
                <geom name="thumb_distal_lvs" type="mesh" mesh="thumb_distal_lvs" contype="1" conaffinity="2"/>
                <inertial pos="       0 -0.068095        0" mass="0.424482657923729" fullinertia="0.000827625 0.000507524 0.00124329        0        0        0" />
                <joint name="wrist_flex_l" type="hinge" pos="0 0 0" axis="-3.55271e-15 -3.55271e-15        1" limited="false" range="-1.22173  1.22173" ref="0" />
                <joint name="wrist_dev_l" type="hinge" pos="0 0 0" axis="      -1        0 -3.55271e-15" limited="false" range="-0.436332 0.610865" ref="0" />
              </body>
            </body>
          </body>
        </body>
      </body>
    </body>
    <camera name="for_testing" pos="0 0 0" euler="0 0 0" />
  </worldbody>
  <asset>
    <mesh name="r_pelvis" file="Geometry/r_pelvis.stl" scale=" 1.15666  1.15666 0.936706" />
    <mesh name="l_pelvis" file="Geometry/l_pelvis.stl" scale=" 1.15666  1.15666 0.936706" />
    <mesh name="sacrum" file="Geometry/sacrum.stl" scale=" 1.15666  1.15666 0.936706" />
    <mesh name="r_femur" file="Geometry/r_femur.stl" scale="0.974653 0.974653 0.974653" />
    <mesh name="r_tibia" file="Geometry/r_tibia.stl" scale=" 1.10963  1.10963  1.10963" />
    <mesh name="r_fibula" file="Geometry/r_fibula.stl" scale=" 1.10963  1.10963  1.10963" />
    <mesh name="r_talus" file="Geometry/r_talus.stl" scale="0.863394 0.863394 0.863394" />
    <mesh name="r_foot" file="Geometry/r_foot.stl" scale="0.863394 0.863394 0.863394" />
    <mesh name="r_bofoot" file="Geometry/r_bofoot.stl" scale="0.863394 0.863394 0.863394" />
    <mesh name="r_patella" file="Geometry/r_patella.stl" scale="       1        1        1" />
    <mesh name="l_femur" file="Geometry/l_femur.stl" scale="0.981062 0.981062 0.981062" />
    <mesh name="l_tibia" file="Geometry/l_tibia.stl" scale=" 1.13552  1.13552  1.13552" />
    <mesh name="l_fibula" file="Geometry/l_fibula.stl" scale=" 1.13552  1.13552  1.13552" />
    <mesh name="l_talus" file="Geometry/l_talus.stl" scale="0.919209 0.919209 0.919209" />
    <mesh name="l_foot" file="Geometry/l_foot.stl" scale="0.919209 0.919209 0.919209" />
    <mesh name="l_bofoot" file="Geometry/l_bofoot.stl" scale="0.919209 0.919209 0.919209" />
    <mesh name="l_patella" file="Geometry/l_patella.stl" scale="       1        1        1" />
    <mesh name="hat_spine" file="Geometry/hat_spine.stl" scale=" 1.09445  1.09445  1.09445" />
    <mesh name="hat_jaw" file="Geometry/hat_jaw.stl" scale=" 1.09445  1.09445  1.09445" />
    <mesh name="hat_skull" file="Geometry/hat_skull.stl" scale=" 1.09445  1.09445  1.09445" />
    <mesh name="hat_ribs_scap" file="Geometry/hat_ribs_scap.stl" scale=" 1.09445  1.09445  1.09445" />
    <mesh name="humerus_rv" file="Geometry/humerus_rv.stl" scale=" 1.08795  1.08795  1.08795" />
    <mesh name="ulna_rv" file="Geometry/ulna_rv.stl" scale=" 1.10717  1.10717  1.10717" />
    <mesh name="radius_rv" file="Geometry/radius_rv.stl" scale=" 1.16388  1.16388  1.16388" />
    <mesh name="pisiform_rvs" file="Geometry/pisiform_rvs.stl" scale="    0.85     0.85     0.85" />
    <mesh name="lunate_rvs" file="Geometry/lunate_rvs.stl" scale="    0.85     0.85     0.85" />
    <mesh name="scaphoid_rvs" file="Geometry/scaphoid_rvs.stl" scale="    0.85     0.85     0.85" />
    <mesh name="triquetrum_rvs" file="Geometry/triquetrum_rvs.stl" scale="    0.85     0.85     0.85" />
    <mesh name="hamate_rvs" file="Geometry/hamate_rvs.stl" scale="    0.85     0.85     0.85" />
    <mesh name="capitate_rvs" file="Geometry/capitate_rvs.stl" scale="    0.85     0.85     0.85" />
    <mesh name="trapezoid_rvs" file="Geometry/trapezoid_rvs.stl" scale="    0.85     0.85     0.85" />
    <mesh name="trapezium_rvs" file="Geometry/trapezium_rvs.stl" scale="    0.85     0.85     0.85" />
    <mesh name="metacarpal2_rvs" file="Geometry/metacarpal2_rvs.stl" scale="    0.85     0.85     0.85" />
    <mesh name="index_proximal_rvs" file="Geometry/index_proximal_rvs.stl" scale="    0.85     0.85     0.85" />
    <mesh name="index_medial_rvs" file="Geometry/index_medial_rvs.stl" scale="    0.85     0.85     0.85" />
    <mesh name="index_distal_rvs" file="Geometry/index_distal_rvs.stl" scale="    0.85     0.85     0.85" />
    <mesh name="metacarpal3_rvs" file="Geometry/metacarpal3_rvs.stl" scale="    0.85     0.85     0.85" />
    <mesh name="middle_proximal_rvs" file="Geometry/middle_proximal_rvs.stl" scale="    0.85     0.85     0.85" />
    <mesh name="middle_medial_rvs" file="Geometry/middle_medial_rvs.stl" scale="    0.85     0.85     0.85" />
    <mesh name="middle_distal_rvs" file="Geometry/middle_distal_rvs.stl" scale="    0.85     0.85     0.85" />
    <mesh name="metacarpal4_rvs" file="Geometry/metacarpal4_rvs.stl" scale="    0.85     0.85     0.85" />
    <mesh name="ring_proximal_rvs" file="Geometry/ring_proximal_rvs.stl" scale="    0.85     0.85     0.85" />
    <mesh name="ring_medial_rvs" file="Geometry/ring_medial_rvs.stl" scale="    0.85     0.85     0.85" />
    <mesh name="ring_distal_rvs" file="Geometry/ring_distal_rvs.stl" scale="    0.85     0.85     0.85" />
    <mesh name="metacarpal5_rvs" file="Geometry/metacarpal5_rvs.stl" scale="    0.85     0.85     0.85" />
    <mesh name="little_proximal_rvs" file="Geometry/little_proximal_rvs.stl" scale="    0.85     0.85     0.85" />
    <mesh name="little_medial_rvs" file="Geometry/little_medial_rvs.stl" scale="    0.85     0.85     0.85" />
    <mesh name="little_distal_rvs" file="Geometry/little_distal_rvs.stl" scale="    0.85     0.85     0.85" />
    <mesh name="metacarpal1_rvs" file="Geometry/metacarpal1_rvs.stl" scale="    0.85     0.85     0.85" />
    <mesh name="thumb_proximal_rvs" file="Geometry/thumb_proximal_rvs.stl" scale="    0.85     0.85     0.85" />
    <mesh name="thumb_distal_rvs" file="Geometry/thumb_distal_rvs.stl" scale="    0.85     0.85     0.85" />
    <mesh name="humerus_lv" file="Geometry/humerus_lv.stl" scale=" 1.07291  1.07291  1.07291" />
    <mesh name="ulna_lv" file="Geometry/ulna_lv.stl" scale=" 1.11541  1.11541  1.11541" />
    <mesh name="radius_lv" file="Geometry/radius_lv.stl" scale=" 1.16522  1.16522  1.16522" />
    <mesh name="pisiform_lvs" file="Geometry/pisiform_lvs.stl" scale="    0.85     0.85     0.85" />
    <mesh name="lunate_lvs" file="Geometry/lunate_lvs.stl" scale="    0.85     0.85     0.85" />
    <mesh name="scaphoid_lvs" file="Geometry/scaphoid_lvs.stl" scale="    0.85     0.85     0.85" />
    <mesh name="triquetrum_lvs" file="Geometry/triquetrum_lvs.stl" scale="    0.85     0.85     0.85" />
    <mesh name="hamate_lvs" file="Geometry/hamate_lvs.stl" scale="    0.85     0.85     0.85" />
    <mesh name="capitate_lvs" file="Geometry/capitate_lvs.stl" scale="    0.85     0.85     0.85" />
    <mesh name="trapezoid_lvs" file="Geometry/trapezoid_lvs.stl" scale="    0.85     0.85     0.85" />
    <mesh name="trapezium_lvs" file="Geometry/trapezium_lvs.stl" scale="    0.85     0.85     0.85" />
    <mesh name="metacarpal2_lvs" file="Geometry/metacarpal2_lvs.stl" scale="    0.85     0.85     0.85" />
    <mesh name="index_proximal_lvs" file="Geometry/index_proximal_lvs.stl" scale="    0.85     0.85     0.85" />
    <mesh name="index_medial_lvs" file="Geometry/index_medial_lvs.stl" scale="    0.85     0.85     0.85" />
    <mesh name="index_distal_lvs" file="Geometry/index_distal_lvs.stl" scale="    0.85     0.85     0.85" />
    <mesh name="metacarpal3_lvs" file="Geometry/metacarpal3_lvs.stl" scale="    0.85     0.85     0.85" />
    <mesh name="middle_proximal_lvs" file="Geometry/middle_proximal_lvs.stl" scale="    0.85     0.85     0.85" />
    <mesh name="middle_medial_lvs" file="Geometry/middle_medial_lvs.stl" scale="    0.85     0.85     0.85" />
    <mesh name="middle_distal_lvs" file="Geometry/middle_distal_lvs.stl" scale="    0.85     0.85     0.85" />
    <mesh name="metacarpal4_lvs" file="Geometry/metacarpal4_lvs.stl" scale="    0.85     0.85     0.85" />
    <mesh name="ring_proximal_lvs" file="Geometry/ring_proximal_lvs.stl" scale="    0.85     0.85     0.85" />
    <mesh name="ring_medial_lvs" file="Geometry/ring_medial_lvs.stl" scale="    0.85     0.85     0.85" />
    <mesh name="ring_distal_lvs" file="Geometry/ring_distal_lvs.stl" scale="    0.85     0.85     0.85" />
    <mesh name="metacarpal5_lvs" file="Geometry/metacarpal5_lvs.stl" scale="    0.85     0.85     0.85" />
    <mesh name="little_proximal_lvs" file="Geometry/little_proximal_lvs.stl" scale="    0.85     0.85     0.85" />
    <mesh name="little_medial_lvs" file="Geometry/little_medial_lvs.stl" scale="    0.85     0.85     0.85" />
    <mesh name="little_distal_lvs" file="Geometry/little_distal_lvs.stl" scale="    0.85     0.85     0.85" />
    <mesh name="metacarpal1_lvs" file="Geometry/metacarpal1_lvs.stl" scale="    0.85     0.85     0.85" />
    <mesh name="thumb_proximal_lvs" file="Geometry/thumb_proximal_lvs.stl" scale="    0.85     0.85     0.85" />
    <mesh name="thumb_distal_lvs" file="Geometry/thumb_distal_lvs.stl" scale="    0.85     0.85     0.85" />
    <texture name="texplane" type="2d" builtin="checker" rgb1=".2 .3 .4" rgb2=".1 0.15 0.2" width="100" height="100" />
    <material name="MatPlane" reflectance="0.0" texture="texplane" texrepeat="1 1" texuniform="true" />
  </asset>
  <actuator>
    <general name="lumbar_ext" joint="lumbar_extension" class="motor" />
    <general name="lumbar_bend" joint="lumbar_bending" class="motor" />
    <general name="lumbar_rot" joint="lumbar_rotation" class="motor" />
    <general name="shoulder_flex_r" joint="arm_flex_r" class="motor" />
    <general name="shoulder_add_r" joint="arm_add_r" class="motor" />
    <general name="shoulder_rot_r" joint="arm_rot_r" class="motor" />
    <general name="elbow_flex_r" joint="elbow_flex_r" class="motor" />
    <general name="pro_sup_r" joint="pro_sup_r" class="motor" />
    <general name="wrist_flex_r" joint="wrist_flex_r" class="motor" />
    <general name="wrist_dev_r" joint="wrist_dev_r" class="motor" />
    <general name="shoulder_flex_l" joint="arm_flex_l" class="motor" />
    <general name="shoulder_add_l" joint="arm_add_l" class="motor" />
    <general name="shoulder_rot_l" joint="arm_rot_l" class="motor" />
    <general name="elbow_flex_l" joint="elbow_flex_l" class="motor" />
    <general name="pro_sup_l" joint="pro_sup_l" class="motor" />
    <general name="wrist_flex_l" joint="wrist_flex_l" class="motor" />
    <general name="wrist_dev_l" joint="wrist_dev_l" class="motor" />
    <motor name="knee_angle_r_beta_rotation1" joint="knee_angle_r_beta_rotation1" class="motor" />
		<motor name="knee_angle_r_rotation3" joint="knee_angle_r_rotation3" class="motor" />
		<motor name="hip_rotation_l" joint="hip_rotation_l" class="motor" />
		<motor name="knee_angle_l_beta_rotation1" joint="knee_angle_l_beta_rotation1" class="motor" />
		<motor name="hip_flexion_l" joint="hip_flexion_l" class="motor" />
		<motor name="pelvis_list" joint="pelvis_list" class="motor" />
		<motor name="knee_angle_r_translation1" joint="knee_angle_r_translation1" class="motor" />
		<motor name="pelvis_tilt" joint="pelvis_tilt" class="motor" />
		<motor name="knee_angle_l_rotation3" joint="knee_angle_l_rotation3" class="motor" />
		<motor name="knee_angle_l_translation2" joint="knee_angle_l_translation2" class="motor" />
		<motor name="hip_rotation_r" joint="hip_rotation_r" class="motor" />
		<motor name="knee_angle_r_rotation2" joint="knee_angle_r_rotation2" class="motor" />
		<motor name="mtp_angle_r" joint="mtp_angle_r" class="motor" />
		<motor name="knee_angle_r_beta_translation1" joint="knee_angle_r_beta_translation1" class="motor" />
		<motor name="hip_flexion_r" joint="hip_flexion_r" class="motor" />
		<motor name="hip_adduction_l" joint="hip_adduction_l" class="motor" />
		<motor name="ankle_angle_r" joint="ankle_angle_r" class="motor" />
		<motor name="knee_angle_r_beta_translation2" joint="knee_angle_r_beta_translation2" class="motor" />
		<motor name="mtp_angle_l" joint="mtp_angle_l" class="motor" />
		<motor name="ankle_angle_l" joint="ankle_angle_l" class="motor" />
		<motor name="knee_angle_l_beta_translation1" joint="knee_angle_l_beta_translation1" class="motor" />
		<motor name="subtalar_angle_r" joint="subtalar_angle_r" class="motor" />
		<motor name="knee_angle_l_rotation2" joint="knee_angle_l_rotation2" class="motor" />
		<motor name="pelvis_rotation" joint="pelvis_rotation" class="motor" />
		<motor name="knee_angle_r" joint="knee_angle_r" class="motor" />
		<motor name="pelvis_ty" joint="pelvis_ty" class="motor" />
		<motor name="knee_angle_l" joint="knee_angle_l" class="motor" />
		<motor name="pelvis_tx" joint="pelvis_tx" class="motor" />
		<motor name="hip_adduction_r" joint="hip_adduction_r" class="motor" />
		<motor name="knee_angle_r_translation2" joint="knee_angle_r_translation2" class="motor" />
		<motor name="pelvis_tz" joint="pelvis_tz" class="motor" />
		<motor name="knee_angle_l_translation1" joint="knee_angle_l_translation1" class="motor" />
		<motor name="subtalar_angle_l" joint="subtalar_angle_l" class="motor" />
		<motor name="knee_angle_l_beta_translation2" joint="knee_angle_l_beta_translation2" class="motor" />
		</actuator>
  <equality>
    <joint name="knee_angle_r_translation2_constraint" active="true" joint1="knee_angle_r_translation2" joint2="knee_angle_r" polycoef="7.69254e-11 0.00587971 -0.00125622 -2.61846e-06 6.24355e-07" solimp="0.9999 0.9999 0.001 0.5 2" />
    <joint name="knee_angle_r_translation1_constraint" active="true" joint1="knee_angle_r_translation1" joint2="knee_angle_r" polycoef="9.53733e-08 0.00312879 -0.00230804 0.000561561 5.68366e-07" solimp="0.9999 0.9999 0.001 0.5 2" />
    <joint name="knee_angle_r_rotation2_constraint" active="true" joint1="knee_angle_r_rotation2" joint2="knee_angle_r" polycoef="-1.47325e-08   0.0791 -0.0328478 -0.0252183 0.0108321" solimp="0.9999 0.9999 0.001 0.5 2" />
    <joint name="knee_angle_r_rotation3_constraint" active="true" joint1="knee_angle_r_rotation3" joint2="knee_angle_r" polycoef="1.08939e-08 0.369499 -0.169478 0.0251643 3.50498e-07" solimp="0.9999 0.9999 0.001 0.5 2" />
    <joint name="knee_angle_r_beta_translation2_constraint" active="true" joint1="knee_angle_r_beta_translation2" joint2="knee_angle_r" polycoef="-0.0108281 -0.0487847 0.00927644 0.0131673 -0.00349673" solimp="0.9999 0.9999 0.001 0.5 2" />
    <joint name="knee_angle_r_beta_translation1_constraint" active="true" joint1="knee_angle_r_beta_translation1" joint2="knee_angle_r" polycoef="0.0524192 -0.0150188 -0.0340522 0.0133393 -0.000879151" solimp="0.9999 0.9999 0.001 0.5 2" />
    <joint name="knee_angle_r_beta_rotation1_constraint" active="true" joint1="knee_angle_r_beta_rotation1" joint2="knee_angle_r" polycoef="0.010506 0.0247615 -1.31647 0.716337 -0.138302" solimp="0.9999 0.9999 0.001 0.5 2" />
    <joint name="subtalar_angle_r_constraint" active="true" joint1="subtalar_angle_r" polycoef="       0        0        0        0        0" />
    <joint name="mtp_angle_r_constraint" active="true" joint1="mtp_angle_r" polycoef="       0        0        0        0        0" />
    <joint name="knee_angle_l_translation2_constraint" active="true" joint1="knee_angle_l_translation2" joint2="knee_angle_l" polycoef="-7.69254e-11 -0.00587971 0.00125622 2.61846e-06 -6.24355e-07" solimp="0.9999 0.9999 0.001 0.5 2" />
    <joint name="knee_angle_l_translation1_constraint" active="true" joint1="knee_angle_l_translation1" joint2="knee_angle_l" polycoef="9.53733e-08 0.00312879 -0.00230804 0.000561561 5.68366e-07" solimp="0.9999 0.9999 0.001 0.5 2" />
    <joint name="knee_angle_l_rotation2_constraint" active="true" joint1="knee_angle_l_rotation2" joint2="knee_angle_l" polycoef="-1.47325e-08   0.0791 -0.0328478 -0.0252183 0.0108321" solimp="0.9999 0.9999 0.001 0.5 2" />
    <joint name="knee_angle_l_rotation3_constraint" active="true" joint1="knee_angle_l_rotation3" joint2="knee_angle_l" polycoef="-1.08939e-08 -0.369499 0.169478 -0.0251643 -3.50498e-07" solimp="0.9999 0.9999 0.001 0.5 2" />
    <joint name="knee_angle_l_beta_translation2_constraint" active="true" joint1="knee_angle_l_beta_translation2" joint2="knee_angle_l" polycoef="-0.0108281 -0.0487847 0.00927644 0.0131673 -0.00349673" solimp="0.9999 0.9999 0.001 0.5 2" />
    <joint name="knee_angle_l_beta_translation1_constraint" active="true" joint1="knee_angle_l_beta_translation1" joint2="knee_angle_l" polycoef="0.0524192 -0.0150188 -0.0340522 0.0133393 -0.000879151" solimp="0.9999 0.9999 0.001 0.5 2" />
    <joint name="knee_angle_l_beta_rotation1_constraint" active="true" joint1="knee_angle_l_beta_rotation1" joint2="knee_angle_l" polycoef="0.010506 0.0247615 -1.31647 0.716337 -0.138302" solimp="0.9999 0.9999 0.001 0.5 2" />
    <joint name="subtalar_angle_l_constraint" active="true" joint1="subtalar_angle_l" polycoef="       0        0        0        0        0" />
    <joint name="mtp_angle_l_constraint" active="true" joint1="mtp_angle_l" polycoef="       0        0        0        0        0" />
    <joint name="wrist_flex_r_constraint" active="true" joint1="wrist_flex_r" polycoef="       0        0        0        0        0" />
    <joint name="wrist_dev_r_constraint" active="true" joint1="wrist_dev_r" polycoef="       0        0        0        0        0" />
    <joint name="wrist_flex_l_constraint" active="true" joint1="wrist_flex_l" polycoef="       0        0        0        0        0" />
    <joint name="wrist_dev_l_constraint" active="true" joint1="wrist_dev_l" polycoef="       0        0        0        0        0" />
    <weld name="origin_to_worldbody" body1="pelvis" active="false" />
  </equality>
</mujoco>