<mujoco model="SN475_Rajagopal_Scaled">
  <compiler inertiafromgeom="auto" angle="radian" balanceinertia="true" boundmass="0.001" boundinertia="0.001">
    <lengthrange inttotal="50" useexisting="true" />
  </compiler>
  <default>
    <!-- <joint limited="true" damping="0.5" armature="0.1" stiffness="2" /> -->
    <geom rgba="0.8 0.6 .4 1" margin="0.001" />
    <default class="motor">
      <general gainprm="5 0 0 0 0 0 0 0 0 0" />
    </default>
  </default>
  <extension>
    <plugin plugin="mujoco.elasticity.solid"/>
  </extension>
  <option timestep="0.001" />
  <!-- <size njmax="1000" nconmax="400" nuser_jnt="1" /> -->
  <worldbody>
    <geom name="floor" pos="0 0 -1" size="10 10 0.1" type="plane" material="MatPlane" condim="3" contype="3" conaffinity="3" />
    <body name="pelvis" pos="       0        0        0" quat="0.7071067811865475 0.7071067811865475 0.0 0.0">
      <light mode="trackcom" directional="false" pos="0 0 4.0" dir="0 0 -1" />
      <geom name="r_pelvis" type="mesh" mesh="r_pelvis" />
      <geom name="l_pelvis" type="mesh" mesh="l_pelvis" />
      <geom name="sacrum" type="mesh" mesh="sacrum" />
      <inertial pos="-0.0759082        0        0" mass="11.5893980715774" fullinertia="0.116616 0.0988059 0.0656815        0        0        0" />
      <joint name="pelvis_tz" type="slide" pos="0 0 0" axis="       0        0        1" limited="false" range="      -3        3" ref="0" armature="0" damping="0" stiffness="0" />
      <joint name="pelvis_ty" type="slide" pos="0 0 0" axis="       0        1        0" limited="false" range="      -1        2" ref="0" armature="0" damping="0" stiffness="0" />
      <joint name="pelvis_tx" type="slide" pos="0 0 0" axis="       1        0        0" limited="false" range="      -5        5" ref="0" armature="0" damping="0" stiffness="0" />
      <joint name="pelvis_tilt" type="hinge" pos="0 0 0" axis="       0        0        1" limited="false" range=" -1.5708   1.5708" ref="0" armature="0" damping="0" stiffness="0" />
      <joint name="pelvis_list" type="hinge" pos="0 0 0" axis="       1        0        0" limited="false" range=" -1.5708   1.5708" ref="0" armature="0" damping="0" stiffness="0" />
      <joint name="pelvis_rotation" type="hinge" pos="0 0 0" axis="       0        1        0" limited="false" range=" -1.5708   1.5708" ref="0" armature="0" damping="0" stiffness="0" />
      <body name="femur_r" pos="-0.0604216 -0.0842721 0.0829514" quat="1.0 0.0 0.0 0.0">
        <geom name="r_femur" type="mesh" mesh="r_femur" />
        <inertial pos="       0 -0.155893        0" mass="5.70296029242102" fullinertia="0.069038 0.0180973 0.0728018        0        0        0" />
        <joint name="hip_flexion_r" type="hinge" pos="0 0 0" axis="       0        0        1" limited="true" range="-0.523599   2.0944" ref="0" />
        <joint name="hip_adduction_r" type="hinge" pos="0 0 0" axis="       1        0        0" limited="true" range="-0.872665 0.523599" ref="0" />
        <joint name="hip_rotation_r" type="hinge" pos="0 0 0" axis="       0        1        0" limited="true" range="-0.698132 0.698132" ref="0" />
        <body name="tibia_r" pos="0.000321678 -0.370724 -0.00110115" quat="1.0 7.240636975890137e-18 -9.456205735995121e-17 -2.960068750797159e-20">
          <body name="r_calf"  pos="-0.325 1.683 -0.135" quat="-0.7069991  0.7069991 0.0123407 -0.0123407">            
            <flexcomp type="gmsh" file = 'C:\mujoco\mujoco-3.1.1\model\plugin\elasticity\asset\r_calf.msh'
                rgba="0 .7 .7 1" name="softbody_r_calf" mass="3.395399456"
                scale = "0.9 0.8 0.9" pos="0.285 -0.052 -1.340" quat="0.5 0.5 0.5 0.5 ">
                <contact condim="3" solref="0.01 1" solimp=".95 .99 .0001" selfcollide="none" contype="20" conaffinity="10"/>
                <edge equality="true" damping="1"/>
                <pin id="7 9 6 0 8 12"/>
                
              </flexcomp>
          </body>
          <geom name="r_tibia" type="mesh" mesh="r_tibia" />
          <geom name="r_fibula" type="mesh" mesh="r_fibula" />
          <inertial pos="       0 -0.178641        0" mass="2.58232270713756" fullinertia="0.0321391 0.00325217 0.0325855        0        0        0" />
          <joint name="knee_angle_r" type="hinge" pos="0 0 0" axis="-3.98373e-10 -0.0707131 -0.997497" limited="true" range="       0   2.0944" ref="0" />
          <body name="talus_r" pos="-0.00956835 -0.382734        0" quat="1.0 -6.036754011562992e-18 1.5193252867388614e-18 -2.498419531737724e-19">
            <geom name="r_talus" type="mesh" mesh="r_talus" />
            <inertial pos="       0        0        0" mass="0.047281631812007" fullinertia="0.000334355 0.000334355 0.000334355        0        0        0" />
            <joint name="ankle_angle_r" type="hinge" pos="0 0 0" axis="-0.105014 -0.174022 0.979126" limited="true" range="-0.698132 0.523599" ref="0" />
            <body name="calcn_r" pos="-0.041012 -0.0352769 0.00666014" quat="1.0 -5.320429553087796e-19 1.609289071159989e-17 -2.1848634538867752e-17">
              <geom name="r_foot" type="mesh" mesh="r_foot" />
              <inertial pos="0.0840926 0.0252278        0" mass="0.591020397650087" fullinertia="0.000468098 0.00130399 0.00137086        0        0        0" />
              <body name="toes_r" pos="0.150358 -0.00168185 0.000908201" quat="1.0 1.314867274624753e-31 -2.6810890689525335e-17 -3.939849802505862e-32">
                <geom name="r_bofoot" type="mesh" mesh="r_bofoot" />
                <inertial pos="0.0290961 0.00504556 -0.0147162" mass="0.102412014504807" fullinertia="3.34355e-05 6.68711e-05 0.000334355        0        0        0" />
                <body name="r_foot"  pos="-0.325 1.683 -0.135" quat="-0.7069991  0.7069991 0.0123407 -0.0123407">            
                  <flexcomp type="gmsh" file = 'C:\mujoco\mujoco-3.0.0\model\plugin\elasticity\asset\r_ankle_reduceMax.msh'
                      rgba="0 .7 .7 1" name="softbody_r_foot" mass="1.395399456"
                      scale = "0.9 0.8 0.9" pos="0.205 -0.042 -0.930" quat="0.5 0.5 0.5 0.5 ">
                      <contact condim="3" solref="0.01 1" solimp=".95 .99 .0001" selfcollide="none" contype="20" conaffinity="10"/>
                      <edge equality="true" damping="1"/>
                      <pin id="7 9 6 0 8 12"/>
                      
                    </flexcomp>
                </body>
              </body>
            </body>
          </body>
        </body>
      </body>
      <body name="femur_l" pos="-0.0604216 -0.0842721 -0.0829514" quat="1.0 0.0 0.0 0.0">
        <geom name="l_femur" type="mesh" mesh="l_femur" />
        <inertial pos="       0 -0.154827        0" mass="5.58677355859822" fullinertia="0.0667098 0.017487 0.0703467        0        0        0" />
        <joint name="hip_flexion_l" type="hinge" pos="0 0 0" axis="       0        0        1" limited="true" range="-0.523599   2.0944" ref="0" />
        <joint name="hip_adduction_l" type="hinge" pos="0 0 0" axis="      -1       -0       -0" limited="true" range="-0.872665 0.523599" ref="0" />
        <joint name="hip_rotation_l" type="hinge" pos="0 0 0" axis="      -0       -1       -0" limited="true" range="-0.698132 0.698132" ref="0" />
        <body name="tibia_l" pos="0.00040783 -0.368151 0.0010774" quat="1.0 -7.240636975890137e-18 9.456205735995121e-17 -2.960068750797159e-20">
          <geom name="l_tibia" type="mesh" mesh="l_tibia" />
          <geom name="l_fibula" type="mesh" mesh="l_fibula" />
          <inertial pos="       0 -0.179459        0" mass="2.61794166082064" fullinertia="0.0328813 0.00332728 0.033338        0        0        0" />
          <joint name="knee_angle_l" type="hinge" pos="0 0 0" axis="3.98373e-10 0.0707131 -0.997497" limited="true" range="       0   2.0944" ref="0" />
          <body name="talus_l" pos="-0.00961214 -0.384486        0" quat="1.0 6.036754011562992e-18 -1.5193252867388614e-18 -2.498419531737724e-19">
            <geom name="l_talus" type="mesh" mesh="l_talus" />
            <inertial pos="       0        0        0" mass="0.0453135589234355" fullinertia="0.000311483 0.000311483 0.000311483        0        0        0" />
            <joint name="ankle_angle_l" type="hinge" pos="0 0 0" axis="0.105014 0.174022 0.979126" limited="true" range="-0.698132 0.523599" ref="0" />
            <body name="calcn_l" pos="-0.0404349 -0.0347804 -0.00656642" quat="1.0 5.320429553087796e-19 -1.609289071159989e-17 -2.1848634538867752e-17">
              <geom name="l_foot" type="mesh" mesh="l_foot" />
              <inertial pos="0.0829093 0.0248728        0" mass="0.566419486542944" fullinertia="0.000436076 0.00121478 0.00127708        0        0        0" />
              <body name="toes_l" pos="0.148242 -0.00165819 -0.00089542" quat="1.0 1.314867274624753e-31 2.6810890689525335e-17 3.939849802505862e-32">
                <geom name="l_bofoot" type="mesh" mesh="l_bofoot" />
                <inertial pos="0.0286866 0.00497456 0.0145091" mass="0.0981491686281613" fullinertia="3.11483e-05 6.22966e-05 0.000311483        0        0        0" />
                <!-- <body name="l_foot_1"  pos="-0.322 1.691 0.084" quat="-0.7069991  0.7069991 0.0123407 -0.0123407">            
                  <flexcomp type="gmsh" file = 'C:\mujoco\mujoco-3.0.0\model\plugin\elasticity\asset\l_ankle_reducedMax.msh'
                      rgba="0 .7 .7 1" name="softbody_l_foot" mass="1.395399456"
                      scale = "0.85 0.8 0.9" pos="0.205 -0.005 -0.935" quat="0.5 0.5 0.5 0.5 ">
                      <contact condim="3" solref="0.01 1" solimp=".95 .99 .0001" selfcollide="none" contype="28" conaffinity="2"/>
                      <edge equality="true" damping="1"/>
                      <pin id="2 3 10 4 13 9 6"/>
                      
                    </flexcomp>

                </body> -->
              </body>
            </body>
          </body>
        </body>
      </body>
      <body name="torso" pos="-0.108118 0.0875038        0" quat="1.0 0.0 0.0 0.0">
        <geom name="hat_spine" type="mesh" mesh="hat_spine" />
        <geom name="hat_jaw" type="mesh" mesh="hat_jaw" />
        <geom name="hat_skull" type="mesh" mesh="hat_skull" />
        <geom name="hat_ribs_scap" type="mesh" mesh="hat_ribs_scap" />
        <inertial pos="-0.0286665 0.305776        0" mass="18.6099511823664" fullinertia="0.933968 0.478544 0.906667        0        0        0" />
        <joint name="lumbar_extension" type="hinge" pos="0 0 0" axis="       0        0        1" limited="true" range=" -1.5708   1.5708" ref="0" />
        <joint name="lumbar_bending" type="hinge" pos="0 0 0" axis="       1        0        0" limited="true" range=" -1.5708   1.5708" ref="0" />
        <joint name="lumbar_rotation" type="hinge" pos="0 0 0" axis="       0        1        0" limited="true" range=" -1.5708   1.5708" ref="0" />
        <body name="humerus_r" pos="0.00301476 0.354987 0.162444" quat="1.0 0.0 0.0 0.0">
          <geom name="humerus_rv" type="mesh" mesh="humerus_rv" />
          <inertial pos="       0 -0.142672        0" mass="1.0542687374296" fullinertia="0.00466099 0.0016079 0.00523181        0        0        0" />
          <joint name="arm_flex_r" type="hinge" pos="0 0 0" axis="       0        0        1" limited="true" range=" -1.5708   1.5708" ref="0" />
          <joint name="arm_add_r" type="hinge" pos="0 0 0" axis="       1        0        0" limited="true" range=" -2.0944   1.5708" ref="0" />
          <joint name="arm_rot_r" type="hinge" pos="0 0 0" axis="       0        1        0" limited="true" range=" -1.5708   1.5708" ref="0" />
          <body name="ulna_r" pos="0.0113997 -0.248283 -0.00832171" quat="1.0 1.6893809785063376e-18 -6.938893903907228e-18 4.155190089080778e-20">
            <geom name="ulna_rv" type="mesh" mesh="ulna_rv" />
            <inertial pos="       0 -0.116243        0" mass="0.433345425036106" fullinertia="0.00196541 0.000410068 0.00213196        0        0        0" />
            <joint name="elbow_flex_r" type="hinge" pos="0 0 0" axis="0.226047 0.022269 0.973862" limited="true" range="       0    2.618" ref="0" />
            <body name="radius_r" pos="-0.00648801 -0.0125449 0.0251563" quat="1.0 2.301201592641875e-21 -6.933378131686372e-19 1.7489241099837954e-19">
              <geom name="radius_rv" type="mesh" mesh="radius_rv" />
              <inertial pos="       0 -0.122358        0" mass="0.50539511011462" fullinertia="0.00253969 0.000529888 0.0027549        0        0        0" />
              <body name="hand_r" pos="-0.00893079 -0.239428 0.013817" quat="1.0 0.0 8.407790785948892e-45 0.0">
                <geom name="pisiform_rvs" type="mesh" mesh="pisiform_rvs" />
                <geom name="lunate_rvs" type="mesh" mesh="lunate_rvs" />
                <geom name="scaphoid_rvs" type="mesh" mesh="scaphoid_rvs" />
                <geom name="triquetrum_rvs" type="mesh" mesh="triquetrum_rvs" />
                <geom name="hamate_rvs" type="mesh" mesh="hamate_rvs" />
                <geom name="capitate_rvs" type="mesh" mesh="capitate_rvs" />
                <geom name="trapezoid_rvs" type="mesh" mesh="trapezoid_rvs" />
                <geom name="trapezium_rvs" type="mesh" mesh="trapezium_rvs" />
                <geom name="metacarpal2_rvs" type="mesh" mesh="metacarpal2_rvs" />
                <geom name="index_proximal_rvs" type="mesh" mesh="index_proximal_rvs" />
                <geom name="index_medial_rvs" type="mesh" mesh="index_medial_rvs" />
                <geom name="index_distal_rvs" type="mesh" mesh="index_distal_rvs" />
                <geom name="metacarpal3_rvs" type="mesh" mesh="metacarpal3_rvs" />
                <geom name="middle_proximal_rvs" type="mesh" mesh="middle_proximal_rvs" />
                <geom name="middle_medial_rvs" type="mesh" mesh="middle_medial_rvs" />
                <geom name="middle_distal_rvs" type="mesh" mesh="middle_distal_rvs" />
                <geom name="metacarpal4_rvs" type="mesh" mesh="metacarpal4_rvs" />
                <geom name="ring_proximal_rvs" type="mesh" mesh="ring_proximal_rvs" />
                <geom name="ring_medial_rvs" type="mesh" mesh="ring_medial_rvs" />
                <geom name="ring_distal_rvs" type="mesh" mesh="ring_distal_rvs" />
                <geom name="metacarpal5_rvs" type="mesh" mesh="metacarpal5_rvs" />
                <geom name="little_proximal_rvs" type="mesh" mesh="little_proximal_rvs" />
                <geom name="little_medial_rvs" type="mesh" mesh="little_medial_rvs" />
                <geom name="little_distal_rvs" type="mesh" mesh="little_distal_rvs" />
                <geom name="metacarpal1_rvs" type="mesh" mesh="metacarpal1_rvs" />
                <geom name="thumb_proximal_rvs" type="mesh" mesh="thumb_proximal_rvs" />
                <geom name="thumb_distal_rvs" type="mesh" mesh="thumb_distal_rvs" />
                <inertial pos="       0 -0.0639237        0" mass="0.300919501256944" fullinertia="0.000517033 0.000317059 0.000776708        0        0        0" />
              </body>
            </body>
          </body>
        </body>
        <body name="humerus_l" pos="0.00301476 0.354987 -0.162444" quat="1.0 0.0 0.0 0.0">
          <geom name="humerus_lv" type="mesh" mesh="humerus_lv" />
          <inertial pos="       0 -0.143927        0" mass="1.0823274511379" fullinertia="0.00486957 0.00167985 0.00546593        0        0        0" />
          <joint name="arm_flex_l" type="hinge" pos="0 0 0" axis="       0        0        1" limited="true" range=" -1.5708   1.5708" ref="0" />
          <joint name="arm_add_l" type="hinge" pos="0 0 0" axis="      -1        0        0" limited="true" range=" -2.0944   1.5708" ref="0" />
          <joint name="arm_rot_l" type="hinge" pos="0 0 0" axis="       0       -1        0" limited="true" range=" -1.5708   1.5708" ref="0" />
          <body name="ulna_l" pos="  0.0115 -0.250467 0.00839489" quat="1.0 -1.6893809785063376e-18 6.938893903907228e-18 4.155190089080778e-20">
            <geom name="ulna_lv" type="mesh" mesh="ulna_lv" />
            <inertial pos="       0 -0.113553        0" mass="0.403946352717867" fullinertia="0.00174824 0.000364758 0.00189639        0        0        0" />
            <joint name="elbow_flex_l" type="hinge" pos="0 0 0" axis="-0.226047 -0.022269 0.973862" limited="true" range="       0    2.618" ref="0" />
            <body name="radius_l" pos="-0.00633784 -0.0122545 -0.0245741" quat="1.0 -2.301201592641875e-21 6.933378131686372e-19 1.7489241099837954e-19">
              <geom name="radius_lv" type="mesh" mesh="radius_lv" />
              <inertial pos="       0 -0.121639        0" mass="0.496534260946311" fullinertia="0.00246591 0.000514495 0.00267487        0        0        0" />
              <body name="hand_l" pos="-0.00887829 -0.23802 -0.0137358" quat="1.0 0.0 8.407790785948892e-45 0.0">
                <geom name="pisiform_lvs" type="mesh" mesh="pisiform_lvs" />
                <geom name="lunate_lvs" type="mesh" mesh="lunate_lvs" />
                <geom name="scaphoid_lvs" type="mesh" mesh="scaphoid_lvs" />
                <geom name="triquetrum_lvs" type="mesh" mesh="triquetrum_lvs" />
                <geom name="hamate_lvs" type="mesh" mesh="hamate_lvs" />
                <geom name="capitate_lvs" type="mesh" mesh="capitate_lvs" />
                <geom name="trapezoid_lvs" type="mesh" mesh="trapezoid_lvs" />
                <geom name="trapezium_lvs" type="mesh" mesh="trapezium_lvs" />
                <geom name="metacarpal2_lvs" type="mesh" mesh="metacarpal2_lvs" />
                <geom name="index_proximal_lvs" type="mesh" mesh="index_proximal_lvs" />
                <geom name="index_medial_lvs" type="mesh" mesh="index_medial_lvs" />
                <geom name="index_distal_lvs" type="mesh" mesh="index_distal_lvs" />
                <geom name="metacarpal3_lvs" type="mesh" mesh="metacarpal3_lvs" />
                <geom name="middle_proximal_lvs" type="mesh" mesh="middle_proximal_lvs" />
                <geom name="middle_medial_lvs" type="mesh" mesh="middle_medial_lvs" />
                <geom name="middle_distal_lvs" type="mesh" mesh="middle_distal_lvs" />
                <geom name="metacarpal4_lvs" type="mesh" mesh="metacarpal4_lvs" />
                <geom name="ring_proximal_lvs" type="mesh" mesh="ring_proximal_lvs" />
                <geom name="ring_medial_lvs" type="mesh" mesh="ring_medial_lvs" />
                <geom name="ring_distal_lvs" type="mesh" mesh="ring_distal_lvs" />
                <geom name="metacarpal5_lvs" type="mesh" mesh="metacarpal5_lvs" />
                <geom name="little_proximal_lvs" type="mesh" mesh="little_proximal_lvs" />
                <geom name="little_medial_lvs" type="mesh" mesh="little_medial_lvs" />
                <geom name="little_distal_lvs" type="mesh" mesh="little_distal_lvs" />
                <geom name="metacarpal1_lvs" type="mesh" mesh="metacarpal1_lvs" />
                <geom name="thumb_proximal_lvs" type="mesh" mesh="thumb_proximal_lvs" />
                <geom name="thumb_distal_lvs" type="mesh" mesh="thumb_distal_lvs" />
                <inertial pos="       0 -0.0731465        0" mass="0.450863643098478" fullinertia="0.00101432 0.000622012 0.00152376        0        0        0" />
              </body>
            </body>
          </body>
        </body>
      </body>
    </body>

    <!-- <flexcomp type="gmsh" file = 'C:\mujoco\mujoco-3.0.0\model\plugin\elasticity\asset\head.msh'
                      rgba="0 .7 .7 1" name="head" mass="1.395399456"
                      scale = "0.2 0.2 0.2" pos="-0.19 0 0.618" quat="0.5 0.5 0.5 0.5 ">
                      <contact condim="3" solref="0.01 1" solimp=".95 .99 .0001" selfcollide="none" contype="20" conaffinity="10"/>
                      <edge equality="true" damping="1"/>
                      <plugin plugin="mujoco.elasticity.solid">
                        <config key="poisson" value="0"/>
                        
                        <config key="young" value="1e4"/>
                      </plugin>
    </flexcomp> -->
    <!-- <body name="2pelvis" pos="       0        1        0" quat="0.7071067811865475 0.7071067811865475 0.0 0.0">
      <light mode="trackcom" directional="false" pos="0 0 4.0" dir="0 0 -1" />
      <geom name="2r_pelvis" type="mesh" mesh="r_pelvis" />
      <geom name="2l_pelvis" type="mesh" mesh="l_pelvis" />
      <geom name="2sacrum" type="mesh" mesh="sacrum" />
      <inertial pos="-0.0759082        0        0" mass="11.5893980715774" fullinertia="0.116616 0.0988059 0.0656815        0        0        0" />
      <joint name="2pelvis_tz" type="slide" pos="0 0 0" axis="       0        0        1" limited="false" range="      -3        3" ref="0" armature="0" damping="0" stiffness="0" />
      <joint name="2pelvis_ty" type="slide" pos="0 0 0" axis="       0        1        0" limited="false" range="      -1        2" ref="0" armature="0" damping="0" stiffness="0" />
      <joint name="2pelvis_tx" type="slide" pos="0 0 0" axis="       1        0        0" limited="false" range="      -5        5" ref="0" armature="0" damping="0" stiffness="0" />
      <joint name="2pelvis_tilt" type="hinge" pos="0 0 0" axis="       0        0        1" limited="false" range=" -1.5708   1.5708" ref="0" armature="0" damping="0" stiffness="0" />
      <joint name="2pelvis_list" type="hinge" pos="0 0 0" axis="       1        0        0" limited="false" range=" -1.5708   1.5708" ref="0" armature="0" damping="0" stiffness="0" />
      <joint name="2pelvis_rotation" type="hinge" pos="0 0 0" axis="       0        1        0" limited="false" range=" -1.5708   1.5708" ref="0" armature="0" damping="0" stiffness="0" />
      <body name="2femur_r" pos="-0.0604216 -0.0842721 0.0829514" quat="1.0 0.0 0.0 0.0">
        <geom name="2r_femur" type="mesh" mesh="r_femur" />
        <inertial pos="       0 -0.155893        0" mass="5.70296029242102" fullinertia="0.069038 0.0180973 0.0728018        0        0        0" />
        <joint name="2hip_flexion_r" type="hinge" pos="0 0 0" axis="       0        0        1" limited="true" range="-0.523599   2.0944" ref="0" />
        <joint name="2hip_adduction_r" type="hinge" pos="0 0 0" axis="       1        0        0" limited="true" range="-0.872665 0.523599" ref="0" />
        <joint name="2hip_rotation_r" type="hinge" pos="0 0 0" axis="       0        1        0" limited="true" range="-0.698132 0.698132" ref="0" />
        <body name="2tibia_r" pos="0.000321678 -0.370724 -0.00110115" quat="1.0 7.240636975890137e-18 -9.456205735995121e-17 -2.960068750797159e-20">
          <geom name="2r_tibia" type="mesh" mesh="r_tibia" />
          <geom name="2r_fibula" type="mesh" mesh="r_fibula" />
          <inertial pos="       0 -0.178641        0" mass="2.58232270713756" fullinertia="0.0321391 0.00325217 0.0325855        0        0        0" />
          <joint name="2knee_angle_r" type="hinge" pos="0 0 0" axis="-3.98373e-10 -0.0707131 -0.997497" limited="true" range="       0   2.0944" ref="0" />
          <body name="2talus_r" pos="-0.00956835 -0.382734        0" quat="1.0 -6.036754011562992e-18 1.5193252867388614e-18 -2.498419531737724e-19">
            <geom name="2r_talus" type="mesh" mesh="r_talus" />
            <inertial pos="       0        0        0" mass="0.047281631812007" fullinertia="0.000334355 0.000334355 0.000334355        0        0        0" />
            <joint name="2ankle_angle_r" type="hinge" pos="0 0 0" axis="-0.105014 -0.174022 0.979126" limited="true" range="-0.698132 0.523599" ref="0" />
            <body name="2calcn_r" pos="-0.041012 -0.0352769 0.00666014" quat="1.0 -5.320429553087796e-19 1.609289071159989e-17 -2.1848634538867752e-17">
              <geom name="2r_foot" type="mesh" mesh="r_foot" />
              <inertial pos="0.0840926 0.0252278        0" mass="0.591020397650087" fullinertia="0.000468098 0.00130399 0.00137086        0        0        0" />
              <body name="2toes_r" pos="0.150358 -0.00168185 0.000908201" quat="1.0 1.314867274624753e-31 -2.6810890689525335e-17 -3.939849802505862e-32">
                <geom name="2r_bofoot" type="mesh" mesh="r_bofoot" />
                <inertial pos="0.0290961 0.00504556 -0.0147162" mass="0.102412014504807" fullinertia="3.34355e-05 6.68711e-05 0.000334355        0        0        0" />
                <body name="2r_foot"  pos="-0.325 1.683 -0.135" quat="-0.7069991  0.7069991 0.0123407 -0.0123407">            
                  <flexcomp type="gmsh" file = 'C:\mujoco\mujoco-3.0.0\model\plugin\elasticity\asset\r_ankle.msh'
                      rgba="0 .7 .7 1" name="2softbody_r_foot" mass="1.395399456"
                      scale = "0.9 0.8 0.9" pos="0.205 -0.042 -0.925" quat="0.5 0.5 0.5 0.5 ">
                      <contact condim="3" solref="0.01 1" solimp=".95 .99 .0001" selfcollide="none" contype="20" conaffinity="10"/>
                      <edge equality="true" damping="1"/>
                      <pin id="1 2 101 102 201 202 301 302"/>
                  
                    </flexcomp>
                </body>
              </body>
            </body>
          </body>
        </body>
      </body>
      <body name="2femur_l" pos="-0.0604216 -0.0842721 -0.0829514" quat="1.0 0.0 0.0 0.0">
        <geom name="2l_femur" type="mesh" mesh="l_femur" />
        <inertial pos="       0 -0.154827        0" mass="5.58677355859822" fullinertia="0.0667098 0.017487 0.0703467        0        0        0" />
        <joint name="2hip_flexion_l" type="hinge" pos="0 0 0" axis="       0        0        1" limited="true" range="-0.523599   2.0944" ref="0" />
        <joint name="2hip_adduction_l" type="hinge" pos="0 0 0" axis="      -1       -0       -0" limited="true" range="-0.872665 0.523599" ref="0" />
        <joint name="2hip_rotation_l" type="hinge" pos="0 0 0" axis="      -0       -1       -0" limited="true" range="-0.698132 0.698132" ref="0" />
        <body name="2tibia_l" pos="0.00040783 -0.368151 0.0010774" quat="1.0 -7.240636975890137e-18 9.456205735995121e-17 -2.960068750797159e-20">
          <geom name="2l_tibia" type="mesh" mesh="l_tibia" />
          <geom name="2l_fibula" type="mesh" mesh="l_fibula" />
          <inertial pos="       0 -0.179459        0" mass="2.61794166082064" fullinertia="0.0328813 0.00332728 0.033338        0        0        0" />
          <joint name="2knee_angle_l" type="hinge" pos="0 0 0" axis="3.98373e-10 0.0707131 -0.997497" limited="true" range="       0   2.0944" ref="0" />
          <body name="2talus_l" pos="-0.00961214 -0.384486        0" quat="1.0 6.036754011562992e-18 -1.5193252867388614e-18 -2.498419531737724e-19">
            <geom name="2l_talus" type="mesh" mesh="l_talus" />
            <inertial pos="       0        0        0" mass="0.0453135589234355" fullinertia="0.000311483 0.000311483 0.000311483        0        0        0" />
            <joint name="2ankle_angle_l" type="hinge" pos="0 0 0" axis="0.105014 0.174022 0.979126" limited="true" range="-0.698132 0.523599" ref="0" />
            <body name="2calcn_l" pos="-0.0404349 -0.0347804 -0.00656642" quat="1.0 5.320429553087796e-19 -1.609289071159989e-17 -2.1848634538867752e-17">
              <geom name="2l_foot" type="mesh" mesh="l_foot" />
              <inertial pos="0.0829093 0.0248728        0" mass="0.566419486542944" fullinertia="0.000436076 0.00121478 0.00127708        0        0        0" />
              <body name="2toes_l" pos="0.148242 -0.00165819 -0.00089542" quat="1.0 1.314867274624753e-31 2.6810890689525335e-17 3.939849802505862e-32">
                <geom name="2l_bofoot" type="mesh" mesh="l_bofoot" />
                <inertial pos="0.0286866 0.00497456 0.0145091" mass="0.0981491686281613" fullinertia="3.11483e-05 6.22966e-05 0.000311483        0        0        0" />
                <body name="2l_foot_1"  pos="-0.322 1.691 0.084" quat="-0.7069991  0.7069991 0.0123407 -0.0123407">            
                  <flexcomp type="gmsh" file = 'C:\mujoco\mujoco-3.0.0\model\plugin\elasticity\asset\l_ankle.msh'
                      rgba="0 .7 .7 1" name="2softbody_l_foot" mass="1.395399456"
                      scale = "0.85 0.8 0.9" pos="0.205 -0.005 -0.932" quat="0.5 0.5 0.5 0.5 ">
                      <contact condim="3" solref="0.01 1" solimp=".95 .99 .0001" selfcollide="none" contype="28" conaffinity="2"/>
                      <edge equality="true" damping="1"/>
                      <pin id="1 2 101 102 201 202 301 302"/>
                      
                    </flexcomp>

                </body>
              </body>
            </body>
          </body>
        </body>
      </body>
      <body name="2torso" pos="-0.108118 0.0875038        0" quat="1.0 0.0 0.0 0.0">
        <geom name="2hat_spine" type="mesh" mesh="hat_spine" />
        <geom name="2hat_jaw" type="mesh" mesh="hat_jaw" />
        <geom name="2hat_skull" type="mesh" mesh="hat_skull" />
        <geom name="2hat_ribs_scap" type="mesh" mesh="hat_ribs_scap" />
        <inertial pos="-0.0286665 0.305776        0" mass="18.6099511823664" fullinertia="0.933968 0.478544 0.906667        0        0        0" />
        <joint name="2lumbar_extension" type="hinge" pos="0 0 0" axis="       0        0        1" limited="true" range=" -1.5708   1.5708" ref="0" />
        <joint name="2lumbar_bending" type="hinge" pos="0 0 0" axis="       1        0        0" limited="true" range=" -1.5708   1.5708" ref="0" />
        <joint name="2lumbar_rotation" type="hinge" pos="0 0 0" axis="       0        1        0" limited="true" range=" -1.5708   1.5708" ref="0" />
        <body name="2humerus_r" pos="0.00301476 0.354987 0.162444" quat="1.0 0.0 0.0 0.0">
          <geom name="2humerus_rv" type="mesh" mesh="humerus_rv" />
          <inertial pos="       0 -0.142672        0" mass="1.0542687374296" fullinertia="0.00466099 0.0016079 0.00523181        0        0        0" />
          <joint name="2arm_flex_r" type="hinge" pos="0 0 0" axis="       0        0        1" limited="true" range=" -1.5708   1.5708" ref="0" />
          <joint name="2arm_add_r" type="hinge" pos="0 0 0" axis="       1        0        0" limited="true" range=" -2.0944   1.5708" ref="0" />
          <joint name="2arm_rot_r" type="hinge" pos="0 0 0" axis="       0        1        0" limited="true" range=" -1.5708   1.5708" ref="0" />
          <body name="2ulna_r" pos="0.0113997 -0.248283 -0.00832171" quat="1.0 1.6893809785063376e-18 -6.938893903907228e-18 4.155190089080778e-20">
            <geom name="2ulna_rv" type="mesh" mesh="ulna_rv" />
            <inertial pos="       0 -0.116243        0" mass="0.433345425036106" fullinertia="0.00196541 0.000410068 0.00213196        0        0        0" />
            <joint name="2elbow_flex_r" type="hinge" pos="0 0 0" axis="0.226047 0.022269 0.973862" limited="true" range="       0    2.618" ref="0" />
            <body name="2radius_r" pos="-0.00648801 -0.0125449 0.0251563" quat="1.0 2.301201592641875e-21 -6.933378131686372e-19 1.7489241099837954e-19">
              <geom name="2radius_rv" type="mesh" mesh="radius_rv" />
              <inertial pos="       0 -0.122358        0" mass="0.50539511011462" fullinertia="0.00253969 0.000529888 0.0027549        0        0        0" />
              <body name="2hand_r" pos="-0.00893079 -0.239428 0.013817" quat="1.0 0.0 8.407790785948892e-45 0.0">
                <geom name="2pisiform_rvs" type="mesh" mesh="pisiform_rvs" />
                <geom name="2lunate_rvs" type="mesh" mesh="lunate_rvs" />
                <geom name="2scaphoid_rvs" type="mesh" mesh="scaphoid_rvs" />
                <geom name="2triquetrum_rvs" type="mesh" mesh="triquetrum_rvs" />
                <geom name="2hamate_rvs" type="mesh" mesh="hamate_rvs" />
                <geom name="2capitate_rvs" type="mesh" mesh="capitate_rvs" />
                <geom name="2trapezoid_rvs" type="mesh" mesh="trapezoid_rvs" />
                <geom name="2trapezium_rvs" type="mesh" mesh="trapezium_rvs" />
                <geom name="2metacarpal2_rvs" type="mesh" mesh="metacarpal2_rvs" />
                <geom name="2index_proximal_rvs" type="mesh" mesh="index_proximal_rvs" />
                <geom name="2index_medial_rvs" type="mesh" mesh="index_medial_rvs" />
                <geom name="2index_distal_rvs" type="mesh" mesh="index_distal_rvs" />
                <geom name="2metacarpal3_rvs" type="mesh" mesh="metacarpal3_rvs" />
                <geom name="2middle_proximal_rvs" type="mesh" mesh="middle_proximal_rvs" />
                <geom name="2middle_medial_rvs" type="mesh" mesh="middle_medial_rvs" />
                <geom name="2middle_distal_rvs" type="mesh" mesh="middle_distal_rvs" />
                <geom name="2metacarpal4_rvs" type="mesh" mesh="metacarpal4_rvs" />
                <geom name="2ring_proximal_rvs" type="mesh" mesh="ring_proximal_rvs" />
                <geom name="2ring_medial_rvs" type="mesh" mesh="ring_medial_rvs" />
                <geom name="2ring_distal_rvs" type="mesh" mesh="ring_distal_rvs" />
                <geom name="2metacarpal5_rvs" type="mesh" mesh="metacarpal5_rvs" />
                <geom name="2little_proximal_rvs" type="mesh" mesh="little_proximal_rvs" />
                <geom name="2little_medial_rvs" type="mesh" mesh="little_medial_rvs" />
                <geom name="2little_distal_rvs" type="mesh" mesh="little_distal_rvs" />
                <geom name="2metacarpal1_rvs" type="mesh" mesh="metacarpal1_rvs" />
                <geom name="2thumb_proximal_rvs" type="mesh" mesh="thumb_proximal_rvs" />
                <geom name="2thumb_distal_rvs" type="mesh" mesh="thumb_distal_rvs" />
                <inertial pos="       0 -0.0639237        0" mass="0.300919501256944" fullinertia="0.000517033 0.000317059 0.000776708        0        0        0" />
              </body>
            </body>
          </body>
        </body>
        <body name="2humerus_l" pos="0.00301476 0.354987 -0.162444" quat="1.0 0.0 0.0 0.0">
          <geom name="2humerus_lv" type="mesh" mesh="humerus_lv" />
          <inertial pos="       0 -0.143927        0" mass="1.0823274511379" fullinertia="0.00486957 0.00167985 0.00546593        0        0        0" />
          <joint name="2arm_flex_l" type="hinge" pos="0 0 0" axis="       0        0        1" limited="true" range=" -1.5708   1.5708" ref="0" />
          <joint name="2arm_add_l" type="hinge" pos="0 0 0" axis="      -1        0        0" limited="true" range=" -2.0944   1.5708" ref="0" />
          <joint name="2arm_rot_l" type="hinge" pos="0 0 0" axis="       0       -1        0" limited="true" range=" -1.5708   1.5708" ref="0" />
          <body name="2ulna_l" pos="  0.0115 -0.250467 0.00839489" quat="1.0 -1.6893809785063376e-18 6.938893903907228e-18 4.155190089080778e-20">
            <geom name="2ulna_lv" type="mesh" mesh="ulna_lv" />
            <inertial pos="       0 -0.113553        0" mass="0.403946352717867" fullinertia="0.00174824 0.000364758 0.00189639        0        0        0" />
            <joint name="2elbow_flex_l" type="hinge" pos="0 0 0" axis="-0.226047 -0.022269 0.973862" limited="true" range="       0    2.618" ref="0" />
            <body name="2radius_l" pos="-0.00633784 -0.0122545 -0.0245741" quat="1.0 -2.301201592641875e-21 6.933378131686372e-19 1.7489241099837954e-19">
              <geom name="2radius_lv" type="mesh" mesh="radius_lv" />
              <inertial pos="       0 -0.121639        0" mass="0.496534260946311" fullinertia="0.00246591 0.000514495 0.00267487        0        0        0" />
              <body name="2hand_l" pos="-0.00887829 -0.23802 -0.0137358" quat="1.0 0.0 8.407790785948892e-45 0.0">
                <geom name="2pisiform_lvs" type="mesh" mesh="pisiform_lvs" />
                <geom name="2lunate_lvs" type="mesh" mesh="lunate_lvs" />
                <geom name="2scaphoid_lvs" type="mesh" mesh="scaphoid_lvs" />
                <geom name="2triquetrum_lvs" type="mesh" mesh="triquetrum_lvs" />
                <geom name="2hamate_lvs" type="mesh" mesh="hamate_lvs" />
                <geom name="2capitate_lvs" type="mesh" mesh="capitate_lvs" />
                <geom name="2trapezoid_lvs" type="mesh" mesh="trapezoid_lvs" />
                <geom name="2trapezium_lvs" type="mesh" mesh="trapezium_lvs" />
                <geom name="2metacarpal2_lvs" type="mesh" mesh="metacarpal2_lvs" />
                <geom name="2index_proximal_lvs" type="mesh" mesh="index_proximal_lvs" />
                <geom name="2index_medial_lvs" type="mesh" mesh="index_medial_lvs" />
                <geom name="2index_distal_lvs" type="mesh" mesh="index_distal_lvs" />
                <geom name="2metacarpal3_lvs" type="mesh" mesh="metacarpal3_lvs" />
                <geom name="2middle_proximal_lvs" type="mesh" mesh="middle_proximal_lvs" />
                <geom name="2middle_medial_lvs" type="mesh" mesh="middle_medial_lvs" />
                <geom name="2middle_distal_lvs" type="mesh" mesh="middle_distal_lvs" />
                <geom name="2metacarpal4_lvs" type="mesh" mesh="metacarpal4_lvs" />
                <geom name="2ring_proximal_lvs" type="mesh" mesh="ring_proximal_lvs" />
                <geom name="2ring_medial_lvs" type="mesh" mesh="ring_medial_lvs" />
                <geom name="2ring_distal_lvs" type="mesh" mesh="ring_distal_lvs" />
                <geom name="2metacarpal5_lvs" type="mesh" mesh="metacarpal5_lvs" />
                <geom name="2little_proximal_lvs" type="mesh" mesh="little_proximal_lvs" />
                <geom name="2little_medial_lvs" type="mesh" mesh="little_medial_lvs" />
                <geom name="2little_distal_lvs" type="mesh" mesh="little_distal_lvs" />
                <geom name="2metacarpal1_lvs" type="mesh" mesh="metacarpal1_lvs" />
                <geom name="2thumb_proximal_lvs" type="mesh" mesh="thumb_proximal_lvs" />
                <geom name="2thumb_distal_lvs" type="mesh" mesh="thumb_distal_lvs" />
                <inertial pos="       0 -0.0731465        0" mass="0.450863643098478" fullinertia="0.00101432 0.000622012 0.00152376        0        0        0" />
              </body>
            </body>
          </body>
        </body>
      </body>
    </body> -->
    
    <!-- <body name="3pelvis" pos="       0        -1        0" quat="0.7071067811865475 0.7071067811865475 0.0 0.0">
      <light mode="trackcom" directional="false" pos="0 0 4.0" dir="0 0 -1" />
      <geom name="3r_pelvis" type="mesh" mesh="r_pelvis" />
      <geom name="3l_pelvis" type="mesh" mesh="l_pelvis" />
      <geom name="3sacrum" type="mesh" mesh="sacrum" />
      <inertial pos="-0.0759082        0        0" mass="11.5893980715774" fullinertia="0.116616 0.0988059 0.0656815        0        0        0" />
      <joint name="3pelvis_tz" type="slide" pos="0 0 0" axis="       0        0        1" limited="false" range="      -3        3" ref="0" armature="0" damping="0" stiffness="0" />
      <joint name="3pelvis_ty" type="slide" pos="0 0 0" axis="       0        1        0" limited="false" range="      -1        2" ref="0" armature="0" damping="0" stiffness="0" />
      <joint name="3pelvis_tx" type="slide" pos="0 0 0" axis="       1        0        0" limited="false" range="      -5        5" ref="0" armature="0" damping="0" stiffness="0" />
      <joint name="3pelvis_tilt" type="hinge" pos="0 0 0" axis="       0        0        1" limited="false" range=" -1.5708   1.5708" ref="0" armature="0" damping="0" stiffness="0" />
      <joint name="3pelvis_list" type="hinge" pos="0 0 0" axis="       1        0        0" limited="false" range=" -1.5708   1.5708" ref="0" armature="0" damping="0" stiffness="0" />
      <joint name="3pelvis_rotation" type="hinge" pos="0 0 0" axis="       0        1        0" limited="false" range=" -1.5708   1.5708" ref="0" armature="0" damping="0" stiffness="0" />
      <body name="3femur_r" pos="-0.0604216 -0.0842721 0.0829514" quat="1.0 0.0 0.0 0.0">
        <geom name="3r_femur" type="mesh" mesh="r_femur" />
        <inertial pos="       0 -0.155893        0" mass="5.70296029242102" fullinertia="0.069038 0.0180973 0.0728018        0        0        0" />
        <joint name="3hip_flexion_r" type="hinge" pos="0 0 0" axis="       0        0        1" limited="true" range="-0.523599   2.0944" ref="0" />
        <joint name="3hip_adduction_r" type="hinge" pos="0 0 0" axis="       1        0        0" limited="true" range="-0.872665 0.523599" ref="0" />
        <joint name="3hip_rotation_r" type="hinge" pos="0 0 0" axis="       0        1        0" limited="true" range="-0.698132 0.698132" ref="0" />
        <body name="3tibia_r" pos="0.000321678 -0.370724 -0.00110115" quat="1.0 7.240636975890137e-18 -9.456205735995121e-17 -2.960068750797159e-20">
          <geom name="3r_tibia" type="mesh" mesh="r_tibia" />
          <geom name="3r_fibula" type="mesh" mesh="r_fibula" />
          <inertial pos="       0 -0.178641        0" mass="2.58232270713756" fullinertia="0.0321391 0.00325217 0.0325855        0        0        0" />
          <joint name="3knee_angle_r" type="hinge" pos="0 0 0" axis="-3.98373e-10 -0.0707131 -0.997497" limited="true" range="       0   2.0944" ref="0" />
          <body name="3talus_r" pos="-0.00956835 -0.382734        0" quat="1.0 -6.036754011562992e-18 1.5193252867388614e-18 -2.498419531737724e-19">
            <geom name="3r_talus" type="mesh" mesh="r_talus" />
            <inertial pos="       0        0        0" mass="0.047281631812007" fullinertia="0.000334355 0.000334355 0.000334355        0        0        0" />
            <joint name="3ankle_angle_r" type="hinge" pos="0 0 0" axis="-0.105014 -0.174022 0.979126" limited="true" range="-0.698132 0.523599" ref="0" />
            <body name="3calcn_r" pos="-0.041012 -0.0352769 0.00666014" quat="1.0 -5.320429553087796e-19 1.609289071159989e-17 -2.1848634538867752e-17">
              <geom name="3r_foot" type="mesh" mesh="r_foot" />
              <inertial pos="0.0840926 0.0252278        0" mass="0.591020397650087" fullinertia="0.000468098 0.00130399 0.00137086        0        0        0" />
              <body name="3toes_r" pos="0.150358 -0.00168185 0.000908201" quat="1.0 1.314867274624753e-31 -2.6810890689525335e-17 -3.939849802505862e-32">
                <geom name="3r_bofoot" type="mesh" mesh="r_bofoot" />
                <inertial pos="0.0290961 0.00504556 -0.0147162" mass="0.102412014504807" fullinertia="3.34355e-05 6.68711e-05 0.000334355        0        0        0" />
               
              </body>
            </body>
          </body>
        </body>
      </body>
      <body name="3femur_l" pos="-0.0604216 -0.0842721 -0.0829514" quat="1.0 0.0 0.0 0.0">
        <geom name="3l_femur" type="mesh" mesh="l_femur" />
        <inertial pos="       0 -0.154827        0" mass="5.58677355859822" fullinertia="0.0667098 0.017487 0.0703467        0        0        0" />
        <joint name="3hip_flexion_l" type="hinge" pos="0 0 0" axis="       0        0        1" limited="true" range="-0.523599   2.0944" ref="0" />
        <joint name="3hip_adduction_l" type="hinge" pos="0 0 0" axis="      -1       -0       -0" limited="true" range="-0.872665 0.523599" ref="0" />
        <joint name="3hip_rotation_l" type="hinge" pos="0 0 0" axis="      -0       -1       -0" limited="true" range="-0.698132 0.698132" ref="0" />
        <body name="3tibia_l" pos="0.00040783 -0.368151 0.0010774" quat="1.0 -7.240636975890137e-18 9.456205735995121e-17 -2.960068750797159e-20">
          <geom name="3l_tibia" type="mesh" mesh="l_tibia" />
          <geom name="3l_fibula" type="mesh" mesh="l_fibula" />
          <inertial pos="       0 -0.179459        0" mass="2.61794166082064" fullinertia="0.0328813 0.00332728 0.033338        0        0        0" />
          <joint name="3knee_angle_l" type="hinge" pos="0 0 0" axis="3.98373e-10 0.0707131 -0.997497" limited="true" range="       0   2.0944" ref="0" />
          <body name="3talus_l" pos="-0.00961214 -0.384486        0" quat="1.0 6.036754011562992e-18 -1.5193252867388614e-18 -2.498419531737724e-19">
            <geom name="3l_talus" type="mesh" mesh="l_talus" />
            <inertial pos="       0        0        0" mass="0.0453135589234355" fullinertia="0.000311483 0.000311483 0.000311483        0        0        0" />
            <joint name="3ankle_angle_l" type="hinge" pos="0 0 0" axis="0.105014 0.174022 0.979126" limited="true" range="-0.698132 0.523599" ref="0" />
            <body name="3calcn_l" pos="-0.0404349 -0.0347804 -0.00656642" quat="1.0 5.320429553087796e-19 -1.609289071159989e-17 -2.1848634538867752e-17">
              <geom name="3l_foot" type="mesh" mesh="l_foot" />
              <inertial pos="0.0829093 0.0248728        0" mass="0.566419486542944" fullinertia="0.000436076 0.00121478 0.00127708        0        0        0" />
              <body name="3toes_l" pos="0.148242 -0.00165819 -0.00089542" quat="1.0 1.314867274624753e-31 2.6810890689525335e-17 3.939849802505862e-32">
                <geom name="3l_bofoot" type="mesh" mesh="l_bofoot" />
                <inertial pos="0.0286866 0.00497456 0.0145091" mass="0.0981491686281613" fullinertia="3.11483e-05 6.22966e-05 0.000311483        0        0        0" />
                
              </body>
            </body>
          </body>
        </body>
      </body>
      <body name="3torso" pos="-0.108118 0.0875038        0" quat="1.0 0.0 0.0 0.0">
        <geom name="3hat_spine" type="mesh" mesh="hat_spine" />
        <geom name="3hat_jaw" type="mesh" mesh="hat_jaw" />
        <geom name="3hat_skull" type="mesh" mesh="hat_skull" />
        <geom name="3hat_ribs_scap" type="mesh" mesh="hat_ribs_scap" />
        <inertial pos="-0.0286665 0.305776        0" mass="18.6099511823664" fullinertia="0.933968 0.478544 0.906667        0        0        0" />
        <joint name="3lumbar_extension" type="hinge" pos="0 0 0" axis="       0        0        1" limited="true" range=" -1.5708   1.5708" ref="0" />
        <joint name="3lumbar_bending" type="hinge" pos="0 0 0" axis="       1        0        0" limited="true" range=" -1.5708   1.5708" ref="0" />
        <joint name="3lumbar_rotation" type="hinge" pos="0 0 0" axis="       0        1        0" limited="true" range=" -1.5708   1.5708" ref="0" />
        <body name="3humerus_r" pos="0.00301476 0.354987 0.162444" quat="1.0 0.0 0.0 0.0">
          <geom name="3humerus_rv" type="mesh" mesh="humerus_rv" />
          <inertial pos="       0 -0.142672        0" mass="1.0542687374296" fullinertia="0.00466099 0.0016079 0.00523181        0        0        0" />
          <joint name="3arm_flex_r" type="hinge" pos="0 0 0" axis="       0        0        1" limited="true" range=" -1.5708   1.5708" ref="0" />
          <joint name="3arm_add_r" type="hinge" pos="0 0 0" axis="       1        0        0" limited="true" range=" -2.0944   1.5708" ref="0" />
          <joint name="3arm_rot_r" type="hinge" pos="0 0 0" axis="       0        1        0" limited="true" range=" -1.5708   1.5708" ref="0" />
          <body name="3ulna_r" pos="0.0113997 -0.248283 -0.00832171" quat="1.0 1.6893809785063376e-18 -6.938893903907228e-18 4.155190089080778e-20">
            <geom name="3ulna_rv" type="mesh" mesh="ulna_rv" />
            <inertial pos="       0 -0.116243        0" mass="0.433345425036106" fullinertia="0.00196541 0.000410068 0.00213196        0        0        0" />
            <joint name="3elbow_flex_r" type="hinge" pos="0 0 0" axis="0.226047 0.022269 0.973862" limited="true" range="       0    2.618" ref="0" />
            <body name="3radius_r" pos="-0.00648801 -0.0125449 0.0251563" quat="1.0 2.301201592641875e-21 -6.933378131686372e-19 1.7489241099837954e-19">
              <geom name="3radius_rv" type="mesh" mesh="radius_rv" />
              <inertial pos="       0 -0.122358        0" mass="0.50539511011462" fullinertia="0.00253969 0.000529888 0.0027549        0        0        0" />
              <body name="3hand_r" pos="-0.00893079 -0.239428 0.013817" quat="1.0 0.0 8.407790785948892e-45 0.0">
                <geom name="3pisiform_rvs" type="mesh" mesh="pisiform_rvs" />
                <geom name="3lunate_rvs" type="mesh" mesh="lunate_rvs" />
                <geom name="3scaphoid_rvs" type="mesh" mesh="scaphoid_rvs" />
                <geom name="3triquetrum_rvs" type="mesh" mesh="triquetrum_rvs" />
                <geom name="3hamate_rvs" type="mesh" mesh="hamate_rvs" />
                <geom name="3capitate_rvs" type="mesh" mesh="capitate_rvs" />
                <geom name="3trapezoid_rvs" type="mesh" mesh="trapezoid_rvs" />
                <geom name="3trapezium_rvs" type="mesh" mesh="trapezium_rvs" />
                <geom name="3metacarpal2_rvs" type="mesh" mesh="metacarpal2_rvs" />
                <geom name="3index_proximal_rvs" type="mesh" mesh="index_proximal_rvs" />
                <geom name="3index_medial_rvs" type="mesh" mesh="index_medial_rvs" />
                <geom name="3index_distal_rvs" type="mesh" mesh="index_distal_rvs" />
                <geom name="3metacarpal3_rvs" type="mesh" mesh="metacarpal3_rvs" />
                <geom name="3middle_proximal_rvs" type="mesh" mesh="middle_proximal_rvs" />
                <geom name="3middle_medial_rvs" type="mesh" mesh="middle_medial_rvs" />
                <geom name="3middle_distal_rvs" type="mesh" mesh="middle_distal_rvs" />
                <geom name="3metacarpal4_rvs" type="mesh" mesh="metacarpal4_rvs" />
                <geom name="3ring_proximal_rvs" type="mesh" mesh="ring_proximal_rvs" />
                <geom name="3ring_medial_rvs" type="mesh" mesh="ring_medial_rvs" />
                <geom name="3ring_distal_rvs" type="mesh" mesh="ring_distal_rvs" />
                <geom name="3metacarpal5_rvs" type="mesh" mesh="metacarpal5_rvs" />
                <geom name="3little_proximal_rvs" type="mesh" mesh="little_proximal_rvs" />
                <geom name="3little_medial_rvs" type="mesh" mesh="little_medial_rvs" />
                <geom name="3little_distal_rvs" type="mesh" mesh="little_distal_rvs" />
                <geom name="3metacarpal1_rvs" type="mesh" mesh="metacarpal1_rvs" />
                <geom name="3thumb_proximal_rvs" type="mesh" mesh="thumb_proximal_rvs" />
                <geom name="3thumb_distal_rvs" type="mesh" mesh="thumb_distal_rvs" />
                <inertial pos="       0 -0.0639237        0" mass="0.300919501256944" fullinertia="0.000517033 0.000317059 0.000776708        0        0        0" />
              </body>
            </body>
          </body>
        </body>
        <body name="3humerus_l" pos="0.00301476 0.354987 -0.162444" quat="1.0 0.0 0.0 0.0">
          <geom name="3humerus_lv" type="mesh" mesh="humerus_lv" />
          <inertial pos="       0 -0.143927        0" mass="1.0823274511379" fullinertia="0.00486957 0.00167985 0.00546593        0        0        0" />
          <joint name="3arm_flex_l" type="hinge" pos="0 0 0" axis="       0        0        1" limited="true" range=" -1.5708   1.5708" ref="0" />
          <joint name="3arm_add_l" type="hinge" pos="0 0 0" axis="      -1        0        0" limited="true" range=" -2.0944   1.5708" ref="0" />
          <joint name="3arm_rot_l" type="hinge" pos="0 0 0" axis="       0       -1        0" limited="true" range=" -1.5708   1.5708" ref="0" />
          <body name="3ulna_l" pos="  0.0115 -0.250467 0.00839489" quat="1.0 -1.6893809785063376e-18 6.938893903907228e-18 4.155190089080778e-20">
            <geom name="3ulna_lv" type="mesh" mesh="ulna_lv" />
            <inertial pos="       0 -0.113553        0" mass="0.403946352717867" fullinertia="0.00174824 0.000364758 0.00189639        0        0        0" />
            <joint name="3elbow_flex_l" type="hinge" pos="0 0 0" axis="-0.226047 -0.022269 0.973862" limited="true" range="       0    2.618" ref="0" />
            <body name="3radius_l" pos="-0.00633784 -0.0122545 -0.0245741" quat="1.0 -2.301201592641875e-21 6.933378131686372e-19 1.7489241099837954e-19">
              <geom name="3radius_lv" type="mesh" mesh="radius_lv" />
              <inertial pos="       0 -0.121639        0" mass="0.496534260946311" fullinertia="0.00246591 0.000514495 0.00267487        0        0        0" />
              <body name="3hand_l" pos="-0.00887829 -0.23802 -0.0137358" quat="1.0 0.0 8.407790785948892e-45 0.0">
                <geom name="3pisiform_lvs" type="mesh" mesh="pisiform_lvs" />
                <geom name="3lunate_lvs" type="mesh" mesh="lunate_lvs" />
                <geom name="3scaphoid_lvs" type="mesh" mesh="scaphoid_lvs" />
                <geom name="3triquetrum_lvs" type="mesh" mesh="triquetrum_lvs" />
                <geom name="3hamate_lvs" type="mesh" mesh="hamate_lvs" />
                <geom name="3capitate_lvs" type="mesh" mesh="capitate_lvs" />
                <geom name="3trapezoid_lvs" type="mesh" mesh="trapezoid_lvs" />
                <geom name="3trapezium_lvs" type="mesh" mesh="trapezium_lvs" />
                <geom name="3metacarpal2_lvs" type="mesh" mesh="metacarpal2_lvs" />
                <geom name="3index_proximal_lvs" type="mesh" mesh="index_proximal_lvs" />
                <geom name="3index_medial_lvs" type="mesh" mesh="index_medial_lvs" />
                <geom name="3index_distal_lvs" type="mesh" mesh="index_distal_lvs" />
                <geom name="3metacarpal3_lvs" type="mesh" mesh="metacarpal3_lvs" />
                <geom name="3middle_proximal_lvs" type="mesh" mesh="middle_proximal_lvs" />
                <geom name="3middle_medial_lvs" type="mesh" mesh="middle_medial_lvs" />
                <geom name="3middle_distal_lvs" type="mesh" mesh="middle_distal_lvs" />
                <geom name="3metacarpal4_lvs" type="mesh" mesh="metacarpal4_lvs" />
                <geom name="3ring_proximal_lvs" type="mesh" mesh="ring_proximal_lvs" />
                <geom name="3ring_medial_lvs" type="mesh" mesh="ring_medial_lvs" />
                <geom name="3ring_distal_lvs" type="mesh" mesh="ring_distal_lvs" />
                <geom name="3metacarpal5_lvs" type="mesh" mesh="metacarpal5_lvs" />
                <geom name="3little_proximal_lvs" type="mesh" mesh="little_proximal_lvs" />
                <geom name="3little_medial_lvs" type="mesh" mesh="little_medial_lvs" />
                <geom name="3little_distal_lvs" type="mesh" mesh="little_distal_lvs" />
                <geom name="3metacarpal1_lvs" type="mesh" mesh="metacarpal1_lvs" />
                <geom name="3thumb_proximal_lvs" type="mesh" mesh="thumb_proximal_lvs" />
                <geom name="3thumb_distal_lvs" type="mesh" mesh="thumb_distal_lvs" />
                <inertial pos="       0 -0.0731465        0" mass="0.450863643098478" fullinertia="0.00101432 0.000622012 0.00152376        0        0        0" />
              </body>
            </body>
          </body>
        </body>
      </body>
    </body> -->
    <camera name="for_testing" pos="0 0 0" euler="0 0 0" />
  </worldbody>
  <asset>
    <mesh name="r_pelvis" file="Geometry/r_pelvis.stl" scale=" 1.07367  1.07367  1.07367" />
    <mesh name="l_pelvis" file="Geometry/l_pelvis.stl" scale=" 1.07367  1.07367  1.07367" />
    <mesh name="sacrum" file="Geometry/sacrum.stl" scale=" 1.07367  1.07367  1.07367" />
    <mesh name="r_femur" file="Geometry/r_femur.stl" scale="0.917018 0.917018 0.917018" />
    <mesh name="r_tibia" file="Geometry/r_tibia.stl" scale="0.956835 0.956835 0.956835" />
    <mesh name="r_fibula" file="Geometry/r_fibula.stl" scale="0.956835 0.956835 0.956835" />
    <mesh name="r_talus" file="Geometry/r_talus.stl" scale="0.840926 0.840926 0.840926" />
    <mesh name="r_foot" file="Geometry/r_foot.stl" scale="0.840926 0.840926 0.840926" />
    <mesh name="r_bofoot" file="Geometry/r_bofoot.stl" scale="0.840926 0.840926 0.840926" />
    <mesh name="l_femur" file="Geometry/l_femur.stl" scale="0.910748 0.910748 0.910748" />
    <mesh name="l_tibia" file="Geometry/l_tibia.stl" scale="0.961214 0.961214 0.961214" />
    <mesh name="l_fibula" file="Geometry/l_fibula.stl" scale="0.961214 0.961214 0.961214" />
    <mesh name="l_talus" file="Geometry/l_talus.stl" scale="0.829093 0.829093 0.829093" />
    <mesh name="l_foot" file="Geometry/l_foot.stl" scale="0.829093 0.829093 0.829093" />
    <mesh name="l_bofoot" file="Geometry/l_bofoot.stl" scale="0.829093 0.829093 0.829093" />
    <mesh name="hat_spine" file="Geometry/hat_spine.stl" scale="0.955551 0.955551 0.955551" />
    <mesh name="hat_jaw" file="Geometry/hat_jaw.stl" scale="0.955551 0.955551 0.955551" />
    <mesh name="hat_skull" file="Geometry/hat_skull.stl" scale="0.955551 0.955551 0.955551" />
    <mesh name="hat_ribs_scap" file="Geometry/hat_ribs_scap.stl" scale="0.955551 0.955551 0.955551" />
    <mesh name="humerus_rv" file="Geometry/humerus_rv.stl" scale="0.867296 0.867296 0.867296" />
    <mesh name="ulna_rv" file="Geometry/ulna_rv.stl" scale="0.964472 0.964472 0.964472" />
    <mesh name="radius_rv" file="Geometry/radius_rv.stl" scale=" 1.01521  1.01521  1.01521" />
    <mesh name="pisiform_rvs" file="Geometry/pisiform_rvs.stl" scale="0.797932 0.797932 0.797932" />
    <mesh name="lunate_rvs" file="Geometry/lunate_rvs.stl" scale="0.797932 0.797932 0.797932" />
    <mesh name="scaphoid_rvs" file="Geometry/scaphoid_rvs.stl" scale="0.797932 0.797932 0.797932" />
    <mesh name="triquetrum_rvs" file="Geometry/triquetrum_rvs.stl" scale="0.797932 0.797932 0.797932" />
    <mesh name="hamate_rvs" file="Geometry/hamate_rvs.stl" scale="0.797932 0.797932 0.797932" />
    <mesh name="capitate_rvs" file="Geometry/capitate_rvs.stl" scale="0.797932 0.797932 0.797932" />
    <mesh name="trapezoid_rvs" file="Geometry/trapezoid_rvs.stl" scale="0.797932 0.797932 0.797932" />
    <mesh name="trapezium_rvs" file="Geometry/trapezium_rvs.stl" scale="0.797932 0.797932 0.797932" />
    <mesh name="metacarpal2_rvs" file="Geometry/metacarpal2_rvs.stl" scale="0.797932 0.797932 0.797932" />
    <mesh name="index_proximal_rvs" file="Geometry/index_proximal_rvs.stl" scale="0.797932 0.797932 0.797932" />
    <mesh name="index_medial_rvs" file="Geometry/index_medial_rvs.stl" scale="0.797932 0.797932 0.797932" />
    <mesh name="index_distal_rvs" file="Geometry/index_distal_rvs.stl" scale="0.797932 0.797932 0.797932" />
    <mesh name="metacarpal3_rvs" file="Geometry/metacarpal3_rvs.stl" scale="0.797932 0.797932 0.797932" />
    <mesh name="middle_proximal_rvs" file="Geometry/middle_proximal_rvs.stl" scale="0.797932 0.797932 0.797932" />
    <mesh name="middle_medial_rvs" file="Geometry/middle_medial_rvs.stl" scale="0.797932 0.797932 0.797932" />
    <mesh name="middle_distal_rvs" file="Geometry/middle_distal_rvs.stl" scale="0.797932 0.797932 0.797932" />
    <mesh name="metacarpal4_rvs" file="Geometry/metacarpal4_rvs.stl" scale="0.797932 0.797932 0.797932" />
    <mesh name="ring_proximal_rvs" file="Geometry/ring_proximal_rvs.stl" scale="0.797932 0.797932 0.797932" />
    <mesh name="ring_medial_rvs" file="Geometry/ring_medial_rvs.stl" scale="0.797932 0.797932 0.797932" />
    <mesh name="ring_distal_rvs" file="Geometry/ring_distal_rvs.stl" scale="0.797932 0.797932 0.797932" />
    <mesh name="metacarpal5_rvs" file="Geometry/metacarpal5_rvs.stl" scale="0.797932 0.797932 0.797932" />
    <mesh name="little_proximal_rvs" file="Geometry/little_proximal_rvs.stl" scale="0.797932 0.797932 0.797932" />
    <mesh name="little_medial_rvs" file="Geometry/little_medial_rvs.stl" scale="0.797932 0.797932 0.797932" />
    <mesh name="little_distal_rvs" file="Geometry/little_distal_rvs.stl" scale="0.797932 0.797932 0.797932" />
    <mesh name="metacarpal1_rvs" file="Geometry/metacarpal1_rvs.stl" scale="0.797932 0.797932 0.797932" />
    <mesh name="thumb_proximal_rvs" file="Geometry/thumb_proximal_rvs.stl" scale="0.797932 0.797932 0.797932" />
    <mesh name="thumb_distal_rvs" file="Geometry/thumb_distal_rvs.stl" scale="0.797932 0.797932 0.797932" />
    <mesh name="humerus_lv" file="Geometry/humerus_lv.stl" scale="0.874923 0.874923 0.874923" />
    <mesh name="ulna_lv" file="Geometry/ulna_lv.stl" scale="0.942149 0.942149 0.942149" />
    <mesh name="radius_lv" file="Geometry/radius_lv.stl" scale=" 1.00924  1.00924  1.00924" />
    <mesh name="pisiform_lvs" file="Geometry/pisiform_lvs.stl" scale="0.913056 0.913056 0.913056" />
    <mesh name="lunate_lvs" file="Geometry/lunate_lvs.stl" scale="0.913056 0.913056 0.913056" />
    <mesh name="scaphoid_lvs" file="Geometry/scaphoid_lvs.stl" scale="0.913056 0.913056 0.913056" />
    <mesh name="triquetrum_lvs" file="Geometry/triquetrum_lvs.stl" scale="0.913056 0.913056 0.913056" />
    <mesh name="hamate_lvs" file="Geometry/hamate_lvs.stl" scale="0.913056 0.913056 0.913056" />
    <mesh name="capitate_lvs" file="Geometry/capitate_lvs.stl" scale="0.913056 0.913056 0.913056" />
    <mesh name="trapezoid_lvs" file="Geometry/trapezoid_lvs.stl" scale="0.913056 0.913056 0.913056" />
    <mesh name="trapezium_lvs" file="Geometry/trapezium_lvs.stl" scale="0.913056 0.913056 0.913056" />
    <mesh name="metacarpal2_lvs" file="Geometry/metacarpal2_lvs.stl" scale="0.913056 0.913056 0.913056" />
    <mesh name="index_proximal_lvs" file="Geometry/index_proximal_lvs.stl" scale="0.913056 0.913056 0.913056" />
    <mesh name="index_medial_lvs" file="Geometry/index_medial_lvs.stl" scale="0.913056 0.913056 0.913056" />
    <mesh name="index_distal_lvs" file="Geometry/index_distal_lvs.stl" scale="0.913056 0.913056 0.913056" />
    <mesh name="metacarpal3_lvs" file="Geometry/metacarpal3_lvs.stl" scale="0.913056 0.913056 0.913056" />
    <mesh name="middle_proximal_lvs" file="Geometry/middle_proximal_lvs.stl" scale="0.913056 0.913056 0.913056" />
    <mesh name="middle_medial_lvs" file="Geometry/middle_medial_lvs.stl" scale="0.913056 0.913056 0.913056" />
    <mesh name="middle_distal_lvs" file="Geometry/middle_distal_lvs.stl" scale="0.913056 0.913056 0.913056" />
    <mesh name="metacarpal4_lvs" file="Geometry/metacarpal4_lvs.stl" scale="0.913056 0.913056 0.913056" />
    <mesh name="ring_proximal_lvs" file="Geometry/ring_proximal_lvs.stl" scale="0.913056 0.913056 0.913056" />
    <mesh name="ring_medial_lvs" file="Geometry/ring_medial_lvs.stl" scale="0.913056 0.913056 0.913056" />
    <mesh name="ring_distal_lvs" file="Geometry/ring_distal_lvs.stl" scale="0.913056 0.913056 0.913056" />
    <mesh name="metacarpal5_lvs" file="Geometry/metacarpal5_lvs.stl" scale="0.913056 0.913056 0.913056" />
    <mesh name="little_proximal_lvs" file="Geometry/little_proximal_lvs.stl" scale="0.913056 0.913056 0.913056" />
    <mesh name="little_medial_lvs" file="Geometry/little_medial_lvs.stl" scale="0.913056 0.913056 0.913056" />
    <mesh name="little_distal_lvs" file="Geometry/little_distal_lvs.stl" scale="0.913056 0.913056 0.913056" />
    <mesh name="metacarpal1_lvs" file="Geometry/metacarpal1_lvs.stl" scale="0.913056 0.913056 0.913056" />
    <mesh name="thumb_proximal_lvs" file="Geometry/thumb_proximal_lvs.stl" scale="0.913056 0.913056 0.913056" />
    <mesh name="thumb_distal_lvs" file="Geometry/thumb_distal_lvs.stl" scale="0.913056 0.913056 0.913056" />
    <texture name="texplane" type="2d" builtin="checker" rgb1=".2 .3 .4" rgb2=".1 0.15 0.2" width="100" height="100" />
    <material name="MatPlane" reflectance="0.0" texture="texplane" texrepeat="1 1" texuniform="true" />
  </asset>
  <actuator>
    <!-- Root -->
    <motor name="pelvis_tz" joint="pelvis_tz"/>
    <motor name="pelvis_ty" joint="pelvis_ty"/>
    <motor name="pelvis_tx" joint="pelvis_tx"/>
    <motor name="pelvis_tilt" joint="pelvis_tilt"/>
    <motor name="pelvis_list" joint="pelvis_list"/>
    <motor name="pelvis_rotation" joint="pelvis_rotation"/>

    <!-- Right Leg -->
    <motor name="hip_flexion_r" joint="hip_flexion_r"/>
    <motor name="hip_adduction_r" joint="hip_adduction_r"/>
    <motor name="hip_rotation_r" joint="hip_rotation_r"/>
    <motor name="knee_angle_r" joint="knee_angle_r"/>
    <motor name="ankle_angle_r" joint="ankle_angle_r"/>

    <!-- Left Leg -->
    <motor name="hip_flexion_l" joint="hip_flexion_l"/>
    <motor name="hip_adduction_l" joint="hip_adduction_l"/>
    <motor name="hip_rotation_l" joint="hip_rotation_l"/>
    <motor name="knee_angle_l" joint="knee_angle_l"/>
    <motor name="ankle_angle_l" joint="ankle_angle_l"/>

    <!-- Torso -->
    <motor name="lumbar_extension" joint="lumbar_extension" />
    <motor name="lumbar_bending" joint="lumbar_bending"/>
    <motor name="lumbar_rotation" joint="lumbar_rotation"/>

    <!-- Right Arm -->
    <motor name="arm_flex_r" joint="arm_flex_r"/>
    <motor name="arm_add_r" joint="arm_add_r"/>
    <motor name="arm_rot_r" joint="arm_rot_r"/>
    <motor name="elbow_flex_r" joint="elbow_flex_r"/>

    <!-- Left Arm -->
    <motor name="arm_flex_l" joint="arm_flex_l"/>
    <motor name="arm_add_l" joint="arm_add_l" />
    <motor name="arm_rot_l" joint="arm_rot_l" />
    <motor name="elbow_flex_l" joint="elbow_flex_l" />
  </actuator>
  <equality>
    <weld name="origin_to_worldbody" body1="pelvis" active="false" />
    <!-- <weld name="pelvis" body2="head_0" body1="torso"  />
    <weld name="pelvis2" body2="head_150" body1="torso"  />
    <weld name="pelvis3" body2="head_10" body1="torso"  />
    <weld name="pelvis4" body2="head_180" body1="torso"  />
    <weld name="pelvis5" body2="head_145" body1="torso"  />
    <weld name="pelvis6" body2="head_230" body1="torso"  /> -->
  </equality>
</mujoco>
