<?xml version="1.0" encoding="utf-8"?>
<mujoco model="SN372_Rajagopal_Scaled">
  <compiler inertiafromgeom="auto" angle="radian" balanceinertia="true" boundmass="0.001" boundinertia="0.001">
    <lengthrange inttotal="50" useexisting="true"></lengthrange>
  </compiler>
  <default>
    <joint limited="true" damping="0.5" armature="0.1" stiffness="2"></joint>
    <geom rgba="0.8 0.6 .4 1" margin="0.001"></geom>
    <site size="0.001"></site>
    <tendon width="0.001" rgba=".95 .3 .3 1" limited="false"></tendon>
    <default class="muscle">
      <muscle ctrllimited="true" ctrlrange="0 1" scale="200"></muscle>
    </default>
    <default class="motor">
      <general gainprm="5 0 0 0 0 0 0 0 0 0"></general>
    </default>
  </default>
  <option timestep="0.002"></option>
  <size njmax="1000" nconmax="400" nuser_jnt="1"></size>
  <worldbody>
    <geom name="floor" pos="0 0 0" size="10 10 0.125" type="plane" material="MatPlane" condim="3"></geom>
    <body name="pelvis" pos="       0        0        0" quat="0.7071067811865475 0.7071067811865475 0.0 0.0">
      <light mode="trackcom" directional="false" pos="0 0 4.0" dir="0 0 -1"></light>
      <geom name="r_pelvis" type="mesh" mesh="r_pelvis"></geom>
      <geom name="l_pelvis" type="mesh" mesh="l_pelvis"></geom>
      <geom name="sacrum" type="mesh" mesh="sacrum"></geom>
      <inertial pos="-0.0794968        0        0" mass="10.8674200532449" fullinertia="0.119935 0.101618 0.0675509        0        0        0"></inertial>
      <site name="addbrev_r-P1" pos="-0.0214765 -0.105696 0.0173161"></site>
      <site name="addlong_r-P1" pos="-0.00852314 -0.0999614 0.0212291"></site>
      <site name="addmagDist_r-P1" pos="-0.0832524 -0.143555 0.0447746"></site>
      <site name="addmagIsch_r-P1" pos="-0.100771 -0.145905 0.0468998"></site>
      <site name="addmagMid_r-P1" pos="-0.0592122 -0.135774 0.0320911"></site>
      <site name="addmagProx_r-P1" pos="-0.0348347 -0.120932 0.0153484"></site>
      <site name="bflh_r-P1" pos="-0.11694 -0.133919 0.0658913"></site>
      <site name="glmax1_r-P1" pos="-0.138417 0.0387927 0.0633051"></site>
      <site name="glmax1_r-P2" pos="-0.14134 -0.0272111 0.0875927"></site>
      <site name="glmax2_r-P1" pos="-0.148087 0.0097825 0.0519484"></site>
      <site name="glmax2_r-P2" pos="-0.151123 -0.0684775 0.0914157"></site>
      <site name="glmax3_r-P1" pos="-0.146175 -0.0590323 0.0101198"></site>
      <site name="glmax3_r-P2" pos="-0.143139 -0.142015 0.0489125"></site>
      <site name="glmed1_r-P1" pos="-0.0500369 0.0275484 0.131783"></site>
      <site name="glmed2_r-P1" pos="-0.0955761 0.0355318 0.0758987"></site>
      <site name="glmed3_r-P1" pos="-0.129534 -0.0082083 0.0591447"></site>
      <site name="glmin1_r-P1" pos="-0.0521733 -0.0167539 0.117165"></site>
      <site name="glmin2_r-P1" pos="-0.0692646 -0.0159668 0.109182"></site>
      <site name="glmin3_r-P1" pos="-0.0887171 -0.0174286 0.0897291"></site>
      <site name="grac_r-P1" pos="-0.0532528 -0.145411 0.0276159"></site>
      <site name="iliacus_r-P1" pos="-0.0680277 0.0347447 0.094789"></site>
      <site name="iliacus_r-P2" pos="-0.0151797 -0.0626305 0.0850065"></site>
      <site name="piri_r-P1" pos="-0.114478 -0.00734249 0.015191"></site>
      <site name="piri_r-P2" pos="-0.114714 -0.0344749 0.0685"></site>
      <site name="psoas_r-P1" pos="-0.0681401 0.0697143 0.0438526"></site>
      <site name="psoas_r-P2" pos="-0.0230507 -0.0735374 0.0737623"></site>
      <site name="recfem_r-P1" pos="-0.0269862 -0.0436277 0.104909"></site>
      <site name="sart_r-P1" pos="-0.0219263 -0.017541 0.118739"></site>
      <site name="semimem_r-P1" pos="-0.110981 -0.128184 0.0690397"></site>
      <site name="semiten_r-P1" pos="-0.116715 -0.14089 0.0579079"></site>
      <site name="tfl_r-P1" pos="-0.0349696 0.0240627 0.139541"></site>
      <site name="addbrev_l-P1" pos="-0.0214765 -0.105696 -0.0173161"></site>
      <site name="addlong_l-P1" pos="-0.00852314 -0.0999614 -0.0212291"></site>
      <site name="addmagDist_l-P1" pos="-0.0832524 -0.143555 -0.0447746"></site>
      <site name="addmagIsch_l-P1" pos="-0.100771 -0.145905 -0.0468998"></site>
      <site name="addmagMid_l-P1" pos="-0.0592122 -0.135774 -0.0320911"></site>
      <site name="addmagProx_l-P1" pos="-0.0348347 -0.120932 -0.0153484"></site>
      <site name="bflh_l-P1" pos="-0.11694 -0.133919 -0.0658913"></site>
      <site name="glmax1_l-P1" pos="-0.138417 0.0387927 -0.0633051"></site>
      <site name="glmax1_l-P2" pos="-0.14134 -0.0272111 -0.0875927"></site>
      <site name="glmax2_l-P1" pos="-0.148087 0.0097825 -0.0519484"></site>
      <site name="glmax2_l-P2" pos="-0.151123 -0.0684775 -0.0914157"></site>
      <site name="glmax3_l-P1" pos="-0.146175 -0.0590323 -0.0101198"></site>
      <site name="glmax3_l-P2" pos="-0.143139 -0.142015 -0.0489125"></site>
      <site name="glmed1_l-P1" pos="-0.0500369 0.0275484 -0.131783"></site>
      <site name="glmed2_l-P1" pos="-0.0955761 0.0355318 -0.0758987"></site>
      <site name="glmed3_l-P1" pos="-0.129534 -0.0082083 -0.0591447"></site>
      <site name="glmin1_l-P1" pos="-0.0521733 -0.0167539 -0.117165"></site>
      <site name="glmin2_l-P1" pos="-0.0692646 -0.0159668 -0.109182"></site>
      <site name="glmin3_l-P1" pos="-0.0887171 -0.0174286 -0.0897291"></site>
      <site name="grac_l-P1" pos="-0.0532528 -0.145411 -0.0276159"></site>
      <site name="iliacus_l-P1" pos="-0.0680277 0.0347447 -0.094789"></site>
      <site name="iliacus_l-P2" pos="-0.0151797 -0.0626305 -0.0850065"></site>
      <site name="piri_l-P1" pos="-0.114478 -0.00734249 -0.015191"></site>
      <site name="piri_l-P2" pos="-0.114714 -0.0344749 -0.0685"></site>
      <site name="psoas_l-P1" pos="-0.0681401 0.0697143 -0.0438526"></site>
      <site name="psoas_l-P2" pos="-0.0230507 -0.0735374 -0.0737623"></site>
      <site name="recfem_l-P1" pos="-0.0269862 -0.0436277 -0.104909"></site>
      <site name="sart_l-P1" pos="-0.0219263 -0.017541 -0.118739"></site>
      <site name="semimem_l-P1" pos="-0.110981 -0.128184 -0.0690397"></site>
      <site name="semiten_l-P1" pos="-0.116715 -0.14089 -0.0579079"></site>
      <site name="tfl_l-P1" pos="-0.0349696 0.0240627 -0.139541"></site>
      <joint name="pelvis_tz" type="slide" pos="0 0 0" axis="       0        0        1" limited="false" range="      -3        3" ref="0" armature="0" damping="0" stiffness="0"></joint>
      <joint name="pelvis_ty" type="slide" pos="0 0 0" axis="       0        1        0" limited="false" range="      -1        2" ref="0" armature="0" damping="0" stiffness="0"></joint>
      <joint name="pelvis_tx" type="slide" pos="0 0 0" axis="       1        0        0" limited="false" range="      -5        5" ref="0" armature="0" damping="0" stiffness="0"></joint>
      <joint name="pelvis_tilt" type="hinge" pos="0 0 0" axis="       0        0        1" limited="false" range=" -1.5708   1.5708" ref="0" armature="0" damping="0" stiffness="0"></joint>
      <joint name="pelvis_list" type="hinge" pos="0 0 0" axis="       1        0        0" limited="false" range=" -1.5708   1.5708" ref="0" armature="0" damping="0" stiffness="0"></joint>
      <joint name="pelvis_rotation" type="hinge" pos="0 0 0" axis="       0        1        0" limited="false" range=" -1.5708   1.5708" ref="0" armature="0" damping="0" stiffness="0"></joint>
      <body name="femur_r" pos="-0.0632781 -0.0882561 0.0868731" quat="1.0 0.0 0.0 0.0">
        <geom name="r_femur" type="mesh" mesh="r_femur"></geom>
        <inertial pos="       0 -0.173051        0" mass="6.36831761389899" fullinertia="0.0949965 0.024902 0.100176        0        0        0"></inertial>
        <site name="addbrev_r-P2" pos="-0.00203589 -0.120118 0.0253469"></site>
        <site name="addlong_r-P2" pos="0.0114621 -0.243666 0.0161141"></site>
        <site name="addmagDist_r-P2" pos="0.0114519 -0.267211 0.0196464"></site>
        <site name="addmagIsch_r-P2" pos="0.00489633 -0.394933 -0.0333174"></site>
        <site name="addmagMid_r-P2" pos="0.00246343 -0.165315 0.0297444"></site>
        <site name="addmagProx_r-P2" pos="-0.0155441 -0.0802753 0.0325947"></site>
        <site name="bfsh_r-P1" pos="0.00508974 -0.214889 0.02382"></site>
        <site name="gaslat_r-P1" pos="-0.00305384 -0.388245 0.0281971"></site>
        <site name="gasmed_r-P1" pos="0.00814358 -0.385598 -0.0211733"></site>
        <site name="glmax1_r-P3" pos="-0.0451969 -0.0331851 0.030742"></site>
        <site name="glmax1_r-P4" pos="-0.0281971 -0.0576158 0.0478435"></site>
        <site name="glmax2_r-P3" pos="-0.0458076 -0.0594481 0.0256523"></site>
        <site name="glmax2_r-P4" pos="-0.01588 -0.103423 0.042652"></site>
        <site name="glmax3_r-P3" pos="-0.0286043 -0.114519 0.0095687"></site>
        <site name="glmax3_r-P4" pos="-0.00610768 -0.144447 0.0418376"></site>
        <site name="glmed1_r-P2" pos="-0.0221913 -0.01191 0.0564961"></site>
        <site name="glmed2_r-P2" pos="-0.026263 -0.00590409 0.0536458"></site>
        <site name="glmed3_r-P2" pos="-0.0314546 -0.00478435 0.0527297"></site>
        <site name="glmin1_r-P2" pos="-0.00732922 -0.0105867 0.057005"></site>
        <site name="glmin2_r-P2" pos="-0.00977229 -0.0105867 0.057005"></site>
        <site name="glmin3_r-P2" pos="-0.0137423 -0.00844896 0.0559871"></site>
        <site name="iliacus_r-P3" pos="-0.00234128 -0.057514 0.0141495"></site>
        <site name="iliacus_r-P4" pos="-0.012419 -0.0648432 0.0199518"></site>
        <site name="piri_r-P3" pos="-0.0150656 -0.00366461 0.0444843"></site>
        <site name="psoas_r-P3" pos="-0.0134369 -0.0475381 0.00468256"></site>
        <site name="psoas_r-P4" pos="-0.0239218 -0.0533404 0.00895794"></site>
        <site name="sart_r-P2" pos="-0.00305384 -0.363204 -0.0428556"></site>
        <site name="tfl_r-P2" pos="0.0299276 -0.101286 0.0607715"></site>
        <site name="tfl_r-P3" pos="0.010892 -0.412269 0.0329815"></site>
        <site name="vasint_r-P1" pos="0.0295205 -0.195853 0.0315564"></site>
        <site name="vasint_r-P2" pos="0.0341012 -0.21214 0.0290115"></site>
        <site name="vaslat_r-P1" pos="0.00488615 -0.188727 0.0355264"></site>
        <site name="vaslat_r-P2" pos="0.0273828 -0.26375 0.041634"></site>
        <site name="vasmed_r-P1" pos="0.0142513 -0.213667 0.0191374"></site>
        <site name="vasmed_r-P2" pos="0.0362389 -0.28187 0.000916153"></site>
        <joint name="hip_flexion_r" type="hinge" pos="0 0 0" axis="       0        0        1" limited="false" range="-0.523599   2.0944" ref="0"></joint>
        <joint name="hip_adduction_r" type="hinge" pos="0 0 0" axis="       1        0        0" limited="false" range="-0.872665 0.523599" ref="0"></joint>
        <joint name="hip_rotation_r" type="hinge" pos="0 0 0" axis="       0        1        0" limited="false" range="-0.698132 0.698132" ref="0"></joint>
        <body name="tibia_r" pos="-0.000509914 -0.411906 -0.00138147" quat="1.0 7.240636975890137e-18 -9.456205735995121e-17 -2.960068750797159e-20">
          <geom name="r_tibia" type="mesh" mesh="r_tibia"></geom>
          <geom name="r_fibula" type="mesh" mesh="r_fibula"></geom>
          <inertial pos="       0 -0.178293        0" mass="2.09581418420147" fullinertia="0.0259826 0.00262919 0.0263435        0        0        0"></inertial>
          <site name="bflh_r-P2" pos="-0.0321825 -0.033424 0.0241608"></site>
          <site name="bflh_r-P3" pos="-0.0274077 -0.0434512 0.0289356"></site>
          <site name="bfsh_r-P2" pos="-0.0287446 -0.0400133 0.0303681"></site>
          <site name="edl_r-P1" pos="-0.0152795 -0.11049 0.0195769"></site>
          <site name="edl_r-P2" pos="0.0156615 -0.359069 0.0106957"></site>
          <site name="ehl_r-P1" pos="-0.0133696 -0.148021 0.018049"></site>
          <site name="ehl_r-P2" pos="0.0067803 -0.277801 0.0156615"></site>
          <site name="ehl_r-P3" pos="0.0190994 -0.352671 -0.00267392"></site>
          <site name="fdl_r-P1" pos="-0.00219643 -0.174951 -0.00171895"></site>
          <site name="fdl_r-P2" pos="-0.0168075 -0.348087 -0.0118416"></site>
          <site name="fhl_r-P1" pos="-0.0296041 -0.20656 0.0190994"></site>
          <site name="fhl_r-P2" pos="-0.0231103 -0.35057 -0.00725778"></site>
          <site name="grac_r-P2" pos="-0.0175906 -0.0454089 -0.0282767"></site>
          <site name="grac_r-P3" pos="0.00169985 -0.0664851 -0.0150217"></site>
          <site name="perbrev_r-P1" pos="-0.0232058 -0.241799 0.0239698"></site>
          <site name="perbrev_r-P2" pos="-0.0323735 -0.37177 0.0237788"></site>
          <site name="perbrev_r-P3" pos="-0.0272167 -0.382371 0.0243518"></site>
          <site name="perlong_r-P1" pos="-0.0190994 -0.131118 0.0269302"></site>
          <site name="perlong_r-P2" pos="-0.0302726 -0.372439 0.0226328"></site>
          <site name="perlong_r-P3" pos="-0.0259752 -0.383326 0.0229193"></site>
          <site name="recfem_r-P5" pos="0.0311321 -0.0602778 -0.000448837"></site>
          <site name="sart_r-P3" pos="-0.0239698 -0.0382944 -0.0348565"></site>
          <site name="sart_r-P4" pos="-0.015184 -0.0572028 -0.0252112"></site>
          <site name="sart_r-P5" pos="0.0129876 -0.0773527 -0.00248293"></site>
          <site name="semimem_r-P2" pos="-0.0276942 -0.0398223 -0.0187174"></site>
          <site name="semiten_r-P2" pos="-0.0297951 -0.0485125 -0.0218688"></site>
          <site name="semiten_r-P3" pos="0.00181445 -0.0738193 -0.0111732"></site>
          <site name="soleus_r-P1" pos="-0.00725778 -0.0874754 0.00935872"></site>
          <site name="tfl_r-P4" pos="0.0103137 -0.0391538 0.033042"></site>
          <site name="tibant_r-P1" pos="0.0147066 -0.125292 0.0154705"></site>
          <site name="tibant_r-P2" pos="0.0239698 -0.182018 0.0122236"></site>
          <site name="tibant_r-P3" pos="0.0222508 -0.349424 -0.0126056"></site>
          <site name="tibpost_r-P1" pos="-0.00391538 -0.124528 0.00983621"></site>
          <site name="tibpost_r-P2" pos="-0.0156615 -0.349042 -0.016712"></site>
          <site name="vasint_r-P5" pos="0.0311034 -0.0603542 0.000410638"></site>
          <site name="vaslat_r-P5" pos="0.0310748 -0.0605261 0.0048799"></site>
          <site name="vasmed_r-P5" pos="0.0304636 -0.0607075 -0.00647471"></site>
          <joint name="knee_angle_r_translation2" type="slide" pos="0 0 0" axis="0.992246 0.123982 -0.00878916" limited="true" range="7.69254e-11 0.006792" ref="0"></joint>
          <joint name="knee_angle_r_translation1" type="slide" pos="0 0 0" axis="-0.124293 0.989762 -0.0701648" limited="true" range="9.53733e-08 0.00159883" ref="0"></joint>
          <joint name="knee_angle_r" type="hinge" pos="0 0 0" axis="-3.98373e-10 -0.0707131 -0.997497" limited="false" range="       0   2.0944" ref="0"></joint>
          <joint name="knee_angle_r_rotation2" type="hinge" pos="0 0 0" axis="0.992246 0.123982 -0.00878916" limited="true" range="-0.00167821 0.0335354" ref="0"></joint>
          <joint name="knee_angle_r_rotation3" type="hinge" pos="0 0 0" axis="-0.124293 0.989762 -0.0701648" limited="true" range="1.08939e-08 0.262788" ref="0"></joint>
          <body name="talus_r" pos="-0.00954971 -0.381989        0" quat="1.0 -6.036754011562992e-18 1.5193252867388614e-18 -2.498419531737724e-19">
            <geom name="r_talus" type="mesh" mesh="r_talus"></geom>
            <inertial pos="       0        0        0" mass="0.0310047706469076" fullinertia="0.000189458 0.000189458 0.000189458        0        0        0"></inertial>
            <joint name="ankle_angle_r" type="hinge" pos="0 0 0" axis="-0.105014 -0.174022 0.979126" limited="false" range="-0.698132 0.523599" ref="0"></joint>
            <body name="calcn_r" pos="-0.0381237 -0.0327925 0.0061911" quat="1.0 -5.320429553087796e-19 1.609289071159989e-17 -2.1848634538867752e-17">
              <geom name="r_foot" type="mesh" mesh="r_foot"></geom>
              <inertial pos="0.0781705 0.0234511        0" mass="0.387559633086345" fullinertia="0.000265242 0.000738888 0.000776779        0        0        0"></inertial>
              <site name="edl_r-P3" pos="0.0718387 0.0281414 0.000625364"></site>
              <site name="edl_r-P4" pos="0.126323 0.00429938 0.0101622"></site>
              <site name="ehl_r-P4" pos="0.0758253 0.0304083 -0.016494"></site>
              <site name="ehl_r-P5" pos="0.101074 0.0241547 -0.0200898"></site>
              <site name="ehl_r-P6" pos="0.135548 0.0108657 -0.0218877"></site>
              <site name="fdl_r-P3" pos="0.0340823 0.0246237 -0.0218877"></site>
              <site name="fdl_r-P4" pos="0.0553447 0.013758 -0.0205588"></site>
              <site name="fdl_r-P5" pos="0.129607 -0.00633181 0.00906777"></site>
              <site name="fhl_r-P3" pos="0.0292358 0.021575 -0.0188391"></site>
              <site name="fhl_r-P4" pos="0.0811409 0.00531559 -0.0200116"></site>
              <site name="fhl_r-P5" pos="0.134922 -0.00414303 -0.0210279"></site>
              <site name="gaslat_r-P2" pos="0.0034395 0.0242328 -0.00414303"></site>
              <site name="gasmed_r-P2" pos="0.0034395 0.0242328 -0.00414303"></site>
              <site name="perbrev_r-P4" pos="0.0368183 0.021106 0.0182137"></site>
              <site name="perbrev_r-P5" pos="0.0529214 0.0171193 0.0268125"></site>
              <site name="perlong_r-P4" pos="0.0342387 0.0179792 0.0172757"></site>
              <site name="perlong_r-P5" pos="0.0532341 0.00828607 0.0222004"></site>
              <site name="perlong_r-P6" pos="0.0666012 0.00539376 0.00922411"></site>
              <site name="perlong_r-P7" pos="0.0940391 0.00664449 -0.0143834"></site>
              <site name="soleus_r-P2" pos="0.0034395 0.0242328 -0.00414303"></site>
              <site name="tibant_r-P4" pos="0.0911468 0.0139143 -0.023842"></site>
              <site name="tibpost_r-P3" pos="0.0325971 0.0261089 -0.0223568"></site>
              <site name="tibpost_r-P4" pos="0.0603476 0.0124291 -0.0219659"></site>
              <joint name="subtalar_angle_r" type="hinge" pos="0 0 0" axis=" 0.78718 0.604747 -0.120949" limited="false" range="-0.349066 0.349066" ref="0"></joint>
              <body name="toes_r" pos="0.139769 -0.00156341 0.000844241" quat="1.0 1.314867274624753e-31 -2.6810890689525335e-17 -3.939849802505862e-32">
                <geom name="r_bofoot" type="mesh" mesh="r_bofoot"></geom>
                <inertial pos="0.027047 0.00469023 -0.0136798" mass="0.0671563332212019" fullinertia="1.89458e-05 3.78917e-05 0.000189458        0        0        0"></inertial>
                <site name="edl_r-P5" pos="0.000234511 0.00367401 0.0119601"></site>
                <site name="edl_r-P6" pos="0.0346295 -0.000312682 0.0195426"></site>
                <site name="ehl_r-P7" pos="0.0232948 0.00320499 -0.0191518"></site>
                <site name="ehl_r-P8" pos="0.04401 0.0026578 -0.0145397"></site>
                <site name="fdl_r-P6" pos="-0.00148524 -0.0060973 0.0114911"></site>
                <site name="fdl_r-P7" pos="0.0222786 -0.0055501 0.0168066"></site>
                <site name="fdl_r-P8" pos="0.0344732 -0.00469023 0.0189173"></site>
                <site name="fhl_r-P6" pos="0.0121164 -0.00500291 -0.0207152"></site>
                <site name="fhl_r-P7" pos="0.0439318 -0.00797339 -0.0141489"></site>
                <joint name="mtp_angle_r" type="hinge" pos="0 0 0" axis="0.580954 2.6299e-15 -0.813936" limited="false" range="-0.523599 0.523599" ref="0"></joint>
              </body>
            </body>
          </body>
        </body>
        <body name="patella_r" pos="-0.00823519 -0.415282 -4.9355e-05" quat="1.0 0.0 0.0 0.0">
          <geom name="r_patella" type="mesh" mesh="r_patella"></geom>
          <inertial pos="  0.0018   0.0264        0" mass="0.0559509935357129" fullinertia="1.86287e-06 8.50948e-06 8.50948e-06        0        0        0"></inertial>
          <site name="recfem_r-P2" pos="0.01 0.049 0.0007"></site>
          <site name="recfem_r-P3" pos="0.0121 0.0437 -0.001"></site>
          <site name="recfem_r-P4" pos="0.005 0.00247 3e-005"></site>
          <site name="vasint_r-P3" pos="0.0058 0.048 -0.0006"></site>
          <site name="vasint_r-P4" pos="0.005 0.00247 -0.00039"></site>
          <site name="vaslat_r-P3" pos="0.0103 0.0423 0.0141"></site>
          <site name="vaslat_r-P4" pos="0.005 0.00247 0.00733"></site>
          <site name="vasmed_r-P3" pos="0.0063 0.0445 -0.017"></site>
          <site name="vasmed_r-P4" pos="0.005 0.00247 -0.0085"></site>
          <joint name="knee_angle_r_beta_translation2" type="slide" pos="0 0 0" axis="       0        1        0" limited="true" range="-0.0408267 -0.0108281" ref="0"></joint>
          <joint name="knee_angle_r_beta_translation1" type="slide" pos="0 0 0" axis="       1        0        0" limited="true" range="-0.0227731 0.0524192" ref="0"></joint>
          <joint name="knee_angle_r_beta_rotation1" type="hinge" pos="0 0 0" axis="       0        0        1" limited="true" range="-1.79241 0.010506" ref="0"></joint>
        </body>
      </body>
      <body name="femur_l" pos="-0.0632781 -0.0882561 -0.0868731" quat="1.0 0.0 0.0 0.0">
        <geom name="l_femur" type="mesh" mesh="l_femur"></geom>
        <inertial pos="       0 -0.174098        0" mass="6.48464668571865" fullinertia="0.0979062 0.0256647 0.103244        0        0        0"></inertial>
        <site name="addbrev_l-P2" pos="-0.00204822 -0.120845 -0.0255003"></site>
        <site name="addlong_l-P2" pos="0.0115315 -0.245141 -0.0162116"></site>
        <site name="addmagDist_l-P2" pos="0.0115212 -0.268828 -0.0197653"></site>
        <site name="addmagIsch_l-P2" pos="0.00492596 -0.397323 0.0335191"></site>
        <site name="addmagMid_l-P2" pos="0.00247834 -0.166315 -0.0299244"></site>
        <site name="addmagProx_l-P2" pos="-0.0156381 -0.0807612 -0.0327919"></site>
        <site name="bfsh_l-P1" pos="0.00512054 -0.216189 -0.0239641"></site>
        <site name="gaslat_l-P1" pos="-0.00307232 -0.390595 -0.0283678"></site>
        <site name="gasmed_l-P1" pos="0.00819287 -0.387932 0.0213014"></site>
        <site name="glmax1_l-P3" pos="-0.0454704 -0.0333859 -0.0309281"></site>
        <site name="glmax1_l-P4" pos="-0.0283678 -0.0579645 -0.0481331"></site>
        <site name="glmax2_l-P3" pos="-0.0460849 -0.0598079 -0.0258075"></site>
        <site name="glmax2_l-P4" pos="-0.0159761 -0.104049 -0.0429101"></site>
        <site name="glmax3_l-P3" pos="-0.0287774 -0.115212 -0.00962662"></site>
        <site name="glmax3_l-P4" pos="-0.00614465 -0.145321 -0.0420908"></site>
        <site name="glmed1_l-P2" pos="-0.0223256 -0.0119821 -0.056838"></site>
        <site name="glmed2_l-P2" pos="-0.026422 -0.00593983 -0.0539705"></site>
        <site name="glmed3_l-P2" pos="-0.0316449 -0.00481331 -0.0530488"></site>
        <site name="glmin1_l-P2" pos="-0.00737358 -0.0106507 -0.0573501"></site>
        <site name="glmin2_l-P2" pos="-0.00983144 -0.0106507 -0.0573501"></site>
        <site name="glmin3_l-P2" pos="-0.0138255 -0.0085001 -0.0563259"></site>
        <site name="iliacus_l-P3" pos="-0.00235545 -0.0578621 -0.0142351"></site>
        <site name="iliacus_l-P4" pos="-0.0124941 -0.0652357 -0.0200725"></site>
        <site name="piri_l-P3" pos="-0.0151568 -0.00368679 -0.0447535"></site>
        <site name="psoas_l-P3" pos="-0.0135182 -0.0478259 -0.0047109"></site>
        <site name="psoas_l-P4" pos="-0.0240665 -0.0536633 -0.00901215"></site>
        <site name="sart_l-P2" pos="-0.00307232 -0.365402 0.043115"></site>
        <site name="tfl_l-P2" pos="0.0301088 -0.101899 -0.0611393"></site>
        <site name="tfl_l-P3" pos="0.010958 -0.414764 -0.0331811"></site>
        <site name="vasint_l-P1" pos="0.0296991 -0.197038 -0.0317474"></site>
        <site name="vasint_l-P2" pos="0.0343076 -0.213424 -0.0291871"></site>
        <site name="vaslat_l-P1" pos="0.00491572 -0.18987 -0.0357414"></site>
        <site name="vaslat_l-P2" pos="0.0275485 -0.265346 -0.041886"></site>
        <site name="vasmed_l-P1" pos="0.0143375 -0.21496 -0.0192532"></site>
        <site name="vasmed_l-P2" pos="0.0364582 -0.283576 -0.000921697"></site>
        <joint name="hip_flexion_l" type="hinge" pos="0 0 0" axis="       0        0        1" limited="false" range="-0.523599   2.0944" ref="0"></joint>
        <joint name="hip_adduction_l" type="hinge" pos="0 0 0" axis="      -1       -0       -0" limited="false" range="-0.872665 0.523599" ref="0"></joint>
        <joint name="hip_rotation_l" type="hinge" pos="0 0 0" axis="      -0       -1       -0" limited="false" range="-0.698132 0.698132" ref="0"></joint>
        <body name="tibia_l" pos="-0.000552044 -0.414416 0.001397" quat="1.0 -7.240636975890137e-18 9.456205735995121e-17 -2.960068750797159e-20">
          <geom name="l_tibia" type="mesh" mesh="l_tibia"></geom>
          <geom name="l_fibula" type="mesh" mesh="l_fibula"></geom>
          <inertial pos="       0 -0.178471        0" mass="2.10209646967787" fullinertia="0.0261126 0.00264234 0.0264752        0        0        0"></inertial>
          <site name="bflh_l-P2" pos="-0.0322147 -0.0334574 -0.0241849"></site>
          <site name="bflh_l-P3" pos="-0.027435 -0.0434946 -0.0289645"></site>
          <site name="bfsh_l-P2" pos="-0.0287733 -0.0400532 -0.0303984"></site>
          <site name="edl_l-P1" pos="-0.0152948 -0.1106 -0.0195965"></site>
          <site name="edl_l-P2" pos="0.0156772 -0.359428 -0.0107064"></site>
          <site name="ehl_l-P1" pos="-0.0133829 -0.148168 -0.018067"></site>
          <site name="ehl_l-P2" pos="0.00678706 -0.278078 -0.0156772"></site>
          <site name="ehl_l-P3" pos="0.0191185 -0.353023 0.00267659"></site>
          <site name="fdl_l-P1" pos="-0.00219863 -0.175125 0.00172066"></site>
          <site name="fdl_l-P2" pos="-0.0168243 -0.348435 0.0118535"></site>
          <site name="fhl_l-P1" pos="-0.0296337 -0.206766 -0.0191185"></site>
          <site name="fhl_l-P2" pos="-0.0231334 -0.35092 0.00726503"></site>
          <site name="grac_l-P2" pos="-0.0176081 -0.0454542 0.0283049"></site>
          <site name="grac_l-P3" pos="0.00170155 -0.0665515 0.0150367"></site>
          <site name="perbrev_l-P1" pos="-0.023229 -0.24204 -0.0239937"></site>
          <site name="perbrev_l-P2" pos="-0.0324058 -0.372141 -0.0238025"></site>
          <site name="perbrev_l-P3" pos="-0.0272439 -0.382752 -0.0243761"></site>
          <site name="perlong_l-P1" pos="-0.0191185 -0.131248 -0.0269571"></site>
          <site name="perlong_l-P2" pos="-0.0303028 -0.372811 -0.0226554"></site>
          <site name="perlong_l-P3" pos="-0.0260011 -0.383708 -0.0229422"></site>
          <site name="recfem_l-P5" pos="0.0311631 -0.060338 0.000449285"></site>
          <site name="sart_l-P3" pos="-0.0239937 -0.0383326 0.0348912"></site>
          <site name="sart_l-P4" pos="-0.0151992 -0.0572599 0.0252364"></site>
          <site name="sart_l-P5" pos="0.0130006 -0.0774299 0.0024854"></site>
          <site name="semimem_l-P2" pos="-0.0277218 -0.0398621 0.0187361"></site>
          <site name="semiten_l-P2" pos="-0.0298248 -0.048561 0.0218907"></site>
          <site name="semiten_l-P3" pos="0.00181626 -0.073893 0.0111843"></site>
          <site name="soleus_l-P1" pos="-0.00726503 -0.0875627 -0.00936806"></site>
          <site name="tfl_l-P4" pos="0.010324 -0.0391929 -0.033075"></site>
          <site name="tibant_l-P1" pos="0.0147212 -0.125417 -0.015486"></site>
          <site name="tibant_l-P2" pos="0.0239937 -0.182199 -0.0122358"></site>
          <site name="tibant_l-P3" pos="0.022273 -0.349773 0.0126182"></site>
          <site name="tibpost_l-P1" pos="-0.00391929 -0.124653 -0.00984602"></site>
          <site name="tibpost_l-P2" pos="-0.0156772 -0.34939 0.0167287"></site>
          <site name="vasint_l-P5" pos="0.0311345 -0.0604144 -0.000411048"></site>
          <site name="vaslat_l-P5" pos="0.0311058 -0.0605865 -0.00488477"></site>
          <site name="vasmed_l-P5" pos="0.030494 -0.0607681 0.00648117"></site>
          <joint name="knee_angle_l_translation2" type="slide" pos="0 0 0" axis="-0.992246 -0.123982 -0.00878916" limited="true" range="-0.006792 -7.69254e-11" ref="0"></joint>
          <joint name="knee_angle_l_translation1" type="slide" pos="0 0 0" axis="-0.124293 0.989762 0.0701648" limited="true" range="9.53733e-08 0.00159883" ref="0"></joint>
          <joint name="knee_angle_l" type="hinge" pos="0 0 0" axis="3.98373e-10 0.0707131 -0.997497" limited="false" range="       0   2.0944" ref="0"></joint>
          <joint name="knee_angle_l_rotation2" type="hinge" pos="0 0 0" axis="-0.992246 -0.123982 -0.00878916" limited="true" range="-0.00167821 0.0335354" ref="0"></joint>
          <joint name="knee_angle_l_rotation3" type="hinge" pos="0 0 0" axis="-0.124293 0.989762 0.0701648" limited="true" range="-0.262788 -1.08939e-08" ref="0"></joint>
          <body name="talus_l" pos="-0.00955925 -0.38237        0" quat="1.0 6.036754011562992e-18 -1.5193252867388614e-18 -2.498419531737724e-19">
            <geom name="l_talus" type="mesh" mesh="l_talus"></geom>
            <inertial pos="       0        0        0" mass="0.0309917863495998" fullinertia="0.000189326 0.000189326 0.000189326        0        0        0"></inertial>
            <joint name="ankle_angle_l" type="hinge" pos="0 0 0" axis="0.105014 0.174022 0.979126" limited="false" range="-0.698132 0.523599" ref="0"></joint>
            <body name="calcn_l" pos="-0.0381184 -0.0327879 -0.00619024" quat="1.0 5.320429553087796e-19 -1.609289071159989e-17 -2.1848634538867752e-17">
              <geom name="l_foot" type="mesh" mesh="l_foot"></geom>
              <inertial pos="0.0781595 0.0234479        0" mass="0.387397329369998" fullinertia="0.000265057 0.000738372 0.000776237        0        0        0"></inertial>
              <site name="edl_l-P3" pos="0.0718286 0.0281374 -0.000625276"></site>
              <site name="edl_l-P4" pos="0.126306 0.00429877 -0.0101607"></site>
              <site name="ehl_l-P4" pos="0.0758148 0.0304041 0.0164917"></site>
              <site name="ehl_l-P5" pos="0.10106 0.0241513 0.020087"></site>
              <site name="ehl_l-P6" pos="0.135529 0.0108642 0.0218847"></site>
              <site name="fdl_l-P3" pos="0.0340776 0.0246203 0.0218847"></site>
              <site name="fdl_l-P4" pos="0.055337 0.0137561 0.020556"></site>
              <site name="fdl_l-P5" pos="0.129589 -0.00633092 -0.00906651"></site>
              <site name="fhl_l-P3" pos="0.0292317 0.021572 0.0188365"></site>
              <site name="fhl_l-P4" pos="0.0811296 0.00531485 0.0200088"></site>
              <site name="fhl_l-P5" pos="0.134903 -0.00414246 0.0210249"></site>
              <site name="gaslat_l-P2" pos="0.00343902 0.0242295 0.00414246"></site>
              <site name="gasmed_l-P2" pos="0.00343902 0.0242295 0.00414246"></site>
              <site name="perbrev_l-P4" pos="0.0368131 0.0211031 -0.0182112"></site>
              <site name="perbrev_l-P5" pos="0.052914 0.0171169 -0.0268087"></site>
              <site name="perlong_l-P4" pos="0.0342339 0.0179767 -0.0172733"></site>
              <site name="perlong_l-P5" pos="0.0532267 0.00828491 -0.0221973"></site>
              <site name="perlong_l-P6" pos="0.0665919 0.00539301 -0.00922283"></site>
              <site name="perlong_l-P7" pos="0.0940259 0.00664356 0.0143814"></site>
              <site name="soleus_l-P2" pos="0.00343902 0.0242295 0.00414246"></site>
              <site name="tibant_l-P4" pos="0.091134 0.0139124 0.0238387"></site>
              <site name="tibpost_l-P3" pos="0.0325925 0.0261053 0.0223536"></site>
              <site name="tibpost_l-P4" pos="0.0603392 0.0124274 0.0219628"></site>
              <joint name="subtalar_angle_l" type="hinge" pos="0 0 0" axis="-0.78718 -0.604747 -0.120949" limited="false" range="-0.349066 0.349066" ref="0"></joint>
              <body name="toes_l" pos="0.139749 -0.00156319 -0.000844123" quat="1.0 1.314867274624753e-31 2.6810890689525335e-17 3.939849802505862e-32">
                <geom name="l_bofoot" type="mesh" mesh="l_bofoot"></geom>
                <inertial pos="0.0270432 0.00468957 0.0136779" mass="0.0671282092332332" fullinertia="1.89326e-05 3.78652e-05 0.000189326        0        0        0"></inertial>
                <site name="edl_l-P5" pos="0.000234479 0.0036735 -0.0119584"></site>
                <site name="edl_l-P6" pos="0.0346247 -0.000312638 -0.0195399"></site>
                <site name="ehl_l-P7" pos="0.0232915 0.00320454 0.0191491"></site>
                <site name="ehl_l-P8" pos="0.0440038 0.00265742 0.0145377"></site>
                <site name="fdl_l-P6" pos="-0.00148503 -0.00609644 -0.0114895"></site>
                <site name="fdl_l-P7" pos="0.0222755 -0.00554933 -0.0168043"></site>
                <site name="fdl_l-P8" pos="0.0344684 -0.00468957 -0.0189146"></site>
                <site name="fhl_l-P6" pos="0.0121147 -0.00500221 0.0207123"></site>
                <site name="fhl_l-P7" pos="0.0439257 -0.00797227 0.0141469"></site>
                <joint name="mtp_angle_l" type="hinge" pos="0 0 0" axis="-0.580954 2.6299e-15 -0.813936" limited="false" range="-0.523599 0.523599" ref="0"></joint>
              </body>
            </body>
          </body>
        </body>
        <body name="patella_l" pos="-0.00828503 -0.417795 6.62974e-05" quat="1.0 0.0 0.0 0.0">
          <geom name="l_patella" type="mesh" mesh="l_patella"></geom>
          <inertial pos="  0.0018   0.0264        0" mass="0.0559509935357129" fullinertia="1.86287e-06 8.50948e-06 8.50948e-06        0        0        0"></inertial>
          <site name="recfem_l-P2" pos="0.01 0.049 -0.0007"></site>
          <site name="recfem_l-P3" pos="0.0121 0.0437 0.001"></site>
          <site name="recfem_l-P4" pos="0.005 0.00247 -3e-005"></site>
          <site name="vasint_l-P3" pos="0.0058 0.048 0.0006"></site>
          <site name="vasint_l-P4" pos="0.005 0.00247 0.00039"></site>
          <site name="vaslat_l-P3" pos="0.0103 0.0423 -0.0141"></site>
          <site name="vaslat_l-P4" pos="0.005 0.00247 -0.00733"></site>
          <site name="vasmed_l-P3" pos="0.0063 0.0445 0.017"></site>
          <site name="vasmed_l-P4" pos="0.005 0.00247 0.0085"></site>
          <joint name="knee_angle_l_beta_translation2" type="slide" pos="0 0 0" axis="       0        1        0" limited="true" range="-0.0408267 -0.0108281" ref="0"></joint>
          <joint name="knee_angle_l_beta_translation1" type="slide" pos="0 0 0" axis="       1        0        0" limited="true" range="-0.0227731 0.0524192" ref="0"></joint>
          <joint name="knee_angle_l_beta_rotation1" type="hinge" pos="0 0 0" axis="       0        0        1" limited="true" range="-1.79241 0.010506" ref="0"></joint>
        </body>
      </body>
      <body name="torso" pos="-0.11323 0.0916406        0" quat="1.0 0.0 0.0 0.0">
        <geom name="hat_spine" type="mesh" mesh="hat_spine"></geom>
        <geom name="hat_jaw" type="mesh" mesh="hat_jaw"></geom>
        <geom name="hat_skull" type="mesh" mesh="hat_skull"></geom>
        <geom name="hat_ribs_scap" type="mesh" mesh="hat_ribs_scap"></geom>
        <inertial pos="-0.0269199 0.287146        0" mass="12.5812571348254" fullinertia="0.556812 0.285298 0.540536        0        0        0"></inertial>
        <joint name="lumbar_extension" type="hinge" pos="0 0 0" axis="       0        0        1" limited="false" range=" -1.5708   1.5708" ref="0"></joint>
        <joint name="lumbar_bending" type="hinge" pos="0 0 0" axis="       1        0        0" limited="false" range=" -1.5708   1.5708" ref="0"></joint>
        <joint name="lumbar_rotation" type="hinge" pos="0 0 0" axis="       0        1        0" limited="false" range=" -1.5708   1.5708" ref="0"></joint>
        <body name="humerus_r" pos="0.00283108 0.333358 0.152546" quat="1.0 0.0 0.0 0.0">
          <geom name="humerus_rv" type="mesh" mesh="humerus_rv"></geom>
          <inertial pos="       0 -0.146869        0" mass="0.938881203018804" fullinertia="0.00439868 0.00151741 0.00493738        0        0        0"></inertial>
          <joint name="arm_flex_r" type="hinge" pos="0 0 0" axis="       0        0        1" limited="false" range=" -1.5708   1.5708" ref="0"></joint>
          <joint name="arm_add_r" type="hinge" pos="0 0 0" axis="       1        0        0" limited="false" range=" -2.0944   1.5708" ref="0"></joint>
          <joint name="arm_rot_r" type="hinge" pos="0 0 0" axis="       0        1        0" limited="false" range=" -1.5708   1.5708" ref="0"></joint>
          <body name="ulna_r" pos="0.0117351 -0.255588 -0.00856653" quat="1.0 1.6893809785063376e-18 -6.938893903907228e-18 4.155190089080778e-20">
            <geom name="ulna_rv" type="mesh" mesh="ulna_rv"></geom>
            <inertial pos="       0 -0.124003        0" mass="0.429446232045614" fullinertia="0.00221644 0.000462444 0.00240426        0        0        0"></inertial>
            <joint name="elbow_flex_r" type="hinge" pos="0 0 0" axis="0.226047 0.022269 0.973862" limited="false" range="       0    2.618" ref="0"></joint>
            <body name="radius_r" pos="-0.0069211 -0.0133823 0.0268356" quat="1.0 2.301201592641875e-21 -6.933378131686372e-19 1.7489241099837954e-19">
              <geom name="radius_rv" type="mesh" mesh="radius_rv"></geom>
              <inertial pos="       0 -0.12282        0" mass="0.417278522084315" fullinertia="0.00211276 0.000440813 0.0022918        0        0        0"></inertial>
              <joint name="pro_sup_r" type="hinge" pos="0 0 0" axis="0.056398 0.998406 0.001952" limited="false" range="       0   1.5708" ref="0"></joint>
              <body name="hand_r" pos="-0.00896453 -0.240332 0.0138692" quat="1.0 0.0 8.407790785948892e-45 0.0">
                <geom name="pisiform_rvs" type="mesh" mesh="pisiform_rvs"></geom>
                <geom name="lunate_rvs" type="mesh" mesh="lunate_rvs"></geom>
                <geom name="scaphoid_rvs" type="mesh" mesh="scaphoid_rvs"></geom>
                <geom name="triquetrum_rvs" type="mesh" mesh="triquetrum_rvs"></geom>
                <geom name="hamate_rvs" type="mesh" mesh="hamate_rvs"></geom>
                <geom name="capitate_rvs" type="mesh" mesh="capitate_rvs"></geom>
                <geom name="trapezoid_rvs" type="mesh" mesh="trapezoid_rvs"></geom>
                <geom name="trapezium_rvs" type="mesh" mesh="trapezium_rvs"></geom>
                <geom name="metacarpal2_rvs" type="mesh" mesh="metacarpal2_rvs"></geom>
                <geom name="index_proximal_rvs" type="mesh" mesh="index_proximal_rvs"></geom>
                <geom name="index_medial_rvs" type="mesh" mesh="index_medial_rvs"></geom>
                <geom name="index_distal_rvs" type="mesh" mesh="index_distal_rvs"></geom>
                <geom name="metacarpal3_rvs" type="mesh" mesh="metacarpal3_rvs"></geom>
                <geom name="middle_proximal_rvs" type="mesh" mesh="middle_proximal_rvs"></geom>
                <geom name="middle_medial_rvs" type="mesh" mesh="middle_medial_rvs"></geom>
                <geom name="middle_distal_rvs" type="mesh" mesh="middle_distal_rvs"></geom>
                <geom name="metacarpal4_rvs" type="mesh" mesh="metacarpal4_rvs"></geom>
                <geom name="ring_proximal_rvs" type="mesh" mesh="ring_proximal_rvs"></geom>
                <geom name="ring_medial_rvs" type="mesh" mesh="ring_medial_rvs"></geom>
                <geom name="ring_distal_rvs" type="mesh" mesh="ring_distal_rvs"></geom>
                <geom name="metacarpal5_rvs" type="mesh" mesh="metacarpal5_rvs"></geom>
                <geom name="little_proximal_rvs" type="mesh" mesh="little_proximal_rvs"></geom>
                <geom name="little_medial_rvs" type="mesh" mesh="little_medial_rvs"></geom>
                <geom name="little_distal_rvs" type="mesh" mesh="little_distal_rvs"></geom>
                <geom name="metacarpal1_rvs" type="mesh" mesh="metacarpal1_rvs"></geom>
                <geom name="thumb_proximal_rvs" type="mesh" mesh="thumb_proximal_rvs"></geom>
                <geom name="thumb_distal_rvs" type="mesh" mesh="thumb_distal_rvs"></geom>
                <inertial pos="       0 -0.068095        0" mass="0.29695567914836" fullinertia="0.000578982 0.000355049 0.000869772        0        0        0"></inertial>
                <joint name="wrist_flex_r" type="hinge" pos="0 0 0" axis="-3.55271e-15 3.55271e-15        1" limited="false" range="-1.22173  1.22173" ref="0"></joint>
                <joint name="wrist_dev_r" type="hinge" pos="0 0 0" axis="       1        0 3.55271e-15" limited="false" range="-0.436332 0.610865" ref="0"></joint>
              </body>
            </body>
          </body>
        </body>
        <body name="humerus_l" pos="0.00283108 0.333358 -0.152546" quat="1.0 0.0 0.0 0.0">
          <geom name="humerus_lv" type="mesh" mesh="humerus_lv"></geom>
          <inertial pos="       0 -0.146554        0" mass="0.932852696613108" fullinertia="0.00435171 0.0015012 0.00488465        0        0        0"></inertial>
          <joint name="arm_flex_l" type="hinge" pos="0 0 0" axis="       0        0        1" limited="false" range=" -1.5708   1.5708" ref="0"></joint>
          <joint name="arm_add_l" type="hinge" pos="0 0 0" axis="      -1        0        0" limited="false" range=" -2.0944   1.5708" ref="0"></joint>
          <joint name="arm_rot_l" type="hinge" pos="0 0 0" axis="       0       -1        0" limited="false" range=" -1.5708   1.5708" ref="0"></joint>
          <body name="ulna_l" pos="0.0117099 -0.25504 0.00854815" quat="1.0 -1.6893809785063376e-18 6.938893903907228e-18 4.155190089080778e-20">
            <geom name="ulna_lv" type="mesh" mesh="ulna_lv"></geom>
            <inertial pos="       0 -0.117739        0" mass="0.367603859486934" fullinertia="0.00171044 0.000356871 0.00185538        0        0        0"></inertial>
            <joint name="elbow_flex_l" type="hinge" pos="0 0 0" axis="-0.226047 -0.022269 0.973862" limited="false" range="       0    2.618" ref="0"></joint>
            <body name="radius_l" pos="-0.00657152 -0.0127064 -0.0254801" quat="1.0 -2.301201592641875e-21 6.933378131686372e-19 1.7489241099837954e-19">
              <geom name="radius_lv" type="mesh" mesh="radius_lv"></geom>
              <inertial pos="       0 -0.120964        0" mass="0.398644889619542" fullinertia="0.00195787 0.000408496 0.00212378        0        0        0"></inertial>
              <joint name="pro_sup_l" type="hinge" pos="0 0 0" axis="-0.056398 -0.998406 0.001952" limited="false" range="       0   1.5708" ref="0"></joint>
              <body name="hand_l" pos="-0.00882906  -0.2367 -0.0136596" quat="1.0 0.0 8.407790785948892e-45 0.0">
                <geom name="pisiform_lvs" type="mesh" mesh="pisiform_lvs"></geom>
                <geom name="lunate_lvs" type="mesh" mesh="lunate_lvs"></geom>
                <geom name="scaphoid_lvs" type="mesh" mesh="scaphoid_lvs"></geom>
                <geom name="triquetrum_lvs" type="mesh" mesh="triquetrum_lvs"></geom>
                <geom name="hamate_lvs" type="mesh" mesh="hamate_lvs"></geom>
                <geom name="capitate_lvs" type="mesh" mesh="capitate_lvs"></geom>
                <geom name="trapezoid_lvs" type="mesh" mesh="trapezoid_lvs"></geom>
                <geom name="trapezium_lvs" type="mesh" mesh="trapezium_lvs"></geom>
                <geom name="metacarpal2_lvs" type="mesh" mesh="metacarpal2_lvs"></geom>
                <geom name="index_proximal_lvs" type="mesh" mesh="index_proximal_lvs"></geom>
                <geom name="index_medial_lvs" type="mesh" mesh="index_medial_lvs"></geom>
                <geom name="index_distal_lvs" type="mesh" mesh="index_distal_lvs"></geom>
                <geom name="metacarpal3_lvs" type="mesh" mesh="metacarpal3_lvs"></geom>
                <geom name="middle_proximal_lvs" type="mesh" mesh="middle_proximal_lvs"></geom>
                <geom name="middle_medial_lvs" type="mesh" mesh="middle_medial_lvs"></geom>
                <geom name="middle_distal_lvs" type="mesh" mesh="middle_distal_lvs"></geom>
                <geom name="metacarpal4_lvs" type="mesh" mesh="metacarpal4_lvs"></geom>
                <geom name="ring_proximal_lvs" type="mesh" mesh="ring_proximal_lvs"></geom>
                <geom name="ring_medial_lvs" type="mesh" mesh="ring_medial_lvs"></geom>
                <geom name="ring_distal_lvs" type="mesh" mesh="ring_distal_lvs"></geom>
                <geom name="metacarpal5_lvs" type="mesh" mesh="metacarpal5_lvs"></geom>
                <geom name="little_proximal_lvs" type="mesh" mesh="little_proximal_lvs"></geom>
                <geom name="little_medial_lvs" type="mesh" mesh="little_medial_lvs"></geom>
                <geom name="little_distal_lvs" type="mesh" mesh="little_distal_lvs"></geom>
                <geom name="metacarpal1_lvs" type="mesh" mesh="metacarpal1_lvs"></geom>
                <geom name="thumb_proximal_lvs" type="mesh" mesh="thumb_proximal_lvs"></geom>
                <geom name="thumb_distal_lvs" type="mesh" mesh="thumb_distal_lvs"></geom>
                <inertial pos="       0 -0.068095        0" mass="0.29695567914836" fullinertia="0.000578982 0.000355049 0.000869772        0        0        0"></inertial>
                <joint name="wrist_flex_l" type="hinge" pos="0 0 0" axis="-3.55271e-15 -3.55271e-15        1" limited="false" range="-1.22173  1.22173" ref="0"></joint>
                <joint name="wrist_dev_l" type="hinge" pos="0 0 0" axis="      -1        0 -3.55271e-15" limited="false" range="-0.436332 0.610865" ref="0"></joint>
              </body>
            </body>
          </body>
        </body>
      </body>
    </body>
    <camera name="for_testing" pos="0 0 0" euler="0 0 0"></camera>
  </worldbody>
  <asset>
    <mesh name="r_pelvis" file="Geometry/r_pelvis.stl" scale=" 1.12442  1.12442  1.12442"></mesh>
    <mesh name="l_pelvis" file="Geometry/l_pelvis.stl" scale=" 1.12442  1.12442  1.12442"></mesh>
    <mesh name="sacrum" file="Geometry/sacrum.stl" scale=" 1.12442  1.12442  1.12442"></mesh>
    <mesh name="r_femur" file="Geometry/r_femur.stl" scale=" 1.01795  1.01795  1.01795"></mesh>
    <mesh name="r_tibia" file="Geometry/r_tibia.stl" scale="0.954971 0.954971 0.954971"></mesh>
    <mesh name="r_fibula" file="Geometry/r_fibula.stl" scale="0.954971 0.954971 0.954971"></mesh>
    <mesh name="r_talus" file="Geometry/r_talus.stl" scale="0.781705 0.781705 0.781705"></mesh>
    <mesh name="r_foot" file="Geometry/r_foot.stl" scale="0.781705 0.781705 0.781705"></mesh>
    <mesh name="r_bofoot" file="Geometry/r_bofoot.stl" scale="0.781705 0.781705 0.781705"></mesh>
    <mesh name="r_patella" file="Geometry/r_patella.stl" scale="       1        1        1"></mesh>
    <mesh name="l_femur" file="Geometry/l_femur.stl" scale=" 1.02411  1.02411  1.02411"></mesh>
    <mesh name="l_tibia" file="Geometry/l_tibia.stl" scale="0.955925 0.955925 0.955925"></mesh>
    <mesh name="l_fibula" file="Geometry/l_fibula.stl" scale="0.955925 0.955925 0.955925"></mesh>
    <mesh name="l_talus" file="Geometry/l_talus.stl" scale="0.781595 0.781595 0.781595"></mesh>
    <mesh name="l_foot" file="Geometry/l_foot.stl" scale="0.781595 0.781595 0.781595"></mesh>
    <mesh name="l_bofoot" file="Geometry/l_bofoot.stl" scale="0.781595 0.781595 0.781595"></mesh>
    <mesh name="l_patella" file="Geometry/l_patella.stl" scale="       1        1        1"></mesh>
    <mesh name="hat_spine" file="Geometry/hat_spine.stl" scale="0.897331 0.897331 0.897331"></mesh>
    <mesh name="hat_jaw" file="Geometry/hat_jaw.stl" scale="0.897331 0.897331 0.897331"></mesh>
    <mesh name="hat_skull" file="Geometry/hat_skull.stl" scale="0.897331 0.897331 0.897331"></mesh>
    <mesh name="hat_ribs_scap" file="Geometry/hat_ribs_scap.stl" scale="0.897331 0.897331 0.897331"></mesh>
    <mesh name="humerus_rv" file="Geometry/humerus_rv.stl" scale="0.892812 0.892812 0.892812"></mesh>
    <mesh name="ulna_rv" file="Geometry/ulna_rv.stl" scale=" 1.02885  1.02885  1.02885"></mesh>
    <mesh name="radius_rv" file="Geometry/radius_rv.stl" scale=" 1.01904  1.01904  1.01904"></mesh>
    <mesh name="pisiform_rvs" file="Geometry/pisiform_rvs.stl" scale="    0.85     0.85     0.85"></mesh>
    <mesh name="lunate_rvs" file="Geometry/lunate_rvs.stl" scale="    0.85     0.85     0.85"></mesh>
    <mesh name="scaphoid_rvs" file="Geometry/scaphoid_rvs.stl" scale="    0.85     0.85     0.85"></mesh>
    <mesh name="triquetrum_rvs" file="Geometry/triquetrum_rvs.stl" scale="    0.85     0.85     0.85"></mesh>
    <mesh name="hamate_rvs" file="Geometry/hamate_rvs.stl" scale="    0.85     0.85     0.85"></mesh>
    <mesh name="capitate_rvs" file="Geometry/capitate_rvs.stl" scale="    0.85     0.85     0.85"></mesh>
    <mesh name="trapezoid_rvs" file="Geometry/trapezoid_rvs.stl" scale="    0.85     0.85     0.85"></mesh>
    <mesh name="trapezium_rvs" file="Geometry/trapezium_rvs.stl" scale="    0.85     0.85     0.85"></mesh>
    <mesh name="metacarpal2_rvs" file="Geometry/metacarpal2_rvs.stl" scale="    0.85     0.85     0.85"></mesh>
    <mesh name="index_proximal_rvs" file="Geometry/index_proximal_rvs.stl" scale="    0.85     0.85     0.85"></mesh>
    <mesh name="index_medial_rvs" file="Geometry/index_medial_rvs.stl" scale="    0.85     0.85     0.85"></mesh>
    <mesh name="index_distal_rvs" file="Geometry/index_distal_rvs.stl" scale="    0.85     0.85     0.85"></mesh>
    <mesh name="metacarpal3_rvs" file="Geometry/metacarpal3_rvs.stl" scale="    0.85     0.85     0.85"></mesh>
    <mesh name="middle_proximal_rvs" file="Geometry/middle_proximal_rvs.stl" scale="    0.85     0.85     0.85"></mesh>
    <mesh name="middle_medial_rvs" file="Geometry/middle_medial_rvs.stl" scale="    0.85     0.85     0.85"></mesh>
    <mesh name="middle_distal_rvs" file="Geometry/middle_distal_rvs.stl" scale="    0.85     0.85     0.85"></mesh>
    <mesh name="metacarpal4_rvs" file="Geometry/metacarpal4_rvs.stl" scale="    0.85     0.85     0.85"></mesh>
    <mesh name="ring_proximal_rvs" file="Geometry/ring_proximal_rvs.stl" scale="    0.85     0.85     0.85"></mesh>
    <mesh name="ring_medial_rvs" file="Geometry/ring_medial_rvs.stl" scale="    0.85     0.85     0.85"></mesh>
    <mesh name="ring_distal_rvs" file="Geometry/ring_distal_rvs.stl" scale="    0.85     0.85     0.85"></mesh>
    <mesh name="metacarpal5_rvs" file="Geometry/metacarpal5_rvs.stl" scale="    0.85     0.85     0.85"></mesh>
    <mesh name="little_proximal_rvs" file="Geometry/little_proximal_rvs.stl" scale="    0.85     0.85     0.85"></mesh>
    <mesh name="little_medial_rvs" file="Geometry/little_medial_rvs.stl" scale="    0.85     0.85     0.85"></mesh>
    <mesh name="little_distal_rvs" file="Geometry/little_distal_rvs.stl" scale="    0.85     0.85     0.85"></mesh>
    <mesh name="metacarpal1_rvs" file="Geometry/metacarpal1_rvs.stl" scale="    0.85     0.85     0.85"></mesh>
    <mesh name="thumb_proximal_rvs" file="Geometry/thumb_proximal_rvs.stl" scale="    0.85     0.85     0.85"></mesh>
    <mesh name="thumb_distal_rvs" file="Geometry/thumb_distal_rvs.stl" scale="    0.85     0.85     0.85"></mesh>
    <mesh name="humerus_lv" file="Geometry/humerus_lv.stl" scale="0.890897 0.890897 0.890897"></mesh>
    <mesh name="ulna_lv" file="Geometry/ulna_lv.stl" scale="0.976887 0.976887 0.976887"></mesh>
    <mesh name="radius_lv" file="Geometry/radius_lv.stl" scale=" 1.00364  1.00364  1.00364"></mesh>
    <mesh name="pisiform_lvs" file="Geometry/pisiform_lvs.stl" scale="    0.85     0.85     0.85"></mesh>
    <mesh name="lunate_lvs" file="Geometry/lunate_lvs.stl" scale="    0.85     0.85     0.85"></mesh>
    <mesh name="scaphoid_lvs" file="Geometry/scaphoid_lvs.stl" scale="    0.85     0.85     0.85"></mesh>
    <mesh name="triquetrum_lvs" file="Geometry/triquetrum_lvs.stl" scale="    0.85     0.85     0.85"></mesh>
    <mesh name="hamate_lvs" file="Geometry/hamate_lvs.stl" scale="    0.85     0.85     0.85"></mesh>
    <mesh name="capitate_lvs" file="Geometry/capitate_lvs.stl" scale="    0.85     0.85     0.85"></mesh>
    <mesh name="trapezoid_lvs" file="Geometry/trapezoid_lvs.stl" scale="    0.85     0.85     0.85"></mesh>
    <mesh name="trapezium_lvs" file="Geometry/trapezium_lvs.stl" scale="    0.85     0.85     0.85"></mesh>
    <mesh name="metacarpal2_lvs" file="Geometry/metacarpal2_lvs.stl" scale="    0.85     0.85     0.85"></mesh>
    <mesh name="index_proximal_lvs" file="Geometry/index_proximal_lvs.stl" scale="    0.85     0.85     0.85"></mesh>
    <mesh name="index_medial_lvs" file="Geometry/index_medial_lvs.stl" scale="    0.85     0.85     0.85"></mesh>
    <mesh name="index_distal_lvs" file="Geometry/index_distal_lvs.stl" scale="    0.85     0.85     0.85"></mesh>
    <mesh name="metacarpal3_lvs" file="Geometry/metacarpal3_lvs.stl" scale="    0.85     0.85     0.85"></mesh>
    <mesh name="middle_proximal_lvs" file="Geometry/middle_proximal_lvs.stl" scale="    0.85     0.85     0.85"></mesh>
    <mesh name="middle_medial_lvs" file="Geometry/middle_medial_lvs.stl" scale="    0.85     0.85     0.85"></mesh>
    <mesh name="middle_distal_lvs" file="Geometry/middle_distal_lvs.stl" scale="    0.85     0.85     0.85"></mesh>
    <mesh name="metacarpal4_lvs" file="Geometry/metacarpal4_lvs.stl" scale="    0.85     0.85     0.85"></mesh>
    <mesh name="ring_proximal_lvs" file="Geometry/ring_proximal_lvs.stl" scale="    0.85     0.85     0.85"></mesh>
    <mesh name="ring_medial_lvs" file="Geometry/ring_medial_lvs.stl" scale="    0.85     0.85     0.85"></mesh>
    <mesh name="ring_distal_lvs" file="Geometry/ring_distal_lvs.stl" scale="    0.85     0.85     0.85"></mesh>
    <mesh name="metacarpal5_lvs" file="Geometry/metacarpal5_lvs.stl" scale="    0.85     0.85     0.85"></mesh>
    <mesh name="little_proximal_lvs" file="Geometry/little_proximal_lvs.stl" scale="    0.85     0.85     0.85"></mesh>
    <mesh name="little_medial_lvs" file="Geometry/little_medial_lvs.stl" scale="    0.85     0.85     0.85"></mesh>
    <mesh name="little_distal_lvs" file="Geometry/little_distal_lvs.stl" scale="    0.85     0.85     0.85"></mesh>
    <mesh name="metacarpal1_lvs" file="Geometry/metacarpal1_lvs.stl" scale="    0.85     0.85     0.85"></mesh>
    <mesh name="thumb_proximal_lvs" file="Geometry/thumb_proximal_lvs.stl" scale="    0.85     0.85     0.85"></mesh>
    <mesh name="thumb_distal_lvs" file="Geometry/thumb_distal_lvs.stl" scale="    0.85     0.85     0.85"></mesh>
    <texture name="texplane" type="2d" builtin="checker" rgb1=".2 .3 .4" rgb2=".1 0.15 0.2" width="100" height="100"></texture>
    <material name="MatPlane" reflectance="0.0" texture="texplane" texrepeat="1 1" texuniform="true"></material>
  </asset>
  <tendon>
    <spatial name="addbrev_r_tendon">
      <site site="addbrev_r-P1"></site>
      <site site="addbrev_r-P2"></site>
    </spatial>
    <spatial name="addlong_r_tendon">
      <site site="addlong_r-P1"></site>
      <site site="addlong_r-P2"></site>
    </spatial>
    <spatial name="addmagDist_r_tendon">
      <site site="addmagDist_r-P1"></site>
      <site site="addmagDist_r-P2"></site>
    </spatial>
    <spatial name="addmagIsch_r_tendon">
      <site site="addmagIsch_r-P1"></site>
      <site site="addmagIsch_r-P2"></site>
    </spatial>
    <spatial name="addmagMid_r_tendon">
      <site site="addmagMid_r-P1"></site>
      <site site="addmagMid_r-P2"></site>
    </spatial>
    <spatial name="addmagProx_r_tendon">
      <site site="addmagProx_r-P1"></site>
      <site site="addmagProx_r-P2"></site>
    </spatial>
    <spatial name="bflh_r_tendon">
      <site site="bflh_r-P1"></site>
      <site site="bflh_r-P2"></site>
      <site site="bflh_r-P3"></site>
    </spatial>
    <spatial name="bfsh_r_tendon">
      <site site="bfsh_r-P1"></site>
      <site site="bfsh_r-P2"></site>
    </spatial>
    <spatial name="edl_r_tendon">
      <site site="edl_r-P1"></site>
      <site site="edl_r-P2"></site>
      <site site="edl_r-P3"></site>
      <site site="edl_r-P4"></site>
      <site site="edl_r-P5"></site>
      <site site="edl_r-P6"></site>
    </spatial>
    <spatial name="ehl_r_tendon">
      <site site="ehl_r-P1"></site>
      <site site="ehl_r-P2"></site>
      <site site="ehl_r-P3"></site>
      <site site="ehl_r-P4"></site>
      <site site="ehl_r-P5"></site>
      <site site="ehl_r-P6"></site>
      <site site="ehl_r-P7"></site>
      <site site="ehl_r-P8"></site>
    </spatial>
    <spatial name="fdl_r_tendon">
      <site site="fdl_r-P1"></site>
      <site site="fdl_r-P2"></site>
      <site site="fdl_r-P3"></site>
      <site site="fdl_r-P4"></site>
      <site site="fdl_r-P5"></site>
      <site site="fdl_r-P6"></site>
      <site site="fdl_r-P7"></site>
      <site site="fdl_r-P8"></site>
    </spatial>
    <spatial name="fhl_r_tendon">
      <site site="fhl_r-P1"></site>
      <site site="fhl_r-P2"></site>
      <site site="fhl_r-P3"></site>
      <site site="fhl_r-P4"></site>
      <site site="fhl_r-P5"></site>
      <site site="fhl_r-P6"></site>
      <site site="fhl_r-P7"></site>
    </spatial>
    <spatial name="gaslat_r_tendon">
      <site site="gaslat_r-P1"></site>
      <site site="gaslat_r-P2"></site>
    </spatial>
    <spatial name="gasmed_r_tendon">
      <site site="gasmed_r-P1"></site>
      <site site="gasmed_r-P2"></site>
    </spatial>
    <spatial name="glmax1_r_tendon">
      <site site="glmax1_r-P1"></site>
      <site site="glmax1_r-P2"></site>
      <site site="glmax1_r-P3"></site>
      <site site="glmax1_r-P4"></site>
    </spatial>
    <spatial name="glmax2_r_tendon">
      <site site="glmax2_r-P1"></site>
      <site site="glmax2_r-P2"></site>
      <site site="glmax2_r-P3"></site>
      <site site="glmax2_r-P4"></site>
    </spatial>
    <spatial name="glmax3_r_tendon">
      <site site="glmax3_r-P1"></site>
      <site site="glmax3_r-P2"></site>
      <site site="glmax3_r-P3"></site>
      <site site="glmax3_r-P4"></site>
    </spatial>
    <spatial name="glmed1_r_tendon">
      <site site="glmed1_r-P1"></site>
      <site site="glmed1_r-P2"></site>
    </spatial>
    <spatial name="glmed2_r_tendon">
      <site site="glmed2_r-P1"></site>
      <site site="glmed2_r-P2"></site>
    </spatial>
    <spatial name="glmed3_r_tendon">
      <site site="glmed3_r-P1"></site>
      <site site="glmed3_r-P2"></site>
    </spatial>
    <spatial name="glmin1_r_tendon">
      <site site="glmin1_r-P1"></site>
      <site site="glmin1_r-P2"></site>
    </spatial>
    <spatial name="glmin2_r_tendon">
      <site site="glmin2_r-P1"></site>
      <site site="glmin2_r-P2"></site>
    </spatial>
    <spatial name="glmin3_r_tendon">
      <site site="glmin3_r-P1"></site>
      <site site="glmin3_r-P2"></site>
    </spatial>
    <spatial name="grac_r_tendon">
      <site site="grac_r-P1"></site>
      <site site="grac_r-P2"></site>
      <site site="grac_r-P3"></site>
    </spatial>
    <spatial name="iliacus_r_tendon">
      <site site="iliacus_r-P1"></site>
      <site site="iliacus_r-P2"></site>
      <site site="iliacus_r-P3"></site>
      <site site="iliacus_r-P4"></site>
    </spatial>
    <spatial name="perbrev_r_tendon">
      <site site="perbrev_r-P1"></site>
      <site site="perbrev_r-P2"></site>
      <site site="perbrev_r-P3"></site>
      <site site="perbrev_r-P4"></site>
      <site site="perbrev_r-P5"></site>
    </spatial>
    <spatial name="perlong_r_tendon">
      <site site="perlong_r-P1"></site>
      <site site="perlong_r-P2"></site>
      <site site="perlong_r-P3"></site>
      <site site="perlong_r-P4"></site>
      <site site="perlong_r-P5"></site>
      <site site="perlong_r-P6"></site>
      <site site="perlong_r-P7"></site>
    </spatial>
    <spatial name="piri_r_tendon">
      <site site="piri_r-P1"></site>
      <site site="piri_r-P2"></site>
      <site site="piri_r-P3"></site>
    </spatial>
    <spatial name="psoas_r_tendon">
      <site site="psoas_r-P1"></site>
      <site site="psoas_r-P2"></site>
      <site site="psoas_r-P3"></site>
      <site site="psoas_r-P4"></site>
    </spatial>
    <spatial name="recfem_r_tendon">
      <site site="recfem_r-P1"></site>
      <site site="recfem_r-P2"></site>
      <site site="recfem_r-P3"></site>
      <site site="recfem_r-P4"></site>
      <site site="recfem_r-P5"></site>
    </spatial>
    <spatial name="sart_r_tendon">
      <site site="sart_r-P1"></site>
      <site site="sart_r-P2"></site>
      <site site="sart_r-P3"></site>
      <site site="sart_r-P4"></site>
      <site site="sart_r-P5"></site>
    </spatial>
    <spatial name="semimem_r_tendon">
      <site site="semimem_r-P1"></site>
      <site site="semimem_r-P2"></site>
    </spatial>
    <spatial name="semiten_r_tendon">
      <site site="semiten_r-P1"></site>
      <site site="semiten_r-P2"></site>
      <site site="semiten_r-P3"></site>
    </spatial>
    <spatial name="soleus_r_tendon">
      <site site="soleus_r-P1"></site>
      <site site="soleus_r-P2"></site>
    </spatial>
    <spatial name="tfl_r_tendon">
      <site site="tfl_r-P1"></site>
      <site site="tfl_r-P2"></site>
      <site site="tfl_r-P3"></site>
      <site site="tfl_r-P4"></site>
    </spatial>
    <spatial name="tibant_r_tendon">
      <site site="tibant_r-P1"></site>
      <site site="tibant_r-P2"></site>
      <site site="tibant_r-P3"></site>
      <site site="tibant_r-P4"></site>
    </spatial>
    <spatial name="tibpost_r_tendon">
      <site site="tibpost_r-P1"></site>
      <site site="tibpost_r-P2"></site>
      <site site="tibpost_r-P3"></site>
      <site site="tibpost_r-P4"></site>
    </spatial>
    <spatial name="vasint_r_tendon">
      <site site="vasint_r-P1"></site>
      <site site="vasint_r-P2"></site>
      <site site="vasint_r-P3"></site>
      <site site="vasint_r-P4"></site>
      <site site="vasint_r-P5"></site>
    </spatial>
    <spatial name="vaslat_r_tendon">
      <site site="vaslat_r-P1"></site>
      <site site="vaslat_r-P2"></site>
      <site site="vaslat_r-P3"></site>
      <site site="vaslat_r-P4"></site>
      <site site="vaslat_r-P5"></site>
    </spatial>
    <spatial name="vasmed_r_tendon">
      <site site="vasmed_r-P1"></site>
      <site site="vasmed_r-P2"></site>
      <site site="vasmed_r-P3"></site>
      <site site="vasmed_r-P4"></site>
      <site site="vasmed_r-P5"></site>
    </spatial>
    <spatial name="addbrev_l_tendon">
      <site site="addbrev_l-P1"></site>
      <site site="addbrev_l-P2"></site>
    </spatial>
    <spatial name="addlong_l_tendon">
      <site site="addlong_l-P1"></site>
      <site site="addlong_l-P2"></site>
    </spatial>
    <spatial name="addmagDist_l_tendon">
      <site site="addmagDist_l-P1"></site>
      <site site="addmagDist_l-P2"></site>
    </spatial>
    <spatial name="addmagIsch_l_tendon">
      <site site="addmagIsch_l-P1"></site>
      <site site="addmagIsch_l-P2"></site>
    </spatial>
    <spatial name="addmagMid_l_tendon">
      <site site="addmagMid_l-P1"></site>
      <site site="addmagMid_l-P2"></site>
    </spatial>
    <spatial name="addmagProx_l_tendon">
      <site site="addmagProx_l-P1"></site>
      <site site="addmagProx_l-P2"></site>
    </spatial>
    <spatial name="bflh_l_tendon">
      <site site="bflh_l-P1"></site>
      <site site="bflh_l-P2"></site>
      <site site="bflh_l-P3"></site>
    </spatial>
    <spatial name="bfsh_l_tendon">
      <site site="bfsh_l-P1"></site>
      <site site="bfsh_l-P2"></site>
    </spatial>
    <spatial name="edl_l_tendon">
      <site site="edl_l-P1"></site>
      <site site="edl_l-P2"></site>
      <site site="edl_l-P3"></site>
      <site site="edl_l-P4"></site>
      <site site="edl_l-P5"></site>
      <site site="edl_l-P6"></site>
    </spatial>
    <spatial name="ehl_l_tendon">
      <site site="ehl_l-P1"></site>
      <site site="ehl_l-P2"></site>
      <site site="ehl_l-P3"></site>
      <site site="ehl_l-P4"></site>
      <site site="ehl_l-P5"></site>
      <site site="ehl_l-P6"></site>
      <site site="ehl_l-P7"></site>
      <site site="ehl_l-P8"></site>
    </spatial>
    <spatial name="fdl_l_tendon">
      <site site="fdl_l-P1"></site>
      <site site="fdl_l-P2"></site>
      <site site="fdl_l-P3"></site>
      <site site="fdl_l-P4"></site>
      <site site="fdl_l-P5"></site>
      <site site="fdl_l-P6"></site>
      <site site="fdl_l-P7"></site>
      <site site="fdl_l-P8"></site>
    </spatial>
    <spatial name="fhl_l_tendon">
      <site site="fhl_l-P1"></site>
      <site site="fhl_l-P2"></site>
      <site site="fhl_l-P3"></site>
      <site site="fhl_l-P4"></site>
      <site site="fhl_l-P5"></site>
      <site site="fhl_l-P6"></site>
      <site site="fhl_l-P7"></site>
    </spatial>
    <spatial name="gaslat_l_tendon">
      <site site="gaslat_l-P1"></site>
      <site site="gaslat_l-P2"></site>
    </spatial>
    <spatial name="gasmed_l_tendon">
      <site site="gasmed_l-P1"></site>
      <site site="gasmed_l-P2"></site>
    </spatial>
    <spatial name="glmax1_l_tendon">
      <site site="glmax1_l-P1"></site>
      <site site="glmax1_l-P2"></site>
      <site site="glmax1_l-P3"></site>
      <site site="glmax1_l-P4"></site>
    </spatial>
    <spatial name="glmax2_l_tendon">
      <site site="glmax2_l-P1"></site>
      <site site="glmax2_l-P2"></site>
      <site site="glmax2_l-P3"></site>
      <site site="glmax2_l-P4"></site>
    </spatial>
    <spatial name="glmax3_l_tendon">
      <site site="glmax3_l-P1"></site>
      <site site="glmax3_l-P2"></site>
      <site site="glmax3_l-P3"></site>
      <site site="glmax3_l-P4"></site>
    </spatial>
    <spatial name="glmed1_l_tendon">
      <site site="glmed1_l-P1"></site>
      <site site="glmed1_l-P2"></site>
    </spatial>
    <spatial name="glmed2_l_tendon">
      <site site="glmed2_l-P1"></site>
      <site site="glmed2_l-P2"></site>
    </spatial>
    <spatial name="glmed3_l_tendon">
      <site site="glmed3_l-P1"></site>
      <site site="glmed3_l-P2"></site>
    </spatial>
    <spatial name="glmin1_l_tendon">
      <site site="glmin1_l-P1"></site>
      <site site="glmin1_l-P2"></site>
    </spatial>
    <spatial name="glmin2_l_tendon">
      <site site="glmin2_l-P1"></site>
      <site site="glmin2_l-P2"></site>
    </spatial>
    <spatial name="glmin3_l_tendon">
      <site site="glmin3_l-P1"></site>
      <site site="glmin3_l-P2"></site>
    </spatial>
    <spatial name="grac_l_tendon">
      <site site="grac_l-P1"></site>
      <site site="grac_l-P2"></site>
      <site site="grac_l-P3"></site>
    </spatial>
    <spatial name="iliacus_l_tendon">
      <site site="iliacus_l-P1"></site>
      <site site="iliacus_l-P2"></site>
      <site site="iliacus_l-P3"></site>
      <site site="iliacus_l-P4"></site>
    </spatial>
    <spatial name="perbrev_l_tendon">
      <site site="perbrev_l-P1"></site>
      <site site="perbrev_l-P2"></site>
      <site site="perbrev_l-P3"></site>
      <site site="perbrev_l-P4"></site>
      <site site="perbrev_l-P5"></site>
    </spatial>
    <spatial name="perlong_l_tendon">
      <site site="perlong_l-P1"></site>
      <site site="perlong_l-P2"></site>
      <site site="perlong_l-P3"></site>
      <site site="perlong_l-P4"></site>
      <site site="perlong_l-P5"></site>
      <site site="perlong_l-P6"></site>
      <site site="perlong_l-P7"></site>
    </spatial>
    <spatial name="piri_l_tendon">
      <site site="piri_l-P1"></site>
      <site site="piri_l-P2"></site>
      <site site="piri_l-P3"></site>
    </spatial>
    <spatial name="psoas_l_tendon">
      <site site="psoas_l-P1"></site>
      <site site="psoas_l-P2"></site>
      <site site="psoas_l-P3"></site>
      <site site="psoas_l-P4"></site>
    </spatial>
    <spatial name="recfem_l_tendon">
      <site site="recfem_l-P1"></site>
      <site site="recfem_l-P2"></site>
      <site site="recfem_l-P3"></site>
      <site site="recfem_l-P4"></site>
      <site site="recfem_l-P5"></site>
    </spatial>
    <spatial name="sart_l_tendon">
      <site site="sart_l-P1"></site>
      <site site="sart_l-P2"></site>
      <site site="sart_l-P3"></site>
      <site site="sart_l-P4"></site>
      <site site="sart_l-P5"></site>
    </spatial>
    <spatial name="semimem_l_tendon">
      <site site="semimem_l-P1"></site>
      <site site="semimem_l-P2"></site>
    </spatial>
    <spatial name="semiten_l_tendon">
      <site site="semiten_l-P1"></site>
      <site site="semiten_l-P2"></site>
      <site site="semiten_l-P3"></site>
    </spatial>
    <spatial name="soleus_l_tendon">
      <site site="soleus_l-P1"></site>
      <site site="soleus_l-P2"></site>
    </spatial>
    <spatial name="tfl_l_tendon">
      <site site="tfl_l-P1"></site>
      <site site="tfl_l-P2"></site>
      <site site="tfl_l-P3"></site>
      <site site="tfl_l-P4"></site>
    </spatial>
    <spatial name="tibant_l_tendon">
      <site site="tibant_l-P1"></site>
      <site site="tibant_l-P2"></site>
      <site site="tibant_l-P3"></site>
      <site site="tibant_l-P4"></site>
    </spatial>
    <spatial name="tibpost_l_tendon">
      <site site="tibpost_l-P1"></site>
      <site site="tibpost_l-P2"></site>
      <site site="tibpost_l-P3"></site>
      <site site="tibpost_l-P4"></site>
    </spatial>
    <spatial name="vasint_l_tendon">
      <site site="vasint_l-P1"></site>
      <site site="vasint_l-P2"></site>
      <site site="vasint_l-P3"></site>
      <site site="vasint_l-P4"></site>
      <site site="vasint_l-P5"></site>
    </spatial>
    <spatial name="vaslat_l_tendon">
      <site site="vaslat_l-P1"></site>
      <site site="vaslat_l-P2"></site>
      <site site="vaslat_l-P3"></site>
      <site site="vaslat_l-P4"></site>
      <site site="vaslat_l-P5"></site>
    </spatial>
    <spatial name="vasmed_l_tendon">
      <site site="vasmed_l-P1"></site>
      <site site="vasmed_l-P2"></site>
      <site site="vasmed_l-P3"></site>
      <site site="vasmed_l-P4"></site>
      <site site="vasmed_l-P5"></site>
    </spatial>
  </tendon>
  <actuator>
    <general name="lumbar_ext" joint="lumbar_extension" class="motor"></general>
    <general name="lumbar_bend" joint="lumbar_bending" class="motor"></general>
    <general name="lumbar_rot" joint="lumbar_rotation" class="motor"></general>
    <general name="shoulder_flex_r" joint="arm_flex_r" class="motor"></general>
    <general name="shoulder_add_r" joint="arm_add_r" class="motor"></general>
    <general name="shoulder_rot_r" joint="arm_rot_r" class="motor"></general>
    <general name="elbow_flex_r" joint="elbow_flex_r" class="motor"></general>
    <general name="pro_sup_r" joint="pro_sup_r" class="motor"></general>
    <general name="wrist_flex_r" joint="wrist_flex_r" class="motor"></general>
    <general name="wrist_dev_r" joint="wrist_dev_r" class="motor"></general>
    <general name="shoulder_flex_l" joint="arm_flex_l" class="motor"></general>
    <general name="shoulder_add_l" joint="arm_add_l" class="motor"></general>
    <general name="shoulder_rot_l" joint="arm_rot_l" class="motor"></general>
    <general name="elbow_flex_l" joint="elbow_flex_l" class="motor"></general>
    <general name="pro_sup_l" joint="pro_sup_l" class="motor"></general>
    <general name="wrist_flex_l" joint="wrist_flex_l" class="motor"></general>
    <general name="wrist_dev_l" joint="wrist_dev_l" class="motor"></general>
    <muscle name="addbrev_r" tendon="addbrev_r_tendon" class="muscle" force="625.819672131148" lengthrange="0.0907788 0.198067"></muscle>
    <muscle name="addlong_r" tendon="addlong_r_tendon" class="muscle" force="916.8" lengthrange="0.190093 0.299988"></muscle>
    <muscle name="addmagDist_r" tendon="addmagDist_r_tendon" class="muscle" force="597.295081967214" lengthrange="0.174525 0.348595"></muscle>
    <muscle name="addmagIsch_r" tendon="addmagIsch_r_tendon" class="muscle" force="597.295081967214" lengthrange="0.294299   0.4488"></muscle>
    <muscle name="addmagMid_r" tendon="addmagMid_r_tendon" class="muscle" force="597.295081967214" lengthrange="0.115411 0.251827"></muscle>
    <muscle name="addmagProx_r" tendon="addmagProx_r_tendon" class="muscle" force="597.295081967214" lengthrange="0.0963592 0.203287"></muscle>
    <muscle name="bflh_r" tendon="bflh_r_tendon" class="muscle" force="1313.18360655738" lengthrange="0.373898 0.470153"></muscle>
    <muscle name="bfsh_r" tendon="bfsh_r_tendon" class="muscle" force="557.11475409836" lengthrange=" 0.16014 0.267339"></muscle>
    <muscle name="edl_r" tendon="edl_r_tendon" class="muscle" force="603.4981556" lengthrange="0.358723  0.41899"></muscle>
    <muscle name="ehl_r" tendon="ehl_r_tendon" class="muscle" force="285.8675474" lengthrange="0.320762 0.385493"></muscle>
    <muscle name="fdl_r" tendon="fdl_r_tendon" class="muscle" force="423.177049180328" lengthrange="0.348488 0.386318"></muscle>
    <muscle name="fhl_r" tendon="fhl_r_tendon" class="muscle" force="907.839344262294" lengthrange="0.327135 0.371023"></muscle>
    <muscle name="gaslat_r" tendon="gaslat_r_tendon" class="muscle" force="1575.05901639344" lengthrange="0.386398 0.441286"></muscle>
    <muscle name="gasmed_r" tendon="gasmed_r_tendon" class="muscle" force="3115.51475409836" lengthrange=" 0.40531  0.45341"></muscle>
    <muscle name="glmax1_r" tendon="glmax1_r_tendon" class="muscle" force="983.783606557378" lengthrange="0.128536 0.279009"></muscle>
    <muscle name="glmax2_r" tendon="glmax2_r_tendon" class="muscle" force="1406.04590163935" lengthrange="0.152313 0.310425"></muscle>
    <muscle name="glmax3_r" tendon="glmax3_r_tendon" class="muscle" force="947.754098360656" lengthrange=" 0.15714 0.322557"></muscle>
    <muscle name="glmed1_r" tendon="glmed1_r_tendon" class="muscle" force="1093.4667688" lengthrange="0.0999142 0.176501"></muscle>
    <muscle name="glmed2_r" tendon="glmed2_r_tendon" class="muscle" force="765.0916616" lengthrange="0.110061 0.186463"></muscle>
    <muscle name="glmed3_r" tendon="glmed3_r_tendon" class="muscle" force="871.1992642" lengthrange="0.087583 0.163608"></muscle>
    <muscle name="glmin1_r" tendon="glmin1_r_tendon" class="muscle" force="374.045901639344" lengthrange="0.053873 0.126578"></muscle>
    <muscle name="glmin2_r" tendon="glmin2_r_tendon" class="muscle" force="394.819672131148" lengthrange="0.0585475 0.119152"></muscle>
    <muscle name="glmin3_r" tendon="glmin3_r_tendon" class="muscle" force="446.773770491804" lengthrange="0.0754977 0.116552"></muscle>
    <muscle name="grac_r" tendon="grac_r_tendon" class="muscle" force="281.311475409836" lengthrange="0.282857  0.50621"></muscle>
    <muscle name="iliacus_r" tendon="iliacus_r_tendon" class="muscle" force="1021.14098360656" lengthrange="0.161321 0.273489"></muscle>
    <muscle name="perbrev_r" tendon="perbrev_r_tendon" class="muscle" force="521.2015988" lengthrange="0.156736 0.197776"></muscle>
    <muscle name="perlong_r" tendon="perlong_r_tendon" class="muscle" force="1115.3714214" lengthrange="0.322411 0.366905"></muscle>
    <muscle name="piri_r" tendon="piri_r_tendon" class="muscle" force="1029.7868852459" lengthrange=" 0.14095  0.16921"></muscle>
    <muscle name="psoas_r" tendon="psoas_r_tendon" class="muscle" force="1426.79016393443" lengthrange="0.172194 0.297728"></muscle>
    <muscle name="recfem_r" tendon="recfem_r_tendon" class="muscle" force="2191.74098360656" lengthrange="0.495603 0.571256"></muscle>
    <muscle name="sart_r" tendon="sart_r_tendon" class="muscle" force="249.413114754098" lengthrange="0.331745 0.742423"></muscle>
    <muscle name="semimem_r" tendon="semimem_r_tendon" class="muscle" force="2200.9868852459" lengthrange=" 0.38218 0.449167"></muscle>
    <muscle name="semiten_r" tendon="semiten_r_tendon" class="muscle" force="591.295081967214" lengthrange="0.339059 0.525454"></muscle>
    <muscle name="soleus_r" tendon="soleus_r_tendon" class="muscle" force="6194.84262295082" lengthrange="0.281131 0.319764"></muscle>
    <muscle name="tfl_r" tendon="tfl_r_tendon" class="muscle" force="411.20655737705" lengthrange="0.513107 0.611065"></muscle>
    <muscle name="tibant_r" tendon="tibant_r_tendon" class="muscle" force="1227.45245901639" lengthrange="0.253201 0.315126"></muscle>
    <muscle name="tibpost_r" tendon="tibpost_r_tendon" class="muscle" force="1730.15409836065" lengthrange=" 0.27782 0.312023"></muscle>
    <muscle name="vasint_r" tendon="vasint_r_tendon" class="muscle" force="1697.36065573771" lengthrange="0.253859 0.353786"></muscle>
    <muscle name="vaslat_r" tendon="vaslat_r_tendon" class="muscle" force="5148.76721311476" lengthrange="0.271078 0.368162"></muscle>
    <muscle name="vasmed_r" tendon="vasmed_r_tendon" class="muscle" force="2747.82295081966" lengthrange=" 0.24591 0.334881"></muscle>
    <muscle name="addbrev_l" tendon="addbrev_l_tendon" class="muscle" force="625.819672131148" lengthrange="0.0911588 0.198896"></muscle>
    <muscle name="addlong_l" tendon="addlong_l_tendon" class="muscle" force="916.8" lengthrange="0.191149 0.301656"></muscle>
    <muscle name="addmagDist_l" tendon="addmagDist_l_tendon" class="muscle" force="597.295081967214" lengthrange="0.175764 0.351069"></muscle>
    <muscle name="addmagIsch_l" tendon="addmagIsch_l_tendon" class="muscle" force="597.295081967214" lengthrange="0.296353 0.451933"></muscle>
    <muscle name="addmagMid_l" tendon="addmagMid_l_tendon" class="muscle" force="597.295081967214" lengthrange="0.116143 0.253423"></muscle>
    <muscle name="addmagProx_l" tendon="addmagProx_l_tendon" class="muscle" force="597.295081967214" lengthrange="0.0966706 0.203944"></muscle>
    <muscle name="bflh_l" tendon="bflh_l_tendon" class="muscle" force="1313.18360655738" lengthrange="0.376183 0.473026"></muscle>
    <muscle name="bfsh_l" tendon="bfsh_l_tendon" class="muscle" force="557.11475409836" lengthrange="0.160974 0.268732"></muscle>
    <muscle name="edl_l" tendon="edl_l_tendon" class="muscle" force="603.4981556" lengthrange="0.358952 0.419257"></muscle>
    <muscle name="ehl_l" tendon="ehl_l_tendon" class="muscle" force="285.8675474" lengthrange="0.320951  0.38572"></muscle>
    <muscle name="fdl_l" tendon="fdl_l_tendon" class="muscle" force="423.177049180328" lengthrange="0.348662 0.386511"></muscle>
    <muscle name="fhl_l" tendon="fhl_l_tendon" class="muscle" force="907.839344262294" lengthrange="0.327279 0.371186"></muscle>
    <muscle name="gaslat_l" tendon="gaslat_l_tendon" class="muscle" force="1575.05901639344" lengthrange=" 0.38689 0.441848"></muscle>
    <muscle name="gasmed_l" tendon="gasmed_l_tendon" class="muscle" force="3115.51475409836" lengthrange="0.405875 0.454041"></muscle>
    <muscle name="glmax1_l" tendon="glmax1_l_tendon" class="muscle" force="983.783606557378" lengthrange="0.128756 0.279486"></muscle>
    <muscle name="glmax2_l" tendon="glmax2_l_tendon" class="muscle" force="1406.04590163935" lengthrange="0.152673 0.311159"></muscle>
    <muscle name="glmax3_l" tendon="glmax3_l_tendon" class="muscle" force="947.754098360656" lengthrange="0.157604 0.323509"></muscle>
    <muscle name="glmed1_l" tendon="glmed1_l_tendon" class="muscle" force="1093.4667688" lengthrange="0.100016  0.17668"></muscle>
    <muscle name="glmed2_l" tendon="glmed2_l_tendon" class="muscle" force="765.0916616" lengthrange=" 0.11019 0.186682"></muscle>
    <muscle name="glmed3_l" tendon="glmed3_l_tendon" class="muscle" force="871.1992642" lengthrange="0.0877099 0.163845"></muscle>
    <muscle name="glmin1_l" tendon="glmin1_l_tendon" class="muscle" force="374.045901639344" lengthrange="0.053979 0.126827"></muscle>
    <muscle name="glmin2_l" tendon="glmin2_l_tendon" class="muscle" force="394.819672131148" lengthrange="0.0586746 0.119411"></muscle>
    <muscle name="glmin3_l" tendon="glmin3_l_tendon" class="muscle" force="446.773770491804" lengthrange="0.0756702 0.116819"></muscle>
    <muscle name="grac_l" tendon="grac_l_tendon" class="muscle" force="281.311475409836" lengthrange="0.284527 0.509197"></muscle>
    <muscle name="iliacus_l" tendon="iliacus_l_tendon" class="muscle" force="1021.14098360656" lengthrange="0.161566 0.273905"></muscle>
    <muscle name="perbrev_l" tendon="perbrev_l_tendon" class="muscle" force="521.2015988" lengthrange="0.156869 0.197943"></muscle>
    <muscle name="perlong_l" tendon="perlong_l_tendon" class="muscle" force="1115.3714214" lengthrange="0.322642 0.367169"></muscle>
    <muscle name="piri_l" tendon="piri_l_tendon" class="muscle" force="1029.7868852459" lengthrange="0.141099 0.169388"></muscle>
    <muscle name="psoas_l" tendon="psoas_l_tendon" class="muscle" force="1426.79016393443" lengthrange="0.172419 0.298117"></muscle>
    <muscle name="recfem_l" tendon="recfem_l_tendon" class="muscle" force="2191.74098360656" lengthrange="0.498149 0.574192"></muscle>
    <muscle name="sart_l" tendon="sart_l_tendon" class="muscle" force="249.413114754098" lengthrange="0.333207 0.745696"></muscle>
    <muscle name="semimem_l" tendon="semimem_l_tendon" class="muscle" force="2200.9868852459" lengthrange="0.384537 0.451938"></muscle>
    <muscle name="semiten_l" tendon="semiten_l_tendon" class="muscle" force="591.295081967214" lengthrange="0.341009 0.528475"></muscle>
    <muscle name="soleus_l" tendon="soleus_l_tendon" class="muscle" force="6194.84262295082" lengthrange="0.281399 0.320069"></muscle>
    <muscle name="tfl_l" tendon="tfl_l_tendon" class="muscle" force="411.20655737705" lengthrange="0.515453 0.613858"></muscle>
    <muscle name="tibant_l" tendon="tibant_l_tendon" class="muscle" force="1227.45245901639" lengthrange="0.253414 0.315391"></muscle>
    <muscle name="tibpost_l" tendon="tibpost_l_tendon" class="muscle" force="1730.15409836065" lengthrange="0.278058  0.31229"></muscle>
    <muscle name="vasint_l" tendon="vasint_l_tendon" class="muscle" force="1697.36065573771" lengthrange="0.255205 0.355662"></muscle>
    <muscle name="vaslat_l" tendon="vaslat_l_tendon" class="muscle" force="5148.76721311476" lengthrange="0.272521 0.370121"></muscle>
    <muscle name="vasmed_l" tendon="vasmed_l_tendon" class="muscle" force="2747.82295081966" lengthrange="0.247182 0.336612"></muscle>
  </actuator>
  <equality>
    <joint name="knee_angle_r_translation2_constraint" active="true" joint1="knee_angle_r_translation2" joint2="knee_angle_r" polycoef="7.69254e-11 0.00587971 -0.00125622 -2.61846e-06 6.24355e-07" solimp="0.9999 0.9999 0.001 0.5 2"></joint>
    <joint name="knee_angle_r_translation1_constraint" active="true" joint1="knee_angle_r_translation1" joint2="knee_angle_r" polycoef="9.53733e-08 0.00312879 -0.00230804 0.000561561 5.68366e-07" solimp="0.9999 0.9999 0.001 0.5 2"></joint>
    <joint name="knee_angle_r_rotation2_constraint" active="true" joint1="knee_angle_r_rotation2" joint2="knee_angle_r" polycoef="-1.47325e-08   0.0791 -0.0328478 -0.0252183 0.0108321" solimp="0.9999 0.9999 0.001 0.5 2"></joint>
    <joint name="knee_angle_r_rotation3_constraint" active="true" joint1="knee_angle_r_rotation3" joint2="knee_angle_r" polycoef="1.08939e-08 0.369499 -0.169478 0.0251643 3.50498e-07" solimp="0.9999 0.9999 0.001 0.5 2"></joint>
    <joint name="knee_angle_r_beta_translation2_constraint" active="true" joint1="knee_angle_r_beta_translation2" joint2="knee_angle_r" polycoef="-0.0108281 -0.0487847 0.00927644 0.0131673 -0.00349673" solimp="0.9999 0.9999 0.001 0.5 2"></joint>
    <joint name="knee_angle_r_beta_translation1_constraint" active="true" joint1="knee_angle_r_beta_translation1" joint2="knee_angle_r" polycoef="0.0524192 -0.0150188 -0.0340522 0.0133393 -0.000879151" solimp="0.9999 0.9999 0.001 0.5 2"></joint>
    <joint name="knee_angle_r_beta_rotation1_constraint" active="true" joint1="knee_angle_r_beta_rotation1" joint2="knee_angle_r" polycoef="0.010506 0.0247615 -1.31647 0.716337 -0.138302" solimp="0.9999 0.9999 0.001 0.5 2"></joint>
    <joint name="subtalar_angle_r_constraint" active="true" joint1="subtalar_angle_r" polycoef="       0        0        0        0        0"></joint>
    <joint name="mtp_angle_r_constraint" active="true" joint1="mtp_angle_r" polycoef="       0        0        0        0        0"></joint>
    <joint name="knee_angle_l_translation2_constraint" active="true" joint1="knee_angle_l_translation2" joint2="knee_angle_l" polycoef="-7.69254e-11 -0.00587971 0.00125622 2.61846e-06 -6.24355e-07" solimp="0.9999 0.9999 0.001 0.5 2"></joint>
    <joint name="knee_angle_l_translation1_constraint" active="true" joint1="knee_angle_l_translation1" joint2="knee_angle_l" polycoef="9.53733e-08 0.00312879 -0.00230804 0.000561561 5.68366e-07" solimp="0.9999 0.9999 0.001 0.5 2"></joint>
    <joint name="knee_angle_l_rotation2_constraint" active="true" joint1="knee_angle_l_rotation2" joint2="knee_angle_l" polycoef="-1.47325e-08   0.0791 -0.0328478 -0.0252183 0.0108321" solimp="0.9999 0.9999 0.001 0.5 2"></joint>
    <joint name="knee_angle_l_rotation3_constraint" active="true" joint1="knee_angle_l_rotation3" joint2="knee_angle_l" polycoef="-1.08939e-08 -0.369499 0.169478 -0.0251643 -3.50498e-07" solimp="0.9999 0.9999 0.001 0.5 2"></joint>
    <joint name="knee_angle_l_beta_translation2_constraint" active="true" joint1="knee_angle_l_beta_translation2" joint2="knee_angle_l" polycoef="-0.0108281 -0.0487847 0.00927644 0.0131673 -0.00349673" solimp="0.9999 0.9999 0.001 0.5 2"></joint>
    <joint name="knee_angle_l_beta_translation1_constraint" active="true" joint1="knee_angle_l_beta_translation1" joint2="knee_angle_l" polycoef="0.0524192 -0.0150188 -0.0340522 0.0133393 -0.000879151" solimp="0.9999 0.9999 0.001 0.5 2"></joint>
    <joint name="knee_angle_l_beta_rotation1_constraint" active="true" joint1="knee_angle_l_beta_rotation1" joint2="knee_angle_l" polycoef="0.010506 0.0247615 -1.31647 0.716337 -0.138302" solimp="0.9999 0.9999 0.001 0.5 2"></joint>
    <joint name="subtalar_angle_l_constraint" active="true" joint1="subtalar_angle_l" polycoef="       0        0        0        0        0"></joint>
    <joint name="mtp_angle_l_constraint" active="true" joint1="mtp_angle_l" polycoef="       0        0        0        0        0"></joint>
    <joint name="wrist_flex_r_constraint" active="true" joint1="wrist_flex_r" polycoef="       0        0        0        0        0"></joint>
    <joint name="wrist_dev_r_constraint" active="true" joint1="wrist_dev_r" polycoef="       0        0        0        0        0"></joint>
    <joint name="wrist_flex_l_constraint" active="true" joint1="wrist_flex_l" polycoef="       0        0        0        0        0"></joint>
    <joint name="wrist_dev_l_constraint" active="true" joint1="wrist_dev_l" polycoef="       0        0        0        0        0"></joint>
    <weld name="origin_to_worldbody" body1="pelvis" active="false"></weld>
  </equality>
</mujoco>