<mujoco model="SN009_MSK">
  <compiler inertiafromgeom="auto" angle="radian" balanceinertia="true" boundmass="0.001" boundinertia="0.001">
    <lengthrange inttotal="50" useexisting="true" />
  </compiler>
  <default>
    <joint limited="true" damping="0.5" armature="0.1" stiffness="2" />
    <geom rgba="0.8 0.6 .4 1" margin="0.001" />
    <site size="0.001" />
    <tendon width="0.001" rgba=".95 .3 .3 1" limited="false" />
    <default class="muscle">
      <muscle ctrllimited="true" ctrlrange="0 1" scale="200" />
    </default>
    <default class="motor">
      <general gainprm="5 0 0 0 0 0 0 0 0 0" />
    </default>
  </default>
  <option timestep="0.002" />
  <worldbody>
    <geom name="floor" pos="0 0 0" size="10 10 0.125" type="plane" material="MatPlane" condim="3" />
    <body name="pelvis" pos="       0        0        0" quat="0.7071067811865475 0.7071067811865475 0.0 0.0">
      <light mode="trackcom" directional="false" pos="0 0 4.0" dir="0 0 -1" />
      <geom name="r_pelvis" type="mesh" mesh="r_pelvis" />
      <geom name="l_pelvis" type="mesh" mesh="l_pelvis" />
      <geom name="sacrum" type="mesh" mesh="sacrum" />
      <inertial pos="-0.0870299        0        0" mass="8.285185234347" fullinertia="0.077768 0.077768 0.0617226        0        0        0" />
      <site name="addbrev_r-P1" pos="-0.0235116 -0.115712 0.0146329" />
      <site name="addlong_r-P1" pos="-0.00933079 -0.109434 0.0179395" />
      <site name="addmagDist_r-P1" pos="-0.0911414 -0.157159 0.0378364" />
      <site name="addmagIsch_r-P1" pos="-0.11032 -0.159731 0.0396323" />
      <site name="addmagMid_r-P1" pos="-0.0648231 -0.14864 0.0271183" />
      <site name="addmagProx_r-P1" pos="-0.0381356 -0.132391 0.01297" />
      <site name="bflh_r-P1" pos="-0.128021 -0.146609 0.0556809" />
      <site name="glmax1_r-P1" pos="-0.151533 0.0424686 0.0534955" />
      <site name="glmax1_r-P2" pos="-0.154734 -0.0297896 0.0740195" />
      <site name="glmax2_r-P1" pos="-0.162119 0.0107095 0.0438986" />
      <site name="glmax2_r-P2" pos="-0.165443 -0.0749664 0.0772501" />
      <site name="glmax3_r-P1" pos="-0.160027 -0.0646262 0.00855167" />
      <site name="glmax3_r-P2" pos="-0.156703 -0.155472 0.0413331" />
      <site name="glmed1_r-P1" pos="-0.0547784 0.0301589 0.111362" />
      <site name="glmed2_r-P1" pos="-0.104633 0.0388988 0.0641376" />
      <site name="glmed3_r-P1" pos="-0.141808 -0.00898612 0.0499798" />
      <site name="glmin1_r-P1" pos="-0.0571172 -0.0183415 0.0990094" />
      <site name="glmin2_r-P1" pos="-0.075828 -0.0174798 0.0922631" />
      <site name="glmin3_r-P1" pos="-0.0971239 -0.0190801 0.0758248" />
      <site name="grac_r-P1" pos="-0.058299 -0.15919 0.0233366" />
      <site name="iliacus_r-P1" pos="-0.074474 0.0380371 0.0801007" />
      <site name="iliacus_r-P2" pos="-0.0166182 -0.0685653 0.0718341" />
      <site name="piri_r-P1" pos="-0.125326 -0.00803826 0.012837" />
      <site name="piri_r-P2" pos="-0.125584 -0.0377417 0.0578853" />
      <site name="psoas_r-P1" pos="-0.0745971 0.0763204 0.0370573" />
      <site name="psoas_r-P2" pos="-0.025235 -0.0805057 0.0623322" />
      <site name="recfem_r-P1" pos="-0.0295434 -0.0477618 0.0886523" />
      <site name="sart_r-P1" pos="-0.024004 -0.0192032 0.10034" />
      <site name="semimem_r-P1" pos="-0.121497 -0.140331 0.0583414" />
      <site name="semiten_r-P1" pos="-0.127775 -0.154241 0.0489346" />
      <site name="tfl_r-P1" pos="-0.0382833 0.0263429 0.117918" />
      <site name="addbrev_l-P1" pos="-0.0235116 -0.115712 -0.0146329" />
      <site name="addlong_l-P1" pos="-0.00933079 -0.109434 -0.0179395" />
      <site name="addmagDist_l-P1" pos="-0.0911414 -0.157159 -0.0378364" />
      <site name="addmagIsch_l-P1" pos="-0.11032 -0.159731 -0.0396323" />
      <site name="addmagMid_l-P1" pos="-0.0648231 -0.14864 -0.0271183" />
      <site name="addmagProx_l-P1" pos="-0.0381356 -0.132391 -0.01297" />
      <site name="bflh_l-P1" pos="-0.128021 -0.146609 -0.0556809" />
      <site name="glmax1_l-P1" pos="-0.151533 0.0424686 -0.0534955" />
      <site name="glmax1_l-P2" pos="-0.154734 -0.0297896 -0.0740195" />
      <site name="glmax2_l-P1" pos="-0.162119 0.0107095 -0.0438986" />
      <site name="glmax2_l-P2" pos="-0.165443 -0.0749664 -0.0772501" />
      <site name="glmax3_l-P1" pos="-0.160027 -0.0646262 -0.00855167" />
      <site name="glmax3_l-P2" pos="-0.156703 -0.155472 -0.0413331" />
      <site name="glmed1_l-P1" pos="-0.0547784 0.0301589 -0.111362" />
      <site name="glmed2_l-P1" pos="-0.104633 0.0388988 -0.0641376" />
      <site name="glmed3_l-P1" pos="-0.141808 -0.00898612 -0.0499798" />
      <site name="glmin1_l-P1" pos="-0.0571172 -0.0183415 -0.0990094" />
      <site name="glmin2_l-P1" pos="-0.075828 -0.0174798 -0.0922631" />
      <site name="glmin3_l-P1" pos="-0.0971239 -0.0190801 -0.0758248" />
      <site name="grac_l-P1" pos="-0.058299 -0.15919 -0.0233366" />
      <site name="iliacus_l-P1" pos="-0.074474 0.0380371 -0.0801007" />
      <site name="iliacus_l-P2" pos="-0.0166182 -0.0685653 -0.0718341" />
      <site name="piri_l-P1" pos="-0.125326 -0.00803826 -0.012837" />
      <site name="piri_l-P2" pos="-0.125584 -0.0377417 -0.0578853" />
      <site name="psoas_l-P1" pos="-0.0745971 0.0763204 -0.0370573" />
      <site name="psoas_l-P2" pos="-0.025235 -0.0805057 -0.0623322" />
      <site name="recfem_l-P1" pos="-0.0295434 -0.0477618 -0.0886523" />
      <site name="sart_l-P1" pos="-0.024004 -0.0192032 -0.10034" />
      <site name="semimem_l-P1" pos="-0.121497 -0.140331 -0.0583414" />
      <site name="semiten_l-P1" pos="-0.127775 -0.154241 -0.0489346" />
      <site name="tfl_l-P1" pos="-0.0382833 0.0263429 -0.117918" />
      <joint name="pelvis_tz" type="slide" pos="0 0 0" axis="       0        0        1" limited="false" range="      -3        3" ref="0" armature="0" damping="0" stiffness="0" />
      <joint name="pelvis_ty" type="slide" pos="0 0 0" axis="       0        1        0" limited="false" range="      -1        2" ref="0" armature="0" damping="0" stiffness="0" />
      <joint name="pelvis_tx" type="slide" pos="0 0 0" axis="       1        0        0" limited="false" range="      -5        5" ref="0" armature="0" damping="0" stiffness="0" />
      <joint name="pelvis_tilt" type="hinge" pos="0 0 0" axis="       0        0        1" limited="false" range=" -1.5708   1.5708" ref="0" armature="0" damping="0" stiffness="0" />
      <joint name="pelvis_list" type="hinge" pos="0 0 0" axis="       1        0        0" limited="false" range=" -1.5708   1.5708" ref="0" armature="0" damping="0" stiffness="0" />
      <joint name="pelvis_rotation" type="hinge" pos="0 0 0" axis="       0        1        0" limited="false" range=" -1.5708   1.5708" ref="0" armature="0" damping="0" stiffness="0" />
      <body name="femur_r" pos="-0.0692743 -0.0966192 0.0734114" quat="1.0 0.0 0.0 0.0">
        <geom name="r_femur" type="mesh" mesh="r_femur" />
        <inertial pos="       0 -0.149733        0" mass="6.54358681657088" fullinertia="0.0730775 0.0191562 0.0770616        0        0        0" />
        <site name="addbrev_r-P2" pos="-0.00176156 -0.103932 0.0219314" />
        <site name="addlong_r-P2" pos="0.00991759 -0.210832 0.0139428" />
        <site name="addmagDist_r-P2" pos="0.00990878 -0.231205 0.0169991" />
        <site name="addmagIsch_r-P2" pos="0.00423656 -0.341716 -0.028828" />
        <site name="addmagMid_r-P2" pos="0.00213149 -0.143039 0.0257364" />
        <site name="addmagProx_r-P2" pos="-0.0134495 -0.0694584 0.0282026" />
        <site name="bfsh_r-P1" pos="0.0044039 -0.185933 0.0206103" />
        <site name="gaslat_r-P1" pos="-0.00264234 -0.33593 0.0243976" />
        <site name="gasmed_r-P1" pos="0.00704625 -0.33364 -0.0183202" />
        <site name="glmax1_r-P3" pos="-0.0391067 -0.0287135 0.0265996" />
        <site name="glmax1_r-P4" pos="-0.0243976 -0.0498522 0.0413967" />
        <site name="glmax2_r-P3" pos="-0.0396351 -0.0514376 0.0221957" />
        <site name="glmax2_r-P4" pos="-0.0137402 -0.0894873 0.0369047" />
        <site name="glmax3_r-P3" pos="-0.0247499 -0.0990878 0.00827934" />
        <site name="glmax3_r-P4" pos="-0.00528468 -0.124983 0.0362001" />
        <site name="glmed1_r-P2" pos="-0.019201 -0.0103051 0.0488833" />
        <site name="glmed2_r-P2" pos="-0.0227241 -0.00510853 0.0464171" />
        <site name="glmed3_r-P2" pos="-0.0272161 -0.00413967 0.0456244" />
        <site name="glmin1_r-P2" pos="-0.00634162 -0.00916012 0.0493237" />
        <site name="glmin2_r-P2" pos="-0.00845549 -0.00916012 0.0493237" />
        <site name="glmin3_r-P2" pos="-0.0118905 -0.00731048 0.0484429" />
        <site name="iliacus_r-P3" pos="-0.0020258 -0.0497641 0.0122429" />
        <site name="iliacus_r-P4" pos="-0.0107455 -0.0561057 0.0172633" />
        <site name="piri_r-P3" pos="-0.0130356 -0.00317081 0.0384901" />
        <site name="psoas_r-P3" pos="-0.0116263 -0.0411325 0.00405159" />
        <site name="psoas_r-P4" pos="-0.0206983 -0.0461529 0.00775087" />
        <site name="sart_r-P2" pos="-0.00264234 -0.314263 -0.0370809" />
        <site name="tfl_r-P2" pos="0.025895 -0.0876377 0.0525826" />
        <site name="tfl_r-P3" pos="0.00942435 -0.356716 0.0285373" />
        <site name="vasint_r-P1" pos="0.0255426 -0.169462 0.0273042" />
        <site name="vasint_r-P2" pos="0.0295062 -0.183555 0.0251022" />
        <site name="vaslat_r-P1" pos="0.00422775 -0.163297 0.0307392" />
        <site name="vaslat_r-P2" pos="0.023693 -0.22821 0.0360239" />
        <site name="vasmed_r-P1" pos="0.0123309 -0.184876 0.0165587" />
        <site name="vasmed_r-P2" pos="0.0313558 -0.243888 0.000792703" />
        <joint name="hip_flexion_r" type="hinge" pos="0 0 0" axis="       0        0        1" limited="false" range="-0.523599   2.0944" ref="0" />
        <joint name="hip_adduction_r" type="hinge" pos="0 0 0" axis="       1        0        0" limited="false" range="-0.872665 0.523599" ref="0" />
        <joint name="hip_rotation_r" type="hinge" pos="0 0 0" axis="       0        1        0" limited="false" range="-0.698132 0.698132" ref="0" />
        <body name="tibia_r" pos="0.000620795 -0.355938 -0.0010004" quat="1.0 7.240636975890137e-18 -9.456205735995121e-17 -2.960068750797159e-20">
          <geom name="r_tibia" type="mesh" mesh="r_tibia" />
          <geom name="r_fibula" type="mesh" mesh="r_fibula" />
          <inertial pos="       0 -0.178779        0" mass="2.60824694373283" fullinertia="0.0325117 0.00328988 0.0329633        0        0        0" />
          <site name="bflh_r-P2" pos="-0.0322701 -0.033515 0.0242266" />
          <site name="bflh_r-P3" pos="-0.0274823 -0.0435695 0.0290144" />
          <site name="bfsh_r-P2" pos="-0.0288229 -0.0401222 0.0304508" />
          <site name="edl_r-P1" pos="-0.0153211 -0.110791 0.0196302" />
          <site name="edl_r-P2" pos="0.0157042 -0.360047 0.0107248" />
          <site name="ehl_r-P1" pos="-0.013406 -0.148424 0.0180981" />
          <site name="ehl_r-P2" pos="0.00679876 -0.278557 0.0157042" />
          <site name="ehl_r-P3" pos="0.0191514 -0.353631 -0.0026812" />
          <site name="fdl_r-P1" pos="-0.00220241 -0.175427 -0.00172363" />
          <site name="fdl_r-P2" pos="-0.0168533 -0.349035 -0.0118739" />
          <site name="fhl_r-P1" pos="-0.0296847 -0.207123 0.0191514" />
          <site name="fhl_r-P2" pos="-0.0231732 -0.351524 -0.00727754" />
          <site name="grac_r-P2" pos="-0.0176385 -0.0455325 -0.0283537" />
          <site name="grac_r-P3" pos="0.00170448 -0.0666661 -0.0150626" />
          <site name="perbrev_r-P1" pos="-0.023269 -0.242457 0.024035" />
          <site name="perbrev_r-P2" pos="-0.0324617 -0.372782 0.0238435" />
          <site name="perbrev_r-P3" pos="-0.0272908 -0.383412 0.0244181" />
          <site name="perlong_r-P1" pos="-0.0191514 -0.131475 0.0270035" />
          <site name="perlong_r-P2" pos="-0.030355 -0.373453 0.0226944" />
          <site name="perlong_r-P3" pos="-0.0260459 -0.384369 0.0229817" />
          <site name="recfem_r-P5" pos="0.0312168 -0.0604419 -0.000450058" />
          <site name="sart_r-P3" pos="-0.024035 -0.0383986 -0.0349513" />
          <site name="sart_r-P4" pos="-0.0152254 -0.0573585 -0.0252799" />
          <site name="sart_r-P5" pos="0.013023 -0.0775633 -0.00248969" />
          <site name="semimem_r-P2" pos="-0.0277696 -0.0399307 -0.0187684" />
          <site name="semiten_r-P2" pos="-0.0298762 -0.0486446 -0.0219284" />
          <site name="semiten_r-P3" pos="0.00181939 -0.0740203 -0.0112036" />
          <site name="soleus_r-P1" pos="-0.00727754 -0.0877135 0.0093842" />
          <site name="tfl_r-P4" pos="0.0103418 -0.0392604 0.033132" />
          <site name="tibant_r-P1" pos="0.0147466 -0.125633 0.0155127" />
          <site name="tibant_r-P2" pos="0.024035 -0.182513 0.0122569" />
          <site name="tibant_r-P3" pos="0.0223114 -0.350375 -0.0126399" />
          <site name="tibpost_r-P1" pos="-0.00392604 -0.124867 0.00986298" />
          <site name="tibpost_r-P2" pos="-0.0157042 -0.349992 -0.0167575" />
          <site name="vasint_r-P5" pos="0.0311881 -0.0605185 0.000411756" />
          <site name="vaslat_r-P5" pos="0.0311594 -0.0606909 0.00489319" />
          <site name="vasmed_r-P5" pos="0.0305465 -0.0608728 -0.00649233" />
          <joint name="knee_angle_r_translation2" type="slide" pos="0 0 0" axis="0.992246 0.123982 -0.00878916" limited="true" range="7.69254e-11 0.006792" ref="0" />
          <joint name="knee_angle_r_translation1" type="slide" pos="0 0 0" axis="-0.124293 0.989762 -0.0701648" limited="true" range="9.53733e-08 0.00159883" ref="0" />
          <joint name="knee_angle_r" type="hinge" pos="0 0 0" axis="-3.98373e-10 -0.0707131 -0.997497" limited="false" range="       0   2.0944" ref="0" />
          <joint name="knee_angle_r_rotation2" type="hinge" pos="0 0 0" axis="0.992246 0.123982 -0.00878916" limited="true" range="-0.00167821 0.0335354" ref="0" />
          <joint name="knee_angle_r_rotation3" type="hinge" pos="0 0 0" axis="-0.124293 0.989762 -0.0701648" limited="true" range="1.08939e-08 0.262788" ref="0" />
          <body name="talus_r" pos="-0.00957571 -0.383028        0" quat="1.0 -6.036754011562992e-18 1.5193252867388614e-18 -2.498419531737724e-19">
            <geom name="r_talus" type="mesh" mesh="r_talus" />
            <inertial pos="       0        0        0" mass="0.0703505581586737" fullinertia="0.00044415 0.00044415 0.00044415        0        0        0" />
            <joint name="ankle_angle_r" type="hinge" pos="0 0 0" axis="-0.105014 -0.174022 0.979126" limited="false" range="-0.698132 0.523599" ref="0" />
            <body name="calcn_r" pos="-0.0387511 -0.0333321 0.00629298" quat="1.0 -5.320429553087796e-19 1.609289071159989e-17 -2.1848634538867752e-17">
              <geom name="r_foot" type="mesh" mesh="r_foot" />
              <inertial pos="0.0794568 0.0238371        0" mass="0.879381976983421" fullinertia="0.000621811 0.00173219 0.00182102        0        0        0" />
              <site name="edl_r-P3" pos="0.0730208 0.0286045 0.000635655" />
              <site name="edl_r-P4" pos="0.128402 0.00437013 0.0103294" />
              <site name="ehl_r-P4" pos="0.0770731 0.0309087 -0.0167654" />
              <site name="ehl_r-P5" pos="0.102738 0.0245522 -0.0204204" />
              <site name="ehl_r-P6" pos="0.137778 0.0110445 -0.0222479" />
              <site name="fdl_r-P3" pos="0.0346432 0.0250289 -0.0222479" />
              <site name="fdl_r-P4" pos="0.0562554 0.0139844 -0.0208971" />
              <site name="fdl_r-P5" pos="0.131739 -0.006436 0.00921699" />
              <site name="fhl_r-P3" pos="0.0297169 0.0219301 -0.0191491" />
              <site name="fhl_r-P4" pos="0.0824762 0.00540307 -0.020341" />
              <site name="fhl_r-P5" pos="0.137143 -0.00421121 -0.0213739" />
              <site name="gaslat_r-P2" pos="0.0034961 0.0246316 -0.00421121" />
              <site name="gasmed_r-P2" pos="0.0034961 0.0246316 -0.00421121" />
              <site name="perbrev_r-P4" pos="0.0374242 0.0214533 0.0185134" />
              <site name="perbrev_r-P5" pos="0.0537923 0.017401 0.0272537" />
              <site name="perlong_r-P4" pos="0.0348021 0.0182751 0.01756" />
              <site name="perlong_r-P5" pos="0.0541101 0.00842242 0.0225657" />
              <site name="perlong_r-P6" pos="0.0676972 0.00548252 0.00937591" />
              <site name="perlong_r-P7" pos="0.0955866 0.00675383 -0.0146201" />
              <site name="soleus_r-P2" pos="0.0034961 0.0246316 -0.00421121" />
              <site name="tibant_r-P4" pos="0.0926467 0.0141433 -0.0242343" />
              <site name="tibpost_r-P3" pos="0.0331335 0.0265386 -0.0227247" />
              <site name="tibpost_r-P4" pos="0.0613407 0.0126336 -0.0223274" />
              <joint name="subtalar_angle_r" type="hinge" pos="0 0 0" axis=" 0.78718 0.604747 -0.120949" limited="false" range="-0.349066 0.349066" ref="0" />
              <body name="toes_r" pos="0.142069 -0.00158914 0.000858134" quat="1.0 1.314867274624753e-31 -2.6810890689525335e-17 -3.939849802505862e-32">
                <geom name="r_bofoot" type="mesh" mesh="r_bofoot" />
                <inertial pos="0.0274921 0.00476741 -0.0139049" mass="0.152379308971687" fullinertia="4.4415e-05 8.88301e-05 0.00044415        0        0        0" />
                <site name="edl_r-P5" pos="0.000238371 0.00373447 0.0121569" />
                <site name="edl_r-P6" pos="0.0351994 -0.000317827 0.0198642" />
                <site name="ehl_r-P7" pos="0.0236781 0.00325773 -0.0194669" />
                <site name="ehl_r-P8" pos="0.0447342 0.00270153 -0.014779" />
                <site name="fdl_r-P6" pos="-0.00150968 -0.00619763 0.0116802" />
                <site name="fdl_r-P7" pos="0.0226452 -0.00564144 0.0170832" />
                <site name="fdl_r-P8" pos="0.0350405 -0.00476741 0.0192286" />
                <site name="fhl_r-P6" pos="0.0123158 -0.00508524 -0.0210561" />
                <site name="fhl_r-P7" pos="0.0446547 -0.0081046 -0.0143817" />
                <joint name="mtp_angle_r" type="hinge" pos="0 0 0" axis="0.580954 2.6299e-15 -0.813936" limited="false" range="-0.523599 0.523599" ref="0" />
              </body>
            </body>
          </body>
        </body>
        <body name="patella_r" pos="-0.00712552 -0.359323 0.000327853" quat="1.0 0.0 0.0 0.0">
          <geom name="r_patella" type="mesh" mesh="r_patella" />
          <inertial pos="  0.0018   0.0264        0" mass="0.0606421811327767" fullinertia="2.01906e-06 9.22296e-06 9.22296e-06        0        0        0" />
          <site name="recfem_r-P2" pos="0.01 0.049 0.0007" />
          <site name="recfem_r-P3" pos="0.0121 0.0437 -0.001" />
          <site name="recfem_r-P4" pos="0.005 0.00247 3e-005" />
          <site name="vasint_r-P3" pos="0.0058 0.048 -0.0006" />
          <site name="vasint_r-P4" pos="0.005 0.00247 -0.00039" />
          <site name="vaslat_r-P3" pos="0.0103 0.0423 0.0141" />
          <site name="vaslat_r-P4" pos="0.005 0.00247 0.00733" />
          <site name="vasmed_r-P3" pos="0.0063 0.0445 -0.017" />
          <site name="vasmed_r-P4" pos="0.005 0.00247 -0.0085" />
          <joint name="knee_angle_r_beta_translation2" type="slide" pos="0 0 0" axis="       0        1        0" limited="true" range="-0.0408267 -0.0108281" ref="0" />
          <joint name="knee_angle_r_beta_translation1" type="slide" pos="0 0 0" axis="       1        0        0" limited="true" range="-0.0227731 0.0524192" ref="0" />
          <joint name="knee_angle_r_beta_rotation1" type="hinge" pos="0 0 0" axis="       0        0        1" limited="true" range="-1.79241 0.010506" ref="0" />
        </body>
      </body>
      <body name="femur_l" pos="-0.0692743 -0.0966192 -0.0734114" quat="1.0 0.0 0.0 0.0">
        <geom name="l_femur" type="mesh" mesh="l_femur" />
        <inertial pos="       0 -0.152607        0" mass="6.54358681657088" fullinertia="0.0759099 0.0198987 0.0800484        0        0        0" />
        <site name="addbrev_l-P2" pos="-0.00179538 -0.105927 -0.0223524" />
        <site name="addlong_l-P2" pos="0.010108 -0.214879 -0.0142104" />
        <site name="addmagDist_l-P2" pos="0.010099 -0.235643 -0.0173254" />
        <site name="addmagIsch_l-P2" pos="0.00431788 -0.348276 0.0293813" />
        <site name="addmagMid_l-P2" pos="0.0021724 -0.145784 -0.0262304" />
        <site name="addmagProx_l-P2" pos="-0.0137077 -0.0707916 -0.028744" />
        <site name="bfsh_l-P1" pos="0.00448844 -0.189502 -0.0210059" />
        <site name="gaslat_l-P1" pos="-0.00269306 -0.342378 -0.0248659" />
        <site name="gasmed_l-P1" pos="0.0071815 -0.340044 0.0186719" />
        <site name="glmax1_l-P3" pos="-0.0398573 -0.0292646 -0.0271102" />
        <site name="glmax1_l-P4" pos="-0.0248659 -0.0508091 -0.0421913" />
        <site name="glmax2_l-P3" pos="-0.0403959 -0.052425 -0.0226217" />
        <site name="glmax2_l-P4" pos="-0.0140039 -0.0912051 -0.0376131" />
        <site name="glmax3_l-P3" pos="-0.025225 -0.10099 -0.00843826" />
        <site name="glmax3_l-P4" pos="-0.00538613 -0.127382 -0.036895" />
        <site name="glmed1_l-P2" pos="-0.0195696 -0.0105029 -0.0498217" />
        <site name="glmed2_l-P2" pos="-0.0231603 -0.00520659 -0.0473081" />
        <site name="glmed3_l-P2" pos="-0.0277385 -0.00421913 -0.0465002" />
        <site name="glmin1_l-P2" pos="-0.00646335 -0.00933595 -0.0502705" />
        <site name="glmin2_l-P2" pos="-0.0086178 -0.00933595 -0.0502705" />
        <site name="glmin3_l-P2" pos="-0.0121188 -0.00745081 -0.0493728" />
        <site name="iliacus_l-P3" pos="-0.00206468 -0.0507194 -0.0124779" />
        <site name="iliacus_l-P4" pos="-0.0109518 -0.0571827 -0.0175947" />
        <site name="piri_l-P3" pos="-0.0132858 -0.00323168 -0.0392289" />
        <site name="psoas_l-P3" pos="-0.0118495 -0.041922 -0.00412936" />
        <site name="psoas_l-P4" pos="-0.0210957 -0.0470388 -0.00789965" />
        <site name="sart_l-P2" pos="-0.00269306 -0.320295 0.0377926" />
        <site name="tfl_l-P2" pos="0.026392 -0.0893199 -0.053592" />
        <site name="tfl_l-P3" pos="0.00960526 -0.363563 -0.0290851" />
        <site name="vasint_l-P1" pos="0.0260329 -0.172715 -0.0278283" />
        <site name="vasint_l-P2" pos="0.0300725 -0.187078 -0.0255841" />
        <site name="vaslat_l-P1" pos="0.0043089 -0.166431 -0.0313293" />
        <site name="vaslat_l-P2" pos="0.0241478 -0.232591 -0.0367154" />
        <site name="vasmed_l-P1" pos="0.0125676 -0.188425 -0.0168765" />
        <site name="vasmed_l-P2" pos="0.0319577 -0.24857 -0.000807919" />
        <joint name="hip_flexion_l" type="hinge" pos="0 0 0" axis="       0        0        1" limited="false" range="-0.523599   2.0944" ref="0" />
        <joint name="hip_adduction_l" type="hinge" pos="0 0 0" axis="      -1       -0       -0" limited="false" range="-0.872665 0.523599" ref="0" />
        <joint name="hip_rotation_l" type="hinge" pos="0 0 0" axis="      -0       -1       -0" limited="false" range="-0.698132 0.698132" ref="0" />
        <body name="tibia_l" pos="0.000457354 -0.362847 0.00105179" quat="1.0 -7.240636975890137e-18 9.456205735995121e-17 -2.960068750797159e-20">
          <geom name="l_tibia" type="mesh" mesh="l_tibia" />
          <geom name="l_fibula" type="mesh" mesh="l_fibula" />
          <inertial pos="       0 -0.178163        0" mass="2.60824694373283" fullinertia="0.0322883 0.00326727 0.0327368        0        0        0" />
          <site name="bflh_l-P2" pos="-0.0321591 -0.0333996 -0.0241432" />
          <site name="bflh_l-P3" pos="-0.0273877 -0.0434195 -0.0289145" />
          <site name="bfsh_l-P2" pos="-0.0287237 -0.0399841 -0.0303459" />
          <site name="edl_l-P1" pos="-0.0152684 -0.11041 -0.0195626" />
          <site name="edl_l-P2" pos="0.0156501 -0.358807 -0.0106879" />
          <site name="ehl_l-P1" pos="-0.0133599 -0.147913 -0.0180358" />
          <site name="ehl_l-P2" pos="0.00677535 -0.277599 -0.0156501" />
          <site name="ehl_l-P3" pos="0.0190855 -0.352414 0.00267197" />
          <site name="fdl_l-P1" pos="-0.00219483 -0.174823 0.0017177" />
          <site name="fdl_l-P2" pos="-0.0167952 -0.347833 0.011833" />
          <site name="fhl_l-P1" pos="-0.0295825 -0.20641 -0.0190855" />
          <site name="fhl_l-P2" pos="-0.0230935 -0.350314 0.00725249" />
          <site name="grac_l-P2" pos="-0.0175777 -0.0453758 0.0282561" />
          <site name="grac_l-P3" pos="0.00169861 -0.0664366 0.0150107" />
          <site name="perbrev_l-P1" pos="-0.0231889 -0.241622 -0.0239523" />
          <site name="perbrev_l-P2" pos="-0.0323499 -0.371499 -0.0237615" />
          <site name="perbrev_l-P3" pos="-0.0271968 -0.382092 -0.024334" />
          <site name="perlong_l-P1" pos="-0.0190855 -0.131022 -0.0269106" />
          <site name="perlong_l-P2" pos="-0.0302505 -0.372167 -0.0226163" />
          <site name="perlong_l-P3" pos="-0.0259563 -0.383046 -0.0229026" />
          <site name="recfem_l-P5" pos="0.0311094 -0.0602338 0.000448509" />
          <site name="sart_l-P3" pos="-0.0239523 -0.0382664 0.034831" />
          <site name="sart_l-P4" pos="-0.015173 -0.0571611 0.0251929" />
          <site name="sart_l-P5" pos="0.0129781 -0.0772963 0.00248112" />
          <site name="semimem_l-P2" pos="-0.027674 -0.0397933 0.0187038" />
          <site name="semiten_l-P2" pos="-0.0297734 -0.0484772 0.0218529" />
          <site name="semiten_l-P3" pos="0.00181312 -0.0737655 0.011165" />
          <site name="soleus_l-P1" pos="-0.00725249 -0.0874116 -0.0093519" />
          <site name="tfl_l-P4" pos="0.0103062 -0.0391253 -0.0330179" />
          <site name="tibant_l-P1" pos="0.0146958 -0.125201 -0.0154593" />
          <site name="tibant_l-P2" pos="0.0239523 -0.181885 -0.0122147" />
          <site name="tibant_l-P3" pos="0.0222346 -0.349169 0.0125964" />
          <site name="tibpost_l-P1" pos="-0.00391253 -0.124437 -0.00982903" />
          <site name="tibpost_l-P2" pos="-0.0156501 -0.348788 0.0166998" />
          <site name="vasint_l-P5" pos="0.0310807 -0.0603102 -0.000410338" />
          <site name="vaslat_l-P5" pos="0.0310521 -0.060482 -0.00487635" />
          <site name="vasmed_l-P5" pos="0.0304414 -0.0606633 0.00646999" />
          <joint name="knee_angle_l_translation2" type="slide" pos="0 0 0" axis="-0.992246 -0.123982 -0.00878916" limited="true" range="-0.006792 -7.69254e-11" ref="0" />
          <joint name="knee_angle_l_translation1" type="slide" pos="0 0 0" axis="-0.124293 0.989762 0.0701648" limited="true" range="9.53733e-08 0.00159883" ref="0" />
          <joint name="knee_angle_l" type="hinge" pos="0 0 0" axis="3.98373e-10 0.0707131 -0.997497" limited="false" range="       0   2.0944" ref="0" />
          <joint name="knee_angle_l_rotation2" type="hinge" pos="0 0 0" axis="-0.992246 -0.123982 -0.00878916" limited="true" range="-0.00167821 0.0335354" ref="0" />
          <joint name="knee_angle_l_rotation3" type="hinge" pos="0 0 0" axis="-0.124293 0.989762 0.0701648" limited="true" range="-0.262788 -1.08939e-08" ref="0" />
          <body name="talus_l" pos="-0.00954275 -0.38171        0" quat="1.0 6.036754011562992e-18 -1.5193252867388614e-18 -2.498419531737724e-19">
            <geom name="l_talus" type="mesh" mesh="l_talus" />
            <inertial pos="       0        0        0" mass="0.0703505581586737" fullinertia="0.000446377 0.000446377 0.000446377        0        0        0" />
            <joint name="ankle_angle_l" type="hinge" pos="0 0 0" axis="0.105014 0.174022 0.979126" limited="false" range="-0.698132 0.523599" ref="0" />
            <body name="calcn_l" pos="-0.0388481 -0.0334156 -0.00630873" quat="1.0 5.320429553087796e-19 -1.609289071159989e-17 -2.1848634538867752e-17">
              <geom name="l_foot" type="mesh" mesh="l_foot" />
              <inertial pos="0.0796557 0.0238967        0" mass="0.879381976983421" fullinertia="0.000624927 0.00174087 0.00183014        0        0        0" />
              <site name="edl_l-P3" pos="0.0732036 0.0286761 -0.000637246" />
              <site name="edl_l-P4" pos="0.128724 0.00438106 -0.0103552" />
              <site name="ehl_l-P4" pos="0.077266 0.0309861 0.0168074" />
              <site name="ehl_l-P5" pos="0.102995 0.0246136 0.0204715" />
              <site name="ehl_l-P6" pos="0.138123 0.0110721 0.0223036" />
              <site name="fdl_l-P3" pos="0.0347299 0.0250915 0.0223036" />
              <site name="fdl_l-P4" pos="0.0563962 0.0140194 0.0209495" />
              <site name="fdl_l-P5" pos="0.132069 -0.00645211 -0.00924006" />
              <site name="fhl_l-P3" pos="0.0297912 0.021985 0.019197" />
              <site name="fhl_l-P4" pos="0.0826826 0.00541659 0.0203919" />
              <site name="fhl_l-P5" pos="0.137486 -0.00422175 0.0214274" />
              <site name="gaslat_l-P2" pos="0.00350485 0.0246933 0.00422175" />
              <site name="gasmed_l-P2" pos="0.00350485 0.0246933 0.00422175" />
              <site name="perbrev_l-P4" pos="0.0375178 0.021507 -0.0185598" />
              <site name="perbrev_l-P5" pos="0.0539269 0.0174446 -0.0273219" />
              <site name="perlong_l-P4" pos="0.0348892 0.0183208 -0.0176039" />
              <site name="perlong_l-P5" pos="0.0542455 0.0084435 -0.0226222" />
              <site name="perlong_l-P6" pos="0.0678667 0.00549624 -0.00939937" />
              <site name="perlong_l-P7" pos="0.0958258 0.00677074 0.0146566" />
              <site name="soleus_l-P2" pos="0.00350485 0.0246933 0.00422175" />
              <site name="tibant_l-P4" pos="0.0928786 0.0141787 0.024295" />
              <site name="tibpost_l-P3" pos="0.0332164 0.026605 0.0227815" />
              <site name="tibpost_l-P4" pos="0.0614942 0.0126653 0.0223833" />
              <joint name="subtalar_angle_l" type="hinge" pos="0 0 0" axis="-0.78718 -0.604747 -0.120949" limited="false" range="-0.349066 0.349066" ref="0" />
              <body name="toes_l" pos="0.142424 -0.00159311 -0.000860282" quat="1.0 1.314867274624753e-31 2.6810890689525335e-17 3.939849802505862e-32">
                <geom name="l_bofoot" type="mesh" mesh="l_bofoot" />
                <inertial pos="0.0275609 0.00477934 0.0139397" mass="0.152379308971687" fullinertia="4.46377e-05 8.92753e-05 0.000446377        0        0        0" />
                <site name="edl_l-P5" pos="0.000238967 0.00374382 -0.0121873" />
                <site name="edl_l-P6" pos="0.0352875 -0.000318623 -0.0199139" />
                <site name="ehl_l-P7" pos="0.0237374 0.00326588 0.0195156" />
                <site name="ehl_l-P8" pos="0.0448462 0.00270829 0.014816" />
                <site name="fdl_l-P6" pos="-0.00151346 -0.00621315 -0.0117094" />
                <site name="fdl_l-P7" pos="0.0227019 -0.00565556 -0.017126" />
                <site name="fdl_l-P8" pos="0.0351282 -0.00477934 -0.0192767" />
                <site name="fhl_l-P6" pos="0.0123466 -0.00509797 0.0211088" />
                <site name="fhl_l-P7" pos="0.0447665 -0.00812488 0.0144177" />
                <joint name="mtp_angle_l" type="hinge" pos="0 0 0" axis="-0.580954 2.6299e-15 -0.813936" limited="false" range="-0.523599 0.523599" ref="0" />
              </body>
            </body>
          </body>
        </body>
        <body name="patella_l" pos="-0.00726229 -0.366221 -0.000281359" quat="1.0 0.0 0.0 0.0">
          <geom name="l_patella" type="mesh" mesh="l_patella" />
          <inertial pos="  0.0018   0.0264        0" mass="0.0606421811327767" fullinertia="2.01906e-06 9.22296e-06 9.22296e-06        0        0        0" />
          <site name="recfem_l-P2" pos="0.01 0.049 -0.0007" />
          <site name="recfem_l-P3" pos="0.0121 0.0437 0.001" />
          <site name="recfem_l-P4" pos="0.005 0.00247 -3e-005" />
          <site name="vasint_l-P3" pos="0.0058 0.048 0.0006" />
          <site name="vasint_l-P4" pos="0.005 0.00247 0.00039" />
          <site name="vaslat_l-P3" pos="0.0103 0.0423 -0.0141" />
          <site name="vaslat_l-P4" pos="0.005 0.00247 -0.00733" />
          <site name="vasmed_l-P3" pos="0.0063 0.0445 0.017" />
          <site name="vasmed_l-P4" pos="0.005 0.00247 0.0085" />
          <joint name="knee_angle_l_beta_translation2" type="slide" pos="0 0 0" axis="       0        1        0" limited="true" range="-0.0408267 -0.0108281" ref="0" />
          <joint name="knee_angle_l_beta_translation1" type="slide" pos="0 0 0" axis="       1        0        0" limited="true" range="-0.0227731 0.0524192" ref="0" />
          <joint name="knee_angle_l_beta_rotation1" type="hinge" pos="0 0 0" axis="       0        0        1" limited="true" range="-1.79241 0.010506" ref="0" />
        </body>
      </body>
      <body name="torso" pos="-0.123959 0.100324        0" quat="1.0 0.0 0.0 0.0">
        <geom name="hat_spine" type="mesh" mesh="hat_spine" />
        <geom name="hat_jaw" type="mesh" mesh="hat_jaw" />
        <geom name="hat_skull" type="mesh" mesh="hat_skull" />
        <geom name="hat_ribs_scap" type="mesh" mesh="hat_ribs_scap" />
        <inertial pos="-0.0276017 0.294418        0" mass="18.8726628349948" fullinertia="0.878092 0.449914 0.852426        0        0        0" />
        <joint name="lumbar_extension" type="hinge" pos="0 0 0" axis="       0        0        1" limited="false" range=" -1.5708   1.5708" ref="0" />
        <joint name="lumbar_bending" type="hinge" pos="0 0 0" axis="       1        0        0" limited="false" range=" -1.5708   1.5708" ref="0" />
        <joint name="lumbar_rotation" type="hinge" pos="0 0 0" axis="       0        1        0" limited="false" range=" -1.5708   1.5708" ref="0" />
        <body name="humerus_r" pos="0.00290277 0.341801 0.156409" quat="1.0 0.0 0.0 0.0">
          <geom name="humerus_rv" type="mesh" mesh="humerus_rv" />
          <inertial pos="       0 -0.149286        0" mass="1.42987509457504" fullinertia="0.00692129 0.00238763 0.00776893        0        0        0" />
          <joint name="arm_flex_r" type="hinge" pos="0 0 0" axis="       0        0        1" limited="false" range=" -1.5708   1.5708" ref="0" />
          <joint name="arm_add_r" type="hinge" pos="0 0 0" axis="       1        0        0" limited="false" range=" -2.0944   1.5708" ref="0" />
          <joint name="arm_rot_r" type="hinge" pos="0 0 0" axis="       0        1        0" limited="false" range=" -1.5708   1.5708" ref="0" />
          <body name="ulna_r" pos="0.0119282 -0.259794 -0.0087075" quat="1.0 1.6893809785063376e-18 -6.938893903907228e-18 4.155190089080778e-20">
            <geom name="ulna_rv" type="mesh" mesh="ulna_rv" />
            <inertial pos="       0 -0.122163        0" mass="0.427379640813943" fullinertia="0.0021408 0.000446662 0.00232221        0        0        0" />
            <joint name="elbow_flex_r" type="hinge" pos="0 0 0" axis="0.226047 0.022269 0.973862" limited="false" range="       0    2.618" ref="0" />
            <body name="radius_r" pos="-0.0068184 -0.0131837 0.0264374" quat="1.0 2.301201592641875e-21 -6.933378131686372e-19 1.7489241099837954e-19">
              <geom name="radius_rv" type="mesh" mesh="radius_rv" />
              <inertial pos="       0 -0.122245        0" mass="0.427379640813943" fullinertia="0.00214369 0.000447266 0.00232535        0        0        0" />
              <joint name="pro_sup_r" type="hinge" pos="0 0 0" axis="0.056398 0.998406 0.001952" limited="false" range="       0   1.5708" ref="0" />
              <body name="hand_r" pos="-0.00892256 -0.239207 0.0138043" quat="1.0 0.0 8.407790785948892e-45 0.0">
                <geom name="pisiform_rvs" type="mesh" mesh="pisiform_rvs" />
                <geom name="lunate_rvs" type="mesh" mesh="lunate_rvs" />
                <geom name="scaphoid_rvs" type="mesh" mesh="scaphoid_rvs" />
                <geom name="triquetrum_rvs" type="mesh" mesh="triquetrum_rvs" />
                <geom name="hamate_rvs" type="mesh" mesh="hamate_rvs" />
                <geom name="capitate_rvs" type="mesh" mesh="capitate_rvs" />
                <geom name="trapezoid_rvs" type="mesh" mesh="trapezoid_rvs" />
                <geom name="trapezium_rvs" type="mesh" mesh="trapezium_rvs" />
                <geom name="metacarpal2_rvs" type="mesh" mesh="metacarpal2_rvs" />
                <geom name="index_proximal_rvs" type="mesh" mesh="index_proximal_rvs" />
                <geom name="index_medial_rvs" type="mesh" mesh="index_medial_rvs" />
                <geom name="index_distal_rvs" type="mesh" mesh="index_distal_rvs" />
                <geom name="metacarpal3_rvs" type="mesh" mesh="metacarpal3_rvs" />
                <geom name="middle_proximal_rvs" type="mesh" mesh="middle_proximal_rvs" />
                <geom name="middle_medial_rvs" type="mesh" mesh="middle_medial_rvs" />
                <geom name="middle_distal_rvs" type="mesh" mesh="middle_distal_rvs" />
                <geom name="metacarpal4_rvs" type="mesh" mesh="metacarpal4_rvs" />
                <geom name="ring_proximal_rvs" type="mesh" mesh="ring_proximal_rvs" />
                <geom name="ring_medial_rvs" type="mesh" mesh="ring_medial_rvs" />
                <geom name="ring_distal_rvs" type="mesh" mesh="ring_distal_rvs" />
                <geom name="metacarpal5_rvs" type="mesh" mesh="metacarpal5_rvs" />
                <geom name="little_proximal_rvs" type="mesh" mesh="little_proximal_rvs" />
                <geom name="little_medial_rvs" type="mesh" mesh="little_medial_rvs" />
                <geom name="little_distal_rvs" type="mesh" mesh="little_distal_rvs" />
                <geom name="metacarpal1_rvs" type="mesh" mesh="metacarpal1_rvs" />
                <geom name="thumb_proximal_rvs" type="mesh" mesh="thumb_proximal_rvs" />
                <geom name="thumb_distal_rvs" type="mesh" mesh="thumb_distal_rvs" />
                <inertial pos="       0 -0.068095        0" mass="0.321853803575932" fullinertia="0.000627527 0.000384818 0.000942697        0        0        0" />
                <joint name="wrist_flex_r" type="hinge" pos="0 0 0" axis="-3.55271e-15 3.55271e-15        1" limited="false" range="-1.22173  1.22173" ref="0" />
                <joint name="wrist_dev_r" type="hinge" pos="0 0 0" axis="       1        0 3.55271e-15" limited="false" range="-0.436332 0.610865" ref="0" />
              </body>
            </body>
          </body>
        </body>
        <body name="humerus_l" pos="0.00290277 0.341801 -0.156409" quat="1.0 0.0 0.0 0.0">
          <geom name="humerus_lv" type="mesh" mesh="humerus_lv" />
          <inertial pos="       0 -0.147166        0" mass="1.42987509457504" fullinertia="0.00672611 0.0023203 0.00754984        0        0        0" />
          <joint name="arm_flex_l" type="hinge" pos="0 0 0" axis="       0        0        1" limited="false" range=" -1.5708   1.5708" ref="0" />
          <joint name="arm_add_l" type="hinge" pos="0 0 0" axis="      -1        0        0" limited="false" range=" -2.0944   1.5708" ref="0" />
          <joint name="arm_rot_l" type="hinge" pos="0 0 0" axis="       0       -1        0" limited="false" range=" -1.5708   1.5708" ref="0" />
          <body name="ulna_l" pos="0.0117588 -0.256104 0.00858384" quat="1.0 -1.6893809785063376e-18 6.938893903907228e-18 4.155190089080778e-20">
            <geom name="ulna_lv" type="mesh" mesh="ulna_lv" />
            <inertial pos="       0 -0.115712        0" mass="0.427379640813943" fullinertia="0.00192067 0.000400735 0.00208343        0        0        0" />
            <joint name="elbow_flex_l" type="hinge" pos="0 0 0" axis="-0.226047 -0.022269 0.973862" limited="false" range="       0    2.618" ref="0" />
            <body name="radius_l" pos="-0.00645836 -0.0124876 -0.0250414" quat="1.0 -2.301201592641875e-21 6.933378131686372e-19 1.7489241099837954e-19">
              <geom name="radius_lv" type="mesh" mesh="radius_lv" />
              <inertial pos="       0 -0.119025        0" mass="0.427379640813943" fullinertia="0.00203225 0.000424015 0.00220447        0        0        0" />
              <joint name="pro_sup_l" type="hinge" pos="0 0 0" axis="-0.056398 -0.998406 0.001952" limited="false" range="       0   1.5708" ref="0" />
              <body name="hand_l" pos="-0.00868755 -0.232907 -0.0134407" quat="1.0 0.0 8.407790785948892e-45 0.0">
                <geom name="pisiform_lvs" type="mesh" mesh="pisiform_lvs" />
                <geom name="lunate_lvs" type="mesh" mesh="lunate_lvs" />
                <geom name="scaphoid_lvs" type="mesh" mesh="scaphoid_lvs" />
                <geom name="triquetrum_lvs" type="mesh" mesh="triquetrum_lvs" />
                <geom name="hamate_lvs" type="mesh" mesh="hamate_lvs" />
                <geom name="capitate_lvs" type="mesh" mesh="capitate_lvs" />
                <geom name="trapezoid_lvs" type="mesh" mesh="trapezoid_lvs" />
                <geom name="trapezium_lvs" type="mesh" mesh="trapezium_lvs" />
                <geom name="metacarpal2_lvs" type="mesh" mesh="metacarpal2_lvs" />
                <geom name="index_proximal_lvs" type="mesh" mesh="index_proximal_lvs" />
                <geom name="index_medial_lvs" type="mesh" mesh="index_medial_lvs" />
                <geom name="index_distal_lvs" type="mesh" mesh="index_distal_lvs" />
                <geom name="metacarpal3_lvs" type="mesh" mesh="metacarpal3_lvs" />
                <geom name="middle_proximal_lvs" type="mesh" mesh="middle_proximal_lvs" />
                <geom name="middle_medial_lvs" type="mesh" mesh="middle_medial_lvs" />
                <geom name="middle_distal_lvs" type="mesh" mesh="middle_distal_lvs" />
                <geom name="metacarpal4_lvs" type="mesh" mesh="metacarpal4_lvs" />
                <geom name="ring_proximal_lvs" type="mesh" mesh="ring_proximal_lvs" />
                <geom name="ring_medial_lvs" type="mesh" mesh="ring_medial_lvs" />
                <geom name="ring_distal_lvs" type="mesh" mesh="ring_distal_lvs" />
                <geom name="metacarpal5_lvs" type="mesh" mesh="metacarpal5_lvs" />
                <geom name="little_proximal_lvs" type="mesh" mesh="little_proximal_lvs" />
                <geom name="little_medial_lvs" type="mesh" mesh="little_medial_lvs" />
                <geom name="little_distal_lvs" type="mesh" mesh="little_distal_lvs" />
                <geom name="metacarpal1_lvs" type="mesh" mesh="metacarpal1_lvs" />
                <geom name="thumb_proximal_lvs" type="mesh" mesh="thumb_proximal_lvs" />
                <geom name="thumb_distal_lvs" type="mesh" mesh="thumb_distal_lvs" />
                <inertial pos="       0 -0.068095        0" mass="0.321853803575932" fullinertia="0.000627527 0.000384818 0.000942697        0        0        0" />
                <joint name="wrist_flex_l" type="hinge" pos="0 0 0" axis="-3.55271e-15 -3.55271e-15        1" limited="false" range="-1.22173  1.22173" ref="0" />
                <joint name="wrist_dev_l" type="hinge" pos="0 0 0" axis="      -1        0 -3.55271e-15" limited="false" range="-0.436332 0.610865" ref="0" />
              </body>
            </body>
          </body>
        </body>
      </body>
    </body>
    <camera name="for_testing" pos="0 0 0" euler="0 0 0" />
  </worldbody>
  <asset>
    <mesh name="r_pelvis" file="Geometry/r_pelvis.stl" scale=" 1.23097  1.23097 0.950186" />
    <mesh name="l_pelvis" file="Geometry/l_pelvis.stl" scale=" 1.23097  1.23097 0.950186" />
    <mesh name="sacrum" file="Geometry/sacrum.stl" scale=" 1.23097  1.23097 0.950186" />
    <mesh name="r_femur" file="Geometry/r_femur.stl" scale="0.880781 0.880781 0.880781" />
    <mesh name="r_tibia" file="Geometry/r_tibia.stl" scale="0.957571 0.957571 0.957571" />
    <mesh name="r_fibula" file="Geometry/r_fibula.stl" scale="0.957571 0.957571 0.957571" />
    <mesh name="r_talus" file="Geometry/r_talus.stl" scale="0.794568 0.794568 0.794568" />
    <mesh name="r_foot" file="Geometry/r_foot.stl" scale="0.794568 0.794568 0.794568" />
    <mesh name="r_bofoot" file="Geometry/r_bofoot.stl" scale="0.794568 0.794568 0.794568" />
    <mesh name="r_patella" file="Geometry/r_patella.stl" scale="       1        1        1" />
    <mesh name="l_femur" file="Geometry/l_femur.stl" scale="0.897688 0.897688 0.897688" />
    <mesh name="l_tibia" file="Geometry/l_tibia.stl" scale="0.954275 0.954275 0.954275" />
    <mesh name="l_fibula" file="Geometry/l_fibula.stl" scale="0.954275 0.954275 0.954275" />
    <mesh name="l_talus" file="Geometry/l_talus.stl" scale="0.796557 0.796557 0.796557" />
    <mesh name="l_foot" file="Geometry/l_foot.stl" scale="0.796557 0.796557 0.796557" />
    <mesh name="l_bofoot" file="Geometry/l_bofoot.stl" scale="0.796557 0.796557 0.796557" />
    <mesh name="l_patella" file="Geometry/l_patella.stl" scale="       1        1        1" />
    <mesh name="hat_spine" file="Geometry/hat_spine.stl" scale="0.920055 0.920055 0.920055" />
    <mesh name="hat_jaw" file="Geometry/hat_jaw.stl" scale="0.920055 0.920055 0.920055" />
    <mesh name="hat_skull" file="Geometry/hat_skull.stl" scale="0.920055 0.920055 0.920055" />
    <mesh name="hat_ribs_scap" file="Geometry/hat_ribs_scap.stl" scale="0.920055 0.920055 0.920055" />
    <mesh name="humerus_rv" file="Geometry/humerus_rv.stl" scale="0.907504 0.907504 0.907504" />
    <mesh name="ulna_rv" file="Geometry/ulna_rv.stl" scale=" 1.01359  1.01359  1.01359" />
    <mesh name="radius_rv" file="Geometry/radius_rv.stl" scale=" 1.01427  1.01427  1.01427" />
    <mesh name="pisiform_rvs" file="Geometry/pisiform_rvs.stl" scale="    0.85     0.85     0.85" />
    <mesh name="lunate_rvs" file="Geometry/lunate_rvs.stl" scale="    0.85     0.85     0.85" />
    <mesh name="scaphoid_rvs" file="Geometry/scaphoid_rvs.stl" scale="    0.85     0.85     0.85" />
    <mesh name="triquetrum_rvs" file="Geometry/triquetrum_rvs.stl" scale="    0.85     0.85     0.85" />
    <mesh name="hamate_rvs" file="Geometry/hamate_rvs.stl" scale="    0.85     0.85     0.85" />
    <mesh name="capitate_rvs" file="Geometry/capitate_rvs.stl" scale="    0.85     0.85     0.85" />
    <mesh name="trapezoid_rvs" file="Geometry/trapezoid_rvs.stl" scale="    0.85     0.85     0.85" />
    <mesh name="trapezium_rvs" file="Geometry/trapezium_rvs.stl" scale="    0.85     0.85     0.85" />
    <mesh name="metacarpal2_rvs" file="Geometry/metacarpal2_rvs.stl" scale="    0.85     0.85     0.85" />
    <mesh name="index_proximal_rvs" file="Geometry/index_proximal_rvs.stl" scale="    0.85     0.85     0.85" />
    <mesh name="index_medial_rvs" file="Geometry/index_medial_rvs.stl" scale="    0.85     0.85     0.85" />
    <mesh name="index_distal_rvs" file="Geometry/index_distal_rvs.stl" scale="    0.85     0.85     0.85" />
    <mesh name="metacarpal3_rvs" file="Geometry/metacarpal3_rvs.stl" scale="    0.85     0.85     0.85" />
    <mesh name="middle_proximal_rvs" file="Geometry/middle_proximal_rvs.stl" scale="    0.85     0.85     0.85" />
    <mesh name="middle_medial_rvs" file="Geometry/middle_medial_rvs.stl" scale="    0.85     0.85     0.85" />
    <mesh name="middle_distal_rvs" file="Geometry/middle_distal_rvs.stl" scale="    0.85     0.85     0.85" />
    <mesh name="metacarpal4_rvs" file="Geometry/metacarpal4_rvs.stl" scale="    0.85     0.85     0.85" />
    <mesh name="ring_proximal_rvs" file="Geometry/ring_proximal_rvs.stl" scale="    0.85     0.85     0.85" />
    <mesh name="ring_medial_rvs" file="Geometry/ring_medial_rvs.stl" scale="    0.85     0.85     0.85" />
    <mesh name="ring_distal_rvs" file="Geometry/ring_distal_rvs.stl" scale="    0.85     0.85     0.85" />
    <mesh name="metacarpal5_rvs" file="Geometry/metacarpal5_rvs.stl" scale="    0.85     0.85     0.85" />
    <mesh name="little_proximal_rvs" file="Geometry/little_proximal_rvs.stl" scale="    0.85     0.85     0.85" />
    <mesh name="little_medial_rvs" file="Geometry/little_medial_rvs.stl" scale="    0.85     0.85     0.85" />
    <mesh name="little_distal_rvs" file="Geometry/little_distal_rvs.stl" scale="    0.85     0.85     0.85" />
    <mesh name="metacarpal1_rvs" file="Geometry/metacarpal1_rvs.stl" scale="    0.85     0.85     0.85" />
    <mesh name="thumb_proximal_rvs" file="Geometry/thumb_proximal_rvs.stl" scale="    0.85     0.85     0.85" />
    <mesh name="thumb_distal_rvs" file="Geometry/thumb_distal_rvs.stl" scale="    0.85     0.85     0.85" />
    <mesh name="humerus_lv" file="Geometry/humerus_lv.stl" scale="0.894616 0.894616 0.894616" />
    <mesh name="ulna_lv" file="Geometry/ulna_lv.stl" scale="0.960065 0.960065 0.960065" />
    <mesh name="radius_lv" file="Geometry/radius_lv.stl" scale="0.987558 0.987558 0.987558" />
    <mesh name="pisiform_lvs" file="Geometry/pisiform_lvs.stl" scale="    0.85     0.85     0.85" />
    <mesh name="lunate_lvs" file="Geometry/lunate_lvs.stl" scale="    0.85     0.85     0.85" />
    <mesh name="scaphoid_lvs" file="Geometry/scaphoid_lvs.stl" scale="    0.85     0.85     0.85" />
    <mesh name="triquetrum_lvs" file="Geometry/triquetrum_lvs.stl" scale="    0.85     0.85     0.85" />
    <mesh name="hamate_lvs" file="Geometry/hamate_lvs.stl" scale="    0.85     0.85     0.85" />
    <mesh name="capitate_lvs" file="Geometry/capitate_lvs.stl" scale="    0.85     0.85     0.85" />
    <mesh name="trapezoid_lvs" file="Geometry/trapezoid_lvs.stl" scale="    0.85     0.85     0.85" />
    <mesh name="trapezium_lvs" file="Geometry/trapezium_lvs.stl" scale="    0.85     0.85     0.85" />
    <mesh name="metacarpal2_lvs" file="Geometry/metacarpal2_lvs.stl" scale="    0.85     0.85     0.85" />
    <mesh name="index_proximal_lvs" file="Geometry/index_proximal_lvs.stl" scale="    0.85     0.85     0.85" />
    <mesh name="index_medial_lvs" file="Geometry/index_medial_lvs.stl" scale="    0.85     0.85     0.85" />
    <mesh name="index_distal_lvs" file="Geometry/index_distal_lvs.stl" scale="    0.85     0.85     0.85" />
    <mesh name="metacarpal3_lvs" file="Geometry/metacarpal3_lvs.stl" scale="    0.85     0.85     0.85" />
    <mesh name="middle_proximal_lvs" file="Geometry/middle_proximal_lvs.stl" scale="    0.85     0.85     0.85" />
    <mesh name="middle_medial_lvs" file="Geometry/middle_medial_lvs.stl" scale="    0.85     0.85     0.85" />
    <mesh name="middle_distal_lvs" file="Geometry/middle_distal_lvs.stl" scale="    0.85     0.85     0.85" />
    <mesh name="metacarpal4_lvs" file="Geometry/metacarpal4_lvs.stl" scale="    0.85     0.85     0.85" />
    <mesh name="ring_proximal_lvs" file="Geometry/ring_proximal_lvs.stl" scale="    0.85     0.85     0.85" />
    <mesh name="ring_medial_lvs" file="Geometry/ring_medial_lvs.stl" scale="    0.85     0.85     0.85" />
    <mesh name="ring_distal_lvs" file="Geometry/ring_distal_lvs.stl" scale="    0.85     0.85     0.85" />
    <mesh name="metacarpal5_lvs" file="Geometry/metacarpal5_lvs.stl" scale="    0.85     0.85     0.85" />
    <mesh name="little_proximal_lvs" file="Geometry/little_proximal_lvs.stl" scale="    0.85     0.85     0.85" />
    <mesh name="little_medial_lvs" file="Geometry/little_medial_lvs.stl" scale="    0.85     0.85     0.85" />
    <mesh name="little_distal_lvs" file="Geometry/little_distal_lvs.stl" scale="    0.85     0.85     0.85" />
    <mesh name="metacarpal1_lvs" file="Geometry/metacarpal1_lvs.stl" scale="    0.85     0.85     0.85" />
    <mesh name="thumb_proximal_lvs" file="Geometry/thumb_proximal_lvs.stl" scale="    0.85     0.85     0.85" />
    <mesh name="thumb_distal_lvs" file="Geometry/thumb_distal_lvs.stl" scale="    0.85     0.85     0.85" />
    <texture name="texplane" type="2d" builtin="checker" rgb1=".2 .3 .4" rgb2=".1 0.15 0.2" width="100" height="100" />
    <material name="MatPlane" reflectance="0.0" texture="texplane" texrepeat="1 1" texuniform="true" />
  </asset>
  <tendon>
    <spatial name="addbrev_r_tendon">
      <site site="addbrev_r-P1" />
      <site site="addbrev_r-P2" />
    </spatial>
    <spatial name="addlong_r_tendon">
      <site site="addlong_r-P1" />
      <site site="addlong_r-P2" />
    </spatial>
    <spatial name="addmagDist_r_tendon">
      <site site="addmagDist_r-P1" />
      <site site="addmagDist_r-P2" />
    </spatial>
    <spatial name="addmagIsch_r_tendon">
      <site site="addmagIsch_r-P1" />
      <site site="addmagIsch_r-P2" />
    </spatial>
    <spatial name="addmagMid_r_tendon">
      <site site="addmagMid_r-P1" />
      <site site="addmagMid_r-P2" />
    </spatial>
    <spatial name="addmagProx_r_tendon">
      <site site="addmagProx_r-P1" />
      <site site="addmagProx_r-P2" />
    </spatial>
    <spatial name="bflh_r_tendon">
      <site site="bflh_r-P1" />
      <site site="bflh_r-P2" />
      <site site="bflh_r-P3" />
    </spatial>
    <spatial name="bfsh_r_tendon">
      <site site="bfsh_r-P1" />
      <site site="bfsh_r-P2" />
    </spatial>
    <spatial name="edl_r_tendon">
      <site site="edl_r-P1" />
      <site site="edl_r-P2" />
      <site site="edl_r-P3" />
      <site site="edl_r-P4" />
      <site site="edl_r-P5" />
      <site site="edl_r-P6" />
    </spatial>
    <spatial name="ehl_r_tendon">
      <site site="ehl_r-P1" />
      <site site="ehl_r-P2" />
      <site site="ehl_r-P3" />
      <site site="ehl_r-P4" />
      <site site="ehl_r-P5" />
      <site site="ehl_r-P6" />
      <site site="ehl_r-P7" />
      <site site="ehl_r-P8" />
    </spatial>
    <spatial name="fdl_r_tendon">
      <site site="fdl_r-P1" />
      <site site="fdl_r-P2" />
      <site site="fdl_r-P3" />
      <site site="fdl_r-P4" />
      <site site="fdl_r-P5" />
      <site site="fdl_r-P6" />
      <site site="fdl_r-P7" />
      <site site="fdl_r-P8" />
    </spatial>
    <spatial name="fhl_r_tendon">
      <site site="fhl_r-P1" />
      <site site="fhl_r-P2" />
      <site site="fhl_r-P3" />
      <site site="fhl_r-P4" />
      <site site="fhl_r-P5" />
      <site site="fhl_r-P6" />
      <site site="fhl_r-P7" />
    </spatial>
    <spatial name="gaslat_r_tendon">
      <site site="gaslat_r-P1" />
      <site site="gaslat_r-P2" />
    </spatial>
    <spatial name="gasmed_r_tendon">
      <site site="gasmed_r-P1" />
      <site site="gasmed_r-P2" />
    </spatial>
    <spatial name="glmax1_r_tendon">
      <site site="glmax1_r-P1" />
      <site site="glmax1_r-P2" />
      <site site="glmax1_r-P3" />
      <site site="glmax1_r-P4" />
    </spatial>
    <spatial name="glmax2_r_tendon">
      <site site="glmax2_r-P1" />
      <site site="glmax2_r-P2" />
      <site site="glmax2_r-P3" />
      <site site="glmax2_r-P4" />
    </spatial>
    <spatial name="glmax3_r_tendon">
      <site site="glmax3_r-P1" />
      <site site="glmax3_r-P2" />
      <site site="glmax3_r-P3" />
      <site site="glmax3_r-P4" />
    </spatial>
    <spatial name="glmed1_r_tendon">
      <site site="glmed1_r-P1" />
      <site site="glmed1_r-P2" />
    </spatial>
    <spatial name="glmed2_r_tendon">
      <site site="glmed2_r-P1" />
      <site site="glmed2_r-P2" />
    </spatial>
    <spatial name="glmed3_r_tendon">
      <site site="glmed3_r-P1" />
      <site site="glmed3_r-P2" />
    </spatial>
    <spatial name="glmin1_r_tendon">
      <site site="glmin1_r-P1" />
      <site site="glmin1_r-P2" />
    </spatial>
    <spatial name="glmin2_r_tendon">
      <site site="glmin2_r-P1" />
      <site site="glmin2_r-P2" />
    </spatial>
    <spatial name="glmin3_r_tendon">
      <site site="glmin3_r-P1" />
      <site site="glmin3_r-P2" />
    </spatial>
    <spatial name="grac_r_tendon">
      <site site="grac_r-P1" />
      <site site="grac_r-P2" />
      <site site="grac_r-P3" />
    </spatial>
    <spatial name="iliacus_r_tendon">
      <site site="iliacus_r-P1" />
      <site site="iliacus_r-P2" />
      <site site="iliacus_r-P3" />
      <site site="iliacus_r-P4" />
    </spatial>
    <spatial name="perbrev_r_tendon">
      <site site="perbrev_r-P1" />
      <site site="perbrev_r-P2" />
      <site site="perbrev_r-P3" />
      <site site="perbrev_r-P4" />
      <site site="perbrev_r-P5" />
    </spatial>
    <spatial name="perlong_r_tendon">
      <site site="perlong_r-P1" />
      <site site="perlong_r-P2" />
      <site site="perlong_r-P3" />
      <site site="perlong_r-P4" />
      <site site="perlong_r-P5" />
      <site site="perlong_r-P6" />
      <site site="perlong_r-P7" />
    </spatial>
    <spatial name="piri_r_tendon">
      <site site="piri_r-P1" />
      <site site="piri_r-P2" />
      <site site="piri_r-P3" />
    </spatial>
    <spatial name="psoas_r_tendon">
      <site site="psoas_r-P1" />
      <site site="psoas_r-P2" />
      <site site="psoas_r-P3" />
      <site site="psoas_r-P4" />
    </spatial>
    <spatial name="recfem_r_tendon">
      <site site="recfem_r-P1" />
      <site site="recfem_r-P2" />
      <site site="recfem_r-P3" />
      <site site="recfem_r-P4" />
      <site site="recfem_r-P5" />
    </spatial>
    <spatial name="sart_r_tendon">
      <site site="sart_r-P1" />
      <site site="sart_r-P2" />
      <site site="sart_r-P3" />
      <site site="sart_r-P4" />
      <site site="sart_r-P5" />
    </spatial>
    <spatial name="semimem_r_tendon">
      <site site="semimem_r-P1" />
      <site site="semimem_r-P2" />
    </spatial>
    <spatial name="semiten_r_tendon">
      <site site="semiten_r-P1" />
      <site site="semiten_r-P2" />
      <site site="semiten_r-P3" />
    </spatial>
    <spatial name="soleus_r_tendon">
      <site site="soleus_r-P1" />
      <site site="soleus_r-P2" />
    </spatial>
    <spatial name="tfl_r_tendon">
      <site site="tfl_r-P1" />
      <site site="tfl_r-P2" />
      <site site="tfl_r-P3" />
      <site site="tfl_r-P4" />
    </spatial>
    <spatial name="tibant_r_tendon">
      <site site="tibant_r-P1" />
      <site site="tibant_r-P2" />
      <site site="tibant_r-P3" />
      <site site="tibant_r-P4" />
    </spatial>
    <spatial name="tibpost_r_tendon">
      <site site="tibpost_r-P1" />
      <site site="tibpost_r-P2" />
      <site site="tibpost_r-P3" />
      <site site="tibpost_r-P4" />
    </spatial>
    <spatial name="vasint_r_tendon">
      <site site="vasint_r-P1" />
      <site site="vasint_r-P2" />
      <site site="vasint_r-P3" />
      <site site="vasint_r-P4" />
      <site site="vasint_r-P5" />
    </spatial>
    <spatial name="vaslat_r_tendon">
      <site site="vaslat_r-P1" />
      <site site="vaslat_r-P2" />
      <site site="vaslat_r-P3" />
      <site site="vaslat_r-P4" />
      <site site="vaslat_r-P5" />
    </spatial>
    <spatial name="vasmed_r_tendon">
      <site site="vasmed_r-P1" />
      <site site="vasmed_r-P2" />
      <site site="vasmed_r-P3" />
      <site site="vasmed_r-P4" />
      <site site="vasmed_r-P5" />
    </spatial>
    <spatial name="addbrev_l_tendon">
      <site site="addbrev_l-P1" />
      <site site="addbrev_l-P2" />
    </spatial>
    <spatial name="addlong_l_tendon">
      <site site="addlong_l-P1" />
      <site site="addlong_l-P2" />
    </spatial>
    <spatial name="addmagDist_l_tendon">
      <site site="addmagDist_l-P1" />
      <site site="addmagDist_l-P2" />
    </spatial>
    <spatial name="addmagIsch_l_tendon">
      <site site="addmagIsch_l-P1" />
      <site site="addmagIsch_l-P2" />
    </spatial>
    <spatial name="addmagMid_l_tendon">
      <site site="addmagMid_l-P1" />
      <site site="addmagMid_l-P2" />
    </spatial>
    <spatial name="addmagProx_l_tendon">
      <site site="addmagProx_l-P1" />
      <site site="addmagProx_l-P2" />
    </spatial>
    <spatial name="bflh_l_tendon">
      <site site="bflh_l-P1" />
      <site site="bflh_l-P2" />
      <site site="bflh_l-P3" />
    </spatial>
    <spatial name="bfsh_l_tendon">
      <site site="bfsh_l-P1" />
      <site site="bfsh_l-P2" />
    </spatial>
    <spatial name="edl_l_tendon">
      <site site="edl_l-P1" />
      <site site="edl_l-P2" />
      <site site="edl_l-P3" />
      <site site="edl_l-P4" />
      <site site="edl_l-P5" />
      <site site="edl_l-P6" />
    </spatial>
    <spatial name="ehl_l_tendon">
      <site site="ehl_l-P1" />
      <site site="ehl_l-P2" />
      <site site="ehl_l-P3" />
      <site site="ehl_l-P4" />
      <site site="ehl_l-P5" />
      <site site="ehl_l-P6" />
      <site site="ehl_l-P7" />
      <site site="ehl_l-P8" />
    </spatial>
    <spatial name="fdl_l_tendon">
      <site site="fdl_l-P1" />
      <site site="fdl_l-P2" />
      <site site="fdl_l-P3" />
      <site site="fdl_l-P4" />
      <site site="fdl_l-P5" />
      <site site="fdl_l-P6" />
      <site site="fdl_l-P7" />
      <site site="fdl_l-P8" />
    </spatial>
    <spatial name="fhl_l_tendon">
      <site site="fhl_l-P1" />
      <site site="fhl_l-P2" />
      <site site="fhl_l-P3" />
      <site site="fhl_l-P4" />
      <site site="fhl_l-P5" />
      <site site="fhl_l-P6" />
      <site site="fhl_l-P7" />
    </spatial>
    <spatial name="gaslat_l_tendon">
      <site site="gaslat_l-P1" />
      <site site="gaslat_l-P2" />
    </spatial>
    <spatial name="gasmed_l_tendon">
      <site site="gasmed_l-P1" />
      <site site="gasmed_l-P2" />
    </spatial>
    <spatial name="glmax1_l_tendon">
      <site site="glmax1_l-P1" />
      <site site="glmax1_l-P2" />
      <site site="glmax1_l-P3" />
      <site site="glmax1_l-P4" />
    </spatial>
    <spatial name="glmax2_l_tendon">
      <site site="glmax2_l-P1" />
      <site site="glmax2_l-P2" />
      <site site="glmax2_l-P3" />
      <site site="glmax2_l-P4" />
    </spatial>
    <spatial name="glmax3_l_tendon">
      <site site="glmax3_l-P1" />
      <site site="glmax3_l-P2" />
      <site site="glmax3_l-P3" />
      <site site="glmax3_l-P4" />
    </spatial>
    <spatial name="glmed1_l_tendon">
      <site site="glmed1_l-P1" />
      <site site="glmed1_l-P2" />
    </spatial>
    <spatial name="glmed2_l_tendon">
      <site site="glmed2_l-P1" />
      <site site="glmed2_l-P2" />
    </spatial>
    <spatial name="glmed3_l_tendon">
      <site site="glmed3_l-P1" />
      <site site="glmed3_l-P2" />
    </spatial>
    <spatial name="glmin1_l_tendon">
      <site site="glmin1_l-P1" />
      <site site="glmin1_l-P2" />
    </spatial>
    <spatial name="glmin2_l_tendon">
      <site site="glmin2_l-P1" />
      <site site="glmin2_l-P2" />
    </spatial>
    <spatial name="glmin3_l_tendon">
      <site site="glmin3_l-P1" />
      <site site="glmin3_l-P2" />
    </spatial>
    <spatial name="grac_l_tendon">
      <site site="grac_l-P1" />
      <site site="grac_l-P2" />
      <site site="grac_l-P3" />
    </spatial>
    <spatial name="iliacus_l_tendon">
      <site site="iliacus_l-P1" />
      <site site="iliacus_l-P2" />
      <site site="iliacus_l-P3" />
      <site site="iliacus_l-P4" />
    </spatial>
    <spatial name="perbrev_l_tendon">
      <site site="perbrev_l-P1" />
      <site site="perbrev_l-P2" />
      <site site="perbrev_l-P3" />
      <site site="perbrev_l-P4" />
      <site site="perbrev_l-P5" />
    </spatial>
    <spatial name="perlong_l_tendon">
      <site site="perlong_l-P1" />
      <site site="perlong_l-P2" />
      <site site="perlong_l-P3" />
      <site site="perlong_l-P4" />
      <site site="perlong_l-P5" />
      <site site="perlong_l-P6" />
      <site site="perlong_l-P7" />
    </spatial>
    <spatial name="piri_l_tendon">
      <site site="piri_l-P1" />
      <site site="piri_l-P2" />
      <site site="piri_l-P3" />
    </spatial>
    <spatial name="psoas_l_tendon">
      <site site="psoas_l-P1" />
      <site site="psoas_l-P2" />
      <site site="psoas_l-P3" />
      <site site="psoas_l-P4" />
    </spatial>
    <spatial name="recfem_l_tendon">
      <site site="recfem_l-P1" />
      <site site="recfem_l-P2" />
      <site site="recfem_l-P3" />
      <site site="recfem_l-P4" />
      <site site="recfem_l-P5" />
    </spatial>
    <spatial name="sart_l_tendon">
      <site site="sart_l-P1" />
      <site site="sart_l-P2" />
      <site site="sart_l-P3" />
      <site site="sart_l-P4" />
      <site site="sart_l-P5" />
    </spatial>
    <spatial name="semimem_l_tendon">
      <site site="semimem_l-P1" />
      <site site="semimem_l-P2" />
    </spatial>
    <spatial name="semiten_l_tendon">
      <site site="semiten_l-P1" />
      <site site="semiten_l-P2" />
      <site site="semiten_l-P3" />
    </spatial>
    <spatial name="soleus_l_tendon">
      <site site="soleus_l-P1" />
      <site site="soleus_l-P2" />
    </spatial>
    <spatial name="tfl_l_tendon">
      <site site="tfl_l-P1" />
      <site site="tfl_l-P2" />
      <site site="tfl_l-P3" />
      <site site="tfl_l-P4" />
    </spatial>
    <spatial name="tibant_l_tendon">
      <site site="tibant_l-P1" />
      <site site="tibant_l-P2" />
      <site site="tibant_l-P3" />
      <site site="tibant_l-P4" />
    </spatial>
    <spatial name="tibpost_l_tendon">
      <site site="tibpost_l-P1" />
      <site site="tibpost_l-P2" />
      <site site="tibpost_l-P3" />
      <site site="tibpost_l-P4" />
    </spatial>
    <spatial name="vasint_l_tendon">
      <site site="vasint_l-P1" />
      <site site="vasint_l-P2" />
      <site site="vasint_l-P3" />
      <site site="vasint_l-P4" />
      <site site="vasint_l-P5" />
    </spatial>
    <spatial name="vaslat_l_tendon">
      <site site="vaslat_l-P1" />
      <site site="vaslat_l-P2" />
      <site site="vaslat_l-P3" />
      <site site="vaslat_l-P4" />
      <site site="vaslat_l-P5" />
    </spatial>
    <spatial name="vasmed_l_tendon">
      <site site="vasmed_l-P1" />
      <site site="vasmed_l-P2" />
      <site site="vasmed_l-P3" />
      <site site="vasmed_l-P4" />
      <site site="vasmed_l-P5" />
    </spatial>
  </tendon>
  <actuator>
    <general name="lumbar_ext" joint="lumbar_extension" class="motor" />
    <general name="lumbar_bend" joint="lumbar_bending" class="motor" />
    <general name="lumbar_rot" joint="lumbar_rotation" class="motor" />
    <general name="shoulder_flex_r" joint="arm_flex_r" class="motor" />
    <general name="shoulder_add_r" joint="arm_add_r" class="motor" />
    <general name="shoulder_rot_r" joint="arm_rot_r" class="motor" />
    <general name="elbow_flex_r" joint="elbow_flex_r" class="motor" />
    <general name="pro_sup_r" joint="pro_sup_r" class="motor" />
    <general name="wrist_flex_r" joint="wrist_flex_r" class="motor" />
    <general name="wrist_dev_r" joint="wrist_dev_r" class="motor" />
    <general name="shoulder_flex_l" joint="arm_flex_l" class="motor" />
    <general name="shoulder_add_l" joint="arm_add_l" class="motor" />
    <general name="shoulder_rot_l" joint="arm_rot_l" class="motor" />
    <general name="elbow_flex_l" joint="elbow_flex_l" class="motor" />
    <general name="pro_sup_l" joint="pro_sup_l" class="motor" />
    <general name="wrist_flex_l" joint="wrist_flex_l" class="motor" />
    <general name="wrist_dev_l" joint="wrist_dev_l" class="motor" />
    <muscle name="addbrev_r" tendon="addbrev_r_tendon" class="muscle" force="625.819672131148" lengthrange="0.0784162 0.171093" />
    <muscle name="addlong_r" tendon="addlong_r_tendon" class="muscle" force="916.8" lengthrange=" 0.16437 0.259394" />
    <muscle name="addmagDist_r" tendon="addmagDist_r_tendon" class="muscle" force="597.295081967214" lengthrange="0.141939 0.283508" />
    <muscle name="addmagIsch_r" tendon="addmagIsch_r_tendon" class="muscle" force="597.295081967214" lengthrange="0.244427 0.372747" />
    <muscle name="addmagMid_r" tendon="addmagMid_r_tendon" class="muscle" force="597.295081967214" lengthrange="0.0924285 0.201679" />
    <muscle name="addmagProx_r" tendon="addmagProx_r_tendon" class="muscle" force="597.295081967214" lengthrange="0.0825732 0.174203" />
    <muscle name="bflh_r" tendon="bflh_r_tendon" class="muscle" force="1313.18360655738" lengthrange="0.320187 0.402614" />
    <muscle name="bfsh_r" tendon="bfsh_r_tendon" class="muscle" force="557.11475409836" lengthrange="0.142268 0.237503" />
    <muscle name="edl_r" tendon="edl_r_tendon" class="muscle" force="603.4981556" lengthrange="0.361259 0.421953" />
    <muscle name="ehl_r" tendon="ehl_r_tendon" class="muscle" force="285.8675474" lengthrange="0.323223  0.38845" />
    <muscle name="fdl_r" tendon="fdl_r_tendon" class="muscle" force="423.177049180328" lengthrange="0.351535 0.389696" />
    <muscle name="fhl_r" tendon="fhl_r_tendon" class="muscle" force="907.839344262294" lengthrange="0.330223 0.374525" />
    <muscle name="gaslat_r" tendon="gaslat_r_tendon" class="muscle" force="1575.05901639344" lengthrange="0.384502 0.439121" />
    <muscle name="gasmed_r" tendon="gasmed_r_tendon" class="muscle" force="3115.51475409836" lengthrange=" 0.40199 0.449695" />
    <muscle name="glmax1_r" tendon="glmax1_r_tendon" class="muscle" force="983.783606557378" lengthrange="0.131785 0.286061" />
    <muscle name="glmax2_r" tendon="glmax2_r_tendon" class="muscle" force="1406.04590163935" lengthrange=" 0.15172 0.309218" />
    <muscle name="glmax3_r" tendon="glmax3_r_tendon" class="muscle" force="947.754098360656" lengthrange="0.150698 0.309332" />
    <muscle name="glmed1_r" tendon="glmed1_r_tendon" class="muscle" force="1093.4667688" lengthrange=" 0.10633 0.187834" />
    <muscle name="glmed2_r" tendon="glmed2_r_tendon" class="muscle" force="765.0916616" lengthrange="0.115187 0.195147" />
    <muscle name="glmed3_r" tendon="glmed3_r_tendon" class="muscle" force="871.1992642" lengthrange="0.0886464 0.165595" />
    <muscle name="glmin1_r" tendon="glmin1_r_tendon" class="muscle" force="374.045901639344" lengthrange="0.0564342 0.132596" />
    <muscle name="glmin2_r" tendon="glmin2_r_tendon" class="muscle" force="394.819672131148" lengthrange="0.0608285 0.123794" />
    <muscle name="glmin3_r" tendon="glmin3_r_tendon" class="muscle" force="446.773770491804" lengthrange="0.0768268 0.118604" />
    <muscle name="grac_r" tendon="grac_r_tendon" class="muscle" force="281.311475409836" lengthrange="0.243172 0.435188" />
    <muscle name="iliacus_r" tendon="iliacus_r_tendon" class="muscle" force="1021.14098360656" lengthrange="0.167502 0.283968" />
    <muscle name="perbrev_r" tendon="perbrev_r_tendon" class="muscle" force="521.2015988" lengthrange="0.157456 0.198683" />
    <muscle name="perlong_r" tendon="perlong_r_tendon" class="muscle" force="1115.3714214" lengthrange="0.324382 0.369148" />
    <muscle name="piri_r" tendon="piri_r_tendon" class="muscle" force="1029.7868852459" lengthrange="0.135865 0.163106" />
    <muscle name="psoas_r" tendon="psoas_r_tendon" class="muscle" force="1426.79016393443" lengthrange="0.178865 0.309262" />
    <muscle name="recfem_r" tendon="recfem_r_tendon" class="muscle" force="2191.74098360656" lengthrange="0.444144 0.511942" />
    <muscle name="sart_r" tendon="sart_r_tendon" class="muscle" force="249.413114754098" lengthrange="0.304108 0.680574" />
    <muscle name="semimem_r" tendon="semimem_r_tendon" class="muscle" force="2200.9868852459" lengthrange="0.327301 0.384669" />
    <muscle name="semiten_r" tendon="semiten_r_tendon" class="muscle" force="591.295081967214" lengthrange="0.293751 0.455239" />
    <muscle name="soleus_r" tendon="soleus_r_tendon" class="muscle" force="6194.84262295082" lengthrange="0.282057 0.320817" />
    <muscle name="tfl_r" tendon="tfl_r_tendon" class="muscle" force="411.20655737705" lengthrange="0.472045 0.562164" />
    <muscle name="tibant_r" tendon="tibant_r_tendon" class="muscle" force="1227.45245901639" lengthrange="0.254374 0.316586" />
    <muscle name="tibpost_r" tendon="tibpost_r_tendon" class="muscle" force="1730.15409836065" lengthrange="0.279057 0.313412" />
    <muscle name="vasint_r" tendon="vasint_r_tendon" class="muscle" force="1697.36065573771" lengthrange="0.225241 0.313904" />
    <muscle name="vaslat_r" tendon="vaslat_r_tendon" class="muscle" force="5148.76721311476" lengthrange="0.240351  0.32643" />
    <muscle name="vasmed_r" tendon="vasmed_r_tendon" class="muscle" force="2747.82295081966" lengthrange="0.219029 0.298274" />
    <muscle name="addbrev_l" tendon="addbrev_l_tendon" class="muscle" force="625.819672131148" lengthrange="0.0794258 0.173296" />
    <muscle name="addlong_l" tendon="addlong_l_tendon" class="muscle" force="916.8" lengthrange="0.167228 0.263906" />
    <muscle name="addmagDist_l" tendon="addmagDist_l_tendon" class="muscle" force="597.295081967214" lengthrange="0.145313 0.290247" />
    <muscle name="addmagIsch_l" tendon="addmagIsch_l_tendon" class="muscle" force="597.295081967214" lengthrange=" 0.25004 0.381307" />
    <muscle name="addmagMid_l" tendon="addmagMid_l_tendon" class="muscle" force="597.295081967214" lengthrange="0.0943932 0.205965" />
    <muscle name="addmagProx_l" tendon="addmagProx_l_tendon" class="muscle" force="597.295081967214" lengthrange="0.0833782 0.175901" />
    <muscle name="bflh_l" tendon="bflh_l_tendon" class="muscle" force="1313.18360655738" lengthrange="0.326195 0.410168" />
    <muscle name="bfsh_l" tendon="bfsh_l_tendon" class="muscle" force="557.11475409836" lengthrange="0.144382 0.241033" />
    <muscle name="edl_l" tendon="edl_l_tendon" class="muscle" force="603.4981556" lengthrange="0.360704 0.421304" />
    <muscle name="ehl_l" tendon="ehl_l_tendon" class="muscle" force="285.8675474" lengthrange="0.322811 0.387955" />
    <muscle name="fdl_l" tendon="fdl_l_tendon" class="muscle" force="423.177049180328" lengthrange="0.351249 0.389379" />
    <muscle name="fhl_l" tendon="fhl_l_tendon" class="muscle" force="907.839344262294" lengthrange="0.330054 0.374333" />
    <muscle name="gaslat_l" tendon="gaslat_l_tendon" class="muscle" force="1575.05901639344" lengthrange="0.383645 0.438142" />
    <muscle name="gasmed_l" tendon="gasmed_l_tendon" class="muscle" force="3115.51475409836" lengthrange="0.401283 0.448905" />
    <muscle name="glmax1_l" tendon="glmax1_l_tendon" class="muscle" force="983.783606557378" lengthrange="0.132314 0.287209" />
    <muscle name="glmax2_l" tendon="glmax2_l_tendon" class="muscle" force="1406.04590163935" lengthrange="0.152516 0.310839" />
    <muscle name="glmax3_l" tendon="glmax3_l_tendon" class="muscle" force="947.754098360656" lengthrange="0.151685 0.311359" />
    <muscle name="glmed1_l" tendon="glmed1_l_tendon" class="muscle" force="1093.4667688" lengthrange="0.106596 0.188305" />
    <muscle name="glmed2_l" tendon="glmed2_l_tendon" class="muscle" force="765.0916616" lengthrange="0.115478 0.195641" />
    <muscle name="glmed3_l" tendon="glmed3_l_tendon" class="muscle" force="871.1992642" lengthrange="0.0889055 0.166079" />
    <muscle name="glmin1_l" tendon="glmin1_l_tendon" class="muscle" force="374.045901639344" lengthrange="0.0567013 0.133223" />
    <muscle name="glmin2_l" tendon="glmin2_l_tendon" class="muscle" force="394.819672131148" lengthrange="0.0611424 0.124433" />
    <muscle name="glmin3_l" tendon="glmin3_l_tendon" class="muscle" force="446.773770491804" lengthrange="0.0772393 0.119241" />
    <muscle name="grac_l" tendon="grac_l_tendon" class="muscle" force="281.311475409836" lengthrange="0.247447 0.442838" />
    <muscle name="iliacus_l" tendon="iliacus_l_tendon" class="muscle" force="1021.14098360656" lengthrange="0.168019 0.284844" />
    <muscle name="perbrev_l" tendon="perbrev_l_tendon" class="muscle" force="521.2015988" lengthrange="0.157044 0.198164" />
    <muscle name="perlong_l" tendon="perlong_l_tendon" class="muscle" force="1115.3714214" lengthrange="0.323749 0.368428" />
    <muscle name="piri_l" tendon="piri_l_tendon" class="muscle" force="1029.7868852459" lengthrange="0.136195 0.163501" />
    <muscle name="psoas_l" tendon="psoas_l_tendon" class="muscle" force="1426.79016393443" lengthrange="0.179426 0.310233" />
    <muscle name="recfem_l" tendon="recfem_l_tendon" class="muscle" force="2191.74098360656" lengthrange=" 0.45076 0.519569" />
    <muscle name="sart_l" tendon="sart_l_tendon" class="muscle" force="249.413114754098" lengthrange=" 0.30775 0.688725" />
    <muscle name="semimem_l" tendon="semimem_l_tendon" class="muscle" force="2200.9868852459" lengthrange="0.333553 0.392017" />
    <muscle name="semiten_l" tendon="semiten_l_tendon" class="muscle" force="591.295081967214" lengthrange="0.298689  0.46289" />
    <muscle name="soleus_l" tendon="soleus_l_tendon" class="muscle" force="6194.84262295082" lengthrange="0.281157 0.319793" />
    <muscle name="tfl_l" tendon="tfl_l_tendon" class="muscle" force="411.20655737705" lengthrange="0.478179 0.569469" />
    <muscle name="tibant_l" tendon="tibant_l_tendon" class="muscle" force="1227.45245901639" lengthrange="0.253713 0.315764" />
    <muscle name="tibpost_l" tendon="tibpost_l_tendon" class="muscle" force="1730.15409836065" lengthrange="0.278308 0.312571" />
    <muscle name="vasint_l" tendon="vasint_l_tendon" class="muscle" force="1697.36065573771" lengthrange=" 0.22859  0.31857" />
    <muscle name="vaslat_l" tendon="vaslat_l_tendon" class="muscle" force="5148.76721311476" lengthrange="0.243955 0.331324" />
    <muscle name="vasmed_l" tendon="vasmed_l_tendon" class="muscle" force="2747.82295081966" lengthrange="0.222154  0.30253" />
  </actuator>
  <equality>
    <joint name="knee_angle_r_translation2_constraint" active="true" joint1="knee_angle_r_translation2" joint2="knee_angle_r" polycoef="7.69254e-11 0.00587971 -0.00125622 -2.61846e-06 6.24355e-07" solimp="0.9999 0.9999 0.001 0.5 2" />
    <joint name="knee_angle_r_translation1_constraint" active="true" joint1="knee_angle_r_translation1" joint2="knee_angle_r" polycoef="9.53733e-08 0.00312879 -0.00230804 0.000561561 5.68366e-07" solimp="0.9999 0.9999 0.001 0.5 2" />
    <joint name="knee_angle_r_rotation2_constraint" active="true" joint1="knee_angle_r_rotation2" joint2="knee_angle_r" polycoef="-1.47325e-08   0.0791 -0.0328478 -0.0252183 0.0108321" solimp="0.9999 0.9999 0.001 0.5 2" />
    <joint name="knee_angle_r_rotation3_constraint" active="true" joint1="knee_angle_r_rotation3" joint2="knee_angle_r" polycoef="1.08939e-08 0.369499 -0.169478 0.0251643 3.50498e-07" solimp="0.9999 0.9999 0.001 0.5 2" />
    <joint name="knee_angle_r_beta_translation2_constraint" active="true" joint1="knee_angle_r_beta_translation2" joint2="knee_angle_r" polycoef="-0.0108281 -0.0487847 0.00927644 0.0131673 -0.00349673" solimp="0.9999 0.9999 0.001 0.5 2" />
    <joint name="knee_angle_r_beta_translation1_constraint" active="true" joint1="knee_angle_r_beta_translation1" joint2="knee_angle_r" polycoef="0.0524192 -0.0150188 -0.0340522 0.0133393 -0.000879151" solimp="0.9999 0.9999 0.001 0.5 2" />
    <joint name="knee_angle_r_beta_rotation1_constraint" active="true" joint1="knee_angle_r_beta_rotation1" joint2="knee_angle_r" polycoef="0.010506 0.0247615 -1.31647 0.716337 -0.138302" solimp="0.9999 0.9999 0.001 0.5 2" />
    <joint name="subtalar_angle_r_constraint" active="true" joint1="subtalar_angle_r" polycoef="       0        0        0        0        0" />
    <joint name="mtp_angle_r_constraint" active="true" joint1="mtp_angle_r" polycoef="       0        0        0        0        0" />
    <joint name="knee_angle_l_translation2_constraint" active="true" joint1="knee_angle_l_translation2" joint2="knee_angle_l" polycoef="-7.69254e-11 -0.00587971 0.00125622 2.61846e-06 -6.24355e-07" solimp="0.9999 0.9999 0.001 0.5 2" />
    <joint name="knee_angle_l_translation1_constraint" active="true" joint1="knee_angle_l_translation1" joint2="knee_angle_l" polycoef="9.53733e-08 0.00312879 -0.00230804 0.000561561 5.68366e-07" solimp="0.9999 0.9999 0.001 0.5 2" />
    <joint name="knee_angle_l_rotation2_constraint" active="true" joint1="knee_angle_l_rotation2" joint2="knee_angle_l" polycoef="-1.47325e-08   0.0791 -0.0328478 -0.0252183 0.0108321" solimp="0.9999 0.9999 0.001 0.5 2" />
    <joint name="knee_angle_l_rotation3_constraint" active="true" joint1="knee_angle_l_rotation3" joint2="knee_angle_l" polycoef="-1.08939e-08 -0.369499 0.169478 -0.0251643 -3.50498e-07" solimp="0.9999 0.9999 0.001 0.5 2" />
    <joint name="knee_angle_l_beta_translation2_constraint" active="true" joint1="knee_angle_l_beta_translation2" joint2="knee_angle_l" polycoef="-0.0108281 -0.0487847 0.00927644 0.0131673 -0.00349673" solimp="0.9999 0.9999 0.001 0.5 2" />
    <joint name="knee_angle_l_beta_translation1_constraint" active="true" joint1="knee_angle_l_beta_translation1" joint2="knee_angle_l" polycoef="0.0524192 -0.0150188 -0.0340522 0.0133393 -0.000879151" solimp="0.9999 0.9999 0.001 0.5 2" />
    <joint name="knee_angle_l_beta_rotation1_constraint" active="true" joint1="knee_angle_l_beta_rotation1" joint2="knee_angle_l" polycoef="0.010506 0.0247615 -1.31647 0.716337 -0.138302" solimp="0.9999 0.9999 0.001 0.5 2" />
    <joint name="subtalar_angle_l_constraint" active="true" joint1="subtalar_angle_l" polycoef="       0        0        0        0        0" />
    <joint name="mtp_angle_l_constraint" active="true" joint1="mtp_angle_l" polycoef="       0        0        0        0        0" />
    <joint name="wrist_flex_r_constraint" active="true" joint1="wrist_flex_r" polycoef="       0        0        0        0        0" />
    <joint name="wrist_dev_r_constraint" active="true" joint1="wrist_dev_r" polycoef="       0        0        0        0        0" />
    <joint name="wrist_flex_l_constraint" active="true" joint1="wrist_flex_l" polycoef="       0        0        0        0        0" />
    <joint name="wrist_dev_l_constraint" active="true" joint1="wrist_dev_l" polycoef="       0        0        0        0        0" />
    <weld name="origin_to_worldbody" body1="pelvis" active="false" />
  </equality>
</mujoco>